Workbook
Name NAV_MKT: [1]LS!$T$1
Name NAV_MKT: [2]LS!$T$1
Name NAV_MKT: LS!$T$1
Name NEW_TCV: [3]Portfolio!$F$38
Name NEW_TMV: [3]Portfolio!$H$38
Name TCV_STOCKS: #REF!
Name TCV_STOCKS: #REF!
Name TCV_STOCKS: #REF!
Name TMV_STOCKS: #REF!
Name TMV_STOCKS: #REF!
Name TMV_STOCKS: #REF!

Sheet DASHBOARD
A1: =LS!Q1+SIP!P1 -> 208573040 | C1: =LS!R1+SIP!Q1 -> 7244346.2
A4: 208565050 | B4: =A1-A4 -> 7990
A5: 7242336.2 | B5: =C1-A5 -> 2010

Sheet INVESTORS
A1: INVESTOR NAME | B1: INVESTOR CODE | C1: TITLE | D1: TYPE OF INVESTOR | E1: LS_TOTAL UNITS BUY | F1: LS_TOTAL UNITS SOLD | G1: LS_TOTAL CURRENT UNITS | H1: LS_TOTAL COST VALUE | I1: LS_TOTAL COST OF UNITS SOLD | J1: LS_TOTAL COST VALUE OF CURRENT UNITS | K1: LS_TOTAL REALIZED GAIN | L1: SIP_TOTAL UNITS BUY | M1: SIP_TOTAL UNITS SOLD | N1: SIP_TOTAL CURRENT UNITS | O1: SIP_TOTAL COST VALUE | P1: SIP_TOTAL COST OF UNITS SOLD | Q1: SIP_TOTAL COST VALUE OF CURRENT UNITS | R1: SIP_TOTAL REALIZED GAIN | S1: TOTAL UNITS BUY | T1: TOTAL UNITS SOLD | U1: BO OPENING BALANCE | V1: LS- BO UNITS SELL | W1: LS- BO UNITS REPURCHASE | X1: SIP- BO UNITS SELL | Y1: SIP- BO UNITS REPURCHASE | Z1: BO UNITS HOLD | AA1: TOTAL CURRENT UNITS | AB1: Column1 | AC1: BO | AD1: TOTAL COST VALUE OF CURRENT INVESTMENT | AE1: LS_WEIGHT | AF1: SIP_WEIGHT | AG1: LS_AVERAGE COST | AH1: SIP_AVERAGE COST | AI1: AVERAGE COST | AJ1: NAV | AK1: TOTAL MARKET VALUE | AL1: LS_TOTAL MARKET VALUE | AM1: SIP_TOTAL MARKET VALUE | AN1: TOTAL SELLABLE UNITS | AO1: MARKET VALUE OF SELLABLE UNITS | AP1: TOTAL REALIZED GAIN | AQ1: TOTAL UNREALIZED GAIN | AR1: TOTAL TAXES | AS1: TOTAL GROSS DIVIDEND | AT1: % of Unit Holding
A2: HARI PADA SAHA | B2: A00002 | C2: Dear Mr. | D2: Individual | E2: =SUMIFS(LS[Unit],LS[Investor ID],INVESTORS_LIST[[#This Row],[INVESTOR CODE]],LS[B/S],"B") -> 74187 | F2: =-SUMIFS(LS[Unit],LS[Investor ID],INVESTORS_LIST[[#This Row],[INVESTOR CODE]],LS[B/S],"S") -> 1 | G2: =IF(INVESTORS_LIST[[#This Row],[LS_TOTAL UNITS BUY]]=0,0,INVESTORS_LIST[[#This Row],[LS_TOTAL UNITS BUY]]-INVESTORS_LIST[[#This Row],[LS_TOTAL UNITS SOLD]]) -> 74186 | H2: =IF(INVESTORS_LIST[[#This Row],[LS_TOTAL UNITS BUY]]=0,0,SUMIFS(LS[Amount],LS[Investor ID],INVESTORS_LIST[[#This Row],[INVESTOR CODE]],LS[B/S],"B")) -> 753785.59 | I2: =IF(INVESTORS_LIST[[#This Row],[LS_TOTAL UNITS SOLD]]=0,0,SUMIFS(LS[Cost of Units Sold],LS[Investor ID],INVESTORS_LIST[[#This Row],[INVESTOR CODE]],LS[B/S],"S")) -> 10.061726 | J2: =IF(INVESTORS_LIST[[#This Row],[LS_TOTAL CURRENT UNITS]]=0,0,INVESTORS_LIST[[#This Row],[LS_TOTAL CURRENT UNITS]]*INVESTORS_LIST[[#This Row],[LS_AVERAGE COST]]) -> 753775.53 | K2: =IF(INVESTORS_LIST[[#This Row],[LS_TOTAL UNITS SOLD]]=0,0,SUMIFS(LS[Realized Gain],LS[Investor ID],INVESTORS_LIST[[#This Row],[INVESTOR CODE]],LS[B/S],"S")) -> -6.7117258 | L2: =SUMIFS(SIP[Unit],SIP[Investor ID],INVESTORS_LIST[[#This Row],[INVESTOR CODE]],SIP[B/S],"B") -> 0 | M2: =-SUMIFS(SIP[Unit],SIP[Investor ID],INVESTORS_LIST[[#This Row],[INVESTOR CODE]],SIP[B/S],"S") -> 0 | N2: =IF(INVESTORS_LIST[[#This Row],[SIP_TOTAL UNITS BUY]]=0,0,INVESTORS_LIST[[#This Row],[SIP_TOTAL UNITS BUY]]-INVESTORS_LIST[[#This Row],[SIP_TOTAL UNITS SOLD]]) -> 0 | O2: =IF(INVESTORS_LIST[[#This Row],[SIP_TOTAL UNITS BUY]]=0,0,SUMIFS(SIP[Amount],SIP[Investor ID],INVESTORS_LIST[[#This Row],[INVESTOR CODE]],SIP[B/S],"B")) -> 0 | P2: =IF(INVESTORS_LIST[[#This Row],[SIP_TOTAL UNITS SOLD]]=0,0,SUMIFS(SIP[Cost of Units Sold],SIP[Investor ID],INVESTORS_LIST[[#This Row],[INVESTOR CODE]],SIP[B/S],"S")) -> 0 | Q2: =IF(INVESTORS_LIST[[#This Row],[SIP_TOTAL CURRENT UNITS]]=0,0,INVESTORS_LIST[[#This Row],[SIP_TOTAL CURRENT UNITS]]*INVESTORS_LIST[[#This Row],[SIP_AVERAGE COST]]) -> 0 | R2: =IF(INVESTORS_LIST[[#This Row],[SIP_TOTAL UNITS SOLD]]=0,0,SUMIFS(SIP[Realized Gain],SIP[Investor ID],INVESTORS_LIST[[#This Row],[INVESTOR CODE]],SIP[B/S],"S")) -> 0 | S2: =INVESTORS_LIST[[#This Row],[LS_TOTAL UNITS BUY]]+INVESTORS_LIST[[#This Row],[SIP_TOTAL UNITS BUY]] -> 74187 | T2: =INVESTORS_LIST[[#This Row],[LS_TOTAL UNITS SOLD]]+INVESTORS_LIST[[#This Row],[SIP_TOTAL UNITS SOLD]] -> 1 | U2: 0 | V2: =SUMIFS(LS[BO UNIT TRANSFER],LS[Investor ID],INVESTORS_LIST[[#This Row],[INVESTOR CODE]],LS[B/S],"B") -> 0 | W2: =SUMIFS(LS[BO UNIT TRANSFER],LS[Investor ID],INVESTORS_LIST[[#This Row],[INVESTOR CODE]],LS[B/S],"S") -> 0 | X2: =SUMIFS(SIP[BO UNIT TRANSFER],SIP[Investor ID],INVESTORS_LIST[[#This Row],[INVESTOR CODE]],SIP[B/S],"S") -> 0 | Y2: =SUMIFS(SIP[BO UNIT TRANSFER],SIP[Investor ID],INVESTORS_LIST[[#This Row],[INVESTOR CODE]],SIP[B/S],"B") -> 0 | Z2: =INVESTORS_LIST[[#This Row],[BO OPENING BALANCE]]+INVESTORS_LIST[[#This Row],[LS- BO UNITS SELL]]+INVESTORS_LIST[[#This Row],[LS- BO UNITS REPURCHASE]]+INVESTORS_LIST[[#This Row],[SIP- BO UNITS REPURCHASE]]-INVESTORS_LIST[[#This Row],[SIP- BO UNITS SELL]] -> 0 | AA2: =INVESTORS_LIST[[#This Row],[TOTAL UNITS BUY]]-INVESTORS_LIST[[#This Row],[TOTAL UNITS SOLD]] -> 74186 | AB2: =INVESTORS_LIST[[#This Row],[TOTAL CURRENT UNITS]]-INVESTORS_LIST[[#This Row],[BO UNITS HOLD]] -> 74186 | AC2: =INDEX([4]!Table_1[BO ID],MATCH(INVESTORS_LIST[[#This Row],[INVESTOR CODE]],[4]!Table_1[INVESTOR CODE],0)) -> #REF! | AD2: =INVESTORS_LIST[[#This Row],[LS_TOTAL COST VALUE OF CURRENT UNITS]]+INVESTORS_LIST[[#This Row],[SIP_TOTAL COST VALUE OF CURRENT UNITS]] -> 753775.53 | AE2: =IF(INVESTORS_LIST[[#This Row],[TOTAL CURRENT UNITS]]=0,0,INVESTORS_LIST[[#This Row],[LS_TOTAL CURRENT UNITS]]/INVESTORS_LIST[[#This Row],[TOTAL CURRENT UNITS]]) -> 1 | AF2: =IF(INVESTORS_LIST[[#This Row],[TOTAL CURRENT UNITS]]=0,0,INVESTORS_LIST[[#This Row],[SIP_TOTAL CURRENT UNITS]]/INVESTORS_LIST[[#This Row],[TOTAL CURRENT UNITS]]) -> 0 | AG2: {=IF(INVESTORS_LIST[[#This Row],[LS_TOTAL UNITS BUY]]>0,INDEX(LS[NAV at Cost (Average)],MATCH(CONCATENATE(COUNTIFS(LS[Investor ID],INVESTORS_LIST[[#This Row],[INVESTOR CODE]]),INVESTORS_LIST[[#This Row],[INVESTOR CODE]]),LS[Unique Code],0),),0)} -> 10.160617 | AH2: {=IF(INVESTORS_LIST[[#This Row],[SIP_TOTAL UNITS BUY]]>0,INDEX(SIP[NAV at Cost (Average)],MATCH(CONCATENATE(COUNTIFS(SIP[Investor ID],INVESTORS_LIST[[#This Row],[INVESTOR CODE]]),INVESTORS_LIST[[#This Row],[INVESTOR CODE]]),SIP[Unique Code],0),),0)} -> 0 | AI2: =IF(INVESTORS_LIST[[#This Row],[TOTAL CURRENT UNITS]]=0,0,(INVESTORS_LIST[[#This Row],[LS_WEIGHT]]*INVESTORS_LIST[[#This Row],[LS_AVERAGE COST]])+(INVESTORS_LIST[[#This Row],[SIP_WEIGHT]]*INVESTORS_LIST[[#This Row],[SIP_AVERAGE COST]])) -> 10.160617 | AJ2: =NAV_MKT -> 12.552 | AK2: =IF(INVESTORS_LIST[[#This Row],[TOTAL CURRENT UNITS]]=0,0,INVESTORS_LIST[[#This Row],[TOTAL CURRENT UNITS]]*INVESTORS_LIST[[#This Row],[NAV]]) -> 931182.67 | AL2: =IF(INVESTORS_LIST[[#This Row],[LS_TOTAL CURRENT UNITS]]=0,0,INVESTORS_LIST[[#This Row],[LS_TOTAL CURRENT UNITS]]*INVESTORS_LIST[[#This Row],[NAV]]) -> 931182.67 | AM2: =IF(INVESTORS_LIST[[#This Row],[SIP_TOTAL CURRENT UNITS]]=0,0,INVESTORS_LIST[[#This Row],[SIP_TOTAL CURRENT UNITS]]*INVESTORS_LIST[[#This Row],[NAV]]) -> 0 | AO2: =IF(INVESTORS_LIST[[#This Row],[TOTAL SELLABLE UNITS]]=0,0,INVESTORS_LIST[[#This Row],[TOTAL SELLABLE UNITS]]*INVESTORS_LIST[[#This Row],[NAV]]) -> 0 | AP2: =INVESTORS_LIST[[#This Row],[LS_TOTAL REALIZED GAIN]]+INVESTORS_LIST[[#This Row],[SIP_TOTAL REALIZED GAIN]] -> -6.7117258 | AQ2: =INVESTORS_LIST[[#This Row],[TOTAL MARKET VALUE]]-INVESTORS_LIST[[#This Row],[TOTAL COST VALUE OF CURRENT INVESTMENT]] -> 177407.14 | AR2: =SUMIFS(DivAndTax[Tax Amount],DivAndTax[Investor ID],INVESTORS_LIST[[#This Row],[INVESTOR CODE]]) -> 11554.19 | AS2: =SUMIFS(DivAndTax[Gross Dividend],DivAndTax[Investor ID],INVESTORS_LIST[[#This Row],[INVESTOR CODE]]) -> 77027.9 | AT2: =IFERROR(INVESTORS_LIST[[#This Row],[TOTAL CURRENT UNITS]]/SUM(INVESTORS_LIST[TOTAL CURRENT UNITS]),0) -> 0.0035568355
A3: EKUSH WEALTH MANAGEMENT LIMITED | B3: A00003 | C3: Dear | D3: Company/Organization | E3: =SUMIFS(LS[Unit],LS[Investor ID],INVESTORS_LIST[[#This Row],[INVESTOR CODE]],LS[B/S],"B") -> 6509076 | F3: =-SUMIFS(LS[Unit],LS[Investor ID],INVESTORS_LIST[[#This Row],[INVESTOR CODE]],LS[B/S],"S") -> 3596507 | G3: =IF(INVESTORS_LIST[[#This Row],[LS_TOTAL UNITS BUY]]=0,0,INVESTORS_LIST[[#This Row],[LS_TOTAL UNITS BUY]]-INVESTORS_LIST[[#This Row],[LS_TOTAL UNITS SOLD]]) -> 2912569 | H3: =IF(INVESTORS_LIST[[#This Row],[LS_TOTAL UNITS BUY]]=0,0,SUMIFS(LS[Amount],LS[Investor ID],INVESTORS_LIST[[#This Row],[INVESTOR CODE]],LS[B/S],"B")) -> 65776233 | I3: =IF(INVESTORS_LIST[[#This Row],[LS_TOTAL UNITS SOLD]]=0,0,SUMIFS(LS[Cost of Units Sold],LS[Investor ID],INVESTORS_LIST[[#This Row],[INVESTOR CODE]],LS[B/S],"S")) -> 35899827 | J3: =IF(INVESTORS_LIST[[#This Row],[LS_TOTAL CURRENT UNITS]]=0,0,INVESTORS_LIST[[#This Row],[LS_TOTAL CURRENT UNITS]]*INVESTORS_LIST[[#This Row],[LS_AVERAGE COST]]) -> 29876406 | K3: =IF(INVESTORS_LIST[[#This Row],[LS_TOTAL UNITS SOLD]]=0,0,SUMIFS(LS[Realized Gain],LS[Investor ID],INVESTORS_LIST[[#This Row],[INVESTOR CODE]],LS[B/S],"S")) -> 150156.26 | L3: =SUMIFS(SIP[Unit],SIP[Investor ID],INVESTORS_LIST[[#This Row],[INVESTOR CODE]],SIP[B/S],"B") -> 0 | M3: =-SUMIFS(SIP[Unit],SIP[Investor ID],INVESTORS_LIST[[#This Row],[INVESTOR CODE]],SIP[B/S],"S") -> 0 | N3: =IF(INVESTORS_LIST[[#This Row],[SIP_TOTAL UNITS BUY]]=0,0,INVESTORS_LIST[[#This Row],[SIP_TOTAL UNITS BUY]]-INVESTORS_LIST[[#This Row],[SIP_TOTAL UNITS SOLD]]) -> 0 | O3: =IF(INVESTORS_LIST[[#This Row],[SIP_TOTAL UNITS BUY]]=0,0,SUMIFS(SIP[Amount],SIP[Investor ID],INVESTORS_LIST[[#This Row],[INVESTOR CODE]],SIP[B/S],"B")) -> 0 | P3: =IF(INVESTORS_LIST[[#This Row],[SIP_TOTAL UNITS SOLD]]=0,0,SUMIFS(SIP[Cost of Units Sold],SIP[Investor ID],INVESTORS_LIST[[#This Row],[INVESTOR CODE]],SIP[B/S],"S")) -> 0 | Q3: =IF(INVESTORS_LIST[[#This Row],[SIP_TOTAL CURRENT UNITS]]=0,0,INVESTORS_LIST[[#This Row],[SIP_TOTAL CURRENT UNITS]]*INVESTORS_LIST[[#This Row],[SIP_AVERAGE COST]]) -> 0 | R3: =IF(INVESTORS_LIST[[#This Row],[SIP_TOTAL UNITS SOLD]]=0,0,SUMIFS(SIP[Realized Gain],SIP[Investor ID],INVESTORS_LIST[[#This Row],[INVESTOR CODE]],SIP[B/S],"S")) -> 0 | S3: =INVESTORS_LIST[[#This Row],[LS_TOTAL UNITS BUY]]+INVESTORS_LIST[[#This Row],[SIP_TOTAL UNITS BUY]] -> 6509076 | T3: =INVESTORS_LIST[[#This Row],[LS_TOTAL UNITS SOLD]]+INVESTORS_LIST[[#This Row],[SIP_TOTAL UNITS SOLD]] -> 3596507 | U3: 672004 | V3: =SUMIFS(LS[BO UNIT TRANSFER],LS[Investor ID],INVESTORS_LIST[[#This Row],[INVESTOR CODE]],LS[B/S],"B") -> 0 | W3: =SUMIFS(LS[BO UNIT TRANSFER],LS[Investor ID],INVESTORS_LIST[[#This Row],[INVESTOR CODE]],LS[B/S],"S") -> 0 | X3: =SUMIFS(SIP[BO UNIT TRANSFER],SIP[Investor ID],INVESTORS_LIST[[#This Row],[INVESTOR CODE]],SIP[B/S],"S") -> 0 | Y3: =SUMIFS(SIP[BO UNIT TRANSFER],SIP[Investor ID],INVESTORS_LIST[[#This Row],[INVESTOR CODE]],SIP[B/S],"B") -> 0 | Z3: =INVESTORS_LIST[[#This Row],[BO OPENING BALANCE]]+INVESTORS_LIST[[#This Row],[LS- BO UNITS SELL]]+INVESTORS_LIST[[#This Row],[LS- BO UNITS REPURCHASE]]+INVESTORS_LIST[[#This Row],[SIP- BO UNITS REPURCHASE]]-INVESTORS_LIST[[#This Row],[SIP- BO UNITS SELL]] -> 672004 | AA3: =INVESTORS_LIST[[#This Row],[TOTAL UNITS BUY]]-INVESTORS_LIST[[#This Row],[TOTAL UNITS SOLD]] -> 2912569 | AB3: =INVESTORS_LIST[[#This Row],[TOTAL CURRENT UNITS]]-INVESTORS_LIST[[#This Row],[BO UNITS HOLD]] -> 2240565 | AC3: =INDEX([4]!Table_1[BO ID],MATCH(INVESTORS_LIST[[#This Row],[INVESTOR CODE]],[4]!Table_1[INVESTOR CODE],0)) -> #REF! | AD3: =INVESTORS_LIST[[#This Row],[LS_TOTAL COST VALUE OF CURRENT UNITS]]+INVESTORS_LIST[[#This Row],[SIP_TOTAL COST VALUE OF CURRENT UNITS]] -> 29876406 | AE3: =IF(INVESTORS_LIST[[#This Row],[TOTAL CURRENT UNITS]]=0,0,INVESTORS_LIST[[#This Row],[LS_TOTAL CURRENT UNITS]]/INVESTORS_LIST[[#This Row],[TOTAL CURRENT UNITS]]) -> 1 | AF3: =IF(INVESTORS_LIST[[#This Row],[TOTAL CURRENT UNITS]]=0,0,INVESTORS_LIST[[#This Row],[SIP_TOTAL CURRENT UNITS]]/INVESTORS_LIST[[#This Row],[TOTAL CURRENT UNITS]]) -> 0 | AG3: {=IF(INVESTORS_LIST[[#This Row],[LS_TOTAL UNITS BUY]]>0,INDEX(LS[NAV at Cost (Average)],MATCH(CONCATENATE(COUNTIFS(LS[Investor ID],INVESTORS_LIST[[#This Row],[INVESTOR CODE]]),INVESTORS_LIST[[#This Row],[INVESTOR CODE]]),LS[Unique Code],0),),0)} -> 10.25775 | AH3: {=IF(INVESTORS_LIST[[#This Row],[SIP_TOTAL UNITS BUY]]>0,INDEX(SIP[NAV at Cost (Average)],MATCH(CONCATENATE(COUNTIFS(SIP[Investor ID],INVESTORS_LIST[[#This Row],[INVESTOR CODE]]),INVESTORS_LIST[[#This Row],[INVESTOR CODE]]),SIP[Unique Code],0),),0)} -> 0 | AI3: =IF(INVESTORS_LIST[[#This Row],[TOTAL CURRENT UNITS]]=0,0,(INVESTORS_LIST[[#This Row],[LS_WEIGHT]]*INVESTORS_LIST[[#This Row],[LS_AVERAGE COST]])+(INVESTORS_LIST[[#This Row],[SIP_WEIGHT]]*INVESTORS_LIST[[#This Row],[SIP_AVERAGE COST]])) -> 10.25775 | AJ3: =NAV_MKT -> 12.552 | AK3: =IF(INVESTORS_LIST[[#This Row],[TOTAL CURRENT UNITS]]=0,0,INVESTORS_LIST[[#This Row],[TOTAL CURRENT UNITS]]*INVESTORS_LIST[[#This Row],[NAV]]) -> 36558566 | AL3: =IF(INVESTORS_LIST[[#This Row],[LS_TOTAL CURRENT UNITS]]=0,0,INVESTORS_LIST[[#This Row],[LS_TOTAL CURRENT UNITS]]*INVESTORS_LIST[[#This Row],[NAV]]) -> 36558566 | AM3: =IF(INVESTORS_LIST[[#This Row],[SIP_TOTAL CURRENT UNITS]]=0,0,INVESTORS_LIST[[#This Row],[SIP_TOTAL CURRENT UNITS]]*INVESTORS_LIST[[#This Row],[NAV]]) -> 0 | AO3: =IF(INVESTORS_LIST[[#This Row],[TOTAL SELLABLE UNITS]]=0,0,INVESTORS_LIST[[#This Row],[TOTAL SELLABLE UNITS]]*INVESTORS_LIST[[#This Row],[NAV]]) -> 0 | AP3: =INVESTORS_LIST[[#This Row],[LS_TOTAL REALIZED GAIN]]+INVESTORS_LIST[[#This Row],[SIP_TOTAL REALIZED GAIN]] -> 150156.26 | AQ3: =INVESTORS_LIST[[#This Row],[TOTAL MARKET VALUE]]-INVESTORS_LIST[[#This Row],[TOTAL COST VALUE OF CURRENT INVESTMENT]] -> 6682160.1 | AR3: =SUMIFS(DivAndTax[Tax Amount],DivAndTax[Investor ID],INVESTORS_LIST[[#This Row],[INVESTOR CODE]]) -> 532968.47 | AS3: =SUMIFS(DivAndTax[Gross Dividend],DivAndTax[Investor ID],INVESTORS_LIST[[#This Row],[INVESTOR CODE]]) -> 2664842.4 | AT3: =IFERROR(INVESTORS_LIST[[#This Row],[TOTAL CURRENT UNITS]]/SUM(INVESTORS_LIST[TOTAL CURRENT UNITS]),0) -> 0.13964264
A4: SADIA AHMED | B4: A00004 | C4: Dear Mrs. | D4: Individual | E4: =SUMIFS(LS[Unit],LS[Investor ID],INVESTORS_LIST[[#This Row],[INVESTOR CODE]],LS[B/S],"B") -> 0 | F4: =-SUMIFS(LS[Unit],LS[Investor ID],INVESTORS_LIST[[#This Row],[INVESTOR CODE]],LS[B/S],"S") -> 0 | G4: =IF(INVESTORS_LIST[[#This Row],[LS_TOTAL UNITS BUY]]=0,0,INVESTORS_LIST[[#This Row],[LS_TOTAL UNITS BUY]]-INVESTORS_LIST[[#This Row],[LS_TOTAL UNITS SOLD]]) -> 0 | H4: =IF(INVESTORS_LIST[[#This Row],[LS_TOTAL UNITS BUY]]=0,0,SUMIFS(LS[Amount],LS[Investor ID],INVESTORS_LIST[[#This Row],[INVESTOR CODE]],LS[B/S],"B")) -> 0 | I4: =IF(INVESTORS_LIST[[#This Row],[LS_TOTAL UNITS SOLD]]=0,0,SUMIFS(LS[Cost of Units Sold],LS[Investor ID],INVESTORS_LIST[[#This Row],[INVESTOR CODE]],LS[B/S],"S")) -> 0 | J4: =IF(INVESTORS_LIST[[#This Row],[LS_TOTAL CURRENT UNITS]]=0,0,INVESTORS_LIST[[#This Row],[LS_TOTAL CURRENT UNITS]]*INVESTORS_LIST[[#This Row],[LS_AVERAGE COST]]) -> 0 | K4: =IF(INVESTORS_LIST[[#This Row],[LS_TOTAL UNITS SOLD]]=0,0,SUMIFS(LS[Realized Gain],LS[Investor ID],INVESTORS_LIST[[#This Row],[INVESTOR CODE]],LS[B/S],"S")) -> 0 | L4: =SUMIFS(SIP[Unit],SIP[Investor ID],INVESTORS_LIST[[#This Row],[INVESTOR CODE]],SIP[B/S],"B") -> 0 | M4: =-SUMIFS(SIP[Unit],SIP[Investor ID],INVESTORS_LIST[[#This Row],[INVESTOR CODE]],SIP[B/S],"S") -> 0 | N4: =IF(INVESTORS_LIST[[#This Row],[SIP_TOTAL UNITS BUY]]=0,0,INVESTORS_LIST[[#This Row],[SIP_TOTAL UNITS BUY]]-INVESTORS_LIST[[#This Row],[SIP_TOTAL UNITS SOLD]]) -> 0 | O4: =IF(INVESTORS_LIST[[#This Row],[SIP_TOTAL UNITS BUY]]=0,0,SUMIFS(SIP[Amount],SIP[Investor ID],INVESTORS_LIST[[#This Row],[INVESTOR CODE]],SIP[B/S],"B")) -> 0 | P4: =IF(INVESTORS_LIST[[#This Row],[SIP_TOTAL UNITS SOLD]]=0,0,SUMIFS(SIP[Cost of Units Sold],SIP[Investor ID],INVESTORS_LIST[[#This Row],[INVESTOR CODE]],SIP[B/S],"S")) -> 0 | Q4: =IF(INVESTORS_LIST[[#This Row],[SIP_TOTAL CURRENT UNITS]]=0,0,INVESTORS_LIST[[#This Row],[SIP_TOTAL CURRENT UNITS]]*INVESTORS_LIST[[#This Row],[SIP_AVERAGE COST]]) -> 0 | R4: =IF(INVESTORS_LIST[[#This Row],[SIP_TOTAL UNITS SOLD]]=0,0,SUMIFS(SIP[Realized Gain],SIP[Investor ID],INVESTORS_LIST[[#This Row],[INVESTOR CODE]],SIP[B/S],"S")) -> 0 | S4: =INVESTORS_LIST[[#This Row],[LS_TOTAL UNITS BUY]]+INVESTORS_LIST[[#This Row],[SIP_TOTAL UNITS BUY]] -> 0 | T4: =INVESTORS_LIST[[#This Row],[LS_TOTAL UNITS SOLD]]+INVESTORS_LIST[[#This Row],[SIP_TOTAL UNITS SOLD]] -> 0 | U4: 0 | V4: =SUMIFS(LS[BO UNIT TRANSFER],LS[Investor ID],INVESTORS_LIST[[#This Row],[INVESTOR CODE]],LS[B/S],"B") -> 0 | W4: =SUMIFS(LS[BO UNIT TRANSFER],LS[Investor ID],INVESTORS_LIST[[#This Row],[INVESTOR CODE]],LS[B/S],"S") -> 0 | X4: =SUMIFS(SIP[BO UNIT TRANSFER],SIP[Investor ID],INVESTORS_LIST[[#This Row],[INVESTOR CODE]],SIP[B/S],"S") -> 0 | Y4: =SUMIFS(SIP[BO UNIT TRANSFER],SIP[Investor ID],INVESTORS_LIST[[#This Row],[INVESTOR CODE]],SIP[B/S],"B") -> 0 | Z4: =INVESTORS_LIST[[#This Row],[BO OPENING BALANCE]]+INVESTORS_LIST[[#This Row],[LS- BO UNITS SELL]]+INVESTORS_LIST[[#This Row],[LS- BO UNITS REPURCHASE]]+INVESTORS_LIST[[#This Row],[SIP- BO UNITS REPURCHASE]]-INVESTORS_LIST[[#This Row],[SIP- BO UNITS SELL]] -> 0 | AA4: =INVESTORS_LIST[[#This Row],[TOTAL UNITS BUY]]-INVESTORS_LIST[[#This Row],[TOTAL UNITS SOLD]] -> 0 | AB4: =INVESTORS_LIST[[#This Row],[TOTAL CURRENT UNITS]]-INVESTORS_LIST[[#This Row],[BO UNITS HOLD]] -> 0 | AC4: =INDEX([4]!Table_1[BO ID],MATCH(INVESTORS_LIST[[#This Row],[INVESTOR CODE]],[4]!Table_1[INVESTOR CODE],0)) -> #REF! | AD4: =INVESTORS_LIST[[#This Row],[LS_TOTAL COST VALUE OF CURRENT UNITS]]+INVESTORS_LIST[[#This Row],[SIP_TOTAL COST VALUE OF CURRENT UNITS]] -> 0 | AE4: =IF(INVESTORS_LIST[[#This Row],[TOTAL CURRENT UNITS]]=0,0,INVESTORS_LIST[[#This Row],[LS_TOTAL CURRENT UNITS]]/INVESTORS_LIST[[#This Row],[TOTAL CURRENT UNITS]]) -> 0 | AF4: =IF(INVESTORS_LIST[[#This Row],[TOTAL CURRENT UNITS]]=0,0,INVESTORS_LIST[[#This Row],[SIP_TOTAL CURRENT UNITS]]/INVESTORS_LIST[[#This Row],[TOTAL CURRENT UNITS]]) -> 0 | AG4: {=IF(INVESTORS_LIST[[#This Row],[LS_TOTAL UNITS BUY]]>0,INDEX(LS[NAV at Cost (Average)],MATCH(CONCATENATE(COUNTIFS(LS[Investor ID],INVESTORS_LIST[[#This Row],[INVESTOR CODE]]),INVESTORS_LIST[[#This Row],[INVESTOR CODE]]),LS[Unique Code],0),),0)} -> 0 | AH4: {=IF(INVESTORS_LIST[[#This Row],[SIP_TOTAL UNITS BUY]]>0,INDEX(SIP[NAV at Cost (Average)],MATCH(CONCATENATE(COUNTIFS(SIP[Investor ID],INVESTORS_LIST[[#This Row],[INVESTOR CODE]]),INVESTORS_LIST[[#This Row],[INVESTOR CODE]]),SIP[Unique Code],0),),0)} -> 0 | AI4: =IF(INVESTORS_LIST[[#This Row],[TOTAL CURRENT UNITS]]=0,0,(INVESTORS_LIST[[#This Row],[LS_WEIGHT]]*INVESTORS_LIST[[#This Row],[LS_AVERAGE COST]])+(INVESTORS_LIST[[#This Row],[SIP_WEIGHT]]*INVESTORS_LIST[[#This Row],[SIP_AVERAGE COST]])) -> 0 | AJ4: =NAV_MKT -> 12.552 | AK4: =IF(INVESTORS_LIST[[#This Row],[TOTAL CURRENT UNITS]]=0,0,INVESTORS_LIST[[#This Row],[TOTAL CURRENT UNITS]]*INVESTORS_LIST[[#This Row],[NAV]]) -> 0 | AL4: =IF(INVESTORS_LIST[[#This Row],[LS_TOTAL CURRENT UNITS]]=0,0,INVESTORS_LIST[[#This Row],[LS_TOTAL CURRENT UNITS]]*INVESTORS_LIST[[#This Row],[NAV]]) -> 0 | AM4: =IF(INVESTORS_LIST[[#This Row],[SIP_TOTAL CURRENT UNITS]]=0,0,INVESTORS_LIST[[#This Row],[SIP_TOTAL CURRENT UNITS]]*INVESTORS_LIST[[#This Row],[NAV]]) -> 0 | AO4: =IF(INVESTORS_LIST[[#This Row],[TOTAL SELLABLE UNITS]]=0,0,INVESTORS_LIST[[#This Row],[TOTAL SELLABLE UNITS]]*INVESTORS_LIST[[#This Row],[NAV]]) -> 0 | AP4: =INVESTORS_LIST[[#This Row],[LS_TOTAL REALIZED GAIN]]+INVESTORS_LIST[[#This Row],[SIP_TOTAL REALIZED GAIN]] -> 0 | AQ4: =INVESTORS_LIST[[#This Row],[TOTAL MARKET VALUE]]-INVESTORS_LIST[[#This Row],[TOTAL COST VALUE OF CURRENT INVESTMENT]] -> 0 | AR4: =SUMIFS(DivAndTax[Tax Amount],DivAndTax[Investor ID],INVESTORS_LIST[[#This Row],[INVESTOR CODE]]) -> 0 | AS4: =SUMIFS(DivAndTax[Gross Dividend],DivAndTax[Investor ID],INVESTORS_LIST[[#This Row],[INVESTOR CODE]]) -> 0 | AT4: =IFERROR(INVESTORS_LIST[[#This Row],[TOTAL CURRENT UNITS]]/SUM(INVESTORS_LIST[TOTAL CURRENT UNITS]),0) -> 0
A5: MORSHEDA MIM | B5: A00005 | C5: Dear Mrs. | D5: Individual | E5: =SUMIFS(LS[Unit],LS[Investor ID],INVESTORS_LIST[[#This Row],[INVESTOR CODE]],LS[B/S],"B") -> 62130 | F5: =-SUMIFS(LS[Unit],LS[Investor ID],INVESTORS_LIST[[#This Row],[INVESTOR CODE]],LS[B/S],"S") -> 62130 | G5: =IF(INVESTORS_LIST[[#This Row],[LS_TOTAL UNITS BUY]]=0,0,INVESTORS_LIST[[#This Row],[LS_TOTAL UNITS BUY]]-INVESTORS_LIST[[#This Row],[LS_TOTAL UNITS SOLD]]) -> 0 | H5: =IF(INVESTORS_LIST[[#This Row],[LS_TOTAL UNITS BUY]]=0,0,SUMIFS(LS[Amount],LS[Investor ID],INVESTORS_LIST[[#This Row],[INVESTOR CODE]],LS[B/S],"B")) -> 655381.42 | I5: =IF(INVESTORS_LIST[[#This Row],[LS_TOTAL UNITS SOLD]]=0,0,SUMIFS(LS[Cost of Units Sold],LS[Investor ID],INVESTORS_LIST[[#This Row],[INVESTOR CODE]],LS[B/S],"S")) -> 655381.42 | J5: =IF(INVESTORS_LIST[[#This Row],[LS_TOTAL CURRENT UNITS]]=0,0,INVESTORS_LIST[[#This Row],[LS_TOTAL CURRENT UNITS]]*INVESTORS_LIST[[#This Row],[LS_AVERAGE COST]]) -> 0 | K5: =IF(INVESTORS_LIST[[#This Row],[LS_TOTAL UNITS SOLD]]=0,0,SUMIFS(LS[Realized Gain],LS[Investor ID],INVESTORS_LIST[[#This Row],[INVESTOR CODE]],LS[B/S],"S")) -> 81418.25 | L5: =SUMIFS(SIP[Unit],SIP[Investor ID],INVESTORS_LIST[[#This Row],[INVESTOR CODE]],SIP[B/S],"B") -> 0 | M5: =-SUMIFS(SIP[Unit],SIP[Investor ID],INVESTORS_LIST[[#This Row],[INVESTOR CODE]],SIP[B/S],"S") -> 0 | N5: =IF(INVESTORS_LIST[[#This Row],[SIP_TOTAL UNITS BUY]]=0,0,INVESTORS_LIST[[#This Row],[SIP_TOTAL UNITS BUY]]-INVESTORS_LIST[[#This Row],[SIP_TOTAL UNITS SOLD]]) -> 0 | O5: =IF(INVESTORS_LIST[[#This Row],[SIP_TOTAL UNITS BUY]]=0,0,SUMIFS(SIP[Amount],SIP[Investor ID],INVESTORS_LIST[[#This Row],[INVESTOR CODE]],SIP[B/S],"B")) -> 0 | P5: =IF(INVESTORS_LIST[[#This Row],[SIP_TOTAL UNITS SOLD]]=0,0,SUMIFS(SIP[Cost of Units Sold],SIP[Investor ID],INVESTORS_LIST[[#This Row],[INVESTOR CODE]],SIP[B/S],"S")) -> 0 | Q5: =IF(INVESTORS_LIST[[#This Row],[SIP_TOTAL CURRENT UNITS]]=0,0,INVESTORS_LIST[[#This Row],[SIP_TOTAL CURRENT UNITS]]*INVESTORS_LIST[[#This Row],[SIP_AVERAGE COST]]) -> 0 | R5: =IF(INVESTORS_LIST[[#This Row],[SIP_TOTAL UNITS SOLD]]=0,0,SUMIFS(SIP[Realized Gain],SIP[Investor ID],INVESTORS_LIST[[#This Row],[INVESTOR CODE]],SIP[B/S],"S")) -> 0 | S5: =INVESTORS_LIST[[#This Row],[LS_TOTAL UNITS BUY]]+INVESTORS_LIST[[#This Row],[SIP_TOTAL UNITS BUY]] -> 62130 | T5: =INVESTORS_LIST[[#This Row],[LS_TOTAL UNITS SOLD]]+INVESTORS_LIST[[#This Row],[SIP_TOTAL UNITS SOLD]] -> 62130 | U5: 0 | V5: =SUMIFS(LS[BO UNIT TRANSFER],LS[Investor ID],INVESTORS_LIST[[#This Row],[INVESTOR CODE]],LS[B/S],"B") -> 0 | W5: =SUMIFS(LS[BO UNIT TRANSFER],LS[Investor ID],INVESTORS_LIST[[#This Row],[INVESTOR CODE]],LS[B/S],"S") -> 0 | X5: =SUMIFS(SIP[BO UNIT TRANSFER],SIP[Investor ID],INVESTORS_LIST[[#This Row],[INVESTOR CODE]],SIP[B/S],"S") -> 0 | Y5: =SUMIFS(SIP[BO UNIT TRANSFER],SIP[Investor ID],INVESTORS_LIST[[#This Row],[INVESTOR CODE]],SIP[B/S],"B") -> 0 | Z5: =INVESTORS_LIST[[#This Row],[BO OPENING BALANCE]]+INVESTORS_LIST[[#This Row],[LS- BO UNITS SELL]]+INVESTORS_LIST[[#This Row],[LS- BO UNITS REPURCHASE]]+INVESTORS_LIST[[#This Row],[SIP- BO UNITS REPURCHASE]]-INVESTORS_LIST[[#This Row],[SIP- BO UNITS SELL]] -> 0 | AA5: =INVESTORS_LIST[[#This Row],[TOTAL UNITS BUY]]-INVESTORS_LIST[[#This Row],[TOTAL UNITS SOLD]] -> 0 | AB5: =INVESTORS_LIST[[#This Row],[TOTAL CURRENT UNITS]]-INVESTORS_LIST[[#This Row],[BO UNITS HOLD]] -> 0 | AC5: =INDEX([4]!Table_1[BO ID],MATCH(INVESTORS_LIST[[#This Row],[INVESTOR CODE]],[4]!Table_1[INVESTOR CODE],0)) -> #REF! | AD5: =INVESTORS_LIST[[#This Row],[LS_TOTAL COST VALUE OF CURRENT UNITS]]+INVESTORS_LIST[[#This Row],[SIP_TOTAL COST VALUE OF CURRENT UNITS]] -> 0 | AE5: =IF(INVESTORS_LIST[[#This Row],[TOTAL CURRENT UNITS]]=0,0,INVESTORS_LIST[[#This Row],[LS_TOTAL CURRENT UNITS]]/INVESTORS_LIST[[#This Row],[TOTAL CURRENT UNITS]]) -> 0 | AF5: =IF(INVESTORS_LIST[[#This Row],[TOTAL CURRENT UNITS]]=0,0,INVESTORS_LIST[[#This Row],[SIP_TOTAL CURRENT UNITS]]/INVESTORS_LIST[[#This Row],[TOTAL CURRENT UNITS]]) -> 0 | AG5: {=IF(INVESTORS_LIST[[#This Row],[LS_TOTAL UNITS BUY]]>0,INDEX(LS[NAV at Cost (Average)],MATCH(CONCATENATE(COUNTIFS(LS[Investor ID],INVESTORS_LIST[[#This Row],[INVESTOR CODE]]),INVESTORS_LIST[[#This Row],[INVESTOR CODE]]),LS[Unique Code],0),),0)} -> 0 | AH5: {=IF(INVESTORS_LIST[[#This Row],[SIP_TOTAL UNITS BUY]]>0,INDEX(SIP[NAV at Cost (Average)],MATCH(CONCATENATE(COUNTIFS(SIP[Investor ID],INVESTORS_LIST[[#This Row],[INVESTOR CODE]]),INVESTORS_LIST[[#This Row],[INVESTOR CODE]]),SIP[Unique Code],0),),0)} -> 0 | AI5: =IF(INVESTORS_LIST[[#This Row],[TOTAL CURRENT UNITS]]=0,0,(INVESTORS_LIST[[#This Row],[LS_WEIGHT]]*INVESTORS_LIST[[#This Row],[LS_AVERAGE COST]])+(INVESTORS_LIST[[#This Row],[SIP_WEIGHT]]*INVESTORS_LIST[[#This Row],[SIP_AVERAGE COST]])) -> 0 | AJ5: =NAV_MKT -> 12.552 | AK5: =IF(INVESTORS_LIST[[#This Row],[TOTAL CURRENT UNITS]]=0,0,INVESTORS_LIST[[#This Row],[TOTAL CURRENT UNITS]]*INVESTORS_LIST[[#This Row],[NAV]]) -> 0 | AL5: =IF(INVESTORS_LIST[[#This Row],[LS_TOTAL CURRENT UNITS]]=0,0,INVESTORS_LIST[[#This Row],[LS_TOTAL CURRENT UNITS]]*INVESTORS_LIST[[#This Row],[NAV]]) -> 0 | AM5: =IF(INVESTORS_LIST[[#This Row],[SIP_TOTAL CURRENT UNITS]]=0,0,INVESTORS_LIST[[#This Row],[SIP_TOTAL CURRENT UNITS]]*INVESTORS_LIST[[#This Row],[NAV]]) -> 0 | AO5: =IF(INVESTORS_LIST[[#This Row],[TOTAL SELLABLE UNITS]]=0,0,INVESTORS_LIST[[#This Row],[TOTAL SELLABLE UNITS]]*INVESTORS_LIST[[#This Row],[NAV]]) -> 0 | AP5: =INVESTORS_LIST[[#This Row],[LS_TOTAL REALIZED GAIN]]+INVESTORS_LIST[[#This Row],[SIP_TOTAL REALIZED GAIN]] -> 81418.25 | AQ5: =INVESTORS_LIST[[#This Row],[TOTAL MARKET VALUE]]-INVESTORS_LIST[[#This Row],[TOTAL COST VALUE OF CURRENT INVESTMENT]] -> 0 | AR5: =SUMIFS(DivAndTax[Tax Amount],DivAndTax[Investor ID],INVESTORS_LIST[[#This Row],[INVESTOR CODE]]) -> 4479.08 | AS5: =SUMIFS(DivAndTax[Gross Dividend],DivAndTax[Investor ID],INVESTORS_LIST[[#This Row],[INVESTOR CODE]]) -> 29860.5 | AT5: =IFERROR(INVESTORS_LIST[[#This Row],[TOTAL CURRENT UNITS]]/SUM(INVESTORS_LIST[TOTAL CURRENT UNITS]),0) -> 0
A6: MD. JAHANGIR ALAM | B6: A00006 | C6: Dear Mr. | D6: Individual | E6: =SUMIFS(LS[Unit],LS[Investor ID],INVESTORS_LIST[[#This Row],[INVESTOR CODE]],LS[B/S],"B") -> 0 | F6: =-SUMIFS(LS[Unit],LS[Investor ID],INVESTORS_LIST[[#This Row],[INVESTOR CODE]],LS[B/S],"S") -> 0 | G6: =IF(INVESTORS_LIST[[#This Row],[LS_TOTAL UNITS BUY]]=0,0,INVESTORS_LIST[[#This Row],[LS_TOTAL UNITS BUY]]-INVESTORS_LIST[[#This Row],[LS_TOTAL UNITS SOLD]]) -> 0 | H6: =IF(INVESTORS_LIST[[#This Row],[LS_TOTAL UNITS BUY]]=0,0,SUMIFS(LS[Amount],LS[Investor ID],INVESTORS_LIST[[#This Row],[INVESTOR CODE]],LS[B/S],"B")) -> 0 | I6: =IF(INVESTORS_LIST[[#This Row],[LS_TOTAL UNITS SOLD]]=0,0,SUMIFS(LS[Cost of Units Sold],LS[Investor ID],INVESTORS_LIST[[#This Row],[INVESTOR CODE]],LS[B/S],"S")) -> 0 | J6: =IF(INVESTORS_LIST[[#This Row],[LS_TOTAL CURRENT UNITS]]=0,0,INVESTORS_LIST[[#This Row],[LS_TOTAL CURRENT UNITS]]*INVESTORS_LIST[[#This Row],[LS_AVERAGE COST]]) -> 0 | K6: =IF(INVESTORS_LIST[[#This Row],[LS_TOTAL UNITS SOLD]]=0,0,SUMIFS(LS[Realized Gain],LS[Investor ID],INVESTORS_LIST[[#This Row],[INVESTOR CODE]],LS[B/S],"S")) -> 0 | L6: =SUMIFS(SIP[Unit],SIP[Investor ID],INVESTORS_LIST[[#This Row],[INVESTOR CODE]],SIP[B/S],"B") -> 0 | M6: =-SUMIFS(SIP[Unit],SIP[Investor ID],INVESTORS_LIST[[#This Row],[INVESTOR CODE]],SIP[B/S],"S") -> 0 | N6: =IF(INVESTORS_LIST[[#This Row],[SIP_TOTAL UNITS BUY]]=0,0,INVESTORS_LIST[[#This Row],[SIP_TOTAL UNITS BUY]]-INVESTORS_LIST[[#This Row],[SIP_TOTAL UNITS SOLD]]) -> 0 | O6: =IF(INVESTORS_LIST[[#This Row],[SIP_TOTAL UNITS BUY]]=0,0,SUMIFS(SIP[Amount],SIP[Investor ID],INVESTORS_LIST[[#This Row],[INVESTOR CODE]],SIP[B/S],"B")) -> 0 | P6: =IF(INVESTORS_LIST[[#This Row],[SIP_TOTAL UNITS SOLD]]=0,0,SUMIFS(SIP[Cost of Units Sold],SIP[Investor ID],INVESTORS_LIST[[#This Row],[INVESTOR CODE]],SIP[B/S],"S")) -> 0 | Q6: =IF(INVESTORS_LIST[[#This Row],[SIP_TOTAL CURRENT UNITS]]=0,0,INVESTORS_LIST[[#This Row],[SIP_TOTAL CURRENT UNITS]]*INVESTORS_LIST[[#This Row],[SIP_AVERAGE COST]]) -> 0 | R6: =IF(INVESTORS_LIST[[#This Row],[SIP_TOTAL UNITS SOLD]]=0,0,SUMIFS(SIP[Realized Gain],SIP[Investor ID],INVESTORS_LIST[[#This Row],[INVESTOR CODE]],SIP[B/S],"S")) -> 0 | S6: =INVESTORS_LIST[[#This Row],[LS_TOTAL UNITS BUY]]+INVESTORS_LIST[[#This Row],[SIP_TOTAL UNITS BUY]] -> 0 | T6: =INVESTORS_LIST[[#This Row],[LS_TOTAL UNITS SOLD]]+INVESTORS_LIST[[#This Row],[SIP_TOTAL UNITS SOLD]] -> 0 | U6: 0 | V6: =SUMIFS(LS[BO UNIT TRANSFER],LS[Investor ID],INVESTORS_LIST[[#This Row],[INVESTOR CODE]],LS[B/S],"B") -> 0 | W6: =SUMIFS(LS[BO UNIT TRANSFER],LS[Investor ID],INVESTORS_LIST[[#This Row],[INVESTOR CODE]],LS[B/S],"S") -> 0 | X6: =SUMIFS(SIP[BO UNIT TRANSFER],SIP[Investor ID],INVESTORS_LIST[[#This Row],[INVESTOR CODE]],SIP[B/S],"S") -> 0 | Y6: =SUMIFS(SIP[BO UNIT TRANSFER],SIP[Investor ID],INVESTORS_LIST[[#This Row],[INVESTOR CODE]],SIP[B/S],"B") -> 0 | Z6: =INVESTORS_LIST[[#This Row],[BO OPENING BALANCE]]+INVESTORS_LIST[[#This Row],[LS- BO UNITS SELL]]+INVESTORS_LIST[[#This Row],[LS- BO UNITS REPURCHASE]]+INVESTORS_LIST[[#This Row],[SIP- BO UNITS REPURCHASE]]-INVESTORS_LIST[[#This Row],[SIP- BO UNITS SELL]] -> 0 | AA6: =INVESTORS_LIST[[#This Row],[TOTAL UNITS BUY]]-INVESTORS_LIST[[#This Row],[TOTAL UNITS SOLD]] -> 0 | AB6: =INVESTORS_LIST[[#This Row],[TOTAL CURRENT UNITS]]-INVESTORS_LIST[[#This Row],[BO UNITS HOLD]] -> 0 | AC6: =INDEX([4]!Table_1[BO ID],MATCH(INVESTORS_LIST[[#This Row],[INVESTOR CODE]],[4]!Table_1[INVESTOR CODE],0)) -> #REF! | AD6: =INVESTORS_LIST[[#This Row],[LS_TOTAL COST VALUE OF CURRENT UNITS]]+INVESTORS_LIST[[#This Row],[SIP_TOTAL COST VALUE OF CURRENT UNITS]] -> 0 | AE6: =IF(INVESTORS_LIST[[#This Row],[TOTAL CURRENT UNITS]]=0,0,INVESTORS_LIST[[#This Row],[LS_TOTAL CURRENT UNITS]]/INVESTORS_LIST[[#This Row],[TOTAL CURRENT UNITS]]) -> 0 | AF6: =IF(INVESTORS_LIST[[#This Row],[TOTAL CURRENT UNITS]]=0,0,INVESTORS_LIST[[#This Row],[SIP_TOTAL CURRENT UNITS]]/INVESTORS_LIST[[#This Row],[TOTAL CURRENT UNITS]]) -> 0 | AG6: {=IF(INVESTORS_LIST[[#This Row],[LS_TOTAL UNITS BUY]]>0,INDEX(LS[NAV at Cost (Average)],MATCH(CONCATENATE(COUNTIFS(LS[Investor ID],INVESTORS_LIST[[#This Row],[INVESTOR CODE]]),INVESTORS_LIST[[#This Row],[INVESTOR CODE]]),LS[Unique Code],0),),0)} -> 0 | AH6: {=IF(INVESTORS_LIST[[#This Row],[SIP_TOTAL UNITS BUY]]>0,INDEX(SIP[NAV at Cost (Average)],MATCH(CONCATENATE(COUNTIFS(SIP[Investor ID],INVESTORS_LIST[[#This Row],[INVESTOR CODE]]),INVESTORS_LIST[[#This Row],[INVESTOR CODE]]),SIP[Unique Code],0),),0)} -> 0 | AI6: =IF(INVESTORS_LIST[[#This Row],[TOTAL CURRENT UNITS]]=0,0,(INVESTORS_LIST[[#This Row],[LS_WEIGHT]]*INVESTORS_LIST[[#This Row],[LS_AVERAGE COST]])+(INVESTORS_LIST[[#This Row],[SIP_WEIGHT]]*INVESTORS_LIST[[#This Row],[SIP_AVERAGE COST]])) -> 0 | AJ6: =NAV_MKT -> 12.552 | AK6: =IF(INVESTORS_LIST[[#This Row],[TOTAL CURRENT UNITS]]=0,0,INVESTORS_LIST[[#This Row],[TOTAL CURRENT UNITS]]*INVESTORS_LIST[[#This Row],[NAV]]) -> 0 | AL6: =IF(INVESTORS_LIST[[#This Row],[LS_TOTAL CURRENT UNITS]]=0,0,INVESTORS_LIST[[#This Row],[LS_TOTAL CURRENT UNITS]]*INVESTORS_LIST[[#This Row],[NAV]]) -> 0 | AM6: =IF(INVESTORS_LIST[[#This Row],[SIP_TOTAL CURRENT UNITS]]=0,0,INVESTORS_LIST[[#This Row],[SIP_TOTAL CURRENT UNITS]]*INVESTORS_LIST[[#This Row],[NAV]]) -> 0 | AO6: =IF(INVESTORS_LIST[[#This Row],[TOTAL SELLABLE UNITS]]=0,0,INVESTORS_LIST[[#This Row],[TOTAL SELLABLE UNITS]]*INVESTORS_LIST[[#This Row],[NAV]]) -> 0 | AP6: =INVESTORS_LIST[[#This Row],[LS_TOTAL REALIZED GAIN]]+INVESTORS_LIST[[#This Row],[SIP_TOTAL REALIZED GAIN]] -> 0 | AQ6: =INVESTORS_LIST[[#This Row],[TOTAL MARKET VALUE]]-INVESTORS_LIST[[#This Row],[TOTAL COST VALUE OF CURRENT INVESTMENT]] -> 0 | AR6: =SUMIFS(DivAndTax[Tax Amount],DivAndTax[Investor ID],INVESTORS_LIST[[#This Row],[INVESTOR CODE]]) -> 0 | AS6: =SUMIFS(DivAndTax[Gross Dividend],DivAndTax[Investor ID],INVESTORS_LIST[[#This Row],[INVESTOR CODE]]) -> 0 | AT6: =IFERROR(INVESTORS_LIST[[#This Row],[TOTAL CURRENT UNITS]]/SUM(INVESTORS_LIST[TOTAL CURRENT UNITS]),0) -> 0
A7: BISWAS ARIFUR RAHMAN | B7: A00007 | C7: Dear Mr. | D7: Individual | E7: =SUMIFS(LS[Unit],LS[Investor ID],INVESTORS_LIST[[#This Row],[INVESTOR CODE]],LS[B/S],"B") -> 20000 | F7: =-SUMIFS(LS[Unit],LS[Investor ID],INVESTORS_LIST[[#This Row],[INVESTOR CODE]],LS[B/S],"S") -> 20000 | G7: =IF(INVESTORS_LIST[[#This Row],[LS_TOTAL UNITS BUY]]=0,0,INVESTORS_LIST[[#This Row],[LS_TOTAL UNITS BUY]]-INVESTORS_LIST[[#This Row],[LS_TOTAL UNITS SOLD]]) -> 0 | H7: =IF(INVESTORS_LIST[[#This Row],[LS_TOTAL UNITS BUY]]=0,0,SUMIFS(LS[Amount],LS[Investor ID],INVESTORS_LIST[[#This Row],[INVESTOR CODE]],LS[B/S],"B")) -> 200000 | I7: =IF(INVESTORS_LIST[[#This Row],[LS_TOTAL UNITS SOLD]]=0,0,SUMIFS(LS[Cost of Units Sold],LS[Investor ID],INVESTORS_LIST[[#This Row],[INVESTOR CODE]],LS[B/S],"S")) -> 200000 | J7: =IF(INVESTORS_LIST[[#This Row],[LS_TOTAL CURRENT UNITS]]=0,0,INVESTORS_LIST[[#This Row],[LS_TOTAL CURRENT UNITS]]*INVESTORS_LIST[[#This Row],[LS_AVERAGE COST]]) -> 0 | K7: =IF(INVESTORS_LIST[[#This Row],[LS_TOTAL UNITS SOLD]]=0,0,SUMIFS(LS[Realized Gain],LS[Investor ID],INVESTORS_LIST[[#This Row],[INVESTOR CODE]],LS[B/S],"S")) -> -1000 | L7: =SUMIFS(SIP[Unit],SIP[Investor ID],INVESTORS_LIST[[#This Row],[INVESTOR CODE]],SIP[B/S],"B") -> 0 | M7: =-SUMIFS(SIP[Unit],SIP[Investor ID],INVESTORS_LIST[[#This Row],[INVESTOR CODE]],SIP[B/S],"S") -> 0 | N7: =IF(INVESTORS_LIST[[#This Row],[SIP_TOTAL UNITS BUY]]=0,0,INVESTORS_LIST[[#This Row],[SIP_TOTAL UNITS BUY]]-INVESTORS_LIST[[#This Row],[SIP_TOTAL UNITS SOLD]]) -> 0 | O7: =IF(INVESTORS_LIST[[#This Row],[SIP_TOTAL UNITS BUY]]=0,0,SUMIFS(SIP[Amount],SIP[Investor ID],INVESTORS_LIST[[#This Row],[INVESTOR CODE]],SIP[B/S],"B")) -> 0 | P7: =IF(INVESTORS_LIST[[#This Row],[SIP_TOTAL UNITS SOLD]]=0,0,SUMIFS(SIP[Cost of Units Sold],SIP[Investor ID],INVESTORS_LIST[[#This Row],[INVESTOR CODE]],SIP[B/S],"S")) -> 0 | Q7: =IF(INVESTORS_LIST[[#This Row],[SIP_TOTAL CURRENT UNITS]]=0,0,INVESTORS_LIST[[#This Row],[SIP_TOTAL CURRENT UNITS]]*INVESTORS_LIST[[#This Row],[SIP_AVERAGE COST]]) -> 0 | R7: =IF(INVESTORS_LIST[[#This Row],[SIP_TOTAL UNITS SOLD]]=0,0,SUMIFS(SIP[Realized Gain],SIP[Investor ID],INVESTORS_LIST[[#This Row],[INVESTOR CODE]],SIP[B/S],"S")) -> 0 | S7: =INVESTORS_LIST[[#This Row],[LS_TOTAL UNITS BUY]]+INVESTORS_LIST[[#This Row],[SIP_TOTAL UNITS BUY]] -> 20000 | T7: =INVESTORS_LIST[[#This Row],[LS_TOTAL UNITS SOLD]]+INVESTORS_LIST[[#This Row],[SIP_TOTAL UNITS SOLD]] -> 20000 | U7: 0 | V7: =SUMIFS(LS[BO UNIT TRANSFER],LS[Investor ID],INVESTORS_LIST[[#This Row],[INVESTOR CODE]],LS[B/S],"B") -> 0 | W7: =SUMIFS(LS[BO UNIT TRANSFER],LS[Investor ID],INVESTORS_LIST[[#This Row],[INVESTOR CODE]],LS[B/S],"S") -> 0 | X7: =SUMIFS(SIP[BO UNIT TRANSFER],SIP[Investor ID],INVESTORS_LIST[[#This Row],[INVESTOR CODE]],SIP[B/S],"S") -> 0 | Y7: =SUMIFS(SIP[BO UNIT TRANSFER],SIP[Investor ID],INVESTORS_LIST[[#This Row],[INVESTOR CODE]],SIP[B/S],"B") -> 0 | Z7: =INVESTORS_LIST[[#This Row],[BO OPENING BALANCE]]+INVESTORS_LIST[[#This Row],[LS- BO UNITS SELL]]+INVESTORS_LIST[[#This Row],[LS- BO UNITS REPURCHASE]]+INVESTORS_LIST[[#This Row],[SIP- BO UNITS REPURCHASE]]-INVESTORS_LIST[[#This Row],[SIP- BO UNITS SELL]] -> 0 | AA7: =INVESTORS_LIST[[#This Row],[TOTAL UNITS BUY]]-INVESTORS_LIST[[#This Row],[TOTAL UNITS SOLD]] -> 0 | AB7: =INVESTORS_LIST[[#This Row],[TOTAL CURRENT UNITS]]-INVESTORS_LIST[[#This Row],[BO UNITS HOLD]] -> 0 | AC7: =INDEX([4]!Table_1[BO ID],MATCH(INVESTORS_LIST[[#This Row],[INVESTOR CODE]],[4]!Table_1[INVESTOR CODE],0)) -> #REF! | AD7: =INVESTORS_LIST[[#This Row],[LS_TOTAL COST VALUE OF CURRENT UNITS]]+INVESTORS_LIST[[#This Row],[SIP_TOTAL COST VALUE OF CURRENT UNITS]] -> 0 | AE7: =IF(INVESTORS_LIST[[#This Row],[TOTAL CURRENT UNITS]]=0,0,INVESTORS_LIST[[#This Row],[LS_TOTAL CURRENT UNITS]]/INVESTORS_LIST[[#This Row],[TOTAL CURRENT UNITS]]) -> 0 | AF7: =IF(INVESTORS_LIST[[#This Row],[TOTAL CURRENT UNITS]]=0,0,INVESTORS_LIST[[#This Row],[SIP_TOTAL CURRENT UNITS]]/INVESTORS_LIST[[#This Row],[TOTAL CURRENT UNITS]]) -> 0 | AG7: {=IF(INVESTORS_LIST[[#This Row],[LS_TOTAL UNITS BUY]]>0,INDEX(LS[NAV at Cost (Average)],MATCH(CONCATENATE(COUNTIFS(LS[Investor ID],INVESTORS_LIST[[#This Row],[INVESTOR CODE]]),INVESTORS_LIST[[#This Row],[INVESTOR CODE]]),LS[Unique Code],0),),0)} -> 0 | AH7: {=IF(INVESTORS_LIST[[#This Row],[SIP_TOTAL UNITS BUY]]>0,INDEX(SIP[NAV at Cost (Average)],MATCH(CONCATENATE(COUNTIFS(SIP[Investor ID],INVESTORS_LIST[[#This Row],[INVESTOR CODE]]),INVESTORS_LIST[[#This Row],[INVESTOR CODE]]),SIP[Unique Code],0),),0)} -> 0 | AI7: =IF(INVESTORS_LIST[[#This Row],[TOTAL CURRENT UNITS]]=0,0,(INVESTORS_LIST[[#This Row],[LS_WEIGHT]]*INVESTORS_LIST[[#This Row],[LS_AVERAGE COST]])+(INVESTORS_LIST[[#This Row],[SIP_WEIGHT]]*INVESTORS_LIST[[#This Row],[SIP_AVERAGE COST]])) -> 0 | AJ7: =NAV_MKT -> 12.552 | AK7: =IF(INVESTORS_LIST[[#This Row],[TOTAL CURRENT UNITS]]=0,0,INVESTORS_LIST[[#This Row],[TOTAL CURRENT UNITS]]*INVESTORS_LIST[[#This Row],[NAV]]) -> 0 | AL7: =IF(INVESTORS_LIST[[#This Row],[LS_TOTAL CURRENT UNITS]]=0,0,INVESTORS_LIST[[#This Row],[LS_TOTAL CURRENT UNITS]]*INVESTORS_LIST[[#This Row],[NAV]]) -> 0 | AM7: =IF(INVESTORS_LIST[[#This Row],[SIP_TOTAL CURRENT UNITS]]=0,0,INVESTORS_LIST[[#This Row],[SIP_TOTAL CURRENT UNITS]]*INVESTORS_LIST[[#This Row],[NAV]]) -> 0 | AO7: =IF(INVESTORS_LIST[[#This Row],[TOTAL SELLABLE UNITS]]=0,0,INVESTORS_LIST[[#This Row],[TOTAL SELLABLE UNITS]]*INVESTORS_LIST[[#This Row],[NAV]]) -> 0 | AP7: =INVESTORS_LIST[[#This Row],[LS_TOTAL REALIZED GAIN]]+INVESTORS_LIST[[#This Row],[SIP_TOTAL REALIZED GAIN]] -> -1000 | AQ7: =INVESTORS_LIST[[#This Row],[TOTAL MARKET VALUE]]-INVESTORS_LIST[[#This Row],[TOTAL COST VALUE OF CURRENT INVESTMENT]] -> 0 | AR7: =SUMIFS(DivAndTax[Tax Amount],DivAndTax[Investor ID],INVESTORS_LIST[[#This Row],[INVESTOR CODE]]) -> 0 | AS7: =SUMIFS(DivAndTax[Gross Dividend],DivAndTax[Investor ID],INVESTORS_LIST[[#This Row],[INVESTOR CODE]]) -> 0 | AT7: =IFERROR(INVESTORS_LIST[[#This Row],[TOTAL CURRENT UNITS]]/SUM(INVESTORS_LIST[TOTAL CURRENT UNITS]),0) -> 0
A8: JEWEL SAHA | B8: A00008 | C8: Dear Mr. | D8: Individual | E8: =SUMIFS(LS[Unit],LS[Investor ID],INVESTORS_LIST[[#This Row],[INVESTOR CODE]],LS[B/S],"B") -> 0 | F8: =-SUMIFS(LS[Unit],LS[Investor ID],INVESTORS_LIST[[#This Row],[INVESTOR CODE]],LS[B/S],"S") -> 0 | G8: =IF(INVESTORS_LIST[[#This Row],[LS_TOTAL UNITS BUY]]=0,0,INVESTORS_LIST[[#This Row],[LS_TOTAL UNITS BUY]]-INVESTORS_LIST[[#This Row],[LS_TOTAL UNITS SOLD]]) -> 0 | H8: =IF(INVESTORS_LIST[[#This Row],[LS_TOTAL UNITS BUY]]=0,0,SUMIFS(LS[Amount],LS[Investor ID],INVESTORS_LIST[[#This Row],[INVESTOR CODE]],LS[B/S],"B")) -> 0 | I8: =IF(INVESTORS_LIST[[#This Row],[LS_TOTAL UNITS SOLD]]=0,0,SUMIFS(LS[Cost of Units Sold],LS[Investor ID],INVESTORS_LIST[[#This Row],[INVESTOR CODE]],LS[B/S],"S")) -> 0 | J8: =IF(INVESTORS_LIST[[#This Row],[LS_TOTAL CURRENT UNITS]]=0,0,INVESTORS_LIST[[#This Row],[LS_TOTAL CURRENT UNITS]]*INVESTORS_LIST[[#This Row],[LS_AVERAGE COST]]) -> 0 | K8: =IF(INVESTORS_LIST[[#This Row],[LS_TOTAL UNITS SOLD]]=0,0,SUMIFS(LS[Realized Gain],LS[Investor ID],INVESTORS_LIST[[#This Row],[INVESTOR CODE]],LS[B/S],"S")) -> 0 | L8: =SUMIFS(SIP[Unit],SIP[Investor ID],INVESTORS_LIST[[#This Row],[INVESTOR CODE]],SIP[B/S],"B") -> 0 | M8: =-SUMIFS(SIP[Unit],SIP[Investor ID],INVESTORS_LIST[[#This Row],[INVESTOR CODE]],SIP[B/S],"S") -> 0 | N8: =IF(INVESTORS_LIST[[#This Row],[SIP_TOTAL UNITS BUY]]=0,0,INVESTORS_LIST[[#This Row],[SIP_TOTAL UNITS BUY]]-INVESTORS_LIST[[#This Row],[SIP_TOTAL UNITS SOLD]]) -> 0 | O8: =IF(INVESTORS_LIST[[#This Row],[SIP_TOTAL UNITS BUY]]=0,0,SUMIFS(SIP[Amount],SIP[Investor ID],INVESTORS_LIST[[#This Row],[INVESTOR CODE]],SIP[B/S],"B")) -> 0 | P8: =IF(INVESTORS_LIST[[#This Row],[SIP_TOTAL UNITS SOLD]]=0,0,SUMIFS(SIP[Cost of Units Sold],SIP[Investor ID],INVESTORS_LIST[[#This Row],[INVESTOR CODE]],SIP[B/S],"S")) -> 0 | Q8: =IF(INVESTORS_LIST[[#This Row],[SIP_TOTAL CURRENT UNITS]]=0,0,INVESTORS_LIST[[#This Row],[SIP_TOTAL CURRENT UNITS]]*INVESTORS_LIST[[#This Row],[SIP_AVERAGE COST]]) -> 0 | R8: =IF(INVESTORS_LIST[[#This Row],[SIP_TOTAL UNITS SOLD]]=0,0,SUMIFS(SIP[Realized Gain],SIP[Investor ID],INVESTORS_LIST[[#This Row],[INVESTOR CODE]],SIP[B/S],"S")) -> 0 | S8: =INVESTORS_LIST[[#This Row],[LS_TOTAL UNITS BUY]]+INVESTORS_LIST[[#This Row],[SIP_TOTAL UNITS BUY]] -> 0 | T8: =INVESTORS_LIST[[#This Row],[LS_TOTAL UNITS SOLD]]+INVESTORS_LIST[[#This Row],[SIP_TOTAL UNITS SOLD]] -> 0 | U8: 0 | V8: =SUMIFS(LS[BO UNIT TRANSFER],LS[Investor ID],INVESTORS_LIST[[#This Row],[INVESTOR CODE]],LS[B/S],"B") -> 0 | W8: =SUMIFS(LS[BO UNIT TRANSFER],LS[Investor ID],INVESTORS_LIST[[#This Row],[INVESTOR CODE]],LS[B/S],"S") -> 0 | X8: =SUMIFS(SIP[BO UNIT TRANSFER],SIP[Investor ID],INVESTORS_LIST[[#This Row],[INVESTOR CODE]],SIP[B/S],"S") -> 0 | Y8: =SUMIFS(SIP[BO UNIT TRANSFER],SIP[Investor ID],INVESTORS_LIST[[#This Row],[INVESTOR CODE]],SIP[B/S],"B") -> 0 | Z8: =INVESTORS_LIST[[#This Row],[BO OPENING BALANCE]]+INVESTORS_LIST[[#This Row],[LS- BO UNITS SELL]]+INVESTORS_LIST[[#This Row],[LS- BO UNITS REPURCHASE]]+INVESTORS_LIST[[#This Row],[SIP- BO UNITS REPURCHASE]]-INVESTORS_LIST[[#This Row],[SIP- BO UNITS SELL]] -> 0 | AA8: =INVESTORS_LIST[[#This Row],[TOTAL UNITS BUY]]-INVESTORS_LIST[[#This Row],[TOTAL UNITS SOLD]] -> 0 | AB8: =INVESTORS_LIST[[#This Row],[TOTAL CURRENT UNITS]]-INVESTORS_LIST[[#This Row],[BO UNITS HOLD]] -> 0 | AC8: =INDEX([4]!Table_1[BO ID],MATCH(INVESTORS_LIST[[#This Row],[INVESTOR CODE]],[4]!Table_1[INVESTOR CODE],0)) -> #REF! | AD8: =INVESTORS_LIST[[#This Row],[LS_TOTAL COST VALUE OF CURRENT UNITS]]+INVESTORS_LIST[[#This Row],[SIP_TOTAL COST VALUE OF CURRENT UNITS]] -> 0 | AE8: =IF(INVESTORS_LIST[[#This Row],[TOTAL CURRENT UNITS]]=0,0,INVESTORS_LIST[[#This Row],[LS_TOTAL CURRENT UNITS]]/INVESTORS_LIST[[#This Row],[TOTAL CURRENT UNITS]]) -> 0 | AF8: =IF(INVESTORS_LIST[[#This Row],[TOTAL CURRENT UNITS]]=0,0,INVESTORS_LIST[[#This Row],[SIP_TOTAL CURRENT UNITS]]/INVESTORS_LIST[[#This Row],[TOTAL CURRENT UNITS]]) -> 0 | AG8: {=IF(INVESTORS_LIST[[#This Row],[LS_TOTAL UNITS BUY]]>0,INDEX(LS[NAV at Cost (Average)],MATCH(CONCATENATE(COUNTIFS(LS[Investor ID],INVESTORS_LIST[[#This Row],[INVESTOR CODE]]),INVESTORS_LIST[[#This Row],[INVESTOR CODE]]),LS[Unique Code],0),),0)} -> 0 | AH8: {=IF(INVESTORS_LIST[[#This Row],[SIP_TOTAL UNITS BUY]]>0,INDEX(SIP[NAV at Cost (Average)],MATCH(CONCATENATE(COUNTIFS(SIP[Investor ID],INVESTORS_LIST[[#This Row],[INVESTOR CODE]]),INVESTORS_LIST[[#This Row],[INVESTOR CODE]]),SIP[Unique Code],0),),0)} -> 0 | AI8: =IF(INVESTORS_LIST[[#This Row],[TOTAL CURRENT UNITS]]=0,0,(INVESTORS_LIST[[#This Row],[LS_WEIGHT]]*INVESTORS_LIST[[#This Row],[LS_AVERAGE COST]])+(INVESTORS_LIST[[#This Row],[SIP_WEIGHT]]*INVESTORS_LIST[[#This Row],[SIP_AVERAGE COST]])) -> 0 | AJ8: =NAV_MKT -> 12.552 | AK8: =IF(INVESTORS_LIST[[#This Row],[TOTAL CURRENT UNITS]]=0,0,INVESTORS_LIST[[#This Row],[TOTAL CURRENT UNITS]]*INVESTORS_LIST[[#This Row],[NAV]]) -> 0 | AL8: =IF(INVESTORS_LIST[[#This Row],[LS_TOTAL CURRENT UNITS]]=0,0,INVESTORS_LIST[[#This Row],[LS_TOTAL CURRENT UNITS]]*INVESTORS_LIST[[#This Row],[NAV]]) -> 0 | AM8: =IF(INVESTORS_LIST[[#This Row],[SIP_TOTAL CURRENT UNITS]]=0,0,INVESTORS_LIST[[#This Row],[SIP_TOTAL CURRENT UNITS]]*INVESTORS_LIST[[#This Row],[NAV]]) -> 0 | AO8: =IF(INVESTORS_LIST[[#This Row],[TOTAL SELLABLE UNITS]]=0,0,INVESTORS_LIST[[#This Row],[TOTAL SELLABLE UNITS]]*INVESTORS_LIST[[#This Row],[NAV]]) -> 0 | AP8: =INVESTORS_LIST[[#This Row],[LS_TOTAL REALIZED GAIN]]+INVESTORS_LIST[[#This Row],[SIP_TOTAL REALIZED GAIN]] -> 0 | AQ8: =INVESTORS_LIST[[#This Row],[TOTAL MARKET VALUE]]-INVESTORS_LIST[[#This Row],[TOTAL COST VALUE OF CURRENT INVESTMENT]] -> 0 | AR8: =SUMIFS(DivAndTax[Tax Amount],DivAndTax[Investor ID],INVESTORS_LIST[[#This Row],[INVESTOR CODE]]) -> 0 | AS8: =SUMIFS(DivAndTax[Gross Dividend],DivAndTax[Investor ID],INVESTORS_LIST[[#This Row],[INVESTOR CODE]]) -> 0 | AT8: =IFERROR(INVESTORS_LIST[[#This Row],[TOTAL CURRENT UNITS]]/SUM(INVESTORS_LIST[TOTAL CURRENT UNITS]),0) -> 0
A9: SHIBBIR AHMED | B9: A00009 | C9: Dear Mr. | D9: Individual | E9: =SUMIFS(LS[Unit],LS[Investor ID],INVESTORS_LIST[[#This Row],[INVESTOR CODE]],LS[B/S],"B") -> 0 | F9: =-SUMIFS(LS[Unit],LS[Investor ID],INVESTORS_LIST[[#This Row],[INVESTOR CODE]],LS[B/S],"S") -> 0 | G9: =IF(INVESTORS_LIST[[#This Row],[LS_TOTAL UNITS BUY]]=0,0,INVESTORS_LIST[[#This Row],[LS_TOTAL UNITS BUY]]-INVESTORS_LIST[[#This Row],[LS_TOTAL UNITS SOLD]]) -> 0 | H9: =IF(INVESTORS_LIST[[#This Row],[LS_TOTAL UNITS BUY]]=0,0,SUMIFS(LS[Amount],LS[Investor ID],INVESTORS_LIST[[#This Row],[INVESTOR CODE]],LS[B/S],"B")) -> 0 | I9: =IF(INVESTORS_LIST[[#This Row],[LS_TOTAL UNITS SOLD]]=0,0,SUMIFS(LS[Cost of Units Sold],LS[Investor ID],INVESTORS_LIST[[#This Row],[INVESTOR CODE]],LS[B/S],"S")) -> 0 | J9: =IF(INVESTORS_LIST[[#This Row],[LS_TOTAL CURRENT UNITS]]=0,0,INVESTORS_LIST[[#This Row],[LS_TOTAL CURRENT UNITS]]*INVESTORS_LIST[[#This Row],[LS_AVERAGE COST]]) -> 0 | K9: =IF(INVESTORS_LIST[[#This Row],[LS_TOTAL UNITS SOLD]]=0,0,SUMIFS(LS[Realized Gain],LS[Investor ID],INVESTORS_LIST[[#This Row],[INVESTOR CODE]],LS[B/S],"S")) -> 0 | L9: =SUMIFS(SIP[Unit],SIP[Investor ID],INVESTORS_LIST[[#This Row],[INVESTOR CODE]],SIP[B/S],"B") -> 0 | M9: =-SUMIFS(SIP[Unit],SIP[Investor ID],INVESTORS_LIST[[#This Row],[INVESTOR CODE]],SIP[B/S],"S") -> 0 | N9: =IF(INVESTORS_LIST[[#This Row],[SIP_TOTAL UNITS BUY]]=0,0,INVESTORS_LIST[[#This Row],[SIP_TOTAL UNITS BUY]]-INVESTORS_LIST[[#This Row],[SIP_TOTAL UNITS SOLD]]) -> 0 | O9: =IF(INVESTORS_LIST[[#This Row],[SIP_TOTAL UNITS BUY]]=0,0,SUMIFS(SIP[Amount],SIP[Investor ID],INVESTORS_LIST[[#This Row],[INVESTOR CODE]],SIP[B/S],"B")) -> 0 | P9: =IF(INVESTORS_LIST[[#This Row],[SIP_TOTAL UNITS SOLD]]=0,0,SUMIFS(SIP[Cost of Units Sold],SIP[Investor ID],INVESTORS_LIST[[#This Row],[INVESTOR CODE]],SIP[B/S],"S")) -> 0 | Q9: =IF(INVESTORS_LIST[[#This Row],[SIP_TOTAL CURRENT UNITS]]=0,0,INVESTORS_LIST[[#This Row],[SIP_TOTAL CURRENT UNITS]]*INVESTORS_LIST[[#This Row],[SIP_AVERAGE COST]]) -> 0 | R9: =IF(INVESTORS_LIST[[#This Row],[SIP_TOTAL UNITS SOLD]]=0,0,SUMIFS(SIP[Realized Gain],SIP[Investor ID],INVESTORS_LIST[[#This Row],[INVESTOR CODE]],SIP[B/S],"S")) -> 0 | S9: =INVESTORS_LIST[[#This Row],[LS_TOTAL UNITS BUY]]+INVESTORS_LIST[[#This Row],[SIP_TOTAL UNITS BUY]] -> 0 | T9: =INVESTORS_LIST[[#This Row],[LS_TOTAL UNITS SOLD]]+INVESTORS_LIST[[#This Row],[SIP_TOTAL UNITS SOLD]] -> 0 | U9: 0 | V9: =SUMIFS(LS[BO UNIT TRANSFER],LS[Investor ID],INVESTORS_LIST[[#This Row],[INVESTOR CODE]],LS[B/S],"B") -> 0 | W9: =SUMIFS(LS[BO UNIT TRANSFER],LS[Investor ID],INVESTORS_LIST[[#This Row],[INVESTOR CODE]],LS[B/S],"S") -> 0 | X9: =SUMIFS(SIP[BO UNIT TRANSFER],SIP[Investor ID],INVESTORS_LIST[[#This Row],[INVESTOR CODE]],SIP[B/S],"S") -> 0 | Y9: =SUMIFS(SIP[BO UNIT TRANSFER],SIP[Investor ID],INVESTORS_LIST[[#This Row],[INVESTOR CODE]],SIP[B/S],"B") -> 0 | Z9: =INVESTORS_LIST[[#This Row],[BO OPENING BALANCE]]+INVESTORS_LIST[[#This Row],[LS- BO UNITS SELL]]+INVESTORS_LIST[[#This Row],[LS- BO UNITS REPURCHASE]]+INVESTORS_LIST[[#This Row],[SIP- BO UNITS REPURCHASE]]-INVESTORS_LIST[[#This Row],[SIP- BO UNITS SELL]] -> 0 | AA9: =INVESTORS_LIST[[#This Row],[TOTAL UNITS BUY]]-INVESTORS_LIST[[#This Row],[TOTAL UNITS SOLD]] -> 0 | AB9: =INVESTORS_LIST[[#This Row],[TOTAL CURRENT UNITS]]-INVESTORS_LIST[[#This Row],[BO UNITS HOLD]] -> 0 | AC9: =INDEX([4]!Table_1[BO ID],MATCH(INVESTORS_LIST[[#This Row],[INVESTOR CODE]],[4]!Table_1[INVESTOR CODE],0)) -> #REF! | AD9: =INVESTORS_LIST[[#This Row],[LS_TOTAL COST VALUE OF CURRENT UNITS]]+INVESTORS_LIST[[#This Row],[SIP_TOTAL COST VALUE OF CURRENT UNITS]] -> 0 | AE9: =IF(INVESTORS_LIST[[#This Row],[TOTAL CURRENT UNITS]]=0,0,INVESTORS_LIST[[#This Row],[LS_TOTAL CURRENT UNITS]]/INVESTORS_LIST[[#This Row],[TOTAL CURRENT UNITS]]) -> 0 | AF9: =IF(INVESTORS_LIST[[#This Row],[TOTAL CURRENT UNITS]]=0,0,INVESTORS_LIST[[#This Row],[SIP_TOTAL CURRENT UNITS]]/INVESTORS_LIST[[#This Row],[TOTAL CURRENT UNITS]]) -> 0 | AG9: {=IF(INVESTORS_LIST[[#This Row],[LS_TOTAL UNITS BUY]]>0,INDEX(LS[NAV at Cost (Average)],MATCH(CONCATENATE(COUNTIFS(LS[Investor ID],INVESTORS_LIST[[#This Row],[INVESTOR CODE]]),INVESTORS_LIST[[#This Row],[INVESTOR CODE]]),LS[Unique Code],0),),0)} -> 0 | AH9: {=IF(INVESTORS_LIST[[#This Row],[SIP_TOTAL UNITS BUY]]>0,INDEX(SIP[NAV at Cost (Average)],MATCH(CONCATENATE(COUNTIFS(SIP[Investor ID],INVESTORS_LIST[[#This Row],[INVESTOR CODE]]),INVESTORS_LIST[[#This Row],[INVESTOR CODE]]),SIP[Unique Code],0),),0)} -> 0 | AI9: =IF(INVESTORS_LIST[[#This Row],[TOTAL CURRENT UNITS]]=0,0,(INVESTORS_LIST[[#This Row],[LS_WEIGHT]]*INVESTORS_LIST[[#This Row],[LS_AVERAGE COST]])+(INVESTORS_LIST[[#This Row],[SIP_WEIGHT]]*INVESTORS_LIST[[#This Row],[SIP_AVERAGE COST]])) -> 0 | AJ9: =NAV_MKT -> 12.552 | AK9: =IF(INVESTORS_LIST[[#This Row],[TOTAL CURRENT UNITS]]=0,0,INVESTORS_LIST[[#This Row],[TOTAL CURRENT UNITS]]*INVESTORS_LIST[[#This Row],[NAV]]) -> 0 | AL9: =IF(INVESTORS_LIST[[#This Row],[LS_TOTAL CURRENT UNITS]]=0,0,INVESTORS_LIST[[#This Row],[LS_TOTAL CURRENT UNITS]]*INVESTORS_LIST[[#This Row],[NAV]]) -> 0 | AM9: =IF(INVESTORS_LIST[[#This Row],[SIP_TOTAL CURRENT UNITS]]=0,0,INVESTORS_LIST[[#This Row],[SIP_TOTAL CURRENT UNITS]]*INVESTORS_LIST[[#This Row],[NAV]]) -> 0 | AO9: =IF(INVESTORS_LIST[[#This Row],[TOTAL SELLABLE UNITS]]=0,0,INVESTORS_LIST[[#This Row],[TOTAL SELLABLE UNITS]]*INVESTORS_LIST[[#This Row],[NAV]]) -> 0 | AP9: =INVESTORS_LIST[[#This Row],[LS_TOTAL REALIZED GAIN]]+INVESTORS_LIST[[#This Row],[SIP_TOTAL REALIZED GAIN]] -> 0 | AQ9: =INVESTORS_LIST[[#This Row],[TOTAL MARKET VALUE]]-INVESTORS_LIST[[#This Row],[TOTAL COST VALUE OF CURRENT INVESTMENT]] -> 0 | AR9: =SUMIFS(DivAndTax[Tax Amount],DivAndTax[Investor ID],INVESTORS_LIST[[#This Row],[INVESTOR CODE]]) -> 0 | AS9: =SUMIFS(DivAndTax[Gross Dividend],DivAndTax[Investor ID],INVESTORS_LIST[[#This Row],[INVESTOR CODE]]) -> 0 | AT9: =IFERROR(INVESTORS_LIST[[#This Row],[TOTAL CURRENT UNITS]]/SUM(INVESTORS_LIST[TOTAL CURRENT UNITS]),0) -> 0
A10: SHYAMAL KRISHNA SAHA | B10: A00010 | C10: Dear Mr. | D10: Individual | E10: =SUMIFS(LS[Unit],LS[Investor ID],INVESTORS_LIST[[#This Row],[INVESTOR CODE]],LS[B/S],"B") -> 50000 | F10: =-SUMIFS(LS[Unit],LS[Investor ID],INVESTORS_LIST[[#This Row],[INVESTOR CODE]],LS[B/S],"S") -> 50000 | G10: =IF(INVESTORS_LIST[[#This Row],[LS_TOTAL UNITS BUY]]=0,0,INVESTORS_LIST[[#This Row],[LS_TOTAL UNITS BUY]]-INVESTORS_LIST[[#This Row],[LS_TOTAL UNITS SOLD]]) -> 0 | H10: =IF(INVESTORS_LIST[[#This Row],[LS_TOTAL UNITS BUY]]=0,0,SUMIFS(LS[Amount],LS[Investor ID],INVESTORS_LIST[[#This Row],[INVESTOR CODE]],LS[B/S],"B")) -> 500000 | I10: =IF(INVESTORS_LIST[[#This Row],[LS_TOTAL UNITS SOLD]]=0,0,SUMIFS(LS[Cost of Units Sold],LS[Investor ID],INVESTORS_LIST[[#This Row],[INVESTOR CODE]],LS[B/S],"S")) -> 500000 | J10: =IF(INVESTORS_LIST[[#This Row],[LS_TOTAL CURRENT UNITS]]=0,0,INVESTORS_LIST[[#This Row],[LS_TOTAL CURRENT UNITS]]*INVESTORS_LIST[[#This Row],[LS_AVERAGE COST]]) -> 0 | K10: =IF(INVESTORS_LIST[[#This Row],[LS_TOTAL UNITS SOLD]]=0,0,SUMIFS(LS[Realized Gain],LS[Investor ID],INVESTORS_LIST[[#This Row],[INVESTOR CODE]],LS[B/S],"S")) -> 1000 | L10: =SUMIFS(SIP[Unit],SIP[Investor ID],INVESTORS_LIST[[#This Row],[INVESTOR CODE]],SIP[B/S],"B") -> 0 | M10: =-SUMIFS(SIP[Unit],SIP[Investor ID],INVESTORS_LIST[[#This Row],[INVESTOR CODE]],SIP[B/S],"S") -> 0 | N10: =IF(INVESTORS_LIST[[#This Row],[SIP_TOTAL UNITS BUY]]=0,0,INVESTORS_LIST[[#This Row],[SIP_TOTAL UNITS BUY]]-INVESTORS_LIST[[#This Row],[SIP_TOTAL UNITS SOLD]]) -> 0 | O10: =IF(INVESTORS_LIST[[#This Row],[SIP_TOTAL UNITS BUY]]=0,0,SUMIFS(SIP[Amount],SIP[Investor ID],INVESTORS_LIST[[#This Row],[INVESTOR CODE]],SIP[B/S],"B")) -> 0 | P10: =IF(INVESTORS_LIST[[#This Row],[SIP_TOTAL UNITS SOLD]]=0,0,SUMIFS(SIP[Cost of Units Sold],SIP[Investor ID],INVESTORS_LIST[[#This Row],[INVESTOR CODE]],SIP[B/S],"S")) -> 0 | Q10: =IF(INVESTORS_LIST[[#This Row],[SIP_TOTAL CURRENT UNITS]]=0,0,INVESTORS_LIST[[#This Row],[SIP_TOTAL CURRENT UNITS]]*INVESTORS_LIST[[#This Row],[SIP_AVERAGE COST]]) -> 0 | R10: =IF(INVESTORS_LIST[[#This Row],[SIP_TOTAL UNITS SOLD]]=0,0,SUMIFS(SIP[Realized Gain],SIP[Investor ID],INVESTORS_LIST[[#This Row],[INVESTOR CODE]],SIP[B/S],"S")) -> 0 | S10: =INVESTORS_LIST[[#This Row],[LS_TOTAL UNITS BUY]]+INVESTORS_LIST[[#This Row],[SIP_TOTAL UNITS BUY]] -> 50000 | T10: =INVESTORS_LIST[[#This Row],[LS_TOTAL UNITS SOLD]]+INVESTORS_LIST[[#This Row],[SIP_TOTAL UNITS SOLD]] -> 50000 | U10: 50000 | V10: =SUMIFS(LS[BO UNIT TRANSFER],LS[Investor ID],INVESTORS_LIST[[#This Row],[INVESTOR CODE]],LS[B/S],"B") -> 0 | W10: =SUMIFS(LS[BO UNIT TRANSFER],LS[Investor ID],INVESTORS_LIST[[#This Row],[INVESTOR CODE]],LS[B/S],"S") -> 0 | X10: =SUMIFS(SIP[BO UNIT TRANSFER],SIP[Investor ID],INVESTORS_LIST[[#This Row],[INVESTOR CODE]],SIP[B/S],"S") -> 0 | Y10: =SUMIFS(SIP[BO UNIT TRANSFER],SIP[Investor ID],INVESTORS_LIST[[#This Row],[INVESTOR CODE]],SIP[B/S],"B") -> 0 | Z10: =INVESTORS_LIST[[#This Row],[BO OPENING BALANCE]]+INVESTORS_LIST[[#This Row],[LS- BO UNITS SELL]]+INVESTORS_LIST[[#This Row],[LS- BO UNITS REPURCHASE]]+INVESTORS_LIST[[#This Row],[SIP- BO UNITS REPURCHASE]]-INVESTORS_LIST[[#This Row],[SIP- BO UNITS SELL]] -> 50000 | AA10: =INVESTORS_LIST[[#This Row],[TOTAL UNITS BUY]]-INVESTORS_LIST[[#This Row],[TOTAL UNITS SOLD]] -> 0 | AB10: =INVESTORS_LIST[[#This Row],[TOTAL CURRENT UNITS]]-INVESTORS_LIST[[#This Row],[BO UNITS HOLD]] -> -50000 | AC10: =INDEX([4]!Table_1[BO ID],MATCH(INVESTORS_LIST[[#This Row],[INVESTOR CODE]],[4]!Table_1[INVESTOR CODE],0)) -> #REF! | AD10: =INVESTORS_LIST[[#This Row],[LS_TOTAL COST VALUE OF CURRENT UNITS]]+INVESTORS_LIST[[#This Row],[SIP_TOTAL COST VALUE OF CURRENT UNITS]] -> 0 | AE10: =IF(INVESTORS_LIST[[#This Row],[TOTAL CURRENT UNITS]]=0,0,INVESTORS_LIST[[#This Row],[LS_TOTAL CURRENT UNITS]]/INVESTORS_LIST[[#This Row],[TOTAL CURRENT UNITS]]) -> 0 | AF10: =IF(INVESTORS_LIST[[#This Row],[TOTAL CURRENT UNITS]]=0,0,INVESTORS_LIST[[#This Row],[SIP_TOTAL CURRENT UNITS]]/INVESTORS_LIST[[#This Row],[TOTAL CURRENT UNITS]]) -> 0 | AG10: {=IF(INVESTORS_LIST[[#This Row],[LS_TOTAL UNITS BUY]]>0,INDEX(LS[NAV at Cost (Average)],MATCH(CONCATENATE(COUNTIFS(LS[Investor ID],INVESTORS_LIST[[#This Row],[INVESTOR CODE]]),INVESTORS_LIST[[#This Row],[INVESTOR CODE]]),LS[Unique Code],0),),0)} -> 0 | AH10: {=IF(INVESTORS_LIST[[#This Row],[SIP_TOTAL UNITS BUY]]>0,INDEX(SIP[NAV at Cost (Average)],MATCH(CONCATENATE(COUNTIFS(SIP[Investor ID],INVESTORS_LIST[[#This Row],[INVESTOR CODE]]),INVESTORS_LIST[[#This Row],[INVESTOR CODE]]),SIP[Unique Code],0),),0)} -> 0 | AI10: =IF(INVESTORS_LIST[[#This Row],[TOTAL CURRENT UNITS]]=0,0,(INVESTORS_LIST[[#This Row],[LS_WEIGHT]]*INVESTORS_LIST[[#This Row],[LS_AVERAGE COST]])+(INVESTORS_LIST[[#This Row],[SIP_WEIGHT]]*INVESTORS_LIST[[#This Row],[SIP_AVERAGE COST]])) -> 0 | AJ10: =NAV_MKT -> 12.552 | AK10: =IF(INVESTORS_LIST[[#This Row],[TOTAL CURRENT UNITS]]=0,0,INVESTORS_LIST[[#This Row],[TOTAL CURRENT UNITS]]*INVESTORS_LIST[[#This Row],[NAV]]) -> 0 | AL10: =IF(INVESTORS_LIST[[#This Row],[LS_TOTAL CURRENT UNITS]]=0,0,INVESTORS_LIST[[#This Row],[LS_TOTAL CURRENT UNITS]]*INVESTORS_LIST[[#This Row],[NAV]]) -> 0 | AM10: =IF(INVESTORS_LIST[[#This Row],[SIP_TOTAL CURRENT UNITS]]=0,0,INVESTORS_LIST[[#This Row],[SIP_TOTAL CURRENT UNITS]]*INVESTORS_LIST[[#This Row],[NAV]]) -> 0 | AO10: =IF(INVESTORS_LIST[[#This Row],[TOTAL SELLABLE UNITS]]=0,0,INVESTORS_LIST[[#This Row],[TOTAL SELLABLE UNITS]]*INVESTORS_LIST[[#This Row],[NAV]]) -> 0 | AP10: =INVESTORS_LIST[[#This Row],[LS_TOTAL REALIZED GAIN]]+INVESTORS_LIST[[#This Row],[SIP_TOTAL REALIZED GAIN]] -> 1000 | AQ10: =INVESTORS_LIST[[#This Row],[TOTAL MARKET VALUE]]-INVESTORS_LIST[[#This Row],[TOTAL COST VALUE OF CURRENT INVESTMENT]] -> 0 | AR10: =SUMIFS(DivAndTax[Tax Amount],DivAndTax[Investor ID],INVESTORS_LIST[[#This Row],[INVESTOR CODE]]) -> 0 | AS10: =SUMIFS(DivAndTax[Gross Dividend],DivAndTax[Investor ID],INVESTORS_LIST[[#This Row],[INVESTOR CODE]]) -> 0 | AT10: =IFERROR(INVESTORS_LIST[[#This Row],[TOTAL CURRENT UNITS]]/SUM(INVESTORS_LIST[TOTAL CURRENT UNITS]),0) -> 0
