Workbook
Name CURRENT_NAV: BS!$C$45
Name NAV: BS!$C$43
Name NAV_MKT: Journals!$T$1
Name TCV_STOCKS: #REF!
Name TMV_STOCKS: #REF!

Sheet Chart of Accounts
B2: Accounts Name | C2: Normal Balance
B3: Investments in stock | C3: DEBIT
B4: Interest Receivables from Bank A/C | C4: DEBIT
B5: Preliminary & issue expenses | C5: DEBIT
B6: Accrued Management Fee | C6: CREDIT
B7: Accrued Trustee Fee | C7: CREDIT
B8: Accrued Custodian Fee | C8: CREDIT
B9: Accrued BSEC fee | C9: CREDIT
B10: Accrued Audit Fee | C10: CREDIT
B11: Accrued CDBL Fee | C11: CREDIT
B12: Fixed Deposit Receipts (FDR) | C12: DEBIT
B13: Cash and cash equivalents | C13: DEBIT
... B19: Unrealized gain on securities | C19: CREDIT
B20: Unrealized gain on T-Bill
B21: Unrealized gain on T-Bond
B22: Unrealized loss on securities | C22: DEBIT
B23: Amortization of preliminary and issue expense | C23: DEBIT
B24: Management Fee | C24: DEBIT
B25: Trustee fee | C25: DEBIT
B26: BSEC Annual Fee | C26: DEBIT
B27: Audit fee | C27: DEBIT
B28: CDBL charges | C28: DEBIT
B29: Fair value adjustment | C29: DEBIT
B30: Fair value adjustment T-Bill
B31: Fair value adjustment T-Bond
B32: Interest receivables from FDR | C32: DEBIT
B33: Payable to broker | C33: CREDIT
B34: Other operating expenses | C34: DEBIT
B35: Dividend income | C35: CREDIT
B36: Dividend receivable | C36: DEBIT
B37: Custodian fee | C37: DEBIT
B38: IPO Application | C38: DEBIT
B39: IPO Application Fee | C39: DEBIT
B40: Receivable from broker | C40: DEBIT
B41: Realized gain | C41: CREDIT
B42: Realized gain on T-Bill
B43: Realized gain on T-Bond
B44: Other Income | C44: CREDIT
B45: Dividend Equalization Reserve | C45: CREDIT
B46: Retained Earnings
...

Sheet INVESTORS_LIST
A1: INVESTOR NAME | B1: INVESTOR CODE
A2: HARI PADA SAHA | B2: A00002
A3: EKUSH WEALTH MANAGEMENT LIMITED | B3: A00003
A4: SADIA AHMED | B4: A00004
A5: MORSHEDA MIM | B5: A00005
A6: MD. JAHANGIR ALAM | B6: A00006
A7: BISWAS ARIFUR RAHMAN | B7: A00007
A8: JEWEL SAHA | B8: A00008
A9: SHIBBIR AHMED | B9: A00009
A10: SHYAMAL KRISHNA SAHA | B10: A00010
A11: NASRIN AKHTER | B11: A00011
A12: MRINMOY GHOSH | B12: A00012
... A500: MUHAMMAD SAJJAD HOSSAIN | B500: A00500

Sheet Journals
A2: Check of Journal Entries | L2: =K6-L6 -> 0.044296265
A3: Check of Trial Balance | L3: =SUM('TB-C'!H7:H5011)-SUM('TB-C'!I7:I5011) -> 0.035499945
A4: Check of Balance Seet | L4: =BS!C25-BS!C41 -> 0
A5: Check of Cash Balance | G5: =BS!C23-CF!B44 -> -3620314.1
J6: =K6-L6 -> 0.044296265 | K6: =SUBTOTAL(9,K9:K16883) -> 4.7981054e+09 | L6: =SUBTOTAL(9,L9:L16883) -> 4.7981054e+09
A7: Year | B7: Month | C7: Day | D7: Value | F7: Transaction | G7: Transaction Type | J7: Account Name | K7: Debit | L7: Credit
E8: Date
A9: 2021 | B9: 10 | C9: 13 | D9: =DATE(A9,B9,C9) -> 44482 | E9: =DATE(A9,B9,C9) -> 44482 | F9: Unit Subscription - LUMPSUM | G9: C | H9: {=IFERROR(INDEX(INVESTOR_LIST[INVESTOR NAME],MATCH(I9,INVESTOR_LIST[INVESTOR CODE],0),)," ")} -> EKUSH WEALTH MANAGEMENT LIMITED | I9: A00003 | J9: Cash and cash equivalents | K9: 1000
A10: 2021 | B10: 10 | C10: 13 | D10: =DATE(A10,B10,C10) -> 44482 | E10: =DATE(A10,B10,C10) -> 44482 | G10: C | H10: {=IFERROR(INDEX(INVESTOR_LIST[INVESTOR NAME],MATCH(I10,INVESTOR_LIST[INVESTOR CODE],0),)," ")} -> EKUSH WEALTH MANAGEMENT LIMITED | I10: A00003 | J10: Unit Capital | L10: 1000
A11: 2021 | B11: 10 | C11: 18 | D11: =DATE(A11,B11,C11) -> 44487 | E11: =DATE(A11,B11,C11) -> 44487 | F11: Unit Subscription - LUMPSUM | G11: C | H11: {=IFERROR(INDEX(INVESTOR_LIST[INVESTOR NAME],MATCH(I11,INVESTOR_LIST[INVESTOR CODE],0),)," ")} -> EKUSH WEALTH MANAGEMENT LIMITED | I11: A00003 | J11: Cash and cash equivalents | K11: 10000000
A12: 2021 | B12: 10 | C12: 18 | D12: =DATE(A12,B12,C12) -> 44487 | E12: =DATE(A12,B12,C12) -> 44487 | G12: C | H12: {=IFERROR(INDEX(INVESTOR_LIST[INVESTOR NAME],MATCH(I12,INVESTOR_LIST[INVESTOR CODE],0),)," ")} -> EKUSH WEALTH MANAGEMENT LIMITED | I12: A00003 | J12: Unit Capital | L12: 10000000
A13: 2021 | B13: 10 | C13: 18 | D13: =DATE(A13,B13,C13) -> 44487 | E13: =DATE(A13,B13,C13) -> 44487 | F13: Bank Charges | G13: C | H13: {=IFERROR(INDEX(INVESTOR_LIST[INVESTOR NAME],MATCH(I13,INVESTOR_LIST[INVESTOR CODE],0),)," ")} | J13: Bank charges and excise duties | K13: 60
A14: 2021 | B14: 10 | C14: 18 | D14: =DATE(A14,B14,C14) -> 44487 | E14: =DATE(A14,B14,C14) -> 44487 | G14: C | H14: {=IFERROR(INDEX(INVESTOR_LIST[INVESTOR NAME],MATCH(I14,INVESTOR_LIST[INVESTOR CODE],0),)," ")} | J14: Cash and cash equivalents | L14: 60
A15: 2021 | B15: 11 | C15: 4 | D15: =DATE(A15,B15,C15) -> 44504 | E15: =DATE(A15,B15,C15) -> 44504 | F15: Unit Subscription - LUMPSUM | G15: C | H15: {=IFERROR(INDEX(INVESTOR_LIST[INVESTOR NAME],MATCH(I15,INVESTOR_LIST[INVESTOR CODE],0),)," ")} -> JHARNA RANI SAHA | I15: A00077 | J15: Cash and cash equivalents | K15: 150000
A16: 2021 | B16: 11 | C16: 4 | D16: =DATE(A16,B16,C16) -> 44504 | E16: =DATE(A16,B16,C16) -> 44504 | G16: C | H16: {=IFERROR(INDEX(INVESTOR_LIST[INVESTOR NAME],MATCH(I16,INVESTOR_LIST[INVESTOR CODE],0),)," ")} -> JHARNA RANI SAHA | I16: A00077 | J16: Unit Capital | L16: 150000
A17: 2021 | B17: 11 | C17: 8 | D17: =DATE(A17,B17,C17) -> 44508 | E17: =DATE(A17,B17,C17) -> 44508 | F17: Unit Subscription - LUMPSUM | G17: C | H17: {=IFERROR(INDEX(INVESTOR_LIST[INVESTOR NAME],MATCH(I17,INVESTOR_LIST[INVESTOR CODE],0),)," ")} -> SHUVA SAHA | I17: A00053 | J17: Cash and cash equivalents | K17: 1200000
A18: 2021 | B18: 11 | C18: 8 | D18: =DATE(A18,B18,C18) -> 44508 | E18: =DATE(A18,B18,C18) -> 44508 | G18: C | H18: {=IFERROR(INDEX(INVESTOR_LIST[INVESTOR NAME],MATCH(I18,INVESTOR_LIST[INVESTOR CODE],0),)," ")} -> SHUVA SAHA | I18: A00053 | J18: Unit Capital | L18: 1200000
A19: 2021 | B19: 11 | C19: 8 | D19: =DATE(A19,B19,C19) -> 44508 | E19: =DATE(A19,B19,C19) -> 44508 | F19: Unit Subscription - LUMPSUM | G19: C | H19: {=IFERROR(INDEX(INVESTOR_LIST[INVESTOR NAME],MATCH(I19,INVESTOR_LIST[INVESTOR CODE],0),)," ")} -> SHYAMAL KRISHNA SAHA | I19: A00010 | J19: Cash and cash equivalents | K19: 500000
A20: 2021 | B20: 11 | C20: 8 | D20: =DATE(A20,B20,C20) -> 44508 | E20: =DATE(A20,B20,C20) -> 44508 | G20: C | H20: {=IFERROR(INDEX(INVESTOR_LIST[INVESTOR NAME],MATCH(I20,INVESTOR_LIST[INVESTOR CODE],0),)," ")} -> SHYAMAL KRISHNA SAHA | I20: A00010 | J20: Unit Capital | L20: 500000
A21: 2021 | B21: 11 | C21: 9 | D21: =DATE(A21,B21,C21) -> 44509 | E21: =DATE(A21,B21,C21) -> 44509 | F21: Bank Charges | G21: C | H21: {=IFERROR(INDEX(INVESTOR_LIST[INVESTOR NAME],MATCH(I21,INVESTOR_LIST[INVESTOR CODE],0),)," ")} | J21: Bank charges and excise duties | K21: 10
A22: 2021 | B22: 11 | C22: 9 | D22: =DATE(A22,B22,C22) -> 44509 | E22: =DATE(A22,B22,C22) -> 44509 | G22: C | H22: {=IFERROR(INDEX(INVESTOR_LIST[INVESTOR NAME],MATCH(I22,INVESTOR_LIST[INVESTOR CODE],0),)," ")} | J22: Cash and cash equivalents | L22: 10
A23: 2021 | B23: 11 | C23: 9 | D23: =DATE(A23,B23,C23) -> 44509 | E23: =DATE(A23,B23,C23) -> 44509 | F23: Unit Subscription - LUMPSUM | G23: C | H23: {=IFERROR(INDEX(INVESTOR_LIST[INVESTOR NAME],MATCH(I23,INVESTOR_LIST[INVESTOR CODE],0),)," ")} -> BILKISS ARA | I23: A00073 | J23: Cash and cash equivalents | K23: 450000
A24: 2021 | B24: 11 | C24: 9 | D24: =DATE(A24,B24,C24) -> 44509 | E24: =DATE(A24,B24,C24) -> 44509 | G24: C | H24: {=IFERROR(INDEX(INVESTOR_LIST[INVESTOR NAME],MATCH(I24,INVESTOR_LIST[INVESTOR CODE],0),)," ")} -> BILKISS ARA | I24: A00073 | J24: Unit Capital | L24: 450000
A25: 2021 | B25: 11 | C25: 25 | D25: =DATE(A25,B25,C25) -> 44525 | E25: =DATE(A25,B25,C25) -> 44525 | F25: Unit Subscription - LUMPSUM | G25: C | H25: {=IFERROR(INDEX(INVESTOR_LIST[INVESTOR NAME],MATCH(I25,INVESTOR_LIST[INVESTOR CODE],0),)," ")} -> HARI PADA SAHA | I25: A00002 | J25: Cash and cash equivalents | K25: 200000
A26: 2021 | B26: 11 | C26: 25 | D26: =DATE(A26,B26,C26) -> 44525 | E26: =DATE(A26,B26,C26) -> 44525 | G26: C | H26: {=IFERROR(INDEX(INVESTOR_LIST[INVESTOR NAME],MATCH(I26,INVESTOR_LIST[INVESTOR CODE],0),)," ")} -> HARI PADA SAHA | I26: A00002 | J26: Unit Capital | L26: 200000
A27: 2021 | B27: 12 | C27: 26 | D27: =DATE(A27,B27,C27) -> 44556 | E27: =DATE(A27,B27,C27) -> 44556 | F27: Bank Charges | G27: C | H27: {=IFERROR(INDEX(INVESTOR_LIST[INVESTOR NAME],MATCH(I27,INVESTOR_LIST[INVESTOR CODE],0),)," ")} | J27: Bank charges and excise duties | K27: 10
A28: 2021 | B28: 12 | C28: 26 | D28: =DATE(A28,B28,C28) -> 44556 | E28: =DATE(A28,B28,C28) -> 44556 | G28: C | H28: {=IFERROR(INDEX(INVESTOR_LIST[INVESTOR NAME],MATCH(I28,INVESTOR_LIST[INVESTOR CODE],0),)," ")} | J28: Cash and cash equivalents | L28: 10
A29: 2021 | B29: 12 | C29: 26 | D29: =DATE(A29,B29,C29) -> 44556 | E29: =DATE(A29,B29,C29) -> 44556 | F29: Bank Charges | G29: C | H29: {=IFERROR(INDEX(INVESTOR_LIST[INVESTOR NAME],MATCH(I29,INVESTOR_LIST[INVESTOR CODE],0),)," ")} | J29: Bank charges and excise duties | K29: 10
A30: 2021 | B30: 12 | C30: 26 | D30: =DATE(A30,B30,C30) -> 44556 | E30: =DATE(A30,B30,C30) -> 44556 | G30: C | H30: {=IFERROR(INDEX(INVESTOR_LIST[INVESTOR NAME],MATCH(I30,INVESTOR_LIST[INVESTOR CODE],0),)," ")} | J30: Cash and cash equivalents | L30: 10
A31: 2021 | B31: 12 | C31: 26 | D31: =DATE(A31,B31,C31) -> 44556 | E31: =DATE(A31,B31,C31) -> 44556 | F31: Unit Subscription - LUMPSUM | G31: C | H31: {=IFERROR(INDEX(INVESTOR_LIST[INVESTOR NAME],MATCH(I31,INVESTOR_LIST[INVESTOR CODE],0),)," ")} -> JANNATUL FERDOUS SHARNA | I31: A00301 | J31: Cash and cash equivalents | K31: 200000
A32: 2021 | B32: 12 | C32: 26 | D32: =DATE(A32,B32,C32) -> 44556 | E32: =DATE(A32,B32,C32) -> 44556 | G32: C | H32: {=IFERROR(INDEX(INVESTOR_LIST[INVESTOR NAME],MATCH(I32,INVESTOR_LIST[INVESTOR CODE],0),)," ")} -> JANNATUL FERDOUS SHARNA | I32: A00301 | J32: Unit Capital | L32: 200000
A33: 2021 | B33: 12 | C33: 26 | D33: =DATE(A33,B33,C33) -> 44556 | E33: =DATE(A33,B33,C33) -> 44556 | F33: Unit Subscription - LUMPSUM | G33: C | H33: {=IFERROR(INDEX(INVESTOR_LIST[INVESTOR NAME],MATCH(I33,INVESTOR_LIST[INVESTOR CODE],0),)," ")} -> BIJOY CHANDRA DAS | I33: A00224 | J33: Cash and cash equivalents | K33: 100000
A34: 2021 | B34: 12 | C34: 26 | D34: =DATE(A34,B34,C34) -> 44556 | E34: =DATE(A34,B34,C34) -> 44556 | G34: C | H34: {=IFERROR(INDEX(INVESTOR_LIST[INVESTOR NAME],MATCH(I34,INVESTOR_LIST[INVESTOR CODE],0),)," ")} -> BIJOY CHANDRA DAS | I34: A00224 | J34: Unit Capital | L34: 100000
A35: 2021 | B35: 12 | C35: 30 | D35: =DATE(A35,B35,C35) -> 44560 | E35: =DATE(A35,B35,C35) -> 44560 | F35: Unit Subscription - LUMPSUM | G35: C | H35: {=IFERROR(INDEX(INVESTOR_LIST[INVESTOR NAME],MATCH(I35,INVESTOR_LIST[INVESTOR CODE],0),)," ")} -> SHARMIN JAHAN SHANTA | I35: A00318 | J35: Cash and cash equivalents | K35: 50000
A36: 2021 | B36: 12 | C36: 30 | D36: =DATE(A36,B36,C36) -> 44560 | E36: =DATE(A36,B36,C36) -> 44560 | G36: C | H36: {=IFERROR(INDEX(INVESTOR_LIST[INVESTOR NAME],MATCH(I36,INVESTOR_LIST[INVESTOR CODE],0),)," ")} -> SHARMIN JAHAN SHANTA | I36: A00318 | J36: Unit Capital | L36: 50000
A37: 2021 | B37: 12 | C37: 30 | D37: =DATE(A37,B37,C37) -> 44560 | E37: =DATE(A37,B37,C37) -> 44560 | F37: Bank Charges | G37: C | H37: {=IFERROR(INDEX(INVESTOR_LIST[INVESTOR NAME],MATCH(I37,INVESTOR_LIST[INVESTOR CODE],0),)," ")} | J37: Bank charges and excise duties | K37: 345
A38: 2021 | B38: 12 | C38: 30 | D38: =DATE(A38,B38,C38) -> 44560 | E38: =DATE(A38,B38,C38) -> 44560 | G38: C | H38: {=IFERROR(INDEX(INVESTOR_LIST[INVESTOR NAME],MATCH(I38,INVESTOR_LIST[INVESTOR CODE],0),)," ")} | J38: Cash and cash equivalents | L38: 345
A39: 2021 | B39: 12 | C39: 30 | D39: =DATE(A39,B39,C39) -> 44560 | E39: =DATE(A39,B39,C39) -> 44560 | F39: Interest Income - Bank | G39: C | H39: {=IFERROR(INDEX(INVESTOR_LIST[INVESTOR NAME],MATCH(I39,INVESTOR_LIST[INVESTOR CODE],0),)," ")} | J39: Cash and cash equivalents | K39: 107974
A40: 2021 | B40: 12 | C40: 30 | D40: =DATE(A40,B40,C40) -> 44560 | E40: =DATE(A40,B40,C40) -> 44560 | G40: C | H40: {=IFERROR(INDEX(INVESTOR_LIST[INVESTOR NAME],MATCH(I40,INVESTOR_LIST[INVESTOR CODE],0),)," ")} | J40: Interest Income | L40: 107974
A41: 2021 | B41: 12 | C41: 30 | D41: =DATE(A41,B41,C41) -> 44560 | E41: =DATE(A41,B41,C41) -> 44560 | F41: Bank Charges | G41: C | H41: {=IFERROR(INDEX(INVESTOR_LIST[INVESTOR NAME],MATCH(I41,INVESTOR_LIST[INVESTOR CODE],0),)," ")} | J41: Bank charges and excise duties | K41: 16196
...

Sheet TB-C
A1: Check of Trial Balance | G1: =SUM(H7:H88)-SUM(I7:I88) -> 0.035499945
A2: Check of Balance Sheet | G2: =BS!C25-BS!C41 -> 0
A3: Check of Cash Balance | G3: =BS!C23-CF!B44 -> -3620314.1
B5: Desired Reporting Period | H5: During the Reporting Period | J5: For Balance Sheet | N5: For Retained Earnings
B6: Year | C6: Month | D6: Day | E6: Value | F6: Value | G6: Accounts | H6: Debit | I6: Credit | J6: Carry Forward Balance | K6: Carry Forward Balance | L6: On date | M6: On date | N6: Debit | O6: Credit
A7: Beginning | B7: 2026 | C7: 1 | D7: 1 | E7: =DATE(B7,C7,D7)-1 -> 46022 | F7: =DATE(B7,C7,D7) -> 46023 | G7: ='Chart of Accounts'!B3 -> Investments in stock | H7: =MAX(0,SUMIFS(Journals!$K$9:$K$1005679,Journals!$D$9:$D$1005679,">"&$E$7,Journals!$D$9:$D$1005679,"<"&$E$8,Journals!$J$9:$J$1005679,"investments in stock")-SUMIFS(Journals!$L$9:$L$1005679,Journals!$D$9:$D$1005679,">"&$E$7,Journals!$D$9:$D$1005679,"<"&$E$8,Journals!$J$9:$J$1005679,"investments in stock")) -> 34499330 | I7: =MAX(0,SUMIFS(Journals!$L$9:$L$1005679,Journals!$D$9:$D$1005679,">"&$E$7,Journals!$D$9:$D$1005679,"<"&$E$8,Journals!$J$9:$J$1005679,"Investments in stock")-SUMIFS(Journals!$K$9:$K$1005679,Journals!$D$9:$D$1005679,">"&$E$7,Journals!$D$9:$D$1005679,"<"&$E$8,Journals!$J$9:$J$1005679,"Investments in stock")) -> 0 | J7: =SUMIFS(Journals!$K$9:$K$1005679,Journals!$D$9:$D$1005679,"<"&$F$7,Journals!$J$9:$J$1005679,"investments in stock")-SUMIFS(Journals!$L$9:$L$1005679,Journals!$D$9:$D$1005679,"<"&$F$7,Journals!$J$9:$J$1005679,"investments in stock") -> 2.0327918e+08 | L7: =J7+H7-I7 -> 2.3777851e+08
A8: Ending | B8: 2026 | C8: 12 | D8: 31 | E8: =DATE(B8,C8,D8)+1 -> 46388 | F8: =DATE(B8,C8,D8) -> 46387 | G8: ='Chart of Accounts'!B4 -> Interest Receivables from Bank A/C | H8: =MAX(0,SUMIFS(Journals!$K$9:$K$1005679,Journals!$D$9:$D$1005679,">"&$E$7,Journals!$D$9:$D$1005679,"<"&$E$8,Journals!$J$9:$J$1005679,"Interest Receivables from Bank A/C")-SUMIFS(Journals!$L$9:$L$1005679,Journals!$D$9:$D$1005679,">"&$E$7,Journals!$D$9:$D$1005679,"<"&$E$8,Journals!$J$9:$J$1005679,"Interest Receivables from Bank A/C")) -> 75951.562 | I8: =MAX(0,SUMIFS(Journals!$L$9:$L$1005679,Journals!$D$9:$D$1005679,">"&$E$7,Journals!$D$9:$D$1005679,"<"&$E$8,Journals!$J$9:$J$1005679,"Interest Receivables from Bank A/C")-SUMIFS(Journals!$K$9:$K$1005679,Journals!$D$9:$D$1005679,">"&$E$7,Journals!$D$9:$D$1005679,"<"&$E$8,Journals!$J$9:$J$1005679,"Interest Receivables from Bank A/C")) -> 0 | J8: =SUMIFS(Journals!$K$9:$K$1005679,Journals!$D$9:$D$1005679,"<"&$F$7,Journals!$J$9:$J$1005679,"Interest Receivables from Bank A/C")-SUMIFS(Journals!$L$9:$L$1005679,Journals!$D$9:$D$1005679,"<"&$F$7,Journals!$J$9:$J$1005679,"Interest Receivables from Bank A/C") -> 10693.788 | L8: =J8+H8-I8 -> 86645.35
G9: ='Chart of Accounts'!B5 -> Preliminary & issue expenses | H9: =MAX(0,SUMIFS(Journals!$K$9:$K$1005679,Journals!$D$9:$D$1005679,">"&$E$7,Journals!$D$9:$D$1005679,"<"&$E$8,Journals!$J$9:$J$1005679,"Preliminary & issue expenses")-SUMIFS(Journals!$L$9:$L$1005679,Journals!$D$9:$D$1005679,">"&$E$7,Journals!$D$9:$D$1005679,"<"&$E$8,Journals!$J$9:$J$1005679,"Preliminary & issue expenses")) -> 0 | I9: =MAX(0,SUMIFS(Journals!$L$9:$L$1005679,Journals!$D$9:$D$1005679,">"&$E$7,Journals!$D$9:$D$1005679,"<"&$E$8,Journals!$J$9:$J$1005679,"Preliminary & issue expenses")-SUMIFS(Journals!$K$9:$K$1005679,Journals!$D$9:$D$1005679,">"&$E$7,Journals!$D$9:$D$1005679,"<"&$E$8,Journals!$J$9:$J$1005679,"Preliminary & issue expenses")) -> 32967.033 | J9: =SUMIFS(Journals!$K$9:$K$1005679,Journals!$D$9:$D$1005679,"<"&$F$7,Journals!$J$9:$J$1005679,"Preliminary & issue expenses")-SUMIFS(Journals!$L$9:$L$1005679,Journals!$D$9:$D$1005679,"<"&$F$7,Journals!$J$9:$J$1005679,"Preliminary & issue expenses") -> 445054.95 | L9: =J9+H9-I9 -> 412087.91
G10: ='Chart of Accounts'!B6 -> Accrued Management Fee | H10: =SUMIFS(Journals!$K$9:$K$1005679,Journals!$D$9:$D$1005679,">"&$E$7,Journals!$D$9:$D$1005679,"<"&$E$8,Journals!$J$9:$J$1005679,"Accrued Management Fee") -> 1235848 | I10: =MAX(0,SUMIFS(Journals!$L$9:$L$1005679,Journals!$D$9:$D$1005679,">"&$E$7,Journals!$D$9:$D$1005679,"<"&$E$8,Journals!$J$9:$J$1005679,"Accrued Management Fee")) -> 1183783.6 | K10: =SUMIFS(Journals!$L$9:$L$1005679,Journals!$D$9:$D$1005679,"<"&$F$7,Journals!$J$9:$J$1005679,"Accrued Management Fee")-SUMIFS(Journals!$K$9:$K$1005679,Journals!$D$9:$D$1005679,"<"&$F$7,Journals!$J$9:$J$1005679,"Accrued Management Fee") -> 775470.14 | M10: =K10+I10-H10 -> 723405.79
G11: Accrued Trustee Fee | H11: =SUMIFS(Journals!$K$9:$K$1005679,Journals!$D$9:$D$1005679,">"&$E$7,Journals!$D$9:$D$1005679,"<"&$E$8,Journals!$J$9:$J$1005679,"Accrued Trustee Fee") -> 0 | I11: =MAX(0,SUMIFS(Journals!$L$9:$L$1005679,Journals!$D$9:$D$1005679,">"&$E$7,Journals!$D$9:$D$1005679,"<"&$E$8,Journals!$J$9:$J$1005679,"Accrued Trustee Fee")) -> 56977.77 | K11: =SUMIFS(Journals!$L$9:$L$1005679,Journals!$D$9:$D$1005679,"<"&$F$7,Journals!$J$9:$J$1005679,"Accrued Trustee Fee")-SUMIFS(Journals!$K$9:$K$1005679,Journals!$D$9:$D$1005679,"<"&$F$7,Journals!$J$9:$J$1005679,"Accrued Trustee Fee") -> 108026.58 | M11: =K11+I11-H11 -> 165004.35
G12: ='Chart of Accounts'!B8 -> Accrued Custodian Fee | H12: =MAX(0,SUMIFS(Journals!$K$9:$K$1005679,Journals!$D$9:$D$1005679,">"&$E$7,Journals!$D$9:$D$1005679,"<"&$E$8,Journals!$J$9:$J$1005679,"accrued custodian fee")-SUMIFS(Journals!$L$9:$L$1005679,Journals!$D$9:$D$1005679,">"&$E$7,Journals!$D$9:$D$1005679,"<"&$E$8,Journals!$J$9:$J$1005679,"accrued custodian fee")) -> 0 | I12: =MAX(0,SUMIFS(Journals!$L$9:$L$1005679,Journals!$D$9:$D$1005679,">"&$E$7,Journals!$D$9:$D$1005679,"<"&$E$8,Journals!$J$9:$J$1005679,"accrued custodian fee")-SUMIFS(Journals!$K$9:$K$1005679,Journals!$D$9:$D$1005679,">"&$E$7,Journals!$D$9:$D$1005679,"<"&$E$8,Journals!$J$9:$J$1005679,"accrued custodian fee")) -> 0 | K12: =SUMIFS(Journals!$L$9:$L$1005679,Journals!$D$9:$D$1005679,"<"&$F$7,Journals!$J$9:$J$1005679,"Accrued Custodian Fee")-SUMIFS(Journals!$K$9:$K$1005679,Journals!$D$9:$D$1005679,"<"&$F$7,Journals!$J$9:$J$1005679,"Accrued Custodian Fee") -> 0 | M12: =K12+I12-H12 -> 0
G13: ='Chart of Accounts'!B9 -> Accrued BSEC fee | H13: =MAX(0,SUMIFS(Journals!$K$9:$K$1005679,Journals!$D$9:$D$1005679,">"&$E$7,Journals!$D$9:$D$1005679,"<"&$E$8,Journals!$J$9:$J$1005679,"accrued bsec fee")-SUMIFS(Journals!$L$9:$L$1005679,Journals!$D$9:$D$1005679,">"&$E$7,Journals!$D$9:$D$1005679,"<"&$E$8,Journals!$J$9:$J$1005679,"accrued bsec fee")) -> 0 | I13: =MAX(0,SUMIFS(Journals!$L$9:$L$1005679,Journals!$D$9:$D$1005679,">"&$E$7,Journals!$D$9:$D$1005679,"<"&$E$8,Journals!$J$9:$J$1005679,"accrued bsec fee")-SUMIFS(Journals!$K$9:$K$1005679,Journals!$D$9:$D$1005679,">"&$E$7,Journals!$D$9:$D$1005679,"<"&$E$8,Journals!$J$9:$J$1005679,"accrued bsec fee")) -> 0 | K13: =SUMIFS(Journals!$L$9:$L$1005679,Journals!$D$9:$D$1005679,"<"&$F$7,Journals!$J$9:$J$1005679,"accrued bsec fee")-SUMIFS(Journals!$K$9:$K$1005679,Journals!$D$9:$D$1005679,"<"&$F$7,Journals!$J$9:$J$1005679,"accrued bsec fee") -> 0 | M13: =K13+I13-H13 -> 0
G14: ='Chart of Accounts'!B10 -> Accrued Audit Fee | H14: =MAX(0,SUMIFS(Journals!$K$9:$K$1005679,Journals!$D$9:$D$1005679,">"&$E$7,Journals!$D$9:$D$1005679,"<"&$E$8,Journals!$J$9:$J$1005679,"accrued audit fee")) -> 57500 | I14: =MAX(0,SUMIFS(Journals!$L$9:$L$1005679,Journals!$D$9:$D$1005679,">"&$E$7,Journals!$D$9:$D$1005679,"<"&$E$8,Journals!$J$9:$J$1005679,"accrued audit fee")) -> 0 | K14: =SUMIFS(Journals!$L$9:$L$1005679,Journals!$D$9:$D$1005679,"<"&$F$7,Journals!$J$9:$J$1005679,"accrued audit fee")-SUMIFS(Journals!$K$9:$K$1005679,Journals!$D$9:$D$1005679,"<"&$F$7,Journals!$J$9:$J$1005679,"accrued audit fee") -> 57500 | M14: =K14+I14-H14 -> 0
G15: ='Chart of Accounts'!B11 -> Accrued CDBL Fee | H15: =MAX(0,SUMIFS(Journals!$K$9:$K$1005679,Journals!$D$9:$D$1005679,">"&$E$7,Journals!$D$9:$D$1005679,"<"&$E$8,Journals!$J$9:$J$1005679,"accrued CDBL fee")-SUMIFS(Journals!$L$9:$L$1005679,Journals!$D$9:$D$1005679,">"&$E$7,Journals!$D$9:$D$1005679,"<"&$E$8,Journals!$J$9:$J$1005679,"accrued CDBL fee")) -> 0 | I15: =MAX(0,SUMIFS(Journals!$L$9:$L$1005679,Journals!$D$9:$D$1005679,">"&$E$7,Journals!$D$9:$D$1005679,"<"&$E$8,Journals!$J$9:$J$1005679,"accrued CDBL fee")-SUMIFS(Journals!$K$9:$K$1005679,Journals!$D$9:$D$1005679,">"&$E$7,Journals!$D$9:$D$1005679,"<"&$E$8,Journals!$J$9:$J$1005679,"accrued CDBL fee")) -> 0 | K15: =SUMIFS(Journals!$L$9:$L$1005679,Journals!$D$9:$D$1005679,"<"&$F$7,Journals!$J$9:$J$1005679,"accrued cdbl fee")-SUMIFS(Journals!$K$9:$K$1005679,Journals!$D$9:$D$1005679,"<"&$F$7,Journals!$J$9:$J$1005679,"accrued cdbl fee") -> 0 | M15: =K15+I15-H15 -> 0
G16: ='Chart of Accounts'!B12 -> Fixed Deposit Receipts (FDR) | H16: =MAX(0,SUMIFS(Journals!$K$9:$K$1005679,Journals!$D$9:$D$1005679,">"&$E$7,Journals!$D$9:$D$1005679,"<"&$E$8,Journals!$J$9:$J$1005679,"Fixed Deposit Receipts (FDR)")-SUMIFS(Journals!$L$9:$L$1005679,Journals!$D$9:$D$1005679,">"&$E$7,Journals!$D$9:$D$1005679,"<"&$E$8,Journals!$J$9:$J$1005679,"Fixed Deposit Receipts (FDR)")) -> 0 | I16: =MAX(0,SUMIFS(Journals!$L$9:$L$1005679,Journals!$D$9:$D$1005679,">"&$E$7,Journals!$D$9:$D$1005679,"<"&$E$8,Journals!$J$9:$J$1005679,"Fixed Deposit Receipts (FDR)")-SUMIFS(Journals!$K$9:$K$1005679,Journals!$D$9:$D$1005679,">"&$E$7,Journals!$D$9:$D$1005679,"<"&$E$8,Journals!$J$9:$J$1005679,"Fixed Deposit Receipts (FDR)")) -> 9000000 | J16: =SUMIFS(Journals!$K$9:$K$1005679,Journals!$D$9:$D$1005679,"<"&$F$7,Journals!$J$9:$J$1005679,"Fixed Deposit Receipts (FDR)")-SUMIFS(Journals!$L$9:$L$1005679,Journals!$D$9:$D$1005679,"<"&$F$7,Journals!$J$9:$J$1005679,"Fixed Deposit Receipts (FDR)") -> 13000000 | L16: =J16+H16-I16 -> 4000000
G17: ='Chart of Accounts'!B13 -> Cash and cash equivalents | H17: =MAX(0,SUMIFS(Journals!$K$9:$K$1005679,Journals!$D$9:$D$1005679,">"&$E$7,Journals!$D$9:$D$1005679,"<"&$E$8,Journals!$J$9:$J$1005679,"Cash and cash equivalents")-SUMIFS(Journals!$L$9:$L$1005679,Journals!$D$9:$D$1005679,">"&$E$7,Journals!$D$9:$D$1005679,"<"&$E$8,Journals!$J$9:$J$1005679,"Cash and cash equivalents")) -> 1793058 | I17: =MAX(0,SUMIFS(Journals!$L$9:$L$1005679,Journals!$D$9:$D$1005679,">"&$E$7,Journals!$D$9:$D$1005679,"<"&$E$8,Journals!$J$9:$J$1005679,"Cash and cash equivalents")-SUMIFS(Journals!$K$9:$K$1005679,Journals!$D$9:$D$1005679,">"&$E$7,Journals!$D$9:$D$1005679,"<"&$E$8,Journals!$J$9:$J$1005679,"Cash and cash equivalents")) -> 0 | J17: =SUMIFS(Journals!$K$9:$K$1005679,Journals!$D$9:$D$1005679,"<"&$F$7,Journals!$J$9:$J$1005679,"Cash and cash equivalents")-SUMIFS(Journals!$L$9:$L$1005679,Journals!$D$9:$D$1005679,"<"&$F$7,Journals!$J$9:$J$1005679,"Cash and cash equivalents") -> 512242.08 | L17: =J17+H17-I17 -> 2305300.1
G18: ='Chart of Accounts'!B14 -> Unit Capital | H18: =SUMIFS(Journals!$K$9:$K$1005679,Journals!$D$9:$D$1005679,">"&$E$7,Journals!$D$9:$D$1005679,"<"&$E$8,Journals!$J$9:$J$1005679,"unit capital") -> 10022120 | I18: =MAX(0,SUMIFS(Journals!$L$9:$L$1005679,Journals!$D$9:$D$1005679,">"&$E$7,Journals!$D$9:$D$1005679,"<"&$E$8,Journals!$J$9:$J$1005679,"unit capital")) -> 29659190 | K18: =SUMIFS(Journals!$L$9:$L$1005679,Journals!$D$9:$D$1005679,"<"&$F$7,Journals!$J$9:$J$1005679,"unit capital")-SUMIFS(Journals!$K$9:$K$1005679,Journals!$D$9:$D$1005679,"<"&$F$7,Journals!$J$9:$J$1005679,"unit capital") -> 188935970 | M18: =K18+I18-H18 -> 208573040
G19: ='Chart of Accounts'!B15 -> Unit premium reserve | H19: =SUMIFS(Journals!$K$9:$K$1005679,Journals!$D$9:$D$1005679,">"&$E$7,Journals!$D$9:$D$1005679,"<"&$E$8,Journals!$J$9:$J$1005679,"unit premium reserve") -> 2739914 | I19: =SUMIFS(Journals!$L$9:$L$1005679,Journals!$D$9:$D$1005679,">"&$E$7,Journals!$D$9:$D$1005679,"<"&$E$8,Journals!$J$9:$J$1005679,"unit premium reserve") -> 7480353.9 | K19: =SUMIFS(Journals!$L$9:$L$1005679,Journals!$D$9:$D$1005679,"<"&$F$7,Journals!$J$9:$J$1005679,"unit premium reserve")-SUMIFS(Journals!$K$9:$K$1005679,Journals!$D$9:$D$1005679,"<"&$F$7,Journals!$J$9:$J$1005679,"unit premium reserve") -> 2503906.3 | M19: =K19+I19-H19 -> 7244346.2
G20: ='Chart of Accounts'!B16 -> Interest income | H20: =MAX(0,SUMIFS(Journals!$K$9:$K$1005679,Journals!$D$9:$D$1005679,">"&$E$7,Journals!$D$9:$D$1005679,"<"&$E$8,Journals!$J$9:$J$1005679,"interest income")-SUMIFS(Journals!$L$9:$L$1005679,Journals!$D$9:$D$1005679,">"&$E$7,Journals!$D$9:$D$1005679,"<"&$E$8,Journals!$J$9:$J$1005679,"interest income")) -> 0 | I20: =MAX(0,SUMIFS(Journals!$L$9:$L$1005679,Journals!$D$9:$D$1005679,">"&$E$7,Journals!$D$9:$D$1005679,"<"&$E$8,Journals!$J$9:$J$1005679,"interest income")-SUMIFS(Journals!$K$9:$K$1005679,Journals!$D$9:$D$1005679,">"&$E$7,Journals!$D$9:$D$1005679,"<"&$E$8,Journals!$J$9:$J$1005679,"interest income")) -> 0 | O20: =SUMIFS(Journals!$L$9:$L$1011558,Journals!$D$9:$D$1011558,"<"&$F$7,Journals!$J$9:$J$1011558,"interest income")-SUMIFS(Journals!$K$9:$K$1011558,Journals!$D$9:$D$1011558,"<"&$F$7,Journals!$J$9:$J$1011558,"interest income") -> 21944826
G21: Interest Income from FDR | H21: =MAX(0,SUMIFS(Journals!$K$9:$K$1005679,Journals!$D$9:$D$1005679,">"&$E$7,Journals!$D$9:$D$1005679,"<"&$E$8,Journals!$J$9:$J$1005679,"Interest Income from FDR")-SUMIFS(Journals!$L$9:$L$1005679,Journals!$D$9:$D$1005679,">"&$E$7,Journals!$D$9:$D$1005679,"<"&$E$8,Journals!$J$9:$J$1005679,"Interest Income from FDR")) -> 0 | I21: =MAX(0,SUMIFS(Journals!$L$9:$L$1005679,Journals!$D$9:$D$1005679,">"&$E$7,Journals!$D$9:$D$1005679,"<"&$E$8,Journals!$J$9:$J$1005679,"Interest Income from FDR")-SUMIFS(Journals!$K$9:$K$1005679,Journals!$D$9:$D$1005679,">"&$E$7,Journals!$D$9:$D$1005679,"<"&$E$8,Journals!$J$9:$J$1005679,"Interest Income from FDR")) -> 334458.33 | O21: =SUMIFS(Journals!$L$9:$L$1005679,Journals!$D$9:$D$1005679,"<"&$F$7,Journals!$J$9:$J$1005679,"Interest Income from FDR")-SUMIFS(Journals!$K$9:$K$1005679,Journals!$D$9:$D$1005679,"<"&$F$7,Journals!$J$9:$J$1005679,"Interest Income from FDR") -> 0
G22: Interest Income from Renata Pre. Share | H22: =MAX(0,SUMIFS(Journals!$K$9:$K$1005679,Journals!$D$9:$D$1005679,">"&$E$7,Journals!$D$9:$D$1005679,"<"&$E$8,Journals!$J$9:$J$1005679,"Interest Income from Renata Pre. Share")-SUMIFS(Journals!$L$9:$L$1005679,Journals!$D$9:$D$1005679,">"&$E$7,Journals!$D$9:$D$1005679,"<"&$E$8,Journals!$J$9:$J$1005679,"Interest Income from Renata Pre. Share")) -> 0 | I22: =MAX(0,SUMIFS(Journals!$L$9:$L$1005679,Journals!$D$9:$D$1005679,">"&$E$7,Journals!$D$9:$D$1005679,"<"&$E$8,Journals!$J$9:$J$1005679,"Interest Income from Renata Pre. Share")-SUMIFS(Journals!$K$9:$K$1005679,Journals!$D$9:$D$1005679,">"&$E$7,Journals!$D$9:$D$1005679,"<"&$E$8,Journals!$J$9:$J$1005679,"Interest Income from Renata Pre. Share")) -> 519576.92 | O22: =SUMIFS(Journals!$L$9:$L$1005679,Journals!$D$9:$D$1005679,"<"&$F$7,Journals!$J$9:$J$1005679,"Interest Income from Renata Pre. Share")-SUMIFS(Journals!$K$9:$K$1005679,Journals!$D$9:$D$1005679,"<"&$F$7,Journals!$J$9:$J$1005679,"Interest Income from Renata Pre. Share") -> 402053.57
G23: Interest Income from Bank Acc | H23: =MAX(0,SUMIFS(Journals!$K$9:$K$1005679,Journals!$D$9:$D$1005679,">"&$E$7,Journals!$D$9:$D$1005679,"<"&$E$8,Journals!$J$9:$J$1005679,"Interest Income from Bank Acc")-SUMIFS(Journals!$L$9:$L$1005679,Journals!$D$9:$D$1005679,">"&$E$7,Journals!$D$9:$D$1005679,"<"&$E$8,Journals!$J$9:$J$1005679,"Interest Income from Bank Acc")) -> 0 | I23: =MAX(0,SUMIFS(Journals!$L$9:$L$1005679,Journals!$D$9:$D$1005679,">"&$E$7,Journals!$D$9:$D$1005679,"<"&$E$8,Journals!$J$9:$J$1005679,"Interest Income from Bank Acc")-SUMIFS(Journals!$K$9:$K$1005679,Journals!$D$9:$D$1005679,">"&$E$7,Journals!$D$9:$D$1005679,"<"&$E$8,Journals!$J$9:$J$1005679,"Interest Income from Bank Acc")) -> 75951.562 | O23: =SUMIFS(Journals!$L$9:$L$1005679,Journals!$D$9:$D$1005679,"<"&$F$7,Journals!$J$9:$J$1005679,"Interest Income from Bank Acc")-SUMIFS(Journals!$K$9:$K$1005679,Journals!$D$9:$D$1005679,"<"&$F$7,Journals!$J$9:$J$1005679,"Interest Income from Bank Acc") -> 0
G24: Interest Income from T-Bill | H24: =MAX(0,SUMIFS(Journals!$K$9:$K$1005679,Journals!$D$9:$D$1005679,">"&$E$7,Journals!$D$9:$D$1005679,"<"&$E$8,Journals!$J$9:$J$1005679,"Interest Income from T-Bill")-SUMIFS(Journals!$L$9:$L$1005679,Journals!$D$9:$D$1005679,">"&$E$7,Journals!$D$9:$D$1005679,"<"&$E$8,Journals!$J$9:$J$1005679,"Interest Income from T-Bill")) -> 0 | I24: =MAX(0,SUMIFS(Journals!$L$9:$L$1005679,Journals!$D$9:$D$1005679,">"&$E$7,Journals!$D$9:$D$1005679,"<"&$E$8,Journals!$J$9:$J$1005679,"Interest Income from T-Bill")-SUMIFS(Journals!$K$9:$K$1005679,Journals!$D$9:$D$1005679,">"&$E$7,Journals!$D$9:$D$1005679,"<"&$E$8,Journals!$J$9:$J$1005679,"Interest Income from T-Bill")) -> 0 | O24: =SUMIFS(Journals!$L$9:$L$1005679,Journals!$D$9:$D$1005679,"<"&$F$7,Journals!$J$9:$J$1005679,"Interest Income from T-Bill")-SUMIFS(Journals!$K$9:$K$1005679,Journals!$D$9:$D$1005679,"<"&$F$7,Journals!$J$9:$J$1005679,"Interest Income from T-Bill") -> 0
G25: Interest Income from T-Bond | H25: =MAX(0,SUMIFS(Journals!$K$9:$K$1005679,Journals!$D$9:$D$1005679,">"&$E$7,Journals!$D$9:$D$1005679,"<"&$E$8,Journals!$J$9:$J$1005679,"Interest Income from T-Bond")-SUMIFS(Journals!$L$9:$L$1005679,Journals!$D$9:$D$1005679,">"&$E$7,Journals!$D$9:$D$1005679,"<"&$E$8,Journals!$J$9:$J$1005679,"Interest Income from T-Bond")) -> 0 | I25: =MAX(0,SUMIFS(Journals!$L$9:$L$1005679,Journals!$D$9:$D$1005679,">"&$E$7,Journals!$D$9:$D$1005679,"<"&$E$8,Journals!$J$9:$J$1005679,"Interest Income from T-Bond")-SUMIFS(Journals!$K$9:$K$1005679,Journals!$D$9:$D$1005679,">"&$E$7,Journals!$D$9:$D$1005679,"<"&$E$8,Journals!$J$9:$J$1005679,"Interest Income from T-Bond")) -> 0 | O25: =SUMIFS(Journals!$L$9:$L$1005679,Journals!$D$9:$D$1005679,"<"&$F$7,Journals!$J$9:$J$1005679,"Interest Income from T-Bond")-SUMIFS(Journals!$K$9:$K$1005679,Journals!$D$9:$D$1005679,"<"&$F$7,Journals!$J$9:$J$1005679,"Interest Income from T-Bond") -> 1841200
G26: ='Chart of Accounts'!B17 -> Bank charges and excise duties | H26: =MAX(0,SUMIFS(Journals!$K$9:$K$1005679,Journals!$D$9:$D$1005679,">"&$E$7,Journals!$D$9:$D$1005679,"<"&$E$8,Journals!$J$9:$J$1005679,"Bank charges and excise duties")-SUMIFS(Journals!$L$9:$L$1005679,Journals!$D$9:$D$1005679,">"&$E$7,Journals!$D$9:$D$1005679,"<"&$E$8,Journals!$J$9:$J$1005679,"Bank charges and excise duties")) -> 25803 | I26: =MAX(0,SUMIFS(Journals!$L$9:$L$1005679,Journals!$D$9:$D$1005679,">"&$E$7,Journals!$D$9:$D$1005679,"<"&$E$8,Journals!$J$9:$J$1005679,"Bank charges and excise duties")-SUMIFS(Journals!$K$9:$K$1005679,Journals!$D$9:$D$1005679,">"&$E$7,Journals!$D$9:$D$1005679,"<"&$E$8,Journals!$J$9:$J$1005679,"Bank charges and excise duties")) -> 0 | N26: =SUMIFS(Journals!$K$9:$K$1005679,Journals!$D$9:$D$1005679,"<"&$F$7,Journals!$J$9:$J$1005679,"Bank charges and excise duties")-SUMIFS(Journals!$L$9:$L$1005679,Journals!$D$9:$D$1005679,"<"&$F$7,Journals!$J$9:$J$1005679,"Bank charges and excise duties") -> 702242.76
G27: ='Chart of Accounts'!B18 -> Brokerage commission | H27: =MAX(0,SUMIFS(Journals!$K$9:$K$1005679,Journals!$D$9:$D$1005679,">"&$E$7,Journals!$D$9:$D$1005679,"<"&$E$8,Journals!$J$9:$J$1005679,"brokerage commission")-SUMIFS(Journals!$L$9:$L$1005679,Journals!$D$9:$D$1005679,">"&$E$7,Journals!$D$9:$D$1005679,"<"&$E$8,Journals!$J$9:$J$1005679,"brokerage commission")) -> 479495.29 | I27: =MAX(0,SUMIFS(Journals!$L$9:$L$1005679,Journals!$D$9:$D$1005679,">"&$E$7,Journals!$D$9:$D$1005679,"<"&$E$8,Journals!$J$9:$J$1005679,"brokerage commission")-SUMIFS(Journals!$K$9:$K$1005679,Journals!$D$9:$D$1005679,">"&$E$7,Journals!$D$9:$D$1005679,"<"&$E$8,Journals!$J$9:$J$1005679,"brokerage commission")) -> 0 | N27: =SUMIFS(Journals!$K$9:$K$1005679,Journals!$D$9:$D$1005679,"<"&$F$7,Journals!$J$9:$J$1005679,"brokerage commission")-SUMIFS(Journals!$L$9:$L$1005679,Journals!$D$9:$D$1005679,"<"&$F$7,Journals!$J$9:$J$1005679,"brokerage commission") -> 1991875.8
G28: ='Chart of Accounts'!B19 -> Unrealized gain on securities | H28: =MAX(0,SUMIFS(Journals!$K$9:$K$1005679,Journals!$D$9:$D$1005679,">"&$E$7,Journals!$D$9:$D$1005679,"<"&$E$8,Journals!$J$9:$J$1005679,"Unrealized gain on securities")-SUMIFS(Journals!$L$9:$L$1005679,Journals!$D$9:$D$1005679,">"&$E$7,Journals!$D$9:$D$1005679,"<"&$E$8,Journals!$J$9:$J$1005679,"Unrealized gain on securities")) -> 0 | I28: =MAX(0,SUMIFS(Journals!$L$9:$L$1005679,Journals!$D$9:$D$1005679,">"&$E$7,Journals!$D$9:$D$1005679,"<"&$E$8,Journals!$J$9:$J$1005679,"Unrealized gain on securities")-SUMIFS(Journals!$K$9:$K$1005679,Journals!$D$9:$D$1005679,">"&$E$7,Journals!$D$9:$D$1005679,"<"&$E$8,Journals!$J$9:$J$1005679,"Unrealized gain on securities")) -> 8735993.6 | O28: =SUMIFS(Journals!$L$9:$L$1005679,Journals!$D$9:$D$1005679,"<"&$F$7,Journals!$J$9:$J$1005679,"unrealized gain on securities")-SUMIFS(Journals!$K$9:$K$1005679,Journals!$D$9:$D$1005679,"<"&$F$7,Journals!$J$9:$J$1005679,"unrealized gain on securities") -> 6922812.6
G29: Unrealized gain on T-Bill | H29: =MAX(0,SUMIFS(Journals!$K$9:$K$1005679,Journals!$D$9:$D$1005679,">"&$E$7,Journals!$D$9:$D$1005679,"<"&$E$8,Journals!$J$9:$J$1005679,"Unrealized gain on T-Bill")-SUMIFS(Journals!$L$9:$L$1005679,Journals!$D$9:$D$1005679,">"&$E$7,Journals!$D$9:$D$1005679,"<"&$E$8,Journals!$J$9:$J$1005679,"Unrealized gain on T-Bill")) -> 0 | I29: =MAX(0,SUMIFS(Journals!$L$9:$L$1005679,Journals!$D$9:$D$1005679,">"&$E$7,Journals!$D$9:$D$1005679,"<"&$E$8,Journals!$J$9:$J$1005679,"Unrealized gain on T-Bill")-SUMIFS(Journals!$K$9:$K$1005679,Journals!$D$9:$D$1005679,">"&$E$7,Journals!$D$9:$D$1005679,"<"&$E$8,Journals!$J$9:$J$1005679,"Unrealized gain on T-Bill")) -> 0 | O29: =SUMIFS(Journals!$L$9:$L$1005679,Journals!$D$9:$D$1005679,"<"&$F$7,Journals!$J$9:$J$1005679,"Unrealized gain on T-Bill")-SUMIFS(Journals!$K$9:$K$1005679,Journals!$D$9:$D$1005679,"<"&$F$7,Journals!$J$9:$J$1005679,"Unrealized gain on T-Bill") -> 0
G30: Unrealized gain on T-Bond | H30: =MAX(0,SUMIFS(Journals!$K$9:$K$1005679,Journals!$D$9:$D$1005679,">"&$E$7,Journals!$D$9:$D$1005679,"<"&$E$8,Journals!$J$9:$J$1005679,"Unrealized gain on T-Bond")-SUMIFS(Journals!$L$9:$L$1005679,Journals!$D$9:$D$1005679,">"&$E$7,Journals!$D$9:$D$1005679,"<"&$E$8,Journals!$J$9:$J$1005679,"Unrealized gain on T-Bond")) -> 0 | I30: =MAX(0,SUMIFS(Journals!$L$9:$L$1005679,Journals!$D$9:$D$1005679,">"&$E$7,Journals!$D$9:$D$1005679,"<"&$E$8,Journals!$J$9:$J$1005679,"Unrealized gain on T-Bond")-SUMIFS(Journals!$K$9:$K$1005679,Journals!$D$9:$D$1005679,">"&$E$7,Journals!$D$9:$D$1005679,"<"&$E$8,Journals!$J$9:$J$1005679,"Unrealized gain on T-Bond")) -> 0 | O30: =SUMIFS(Journals!$L$9:$L$1005679,Journals!$D$9:$D$1005679,"<"&$F$7,Journals!$J$9:$J$1005679,"Unrealized gain on T-Bond")-SUMIFS(Journals!$K$9:$K$1005679,Journals!$D$9:$D$1005679,"<"&$F$7,Journals!$J$9:$J$1005679,"Unrealized gain on T-Bond") -> 0
G31: ='Chart of Accounts'!B22 -> Unrealized loss on securities | H31: =MAX(0,SUMIFS(Journals!$K$9:$K$1005679,Journals!$D$9:$D$1005679,">"&$E$7,Journals!$D$9:$D$1005679,"<"&$E$8,Journals!$J$9:$J$1005679,"Unrealized loss on securities")-SUMIFS(Journals!$L$9:$L$1005679,Journals!$D$9:$D$1005679,">"&$E$7,Journals!$D$9:$D$1005679,"<"&$E$8,Journals!$J$9:$J$1005679,"Unrealized loss on securities")) -> 0 | I31: =MAX(0,SUMIFS(Journals!$L$9:$L$1005679,Journals!$D$9:$D$1005679,">"&$E$7,Journals!$D$9:$D$1005679,"<"&$E$8,Journals!$J$9:$J$1005679,"Unrealized loss on securities")-SUMIFS(Journals!$K$9:$K$1005679,Journals!$D$9:$D$1005679,">"&$E$7,Journals!$D$9:$D$1005679,"<"&$E$8,Journals!$J$9:$J$1005679,"Unrealized loss on securities")) -> 0 | N31: =SUMIFS(Journals!K9:K1005679,Journals!D9:D1005679,"<"&F7,Journals!J9:J1005679,"unrealized loss on securities")-SUMIFS(Journals!L9:L1005679,Journals!D9:D1005679,"<"&F7,Journals!J9:J1005679,"unrealized loss on securities") -> 2262855.3
G32: ='Chart of Accounts'!B23 -> Amortization of preliminary and issue expense | H32: =MAX(0,SUMIFS(Journals!$K$9:$K$1005679,Journals!$D$9:$D$1005679,">"&$E$7,Journals!$D$9:$D$1005679,"<"&$E$8,Journals!$J$9:$J$1005679,"Amortization of preliminary and issue expense")-SUMIFS(Journals!$L$9:$L$1005679,Journals!$D$9:$D$1005679,">"&$E$7,Journals!$D$9:$D$1005679,"<"&$E$8,Journals!$J$9:$J$1005679,"Amortization of preliminary and issue expense")) -> 32967.033 | I32: =MAX(0,SUMIFS(Journals!$L$9:$L$1005679,Journals!$D$9:$D$1005679,">"&$E$7,Journals!$D$9:$D$1005679,"<"&$E$8,Journals!$J$9:$J$1005679,"Amortization of preliminary and issue expense")-SUMIFS(Journals!$K$9:$K$1005679,Journals!$D$9:$D$1005679,">"&$E$7,Journals!$D$9:$D$1005679,"<"&$E$8,Journals!$J$9:$J$1005679,"Amortization of preliminary and issue expense")) -> 0 | N32: =SUMIFS(Journals!$K$9:$K$1005679,Journals!$D$9:$D$1005679,"<"&$F$7,Journals!$J$9:$J$1005679,"Amortization of preliminary and issue expense")-SUMIFS(Journals!$L$9:$L$1005679,Journals!$D$9:$D$1005679,"<"&$F$7,Journals!$J$9:$J$1005679,"Amortization of preliminary and issue expense") -> 554945.05
G33: ='Chart of Accounts'!B24 -> Management Fee | H33: =MAX(0,SUMIFS(Journals!$K$9:$K$1005679,Journals!$D$9:$D$1005679,">"&$E$7,Journals!$D$9:$D$1005679,"<"&$E$8,Journals!$J$9:$J$1005679,"management fee")-SUMIFS(Journals!$L$9:$L$1005679,Journals!$D$9:$D$1005679,">"&$E$7,Journals!$D$9:$D$1005679,"<"&$E$8,Journals!$J$9:$J$1005679,"management fee")) -> 1183783.6 | I33: =MAX(0,SUMIFS(Journals!$L$9:$L$1005679,Journals!$D$9:$D$1005679,">"&$E$7,Journals!$D$9:$D$1005679,"<"&$E$8,Journals!$J$9:$J$1005679,"management fee")-SUMIFS(Journals!$K$9:$K$1005679,Journals!$D$9:$D$1005679,">"&$E$7,Journals!$D$9:$D$1005679,"<"&$E$8,Journals!$J$9:$J$1005679,"management fee")) -> 0 | N33: =SUMIFS(Journals!$K$9:$K$1005679,Journals!$D$9:$D$1005679,"<"&$F$7,Journals!$J$9:$J$1005679,"management fee")-SUMIFS(Journals!$L$9:$L$1005679,Journals!$D$9:$D$1005679,"<"&$F$7,Journals!$J$9:$J$1005679,"management fee") -> 14959459
G34: ='Chart of Accounts'!B25 -> Trustee fee | H34: =MAX(0,SUMIFS(Journals!$K$9:$K$1005679,Journals!$D$9:$D$1005679,">"&$E$7,Journals!$D$9:$D$1005679,"<"&$E$8,Journals!$J$9:$J$1005679,"trustee fee")-SUMIFS(Journals!$L$9:$L$1005679,Journals!$D$9:$D$1005679,">"&$E$7,Journals!$D$9:$D$1005679,"<"&$E$8,Journals!$J$9:$J$1005679,"trustee fee")) -> 56977.77 | I34: =MAX(0,SUMIFS(Journals!$L$9:$L$1005679,Journals!$D$9:$D$1005679,">"&$E$7,Journals!$D$9:$D$1005679,"<"&$E$8,Journals!$J$9:$J$1005679,"trustee fee")-SUMIFS(Journals!$K$9:$K$1005679,Journals!$D$9:$D$1005679,">"&$E$7,Journals!$D$9:$D$1005679,"<"&$E$8,Journals!$J$9:$J$1005679,"trustee fee")) -> 0 | N34: =SUMIFS(Journals!$K$9:$K$1005679,Journals!$D$9:$D$1005679,"<"&$F$7,Journals!$J$9:$J$1005679,"trustee fee")-SUMIFS(Journals!$L$9:$L$1005679,Journals!$D$9:$D$1005679,"<"&$F$7,Journals!$J$9:$J$1005679,"trustee fee") -> 755462.36
G35: ='Chart of Accounts'!B26 -> BSEC Annual Fee | H35: =MAX(0,SUMIFS(Journals!$K$9:$K$1005679,Journals!$D$9:$D$1005679,">"&$E$7,Journals!$D$9:$D$1005679,"<"&$E$8,Journals!$J$9:$J$1005679,"bsec annual fee")-SUMIFS(Journals!$L$9:$L$1005679,Journals!$D$9:$D$1005679,">"&$E$7,Journals!$D$9:$D$1005679,"<"&$E$8,Journals!$J$9:$J$1005679,"bsec annual fee")) -> 0 | I35: =MAX(0,SUMIFS(Journals!$L$9:$L$1005679,Journals!$D$9:$D$1005679,">"&$E$7,Journals!$D$9:$D$1005679,"<"&$E$8,Journals!$J$9:$J$1005679,"bsec annual fee")-SUMIFS(Journals!$K$9:$K$1005679,Journals!$D$9:$D$1005679,">"&$E$7,Journals!$D$9:$D$1005679,"<"&$E$8,Journals!$J$9:$J$1005679,"bsec annual fee")) -> 0 | N35: =SUMIFS(Journals!$K$9:$K$1005679,Journals!$D$9:$D$1005679,"<"&$F$7,Journals!$J$9:$J$1005679,"bsec annual fee")-SUMIFS(Journals!$L$9:$L$1005679,Journals!$D$9:$D$1005679,"<"&$F$7,Journals!$J$9:$J$1005679,"bsec annual fee") -> 759042.18
G36: ='Chart of Accounts'!B27 -> Audit fee | H36: =MAX(0,SUMIFS(Journals!$K$9:$K$1005679,Journals!$D$9:$D$1005679,">"&$E$7,Journals!$D$9:$D$1005679,"<"&$E$8,Journals!$J$9:$J$1005679,"audit fee")-SUMIFS(Journals!$L$9:$L$1005679,Journals!$D$9:$D$1005679,">"&$E$7,Journals!$D$9:$D$1005679,"<"&$E$8,Journals!$J$9:$J$1005679,"audit fee")) -> 0 | I36: =MAX(0,SUMIFS(Journals!$L$9:$L$1005679,Journals!$D$9:$D$1005679,">"&$E$7,Journals!$D$9:$D$1005679,"<"&$E$8,Journals!$J$9:$J$1005679,"audit fee")-SUMIFS(Journals!$K$9:$K$1005679,Journals!$D$9:$D$1005679,">"&$E$7,Journals!$D$9:$D$1005679,"<"&$E$8,Journals!$J$9:$J$1005679,"audit fee")) -> 0 | N36: =SUMIFS(Journals!$K$9:$K$1005679,Journals!$D$9:$D$1005679,"<"&$F$7,Journals!$J$9:$J$1005679,"audit fee")-SUMIFS(Journals!$L$9:$L$1005679,Journals!$D$9:$D$1005679,"<"&$F$7,Journals!$J$9:$J$1005679,"audit fee") -> 166750
G37: ='Chart of Accounts'!B28 -> CDBL charges | H37: =MAX(0,SUMIFS(Journals!$K$9:$K$1005679,Journals!$D$9:$D$1005679,">"&$E$7,Journals!$D$9:$D$1005679,"<"&$E$8,Journals!$J$9:$J$1005679,"cdbl charges")-SUMIFS(Journals!$L$9:$L$1005679,Journals!$D$9:$D$1005679,">"&$E$7,Journals!$D$9:$D$1005679,"<"&$E$8,Journals!$J$9:$J$1005679,"cdbl charges")) -> 13947.744 | I37: =MAX(0,SUMIFS(Journals!$L$9:$L$1005679,Journals!$D$9:$D$1005679,">"&$E$7,Journals!$D$9:$D$1005679,"<"&$E$8,Journals!$J$9:$J$1005679,"cdbl charges")-SUMIFS(Journals!$K$9:$K$1005679,Journals!$D$9:$D$1005679,">"&$E$7,Journals!$D$9:$D$1005679,"<"&$E$8,Journals!$J$9:$J$1005679,"cdbl charges")) -> 0 | N37: =SUMIFS(Journals!$K$9:$K$1005679,Journals!$D$9:$D$1005679,"<"&$F$7,Journals!$J$9:$J$1005679,"cdbl charges")-SUMIFS(Journals!$L$9:$L$1005679,Journals!$D$9:$D$1005679,"<"&$F$7,Journals!$J$9:$J$1005679,"cdbl charges") -> 351946.43
G38: ='Chart of Accounts'!B29 -> Fair value adjustment | H38: =MAX(0,SUMIFS(Journals!$K$9:$K$1011420,Journals!$D$9:$D$1011420,">"&$E$7,Journals!$D$9:$D$1011420,"<"&$E$8,Journals!$J$9:$J$1011420,"Fair value adjustment")-SUMIFS(Journals!$L$9:$L$1011420,Journals!$D$9:$D$1011420,">"&$E$7,Journals!$D$9:$D$1011420,"<"&$E$8,Journals!$J$9:$J$1011420,"Fair value adjustment")) -> 8735993.6 | I38: =MAX(0,SUMIFS(Journals!$L$9:$L$1011420,Journals!$D$9:$D$1011420,">"&$E$7,Journals!$D$9:$D$1011420,"<"&$E$8,Journals!$J$9:$J$1011420,"fair value adjustment")-SUMIFS(Journals!$K$9:$K$1011420,Journals!$D$9:$D$1011420,">"&$E$7,Journals!$D$9:$D$1011420,"<"&$E$8,Journals!$J$9:$J$1011420,"fair value adjustment")) -> 0 | J38: =MAX(0,SUMIFS(Journals!K9:K1005679,Journals!D9:D1005679,"<"&F7,Journals!J9:J1005679,"fair value adjustment")-SUMIFS(Journals!L9:L1005679,Journals!D9:D1005679,"<"&F7,Journals!J9:J1005679,"fair value adjustment")) -> 4659957.3 | K38: =MAX(0,SUMIFS(Journals!L9:L1005679,Journals!D9:D1005679,"<"&F7,Journals!J9:J1005679,"Fair value adjustment")-SUMIFS(Journals!K9:K1005679,Journals!D9:D1005679,"<"&F7,Journals!J9:J1005679,"fair value adjustment")) -> 0 | L38: =MAX(0,H38-I38+J38-K38) -> 13395951 | M38: =MAX(0,I38-H38-J38+K38) -> 0
G39: Fair value adjustment T-Bill | H39: =MAX(0,SUMIFS(Journals!$K$9:$K$1011420,Journals!$D$9:$D$1011420,">"&$E$7,Journals!$D$9:$D$1011420,"<"&$E$8,Journals!$J$9:$J$1011420,"Fair value adjustment T-Bill")-SUMIFS(Journals!$L$9:$L$1011420,Journals!$D$9:$D$1011420,">"&$E$7,Journals!$D$9:$D$1011420,"<"&$E$8,Journals!$J$9:$J$1011420,"Fair value adjustment T-Bill")) -> 0 | I39: =MAX(0,SUMIFS(Journals!$L$9:$L$1011420,Journals!$D$9:$D$1011420,">"&$E$7,Journals!$D$9:$D$1011420,"<"&$E$8,Journals!$J$9:$J$1011420,"fair value adjustment T-Bill")-SUMIFS(Journals!$K$9:$K$1011420,Journals!$D$9:$D$1011420,">"&$E$7,Journals!$D$9:$D$1011420,"<"&$E$8,Journals!$J$9:$J$1011420,"fair value adjustment T-Bill")) -> 0 | J39: =MAX(0,SUMIFS(Journals!K9:K1005679,Journals!D9:D1005679,"<"&F7,Journals!J9:J1005679,"fair value adjustment T-Bill")-SUMIFS(Journals!L9:L1005679,Journals!D9:D1005679,"<"&F7,Journals!J9:J1005679,"fair value adjustment T-Bill")) -> 0 | K39: =MAX(0,SUMIFS(Journals!L9:L1005679,Journals!D9:D1005679,"<"&F7,Journals!J9:J1005679,"Fair value adjustment T-Bill")-SUMIFS(Journals!K9:K1005679,Journals!D9:D1005679,"<"&F7,Journals!J9:J1005679,"fair value adjustment T-Bill")) -> 0 | L39: =MAX(0,H39-I39+J39-K39) -> 0 | M39: =MAX(0,I39-H39-J39+K39) -> 0
G40: Fair value adjustment T-Bond | H40: =MAX(0,SUMIFS(Journals!$K$9:$K$1011420,Journals!$D$9:$D$1011420,">"&$E$7,Journals!$D$9:$D$1011420,"<"&$E$8,Journals!$J$9:$J$1011420,"Fair value adjustment T-Bond")-SUMIFS(Journals!$L$9:$L$1011420,Journals!$D$9:$D$1011420,">"&$E$7,Journals!$D$9:$D$1011420,"<"&$E$8,Journals!$J$9:$J$1011420,"Fair value adjustment T-Bond")) -> 0 | I40: =MAX(0,SUMIFS(Journals!$L$9:$L$1011420,Journals!$D$9:$D$1011420,">"&$E$7,Journals!$D$9:$D$1011420,"<"&$E$8,Journals!$J$9:$J$1011420,"fair value adjustment T-Bond")-SUMIFS(Journals!$K$9:$K$1011420,Journals!$D$9:$D$1011420,">"&$E$7,Journals!$D$9:$D$1011420,"<"&$E$8,Journals!$J$9:$J$1011420,"fair value adjustment T-Bond")) -> 0 | J40: =MAX(0,SUMIFS(Journals!K9:K1005679,Journals!D9:D1005679,"<"&F7,Journals!J9:J1005679,"fair value adjustment T-Bond")-SUMIFS(Journals!L9:L1005679,Journals!D9:D1005679,"<"&F7,Journals!J9:J1005679,"fair value adjustment T-Bond")) -> 0 | K40: =MAX(0,SUMIFS(Journals!L9:L1005679,Journals!D9:D1005679,"<"&F7,Journals!J9:J1005679,"Fair value adjustment T-Bond")-SUMIFS(Journals!K9:K1005679,Journals!D9:D1005679,"<"&F7,Journals!J9:J1005679,"fair value adjustment T-Bond")) -> 0 | L40: =MAX(0,H40-I40+J40-K40) -> 0 | M40: =MAX(0,I40-H40-J40+K40) -> 0
G41: Interest receivables from FDR | H41: =MAX(0,SUMIFS(Journals!$K$9:$K$1005679,Journals!$D$9:$D$1005679,">"&$E$7,Journals!$D$9:$D$1005679,"<"&$E$8,Journals!$J$9:$J$1005679,"Interest receivables from FDR")-SUMIFS(Journals!$L$9:$L$1005679,Journals!$D$9:$D$1005679,">"&$E$7,Journals!$D$9:$D$1005679,"<"&$E$8,Journals!$J$9:$J$1005679,"Interest receivables from FDR")) -> 0 | I41: =MAX(0,SUMIFS(Journals!$L$9:$L$1005679,Journals!$D$9:$D$1005679,">"&$E$7,Journals!$D$9:$D$1005679,"<"&$E$8,Journals!$J$9:$J$1005679,"Interest receivables from FDR")-SUMIFS(Journals!$K$9:$K$1005679,Journals!$D$9:$D$1005679,">"&$E$7,Journals!$D$9:$D$1005679,"<"&$E$8,Journals!$J$9:$J$1005679,"Interest receivables from FDR")) -> 70916.667 | J41: =SUMIFS(Journals!$K$9:$K$1005679,Journals!$D$9:$D$1005679,"<"&$F$7,Journals!$J$9:$J$1005679,"Interest receivables from FDR")-SUMIFS(Journals!$L$9:$L$1005679,Journals!$D$9:$D$1005679,"<"&$F$7,Journals!$J$9:$J$1005679,"Interest receivables from FDR") -> 184638.89 | L41: =J41+H41-I41 -> 113722.22
...

Sheet TB-P
A1: Check of Trial Balance | G1: =SUM(H7:H85)-SUM(I7:I85) -> 0.0043032765
A2: Check of Balance Sheet | G2: =BS!C25-BS!C41 -> 0
A3: Check of Cash Balance | G3: =BS!C23-CF!B44 -> -3620314.1
B5: Desired Reporting Period | H5: During the Reporting Period | J5: For Balance Sheet | N5: For Retained Earnings
B6: Year | C6: Month | D6: Day | E6: Value | F6: Value | G6: Accounts | H6: Debit | I6: Credit | J6: Carry Forward Balance | K6: Carry Forward Balance | L6: On date | M6: On date | N6: Debit | O6: Credit
A7: Beginning | B7: 2025 | C7: 1 | D7: 1 | E7: =DATE(B7,C7,D7)-1 -> 45657 | F7: =DATE(B7,C7,D7) -> 45658 | G7: ='Chart of Accounts'!B3 -> Investments in stock | H7: =MAX(0,SUMIFS(Journals!$K$9:$K$1005679,Journals!$D$9:$D$1005679,">"&$E$7,Journals!$D$9:$D$1005679,"<"&$E$8,Journals!$J$9:$J$1005679,"investments in stock")-SUMIFS(Journals!$L$9:$L$1005679,Journals!$D$9:$D$1005679,">"&$E$7,Journals!$D$9:$D$1005679,"<"&$E$8,Journals!$J$9:$J$1005679,"investments in stock")) -> 1.0338876e+08 | I7: =MAX(0,SUMIFS(Journals!$L$9:$L$1005679,Journals!$D$9:$D$1005679,">"&$E$7,Journals!$D$9:$D$1005679,"<"&$E$8,Journals!$J$9:$J$1005679,"Investments in stock")-SUMIFS(Journals!$K$9:$K$1005679,Journals!$D$9:$D$1005679,">"&$E$7,Journals!$D$9:$D$1005679,"<"&$E$8,Journals!$J$9:$J$1005679,"Investments in stock")) -> 0 | J7: =SUMIFS(Journals!$K$9:$K$1005679,Journals!$D$9:$D$1005679,"<"&$F$7,Journals!$J$9:$J$1005679,"investments in stock")-SUMIFS(Journals!$L$9:$L$1005679,Journals!$D$9:$D$1005679,"<"&$F$7,Journals!$J$9:$J$1005679,"investments in stock") -> 99890423 | L7: =J7+H7-I7 -> 2.0327918e+08
A8: Ending | B8: 2025 | C8: 12 | D8: 31 | E8: =DATE(B8,C8,D8)+1 -> 46023 | F8: =DATE(B8,C8,D8) -> 46022 | G8: ='Chart of Accounts'!B4 -> Interest Receivables from Bank A/C | H8: =MAX(0,SUMIFS(Journals!$K$9:$K$1005679,Journals!$D$9:$D$1005679,">"&$E$7,Journals!$D$9:$D$1005679,"<"&$E$8,Journals!$J$9:$J$1005679,"Interest Receivables from Bank A/C")-SUMIFS(Journals!$L$9:$L$1005679,Journals!$D$9:$D$1005679,">"&$E$7,Journals!$D$9:$D$1005679,"<"&$E$8,Journals!$J$9:$J$1005679,"Interest Receivables from Bank A/C")) -> 8231.3282 | I8: =MAX(0,SUMIFS(Journals!$L$9:$L$1005679,Journals!$D$9:$D$1005679,">"&$E$7,Journals!$D$9:$D$1005679,"<"&$E$8,Journals!$J$9:$J$1005679,"Interest Receivables from Bank A/C")-SUMIFS(Journals!$K$9:$K$1005679,Journals!$D$9:$D$1005679,">"&$E$7,Journals!$D$9:$D$1005679,"<"&$E$8,Journals!$J$9:$J$1005679,"Interest Receivables from Bank A/C")) -> 0 | J8: =SUMIFS(Journals!$K$9:$K$1005679,Journals!$D$9:$D$1005679,"<"&$F$7,Journals!$J$9:$J$1005679,"Interest Receivables from Bank A/C")-SUMIFS(Journals!$L$9:$L$1005679,Journals!$D$9:$D$1005679,"<"&$F$7,Journals!$J$9:$J$1005679,"Interest Receivables from Bank A/C") -> 2462.46 | L8: =J8+H8-I8 -> 10693.788
G9: ='Chart of Accounts'!B5 -> Preliminary & issue expenses | H9: =MAX(0,SUMIFS(Journals!$K$9:$K$1005679,Journals!$D$9:$D$1005679,">"&$E$7,Journals!$D$9:$D$1005679,"<"&$E$8,Journals!$J$9:$J$1005679,"Preliminary & issue expenses")-SUMIFS(Journals!$L$9:$L$1005679,Journals!$D$9:$D$1005679,">"&$E$7,Journals!$D$9:$D$1005679,"<"&$E$8,Journals!$J$9:$J$1005679,"Preliminary & issue expenses")) -> 0 | I9: =MAX(0,SUMIFS(Journals!$L$9:$L$1005679,Journals!$D$9:$D$1005679,">"&$E$7,Journals!$D$9:$D$1005679,"<"&$E$8,Journals!$J$9:$J$1005679,"Preliminary & issue expenses")-SUMIFS(Journals!$K$9:$K$1005679,Journals!$D$9:$D$1005679,">"&$E$7,Journals!$D$9:$D$1005679,"<"&$E$8,Journals!$J$9:$J$1005679,"Preliminary & issue expenses")) -> 142464.68 | J9: =SUMIFS(Journals!$K$9:$K$1005679,Journals!$D$9:$D$1005679,"<"&$F$7,Journals!$J$9:$J$1005679,"Preliminary & issue expenses")-SUMIFS(Journals!$L$9:$L$1005679,Journals!$D$9:$D$1005679,"<"&$F$7,Journals!$J$9:$J$1005679,"Preliminary & issue expenses") -> 587519.63 | L9: =J9+H9-I9 -> 445054.95
G10: ='Chart of Accounts'!B6 -> Accrued Management Fee | H10: =MAX(0,SUMIFS(Journals!$K$9:$K$1005679,Journals!$D$9:$D$1005679,">"&$E$7,Journals!$D$9:$D$1005679,"<"&$E$8,Journals!$J$9:$J$1005679,"Accrued Management Fee")-SUMIFS(Journals!$L$9:$L$1005679,Journals!$D$9:$D$1005679,">"&$E$7,Journals!$D$9:$D$1005679,"<"&$E$8,Journals!$J$9:$J$1005679,"Accrued Management Fee")) -> 0 | I10: =MAX(0,SUMIFS(Journals!$L$9:$L$1005679,Journals!$D$9:$D$1005679,">"&$E$7,Journals!$D$9:$D$1005679,"<"&$E$8,Journals!$J$9:$J$1005679,"Accrued Management Fee")-SUMIFS(Journals!$K$9:$K$1005679,Journals!$D$9:$D$1005679,">"&$E$7,Journals!$D$9:$D$1005679,"<"&$E$8,Journals!$J$9:$J$1005679,"Accrued Management Fee")) -> 165061.78 | K10: =SUMIFS(Journals!$L$9:$L$1005679,Journals!$D$9:$D$1005679,"<"&$F$7,Journals!$J$9:$J$1005679,"Accrued Management Fee")-SUMIFS(Journals!$K$9:$K$1005679,Journals!$D$9:$D$1005679,"<"&$F$7,Journals!$J$9:$J$1005679,"Accrued Management Fee") -> 610408.36 | M10: =K10+I10-H10 -> 775470.14
G11: ='Chart of Accounts'!B7 -> Accrued Trustee Fee | H11: =MAX(0,SUMIFS(Journals!$K$9:$K$1005679,Journals!$D$9:$D$1005679,">"&$E$7,Journals!$D$9:$D$1005679,"<"&$E$8,Journals!$J$9:$J$1005679,"accrued trustee fee")-SUMIFS(Journals!$L$9:$L$1005679,Journals!$D$9:$D$1005679,">"&$E$7,Journals!$D$9:$D$1005679,"<"&$E$8,Journals!$J$9:$J$1005679,"accrued trustee fee")) -> 0 | I11: =MAX(0,SUMIFS(Journals!$L$9:$L$1005679,Journals!$D$9:$D$1005679,">"&$E$7,Journals!$D$9:$D$1005679,"<"&$E$8,Journals!$J$9:$J$1005679,"accrued trustee fee")-SUMIFS(Journals!$K$9:$K$1005679,Journals!$D$9:$D$1005679,">"&$E$7,Journals!$D$9:$D$1005679,"<"&$E$8,Journals!$J$9:$J$1005679,"accrued trustee fee")) -> 19610.443 | K11: =SUMIFS(Journals!$L$9:$L$1005679,Journals!$D$9:$D$1005679,"<"&$F$7,Journals!$J$9:$J$1005679,"Accrued Trustee Fee")-SUMIFS(Journals!$K$9:$K$1005679,Journals!$D$9:$D$1005679,"<"&$F$7,Journals!$J$9:$J$1005679,"Accrued Trustee Fee") -> 88416.136 | M11: =K11+I11-H11 -> 108026.58
G12: ='Chart of Accounts'!B8 -> Accrued Custodian Fee | H12: =MAX(0,SUMIFS(Journals!$K$9:$K$1005679,Journals!$D$9:$D$1005679,">"&$E$7,Journals!$D$9:$D$1005679,"<"&$E$8,Journals!$J$9:$J$1005679,"accrued custodian fee")-SUMIFS(Journals!$L$9:$L$1005679,Journals!$D$9:$D$1005679,">"&$E$7,Journals!$D$9:$D$1005679,"<"&$E$8,Journals!$J$9:$J$1005679,"accrued custodian fee")) -> 0 | I12: =MAX(0,SUMIFS(Journals!$L$9:$L$1005679,Journals!$D$9:$D$1005679,">"&$E$7,Journals!$D$9:$D$1005679,"<"&$E$8,Journals!$J$9:$J$1005679,"accrued custodian fee")-SUMIFS(Journals!$K$9:$K$1005679,Journals!$D$9:$D$1005679,">"&$E$7,Journals!$D$9:$D$1005679,"<"&$E$8,Journals!$J$9:$J$1005679,"accrued custodian fee")) -> 0 | K12: =SUMIFS(Journals!$L$9:$L$1005679,Journals!$D$9:$D$1005679,"<"&$F$7,Journals!$J$9:$J$1005679,"Accrued Custodian Fee")-SUMIFS(Journals!$K$9:$K$1005679,Journals!$D$9:$D$1005679,"<"&$F$7,Journals!$J$9:$J$1005679,"Accrued Custodian Fee") -> 0 | M12: =K12+I12-H12 -> 0
G13: ='Chart of Accounts'!B9 -> Accrued BSEC fee | H13: =MAX(0,SUMIFS(Journals!$K$9:$K$1005679,Journals!$D$9:$D$1005679,">"&$E$7,Journals!$D$9:$D$1005679,"<"&$E$8,Journals!$J$9:$J$1005679,"accrued bsec fee")-SUMIFS(Journals!$L$9:$L$1005679,Journals!$D$9:$D$1005679,">"&$E$7,Journals!$D$9:$D$1005679,"<"&$E$8,Journals!$J$9:$J$1005679,"accrued bsec fee")) -> 0 | I13: =MAX(0,SUMIFS(Journals!$L$9:$L$1005679,Journals!$D$9:$D$1005679,">"&$E$7,Journals!$D$9:$D$1005679,"<"&$E$8,Journals!$J$9:$J$1005679,"accrued bsec fee")-SUMIFS(Journals!$K$9:$K$1005679,Journals!$D$9:$D$1005679,">"&$E$7,Journals!$D$9:$D$1005679,"<"&$E$8,Journals!$J$9:$J$1005679,"accrued bsec fee")) -> 0 | K13: =SUMIFS(Journals!$L$9:$L$1005679,Journals!$D$9:$D$1005679,"<"&$F$7,Journals!$J$9:$J$1005679,"accrued bsec fee")-SUMIFS(Journals!$K$9:$K$1005679,Journals!$D$9:$D$1005679,"<"&$F$7,Journals!$J$9:$J$1005679,"accrued bsec fee") -> 0 | M13: =K13+I13-H13 -> 0
G14: ='Chart of Accounts'!B10 -> Accrued Audit Fee | H14: =MAX(0,SUMIFS(Journals!$K$9:$K$1005679,Journals!$D$9:$D$1005679,">"&$E$7,Journals!$D$9:$D$1005679,"<"&$E$8,Journals!$J$9:$J$1005679,"accrued audit fee")-SUMIFS(Journals!$L$9:$L$1005679,Journals!$D$9:$D$1005679,">"&$E$7,Journals!$D$9:$D$1005679,"<"&$E$8,Journals!$J$9:$J$1005679,"accrued audit fee")) -> 0 | I14: =MAX(0,SUMIFS(Journals!$L$9:$L$1005679,Journals!$D$9:$D$1005679,">"&$E$7,Journals!$D$9:$D$1005679,"<"&$E$8,Journals!$J$9:$J$1005679,"accrued audit fee")-SUMIFS(Journals!$K$9:$K$1005679,Journals!$D$9:$D$1005679,">"&$E$7,Journals!$D$9:$D$1005679,"<"&$E$8,Journals!$J$9:$J$1005679,"accrued audit fee")) -> 17250 | K14: =SUMIFS(Journals!$L$9:$L$1005679,Journals!$D$9:$D$1005679,"<"&$F$7,Journals!$J$9:$J$1005679,"accrued audit fee")-SUMIFS(Journals!$K$9:$K$1005679,Journals!$D$9:$D$1005679,"<"&$F$7,Journals!$J$9:$J$1005679,"accrued audit fee") -> 40250 | M14: =K14+I14-H14 -> 57500
G15: ='Chart of Accounts'!B11 -> Accrued CDBL Fee | H15: =MAX(0,SUMIFS(Journals!$K$9:$K$1005679,Journals!$D$9:$D$1005679,">"&$E$7,Journals!$D$9:$D$1005679,"<"&$E$8,Journals!$J$9:$J$1005679,"accrued CDBL fee")-SUMIFS(Journals!$L$9:$L$1005679,Journals!$D$9:$D$1005679,">"&$E$7,Journals!$D$9:$D$1005679,"<"&$E$8,Journals!$J$9:$J$1005679,"accrued CDBL fee")) -> 0 | I15: =MAX(0,SUMIFS(Journals!$L$9:$L$1005679,Journals!$D$9:$D$1005679,">"&$E$7,Journals!$D$9:$D$1005679,"<"&$E$8,Journals!$J$9:$J$1005679,"accrued CDBL fee")-SUMIFS(Journals!$K$9:$K$1005679,Journals!$D$9:$D$1005679,">"&$E$7,Journals!$D$9:$D$1005679,"<"&$E$8,Journals!$J$9:$J$1005679,"accrued CDBL fee")) -> 0 | K15: =SUMIFS(Journals!$L$9:$L$1005679,Journals!$D$9:$D$1005679,"<"&$F$7,Journals!$J$9:$J$1005679,"accrued cdbl fee")-SUMIFS(Journals!$K$9:$K$1005679,Journals!$D$9:$D$1005679,"<"&$F$7,Journals!$J$9:$J$1005679,"accrued cdbl fee") -> 0 | M15: =K15+I15-H15 -> 0
G16: ='Chart of Accounts'!B12 -> Fixed Deposit Receipts (FDR) | H16: =MAX(0,SUMIFS(Journals!$K$9:$K$1005679,Journals!$D$9:$D$1005679,">"&$E$7,Journals!$D$9:$D$1005679,"<"&$E$8,Journals!$J$9:$J$1005679,"Fixed Deposit Receipts (FDR)")-SUMIFS(Journals!$L$9:$L$1005679,Journals!$D$9:$D$1005679,">"&$E$7,Journals!$D$9:$D$1005679,"<"&$E$8,Journals!$J$9:$J$1005679,"Fixed Deposit Receipts (FDR)")) -> 0 | I16: =MAX(0,SUMIFS(Journals!$L$9:$L$1005679,Journals!$D$9:$D$1005679,">"&$E$7,Journals!$D$9:$D$1005679,"<"&$E$8,Journals!$J$9:$J$1005679,"Fixed Deposit Receipts (FDR)")-SUMIFS(Journals!$K$9:$K$1005679,Journals!$D$9:$D$1005679,">"&$E$7,Journals!$D$9:$D$1005679,"<"&$E$8,Journals!$J$9:$J$1005679,"Fixed Deposit Receipts (FDR)")) -> 2060500 | J16: =SUMIFS(Journals!$K$9:$K$1005679,Journals!$D$9:$D$1005679,"<"&$F$7,Journals!$J$9:$J$1005679,"Fixed Deposit Receipts (FDR)")-SUMIFS(Journals!$L$9:$L$1005679,Journals!$D$9:$D$1005679,"<"&$F$7,Journals!$J$9:$J$1005679,"Fixed Deposit Receipts (FDR)") -> 15060500 | L16: =J16+H16-I16 -> 13000000
G17: ='Chart of Accounts'!B13 -> Cash and cash equivalents | H17: =MAX(0,SUMIFS(Journals!$K$9:$K$1005679,Journals!$D$9:$D$1005679,">"&$E$7,Journals!$D$9:$D$1005679,"<"&$E$8,Journals!$J$9:$J$1005679,"Cash and cash equivalents")-SUMIFS(Journals!$L$9:$L$1005679,Journals!$D$9:$D$1005679,">"&$E$7,Journals!$D$9:$D$1005679,"<"&$E$8,Journals!$J$9:$J$1005679,"Cash and cash equivalents")) -> 0 | I17: =MAX(0,SUMIFS(Journals!$L$9:$L$1005679,Journals!$D$9:$D$1005679,">"&$E$7,Journals!$D$9:$D$1005679,"<"&$E$8,Journals!$J$9:$J$1005679,"Cash and cash equivalents")-SUMIFS(Journals!$K$9:$K$1005679,Journals!$D$9:$D$1005679,">"&$E$7,Journals!$D$9:$D$1005679,"<"&$E$8,Journals!$J$9:$J$1005679,"Cash and cash equivalents")) -> 33907914 | J17: =SUMIFS(Journals!$K$9:$K$1005679,Journals!$D$9:$D$1005679,"<"&$F$7,Journals!$J$9:$J$1005679,"Cash and cash equivalents")-SUMIFS(Journals!$L$9:$L$1005679,Journals!$D$9:$D$1005679,"<"&$F$7,Journals!$J$9:$J$1005679,"Cash and cash equivalents") -> 34420156 | L17: =J17+H17-I17 -> 512242.08
G18: ='Chart of Accounts'!B14 -> Unit Capital | H18: =MAX(0,SUMIFS(Journals!$K$9:$K$1005679,Journals!$D$9:$D$1005679,">"&$E$7,Journals!$D$9:$D$1005679,"<"&$E$8,Journals!$J$9:$J$1005679,"unit capital")) -> 12592430 | I18: =MAX(0,SUMIFS(Journals!$L$9:$L$1005679,Journals!$D$9:$D$1005679,">"&$E$7,Journals!$D$9:$D$1005679,"<"&$E$8,Journals!$J$9:$J$1005679,"unit capital")) -> 40652580 | K18: =SUMIFS(Journals!$L$9:$L$1005679,Journals!$D$9:$D$1005679,"<"&$F$7,Journals!$J$9:$J$1005679,"unit capital")-SUMIFS(Journals!$K$9:$K$1005679,Journals!$D$9:$D$1005679,"<"&$F$7,Journals!$J$9:$J$1005679,"unit capital") -> 160875820 | M18: =K18+I18-H18 -> 188935970
G19: ='Chart of Accounts'!B15 -> Unit premium reserve | H19: =MAX(0,SUMIFS(Journals!$K$9:$K$1005679,Journals!$D$9:$D$1005679,">"&$E$7,Journals!$D$9:$D$1005679,"<"&$E$8,Journals!$J$9:$J$1005679,"Unit premium reserve")) -> 2008404 | I19: =MAX(0,SUMIFS(Journals!$L$9:$L$1005679,Journals!$D$9:$D$1005679,">"&$E$7,Journals!$D$9:$D$1005679,"<"&$E$8,Journals!$J$9:$J$1005679,"unit premium reserve")) -> 7019419.9 | K19: =SUMIFS(Journals!$L$9:$L$1005679,Journals!$D$9:$D$1005679,"<"&$F$7,Journals!$J$9:$J$1005679,"unit premium reserve")-SUMIFS(Journals!$K$9:$K$1005679,Journals!$D$9:$D$1005679,"<"&$F$7,Journals!$J$9:$J$1005679,"unit premium reserve") -> -2507109.7 | M19: =K19+I19-H19 -> 2503906.3
