Workbook
Name NAV_MKT: [1]LS!$T$1
Name NAV_MKT: LS!$S$1
Name NEW_TCV: [2]Portfolio!$F$38
Name NEW_TMV: [2]Portfolio!$H$38
Name TCV_STOCKS: #REF!
Name TMV_STOCKS: #REF!
Name TMV_STOCKS: #REF!

Sheet DASHBOARD
A1: =LS!P1+SIP!P1 -> 411925950 | C1: =LS!Q1+SIP!Q1 -> 23036942
A4: 411925950 | B4: =A1-A4 -> 0
A5: 23036942 | B5: =A5-C1 -> 0.53209996

Sheet INVESTORS
A1: INVESTOR NAME | B1: INVESTOR CODE | C1: Title | D1: TYPE OF INVESTOR | E1: LS_TOTAL UNITS BUY | F1: LS_TOTAL UNITS SOLD | G1: LS_TOTAL CURRENT UNITS | H1: LS_TOTAL COST VALUE | I1: LS_TOTAL COST OF UNITS SOLD | J1: LS_TOTAL COST VALUE OF CURRENT UNITS | K1: LS_TOTAL REALIZED GAIN | L1: SIP_TOTAL UNITS BUY | M1: SIP_TOTAL UNITS SOLD | N1: SIP_TOTAL CURRENT UNITS | O1: SIP_TOTAL COST VALUE | P1: SIP_TOTAL COST OF UNITS SOLD | Q1: SIP_TOTAL COST VALUE OF CURRENT UNITS | R1: SIP_TOTAL REALIZED GAIN | S1: TOTAL UNITS BUY | T1: TOTAL UNITS SOLD | U1: BO OPENING BALANCE | V1: BO LS UNITS SELL | W1: BO SIP UNITS SELL | X1: BO LS UNITS REPURCHASE | Y1: BO SIP UNITS REPURCHASE | Z1: BO UNITS HOLD | AA1: TOTAL CURRENT UNITS | AB1: mismatch | AC1: BO ID | AD1: Column3 | AE1: Column4 | AF1: Column2 | AG1: Column1 | AH1: Column12 | AI1: TOTAL COST VALUE OF CURRENT INVESTMENT | AJ1: LS_WEIGHT | AK1: SIP_WEIGHT | AL1: LS_AVERAGE COST | AM1: SIP_AVERAGE COST | AN1: AVERAGE COST | AO1: NAV | AP1: TOTAL MARKET VALUE | AQ1: LS_TOTAL MARKET VALUE | AR1: SIP_TOTAL MARKET VALUE | AS1: TOTAL SELLABLE UNITS | AT1: MARKET VALUE OF SELLABLE UNITS | AU1: TOTAL REALIZED GAIN | AV1: TOTAL UNREALIZED GAIN | AW1: % of Units Hold
A2: HARI PADA SAHA | B2: A00002 | C2: Dear Mr. | D2: Individual | E2: =SUMIFS(LS[Unit],LS[Investor ID],INVESTORS_LIST[[#This Row],[INVESTOR CODE]],LS[B/S],"B") -> 0 | F2: =-SUMIFS(LS[Unit],LS[Investor ID],INVESTORS_LIST[[#This Row],[INVESTOR CODE]],LS[B/S],"S") -> 0 | G2: =IF(INVESTORS_LIST[[#This Row],[LS_TOTAL UNITS BUY]]=0,0,INVESTORS_LIST[[#This Row],[LS_TOTAL UNITS BUY]]-INVESTORS_LIST[[#This Row],[LS_TOTAL UNITS SOLD]]) -> 0 | H2: =IF(INVESTORS_LIST[[#This Row],[LS_TOTAL UNITS BUY]]=0,0,SUMIFS(LS[Amount],LS[Investor ID],INVESTORS_LIST[[#This Row],[INVESTOR CODE]],LS[B/S],"B")) -> 0 | I2: =IF(INVESTORS_LIST[[#This Row],[LS_TOTAL UNITS SOLD]]=0,0,SUMIFS(LS[Cost of Units Sold],LS[Investor ID],INVESTORS_LIST[[#This Row],[INVESTOR CODE]],LS[B/S],"S")) -> 0 | J2: =IF(INVESTORS_LIST[[#This Row],[LS_TOTAL CURRENT UNITS]]=0,0,INVESTORS_LIST[[#This Row],[LS_TOTAL CURRENT UNITS]]*INVESTORS_LIST[[#This Row],[LS_AVERAGE COST]]) -> 0 | K2: =IF(INVESTORS_LIST[[#This Row],[LS_TOTAL UNITS SOLD]]=0,0,SUMIFS(LS[Realized Gain],LS[Investor ID],INVESTORS_LIST[[#This Row],[INVESTOR CODE]],LS[B/S],"S")) -> 0 | L2: =SUMIFS(SIP[Unit],SIP[Investor ID],INVESTORS_LIST[[#This Row],[INVESTOR CODE]],SIP[B/S],"B") -> 0 | M2: =-SUMIFS(SIP[Unit],SIP[Investor ID],INVESTORS_LIST[[#This Row],[INVESTOR CODE]],SIP[B/S],"S") -> 0 | N2: =IF(INVESTORS_LIST[[#This Row],[SIP_TOTAL UNITS BUY]]=0,0,INVESTORS_LIST[[#This Row],[SIP_TOTAL UNITS BUY]]-INVESTORS_LIST[[#This Row],[SIP_TOTAL UNITS SOLD]]) -> 0 | O2: =IF(INVESTORS_LIST[[#This Row],[SIP_TOTAL UNITS BUY]]=0,0,SUMIFS(SIP[Amount],SIP[Investor ID],INVESTORS_LIST[[#This Row],[INVESTOR CODE]],SIP[B/S],"B")) -> 0 | P2: =IF(INVESTORS_LIST[[#This Row],[SIP_TOTAL UNITS SOLD]]=0,0,SUMIFS(SIP[Cost of Units Sold],SIP[Investor ID],INVESTORS_LIST[[#This Row],[INVESTOR CODE]],SIP[B/S],"S")) -> 0 | Q2: =IF(INVESTORS_LIST[[#This Row],[SIP_TOTAL CURRENT UNITS]]=0,0,INVESTORS_LIST[[#This Row],[SIP_TOTAL CURRENT UNITS]]*INVESTORS_LIST[[#This Row],[SIP_AVERAGE COST]]) -> 0 | R2: =IF(INVESTORS_LIST[[#This Row],[SIP_TOTAL UNITS SOLD]]=0,0,SUMIFS(SIP[Realized Gain],SIP[Investor ID],INVESTORS_LIST[[#This Row],[INVESTOR CODE]],SIP[B/S],"S")) -> 0 | S2: =INVESTORS_LIST[[#This Row],[LS_TOTAL UNITS BUY]]+INVESTORS_LIST[[#This Row],[SIP_TOTAL UNITS BUY]] -> 0 | T2: =INVESTORS_LIST[[#This Row],[LS_TOTAL UNITS SOLD]]+INVESTORS_LIST[[#This Row],[SIP_TOTAL UNITS SOLD]] -> 0 | V2: =SUMIFS(LS[BO UNIT TRANSFER],LS[Investor ID],INVESTORS_LIST[[#This Row],[INVESTOR CODE]],LS[B/S],"B") -> 0 | W2: =SUMIFS(SIP[BO UNIT TRANSFER],SIP[Investor ID],INVESTORS_LIST[[#This Row],[INVESTOR CODE]],SIP[B/S],"B") -> 0 | X2: =SUMIFS(LS[BO UNIT TRANSFER],LS[Investor ID],INVESTORS_LIST[[#This Row],[INVESTOR CODE]],LS[B/S],"S") -> 0 | Y2: =SUMIFS(SIP[BO UNIT TRANSFER],SIP[Investor ID],INVESTORS_LIST[[#This Row],[INVESTOR CODE]],SIP[B/S],"S") -> 0 | Z2: =SUM(INVESTORS_LIST[[#This Row],[BO OPENING BALANCE]:[BO SIP UNITS REPURCHASE]]) -> 0 | AA2: =INVESTORS_LIST[[#This Row],[TOTAL UNITS BUY]]-INVESTORS_LIST[[#This Row],[TOTAL UNITS SOLD]] -> 0 | AB2: =INVESTORS_LIST[[#This Row],[TOTAL CURRENT UNITS]]-INVESTORS_LIST[[#This Row],[BO UNITS HOLD]] -> 0 | AC2: =INDEX([3]!Table_1[BO ID],MATCH(INVESTORS_LIST[[#This Row],[INVESTOR CODE]],[3]!Table_1[INVESTOR CODE],0)) -> #REF! | AD2: =INDEX([3]!Table_1[Brokerage Name2],MATCH(INVESTORS_LIST[[#This Row],[INVESTOR CODE]],[3]!Table_1[INVESTOR CODE],0)) -> #REF! | AE2: =MID(INVESTORS_LIST[[#This Row],[BO ID]],4,5) -> #REF! | AF2: =MID(INVESTORS_LIST[[#This Row],[BO ID]],2,7) -> #REF! | AG2: =MID(INVESTORS_LIST[[#This Row],[BO ID]],9,7) -> #REF! | AH2: =RIGHT(INVESTORS_LIST[[#This Row],[BO ID]],1) -> #REF! | AI2: =INVESTORS_LIST[[#This Row],[LS_TOTAL COST VALUE OF CURRENT UNITS]]+INVESTORS_LIST[[#This Row],[SIP_TOTAL COST VALUE OF CURRENT UNITS]] -> 0 | AJ2: =IF(INVESTORS_LIST[[#This Row],[TOTAL CURRENT UNITS]]=0,0,INVESTORS_LIST[[#This Row],[LS_TOTAL CURRENT UNITS]]/INVESTORS_LIST[[#This Row],[TOTAL CURRENT UNITS]]) -> 0 | AK2: =IF(INVESTORS_LIST[[#This Row],[TOTAL CURRENT UNITS]]=0,0,INVESTORS_LIST[[#This Row],[SIP_TOTAL CURRENT UNITS]]/INVESTORS_LIST[[#This Row],[TOTAL CURRENT UNITS]]) -> 0 | AL2: {=IF(INVESTORS_LIST[[#This Row],[LS_TOTAL UNITS BUY]]>0,INDEX(LS[NAV at Cost (Average)],MATCH(CONCATENATE(COUNTIFS(LS[Investor ID],INVESTORS_LIST[[#This Row],[INVESTOR CODE]]),INVESTORS_LIST[[#This Row],[INVESTOR CODE]]),LS[Unique Code],0),),0)} -> 0 | AM2: {=IF(INVESTORS_LIST[[#This Row],[SIP_TOTAL UNITS BUY]]>0,INDEX(SIP[NAV at Cost (Average)],MATCH(CONCATENATE(COUNTIFS(SIP[Investor ID],INVESTORS_LIST[[#This Row],[INVESTOR CODE]]),INVESTORS_LIST[[#This Row],[INVESTOR CODE]]),SIP[Unique Code],0),),0)} -> 0 | AN2: =IF(INVESTORS_LIST[[#This Row],[TOTAL CURRENT UNITS]]=0,0,(INVESTORS_LIST[[#This Row],[LS_WEIGHT]]*INVESTORS_LIST[[#This Row],[LS_AVERAGE COST]])+(INVESTORS_LIST[[#This Row],[SIP_WEIGHT]]*INVESTORS_LIST[[#This Row],[SIP_AVERAGE COST]])) -> 0 | AO2: =NAV_MKT -> 14.224 | AP2: =IF(INVESTORS_LIST[[#This Row],[TOTAL CURRENT UNITS]]=0,0,INVESTORS_LIST[[#This Row],[TOTAL CURRENT UNITS]]*INVESTORS_LIST[[#This Row],[NAV]]) -> 0 | AQ2: =IF(INVESTORS_LIST[[#This Row],[LS_TOTAL CURRENT UNITS]]=0,0,INVESTORS_LIST[[#This Row],[LS_TOTAL CURRENT UNITS]]*INVESTORS_LIST[[#This Row],[NAV]]) -> 0 | AR2: =IF(INVESTORS_LIST[[#This Row],[SIP_TOTAL CURRENT UNITS]]=0,0,INVESTORS_LIST[[#This Row],[SIP_TOTAL CURRENT UNITS]]*INVESTORS_LIST[[#This Row],[NAV]]) -> 0 | AS2: =INVESTORS_LIST[[#This Row],[TOTAL CURRENT UNITS]] -> 0 | AT2: =IF(INVESTORS_LIST[[#This Row],[TOTAL SELLABLE UNITS]]=0,0,INVESTORS_LIST[[#This Row],[TOTAL SELLABLE UNITS]]*INVESTORS_LIST[[#This Row],[NAV]]) -> 0 | AU2: =INVESTORS_LIST[[#This Row],[LS_TOTAL REALIZED GAIN]]+INVESTORS_LIST[[#This Row],[SIP_TOTAL REALIZED GAIN]] -> 0 | AV2: =INVESTORS_LIST[[#This Row],[TOTAL MARKET VALUE]]-INVESTORS_LIST[[#This Row],[TOTAL COST VALUE OF CURRENT INVESTMENT]] -> 0 | AW2: =IFERROR(INVESTORS_LIST[[#This Row],[TOTAL CURRENT UNITS]]/SUM(INVESTORS_LIST[TOTAL CURRENT UNITS]),0) -> 0
A3: EKUSH WEALTH MANAGEMENT LIMITED | B3: A00003 | C3: Dear | D3: Company/Organization | E3: =SUMIFS(LS[Unit],LS[Investor ID],INVESTORS_LIST[[#This Row],[INVESTOR CODE]],LS[B/S],"B") -> 4293158 | F3: =-SUMIFS(LS[Unit],LS[Investor ID],INVESTORS_LIST[[#This Row],[INVESTOR CODE]],LS[B/S],"S") -> 4043106 | G3: =IF(INVESTORS_LIST[[#This Row],[LS_TOTAL UNITS BUY]]=0,0,INVESTORS_LIST[[#This Row],[LS_TOTAL UNITS BUY]]-INVESTORS_LIST[[#This Row],[LS_TOTAL UNITS SOLD]]) -> 250052 | H3: =IF(INVESTORS_LIST[[#This Row],[LS_TOTAL UNITS BUY]]=0,0,SUMIFS(LS[Amount],LS[Investor ID],INVESTORS_LIST[[#This Row],[INVESTOR CODE]],LS[B/S],"B")) -> 45874500 | I3: =IF(INVESTORS_LIST[[#This Row],[LS_TOTAL UNITS SOLD]]=0,0,SUMIFS(LS[Cost of Units Sold],LS[Investor ID],INVESTORS_LIST[[#This Row],[INVESTOR CODE]],LS[B/S],"S")) -> 42680200 | J3: =IF(INVESTORS_LIST[[#This Row],[LS_TOTAL CURRENT UNITS]]=0,0,INVESTORS_LIST[[#This Row],[LS_TOTAL CURRENT UNITS]]*INVESTORS_LIST[[#This Row],[LS_AVERAGE COST]]) -> 3194299.8 | K3: =IF(INVESTORS_LIST[[#This Row],[LS_TOTAL UNITS SOLD]]=0,0,SUMIFS(LS[Realized Gain],LS[Investor ID],INVESTORS_LIST[[#This Row],[INVESTOR CODE]],LS[B/S],"S")) -> 3169268 | L3: =SUMIFS(SIP[Unit],SIP[Investor ID],INVESTORS_LIST[[#This Row],[INVESTOR CODE]],SIP[B/S],"B") -> 0 | M3: =-SUMIFS(SIP[Unit],SIP[Investor ID],INVESTORS_LIST[[#This Row],[INVESTOR CODE]],SIP[B/S],"S") -> 0 | N3: =IF(INVESTORS_LIST[[#This Row],[SIP_TOTAL UNITS BUY]]=0,0,INVESTORS_LIST[[#This Row],[SIP_TOTAL UNITS BUY]]-INVESTORS_LIST[[#This Row],[SIP_TOTAL UNITS SOLD]]) -> 0 | O3: =IF(INVESTORS_LIST[[#This Row],[SIP_TOTAL UNITS BUY]]=0,0,SUMIFS(SIP[Amount],SIP[Investor ID],INVESTORS_LIST[[#This Row],[INVESTOR CODE]],SIP[B/S],"B")) -> 0 | P3: =IF(INVESTORS_LIST[[#This Row],[SIP_TOTAL UNITS SOLD]]=0,0,SUMIFS(SIP[Cost of Units Sold],SIP[Investor ID],INVESTORS_LIST[[#This Row],[INVESTOR CODE]],SIP[B/S],"S")) -> 0 | Q3: =IF(INVESTORS_LIST[[#This Row],[SIP_TOTAL CURRENT UNITS]]=0,0,INVESTORS_LIST[[#This Row],[SIP_TOTAL CURRENT UNITS]]*INVESTORS_LIST[[#This Row],[SIP_AVERAGE COST]]) -> 0 | R3: =IF(INVESTORS_LIST[[#This Row],[SIP_TOTAL UNITS SOLD]]=0,0,SUMIFS(SIP[Realized Gain],SIP[Investor ID],INVESTORS_LIST[[#This Row],[INVESTOR CODE]],SIP[B/S],"S")) -> 0 | S3: =INVESTORS_LIST[[#This Row],[LS_TOTAL UNITS BUY]]+INVESTORS_LIST[[#This Row],[SIP_TOTAL UNITS BUY]] -> 4293158 | T3: =INVESTORS_LIST[[#This Row],[LS_TOTAL UNITS SOLD]]+INVESTORS_LIST[[#This Row],[SIP_TOTAL UNITS SOLD]] -> 4043106 | U3: 500052 | V3: =SUMIFS(LS[BO UNIT TRANSFER],LS[Investor ID],INVESTORS_LIST[[#This Row],[INVESTOR CODE]],LS[B/S],"B") -> 0 | W3: =SUMIFS(SIP[BO UNIT TRANSFER],SIP[Investor ID],INVESTORS_LIST[[#This Row],[INVESTOR CODE]],SIP[B/S],"B") -> 0 | X3: =SUMIFS(LS[BO UNIT TRANSFER],LS[Investor ID],INVESTORS_LIST[[#This Row],[INVESTOR CODE]],LS[B/S],"S") -> 0 | Y3: =SUMIFS(SIP[BO UNIT TRANSFER],SIP[Investor ID],INVESTORS_LIST[[#This Row],[INVESTOR CODE]],SIP[B/S],"S") -> 0 | Z3: =SUM(INVESTORS_LIST[[#This Row],[BO OPENING BALANCE]:[BO SIP UNITS REPURCHASE]]) -> 500052 | AA3: =INVESTORS_LIST[[#This Row],[TOTAL UNITS BUY]]-INVESTORS_LIST[[#This Row],[TOTAL UNITS SOLD]] -> 250052 | AB3: =INVESTORS_LIST[[#This Row],[TOTAL CURRENT UNITS]]-INVESTORS_LIST[[#This Row],[BO UNITS HOLD]] -> -250000 | AC3: =INDEX([3]!Table_1[BO ID],MATCH(INVESTORS_LIST[[#This Row],[INVESTOR CODE]],[3]!Table_1[INVESTOR CODE],0)) -> #REF! | AD3: =INDEX([3]!Table_1[Brokerage Name2],MATCH(INVESTORS_LIST[[#This Row],[INVESTOR CODE]],[3]!Table_1[INVESTOR CODE],0)) -> #REF! | AE3: =MID(INVESTORS_LIST[[#This Row],[BO ID]],4,5) -> #REF! | AF3: =MID(INVESTORS_LIST[[#This Row],[BO ID]],2,7) -> #REF! | AG3: =MID(INVESTORS_LIST[[#This Row],[BO ID]],9,7) -> #REF! | AH3: =RIGHT(INVESTORS_LIST[[#This Row],[BO ID]],1) -> #REF! | AI3: =INVESTORS_LIST[[#This Row],[LS_TOTAL COST VALUE OF CURRENT UNITS]]+INVESTORS_LIST[[#This Row],[SIP_TOTAL COST VALUE OF CURRENT UNITS]] -> 3194299.8 | AJ3: =IF(INVESTORS_LIST[[#This Row],[TOTAL CURRENT UNITS]]=0,0,INVESTORS_LIST[[#This Row],[LS_TOTAL CURRENT UNITS]]/INVESTORS_LIST[[#This Row],[TOTAL CURRENT UNITS]]) -> 1 | AK3: =IF(INVESTORS_LIST[[#This Row],[TOTAL CURRENT UNITS]]=0,0,INVESTORS_LIST[[#This Row],[SIP_TOTAL CURRENT UNITS]]/INVESTORS_LIST[[#This Row],[TOTAL CURRENT UNITS]]) -> 0 | AL3: {=IF(INVESTORS_LIST[[#This Row],[LS_TOTAL UNITS BUY]]>0,INDEX(LS[NAV at Cost (Average)],MATCH(CONCATENATE(COUNTIFS(LS[Investor ID],INVESTORS_LIST[[#This Row],[INVESTOR CODE]]),INVESTORS_LIST[[#This Row],[INVESTOR CODE]]),LS[Unique Code],0),),0)} -> 12.774542 | AM3: {=IF(INVESTORS_LIST[[#This Row],[SIP_TOTAL UNITS BUY]]>0,INDEX(SIP[NAV at Cost (Average)],MATCH(CONCATENATE(COUNTIFS(SIP[Investor ID],INVESTORS_LIST[[#This Row],[INVESTOR CODE]]),INVESTORS_LIST[[#This Row],[INVESTOR CODE]]),SIP[Unique Code],0),),0)} -> 0 | AN3: =IF(INVESTORS_LIST[[#This Row],[TOTAL CURRENT UNITS]]=0,0,(INVESTORS_LIST[[#This Row],[LS_WEIGHT]]*INVESTORS_LIST[[#This Row],[LS_AVERAGE COST]])+(INVESTORS_LIST[[#This Row],[SIP_WEIGHT]]*INVESTORS_LIST[[#This Row],[SIP_AVERAGE COST]])) -> 12.774542 | AO3: =NAV_MKT -> 14.224 | AP3: =IF(INVESTORS_LIST[[#This Row],[TOTAL CURRENT UNITS]]=0,0,INVESTORS_LIST[[#This Row],[TOTAL CURRENT UNITS]]*INVESTORS_LIST[[#This Row],[NAV]]) -> 3556739.6 | AQ3: =IF(INVESTORS_LIST[[#This Row],[LS_TOTAL CURRENT UNITS]]=0,0,INVESTORS_LIST[[#This Row],[LS_TOTAL CURRENT UNITS]]*INVESTORS_LIST[[#This Row],[NAV]]) -> 3556739.6 | AR3: =IF(INVESTORS_LIST[[#This Row],[SIP_TOTAL CURRENT UNITS]]=0,0,INVESTORS_LIST[[#This Row],[SIP_TOTAL CURRENT UNITS]]*INVESTORS_LIST[[#This Row],[NAV]]) -> 0 | AS3: =INVESTORS_LIST[[#This Row],[TOTAL CURRENT UNITS]] -> 250052 | AT3: =IF(INVESTORS_LIST[[#This Row],[TOTAL SELLABLE UNITS]]=0,0,INVESTORS_LIST[[#This Row],[TOTAL SELLABLE UNITS]]*INVESTORS_LIST[[#This Row],[NAV]]) -> 3556739.6 | AU3: =INVESTORS_LIST[[#This Row],[LS_TOTAL REALIZED GAIN]]+INVESTORS_LIST[[#This Row],[SIP_TOTAL REALIZED GAIN]] -> 3169268 | AV3: =INVESTORS_LIST[[#This Row],[TOTAL MARKET VALUE]]-INVESTORS_LIST[[#This Row],[TOTAL COST VALUE OF CURRENT INVESTMENT]] -> 362439.86 | AW3: =IFERROR(INVESTORS_LIST[[#This Row],[TOTAL CURRENT UNITS]]/SUM(INVESTORS_LIST[TOTAL CURRENT UNITS]),0) -> 0.0060703143
A4: SADIA AHMED | B4: A00004 | C4: Dear Mrs. | D4: Individual | E4: =SUMIFS(LS[Unit],LS[Investor ID],INVESTORS_LIST[[#This Row],[INVESTOR CODE]],LS[B/S],"B") -> 0 | F4: =-SUMIFS(LS[Unit],LS[Investor ID],INVESTORS_LIST[[#This Row],[INVESTOR CODE]],LS[B/S],"S") -> 0 | G4: =IF(INVESTORS_LIST[[#This Row],[LS_TOTAL UNITS BUY]]=0,0,INVESTORS_LIST[[#This Row],[LS_TOTAL UNITS BUY]]-INVESTORS_LIST[[#This Row],[LS_TOTAL UNITS SOLD]]) -> 0 | H4: =IF(INVESTORS_LIST[[#This Row],[LS_TOTAL UNITS BUY]]=0,0,SUMIFS(LS[Amount],LS[Investor ID],INVESTORS_LIST[[#This Row],[INVESTOR CODE]],LS[B/S],"B")) -> 0 | I4: =IF(INVESTORS_LIST[[#This Row],[LS_TOTAL UNITS SOLD]]=0,0,SUMIFS(LS[Cost of Units Sold],LS[Investor ID],INVESTORS_LIST[[#This Row],[INVESTOR CODE]],LS[B/S],"S")) -> 0 | J4: =IF(INVESTORS_LIST[[#This Row],[LS_TOTAL CURRENT UNITS]]=0,0,INVESTORS_LIST[[#This Row],[LS_TOTAL CURRENT UNITS]]*INVESTORS_LIST[[#This Row],[LS_AVERAGE COST]]) -> 0 | K4: =IF(INVESTORS_LIST[[#This Row],[LS_TOTAL UNITS SOLD]]=0,0,SUMIFS(LS[Realized Gain],LS[Investor ID],INVESTORS_LIST[[#This Row],[INVESTOR CODE]],LS[B/S],"S")) -> 0 | L4: =SUMIFS(SIP[Unit],SIP[Investor ID],INVESTORS_LIST[[#This Row],[INVESTOR CODE]],SIP[B/S],"B") -> 0 | M4: =-SUMIFS(SIP[Unit],SIP[Investor ID],INVESTORS_LIST[[#This Row],[INVESTOR CODE]],SIP[B/S],"S") -> 0 | N4: =IF(INVESTORS_LIST[[#This Row],[SIP_TOTAL UNITS BUY]]=0,0,INVESTORS_LIST[[#This Row],[SIP_TOTAL UNITS BUY]]-INVESTORS_LIST[[#This Row],[SIP_TOTAL UNITS SOLD]]) -> 0 | O4: =IF(INVESTORS_LIST[[#This Row],[SIP_TOTAL UNITS BUY]]=0,0,SUMIFS(SIP[Amount],SIP[Investor ID],INVESTORS_LIST[[#This Row],[INVESTOR CODE]],SIP[B/S],"B")) -> 0 | P4: =IF(INVESTORS_LIST[[#This Row],[SIP_TOTAL UNITS SOLD]]=0,0,SUMIFS(SIP[Cost of Units Sold],SIP[Investor ID],INVESTORS_LIST[[#This Row],[INVESTOR CODE]],SIP[B/S],"S")) -> 0 | Q4: =IF(INVESTORS_LIST[[#This Row],[SIP_TOTAL CURRENT UNITS]]=0,0,INVESTORS_LIST[[#This Row],[SIP_TOTAL CURRENT UNITS]]*INVESTORS_LIST[[#This Row],[SIP_AVERAGE COST]]) -> 0 | R4: =IF(INVESTORS_LIST[[#This Row],[SIP_TOTAL UNITS SOLD]]=0,0,SUMIFS(SIP[Realized Gain],SIP[Investor ID],INVESTORS_LIST[[#This Row],[INVESTOR CODE]],SIP[B/S],"S")) -> 0 | S4: =INVESTORS_LIST[[#This Row],[LS_TOTAL UNITS BUY]]+INVESTORS_LIST[[#This Row],[SIP_TOTAL UNITS BUY]] -> 0 | T4: =INVESTORS_LIST[[#This Row],[LS_TOTAL UNITS SOLD]]+INVESTORS_LIST[[#This Row],[SIP_TOTAL UNITS SOLD]] -> 0 | V4: =SUMIFS(LS[BO UNIT TRANSFER],LS[Investor ID],INVESTORS_LIST[[#This Row],[INVESTOR CODE]],LS[B/S],"B") -> 0 | W4: =SUMIFS(SIP[BO UNIT TRANSFER],SIP[Investor ID],INVESTORS_LIST[[#This Row],[INVESTOR CODE]],SIP[B/S],"B") -> 0 | X4: =SUMIFS(LS[BO UNIT TRANSFER],LS[Investor ID],INVESTORS_LIST[[#This Row],[INVESTOR CODE]],LS[B/S],"S") -> 0 | Y4: =SUMIFS(SIP[BO UNIT TRANSFER],SIP[Investor ID],INVESTORS_LIST[[#This Row],[INVESTOR CODE]],SIP[B/S],"S") -> 0 | Z4: =SUM(INVESTORS_LIST[[#This Row],[BO OPENING BALANCE]:[BO SIP UNITS REPURCHASE]]) -> 0 | AA4: =INVESTORS_LIST[[#This Row],[TOTAL UNITS BUY]]-INVESTORS_LIST[[#This Row],[TOTAL UNITS SOLD]] -> 0 | AB4: =INVESTORS_LIST[[#This Row],[TOTAL CURRENT UNITS]]-INVESTORS_LIST[[#This Row],[BO UNITS HOLD]] -> 0 | AC4: =INDEX([3]!Table_1[BO ID],MATCH(INVESTORS_LIST[[#This Row],[INVESTOR CODE]],[3]!Table_1[INVESTOR CODE],0)) -> #REF! | AD4: =INDEX([3]!Table_1[Brokerage Name2],MATCH(INVESTORS_LIST[[#This Row],[INVESTOR CODE]],[3]!Table_1[INVESTOR CODE],0)) -> #REF! | AE4: =MID(INVESTORS_LIST[[#This Row],[BO ID]],4,5) -> #REF! | AF4: =MID(INVESTORS_LIST[[#This Row],[BO ID]],2,7) -> #REF! | AG4: =MID(INVESTORS_LIST[[#This Row],[BO ID]],9,7) -> #REF! | AH4: =RIGHT(INVESTORS_LIST[[#This Row],[BO ID]],1) -> #REF! | AI4: =INVESTORS_LIST[[#This Row],[LS_TOTAL COST VALUE OF CURRENT UNITS]]+INVESTORS_LIST[[#This Row],[SIP_TOTAL COST VALUE OF CURRENT UNITS]] -> 0 | AJ4: =IF(INVESTORS_LIST[[#This Row],[TOTAL CURRENT UNITS]]=0,0,INVESTORS_LIST[[#This Row],[LS_TOTAL CURRENT UNITS]]/INVESTORS_LIST[[#This Row],[TOTAL CURRENT UNITS]]) -> 0 | AK4: =IF(INVESTORS_LIST[[#This Row],[TOTAL CURRENT UNITS]]=0,0,INVESTORS_LIST[[#This Row],[SIP_TOTAL CURRENT UNITS]]/INVESTORS_LIST[[#This Row],[TOTAL CURRENT UNITS]]) -> 0 | AL4: {=IF(INVESTORS_LIST[[#This Row],[LS_TOTAL UNITS BUY]]>0,INDEX(LS[NAV at Cost (Average)],MATCH(CONCATENATE(COUNTIFS(LS[Investor ID],INVESTORS_LIST[[#This Row],[INVESTOR CODE]]),INVESTORS_LIST[[#This Row],[INVESTOR CODE]]),LS[Unique Code],0),),0)} -> 0 | AM4: {=IF(INVESTORS_LIST[[#This Row],[SIP_TOTAL UNITS BUY]]>0,INDEX(SIP[NAV at Cost (Average)],MATCH(CONCATENATE(COUNTIFS(SIP[Investor ID],INVESTORS_LIST[[#This Row],[INVESTOR CODE]]),INVESTORS_LIST[[#This Row],[INVESTOR CODE]]),SIP[Unique Code],0),),0)} -> 0 | AN4: =IF(INVESTORS_LIST[[#This Row],[TOTAL CURRENT UNITS]]=0,0,(INVESTORS_LIST[[#This Row],[LS_WEIGHT]]*INVESTORS_LIST[[#This Row],[LS_AVERAGE COST]])+(INVESTORS_LIST[[#This Row],[SIP_WEIGHT]]*INVESTORS_LIST[[#This Row],[SIP_AVERAGE COST]])) -> 0 | AO4: =NAV_MKT -> 14.224 | AP4: =IF(INVESTORS_LIST[[#This Row],[TOTAL CURRENT UNITS]]=0,0,INVESTORS_LIST[[#This Row],[TOTAL CURRENT UNITS]]*INVESTORS_LIST[[#This Row],[NAV]]) -> 0 | AQ4: =IF(INVESTORS_LIST[[#This Row],[LS_TOTAL CURRENT UNITS]]=0,0,INVESTORS_LIST[[#This Row],[LS_TOTAL CURRENT UNITS]]*INVESTORS_LIST[[#This Row],[NAV]]) -> 0 | AR4: =IF(INVESTORS_LIST[[#This Row],[SIP_TOTAL CURRENT UNITS]]=0,0,INVESTORS_LIST[[#This Row],[SIP_TOTAL CURRENT UNITS]]*INVESTORS_LIST[[#This Row],[NAV]]) -> 0 | AS4: =INVESTORS_LIST[[#This Row],[TOTAL CURRENT UNITS]] -> 0 | AT4: =IF(INVESTORS_LIST[[#This Row],[TOTAL SELLABLE UNITS]]=0,0,INVESTORS_LIST[[#This Row],[TOTAL SELLABLE UNITS]]*INVESTORS_LIST[[#This Row],[NAV]]) -> 0 | AU4: =INVESTORS_LIST[[#This Row],[LS_TOTAL REALIZED GAIN]]+INVESTORS_LIST[[#This Row],[SIP_TOTAL REALIZED GAIN]] -> 0 | AV4: =INVESTORS_LIST[[#This Row],[TOTAL MARKET VALUE]]-INVESTORS_LIST[[#This Row],[TOTAL COST VALUE OF CURRENT INVESTMENT]] -> 0 | AW4: =IFERROR(INVESTORS_LIST[[#This Row],[TOTAL CURRENT UNITS]]/SUM(INVESTORS_LIST[TOTAL CURRENT UNITS]),0) -> 0
A5: MORSHEDA MIM | B5: A00005 | C5: Dear Mrs. | D5: Individual | E5: =SUMIFS(LS[Unit],LS[Investor ID],INVESTORS_LIST[[#This Row],[INVESTOR CODE]],LS[B/S],"B") -> 94661 | F5: =-SUMIFS(LS[Unit],LS[Investor ID],INVESTORS_LIST[[#This Row],[INVESTOR CODE]],LS[B/S],"S") -> 94661 | G5: =IF(INVESTORS_LIST[[#This Row],[LS_TOTAL UNITS BUY]]=0,0,INVESTORS_LIST[[#This Row],[LS_TOTAL UNITS BUY]]-INVESTORS_LIST[[#This Row],[LS_TOTAL UNITS SOLD]]) -> 0 | H5: =IF(INVESTORS_LIST[[#This Row],[LS_TOTAL UNITS BUY]]=0,0,SUMIFS(LS[Amount],LS[Investor ID],INVESTORS_LIST[[#This Row],[INVESTOR CODE]],LS[B/S],"B")) -> 1000000 | I5: =IF(INVESTORS_LIST[[#This Row],[LS_TOTAL UNITS SOLD]]=0,0,SUMIFS(LS[Cost of Units Sold],LS[Investor ID],INVESTORS_LIST[[#This Row],[INVESTOR CODE]],LS[B/S],"S")) -> 1000000 | J5: =IF(INVESTORS_LIST[[#This Row],[LS_TOTAL CURRENT UNITS]]=0,0,INVESTORS_LIST[[#This Row],[LS_TOTAL CURRENT UNITS]]*INVESTORS_LIST[[#This Row],[LS_AVERAGE COST]]) -> 0 | K5: =IF(INVESTORS_LIST[[#This Row],[LS_TOTAL UNITS SOLD]]=0,0,SUMIFS(LS[Realized Gain],LS[Investor ID],INVESTORS_LIST[[#This Row],[INVESTOR CODE]],LS[B/S],"S")) -> 49736.91 | L5: =SUMIFS(SIP[Unit],SIP[Investor ID],INVESTORS_LIST[[#This Row],[INVESTOR CODE]],SIP[B/S],"B") -> 0 | M5: =-SUMIFS(SIP[Unit],SIP[Investor ID],INVESTORS_LIST[[#This Row],[INVESTOR CODE]],SIP[B/S],"S") -> 0 | N5: =IF(INVESTORS_LIST[[#This Row],[SIP_TOTAL UNITS BUY]]=0,0,INVESTORS_LIST[[#This Row],[SIP_TOTAL UNITS BUY]]-INVESTORS_LIST[[#This Row],[SIP_TOTAL UNITS SOLD]]) -> 0 | O5: =IF(INVESTORS_LIST[[#This Row],[SIP_TOTAL UNITS BUY]]=0,0,SUMIFS(SIP[Amount],SIP[Investor ID],INVESTORS_LIST[[#This Row],[INVESTOR CODE]],SIP[B/S],"B")) -> 0 | P5: =IF(INVESTORS_LIST[[#This Row],[SIP_TOTAL UNITS SOLD]]=0,0,SUMIFS(SIP[Cost of Units Sold],SIP[Investor ID],INVESTORS_LIST[[#This Row],[INVESTOR CODE]],SIP[B/S],"S")) -> 0 | Q5: =IF(INVESTORS_LIST[[#This Row],[SIP_TOTAL CURRENT UNITS]]=0,0,INVESTORS_LIST[[#This Row],[SIP_TOTAL CURRENT UNITS]]*INVESTORS_LIST[[#This Row],[SIP_AVERAGE COST]]) -> 0 | R5: =IF(INVESTORS_LIST[[#This Row],[SIP_TOTAL UNITS SOLD]]=0,0,SUMIFS(SIP[Realized Gain],SIP[Investor ID],INVESTORS_LIST[[#This Row],[INVESTOR CODE]],SIP[B/S],"S")) -> 0 | S5: =INVESTORS_LIST[[#This Row],[LS_TOTAL UNITS BUY]]+INVESTORS_LIST[[#This Row],[SIP_TOTAL UNITS BUY]] -> 94661 | T5: =INVESTORS_LIST[[#This Row],[LS_TOTAL UNITS SOLD]]+INVESTORS_LIST[[#This Row],[SIP_TOTAL UNITS SOLD]] -> 94661 | U5: 47468 | V5: =SUMIFS(LS[BO UNIT TRANSFER],LS[Investor ID],INVESTORS_LIST[[#This Row],[INVESTOR CODE]],LS[B/S],"B") -> 0 | W5: =SUMIFS(SIP[BO UNIT TRANSFER],SIP[Investor ID],INVESTORS_LIST[[#This Row],[INVESTOR CODE]],SIP[B/S],"B") -> 0 | X5: =SUMIFS(LS[BO UNIT TRANSFER],LS[Investor ID],INVESTORS_LIST[[#This Row],[INVESTOR CODE]],LS[B/S],"S") -> 0 | Y5: =SUMIFS(SIP[BO UNIT TRANSFER],SIP[Investor ID],INVESTORS_LIST[[#This Row],[INVESTOR CODE]],SIP[B/S],"S") -> 0 | Z5: =SUM(INVESTORS_LIST[[#This Row],[BO OPENING BALANCE]:[BO SIP UNITS REPURCHASE]]) -> 47468 | AA5: =INVESTORS_LIST[[#This Row],[TOTAL UNITS BUY]]-INVESTORS_LIST[[#This Row],[TOTAL UNITS SOLD]] -> 0 | AB5: =INVESTORS_LIST[[#This Row],[TOTAL CURRENT UNITS]]-INVESTORS_LIST[[#This Row],[BO UNITS HOLD]] -> -47468 | AC5: =INDEX([3]!Table_1[BO ID],MATCH(INVESTORS_LIST[[#This Row],[INVESTOR CODE]],[3]!Table_1[INVESTOR CODE],0)) -> #REF! | AD5: =INDEX([3]!Table_1[Brokerage Name2],MATCH(INVESTORS_LIST[[#This Row],[INVESTOR CODE]],[3]!Table_1[INVESTOR CODE],0)) -> #REF! | AE5: =MID(INVESTORS_LIST[[#This Row],[BO ID]],4,5) -> #REF! | AF5: =MID(INVESTORS_LIST[[#This Row],[BO ID]],2,7) -> #REF! | AG5: =MID(INVESTORS_LIST[[#This Row],[BO ID]],9,7) -> #REF! | AH5: =RIGHT(INVESTORS_LIST[[#This Row],[BO ID]],1) -> #REF! | AI5: =INVESTORS_LIST[[#This Row],[LS_TOTAL COST VALUE OF CURRENT UNITS]]+INVESTORS_LIST[[#This Row],[SIP_TOTAL COST VALUE OF CURRENT UNITS]] -> 0 | AJ5: =IF(INVESTORS_LIST[[#This Row],[TOTAL CURRENT UNITS]]=0,0,INVESTORS_LIST[[#This Row],[LS_TOTAL CURRENT UNITS]]/INVESTORS_LIST[[#This Row],[TOTAL CURRENT UNITS]]) -> 0 | AK5: =IF(INVESTORS_LIST[[#This Row],[TOTAL CURRENT UNITS]]=0,0,INVESTORS_LIST[[#This Row],[SIP_TOTAL CURRENT UNITS]]/INVESTORS_LIST[[#This Row],[TOTAL CURRENT UNITS]]) -> 0 | AL5: {=IF(INVESTORS_LIST[[#This Row],[LS_TOTAL UNITS BUY]]>0,INDEX(LS[NAV at Cost (Average)],MATCH(CONCATENATE(COUNTIFS(LS[Investor ID],INVESTORS_LIST[[#This Row],[INVESTOR CODE]]),INVESTORS_LIST[[#This Row],[INVESTOR CODE]]),LS[Unique Code],0),),0)} -> 0 | AM5: {=IF(INVESTORS_LIST[[#This Row],[SIP_TOTAL UNITS BUY]]>0,INDEX(SIP[NAV at Cost (Average)],MATCH(CONCATENATE(COUNTIFS(SIP[Investor ID],INVESTORS_LIST[[#This Row],[INVESTOR CODE]]),INVESTORS_LIST[[#This Row],[INVESTOR CODE]]),SIP[Unique Code],0),),0)} -> 0 | AN5: =IF(INVESTORS_LIST[[#This Row],[TOTAL CURRENT UNITS]]=0,0,(INVESTORS_LIST[[#This Row],[LS_WEIGHT]]*INVESTORS_LIST[[#This Row],[LS_AVERAGE COST]])+(INVESTORS_LIST[[#This Row],[SIP_WEIGHT]]*INVESTORS_LIST[[#This Row],[SIP_AVERAGE COST]])) -> 0 | AO5: =NAV_MKT -> 14.224 | AP5: =IF(INVESTORS_LIST[[#This Row],[TOTAL CURRENT UNITS]]=0,0,INVESTORS_LIST[[#This Row],[TOTAL CURRENT UNITS]]*INVESTORS_LIST[[#This Row],[NAV]]) -> 0 | AQ5: =IF(INVESTORS_LIST[[#This Row],[LS_TOTAL CURRENT UNITS]]=0,0,INVESTORS_LIST[[#This Row],[LS_TOTAL CURRENT UNITS]]*INVESTORS_LIST[[#This Row],[NAV]]) -> 0 | AR5: =IF(INVESTORS_LIST[[#This Row],[SIP_TOTAL CURRENT UNITS]]=0,0,INVESTORS_LIST[[#This Row],[SIP_TOTAL CURRENT UNITS]]*INVESTORS_LIST[[#This Row],[NAV]]) -> 0 | AS5: =INVESTORS_LIST[[#This Row],[TOTAL CURRENT UNITS]] -> 0 | AT5: =IF(INVESTORS_LIST[[#This Row],[TOTAL SELLABLE UNITS]]=0,0,INVESTORS_LIST[[#This Row],[TOTAL SELLABLE UNITS]]*INVESTORS_LIST[[#This Row],[NAV]]) -> 0 | AU5: =INVESTORS_LIST[[#This Row],[LS_TOTAL REALIZED GAIN]]+INVESTORS_LIST[[#This Row],[SIP_TOTAL REALIZED GAIN]] -> 49736.91 | AV5: =INVESTORS_LIST[[#This Row],[TOTAL MARKET VALUE]]-INVESTORS_LIST[[#This Row],[TOTAL COST VALUE OF CURRENT INVESTMENT]] -> 0 | AW5: =IFERROR(INVESTORS_LIST[[#This Row],[TOTAL CURRENT UNITS]]/SUM(INVESTORS_LIST[TOTAL CURRENT UNITS]),0) -> 0
A6: MD. JAHANGIR ALAM | B6: A00006 | C6: Dear Mr. | D6: Individual | E6: =SUMIFS(LS[Unit],LS[Investor ID],INVESTORS_LIST[[#This Row],[INVESTOR CODE]],LS[B/S],"B") -> 0 | F6: =-SUMIFS(LS[Unit],LS[Investor ID],INVESTORS_LIST[[#This Row],[INVESTOR CODE]],LS[B/S],"S") -> 0 | G6: =IF(INVESTORS_LIST[[#This Row],[LS_TOTAL UNITS BUY]]=0,0,INVESTORS_LIST[[#This Row],[LS_TOTAL UNITS BUY]]-INVESTORS_LIST[[#This Row],[LS_TOTAL UNITS SOLD]]) -> 0 | H6: =IF(INVESTORS_LIST[[#This Row],[LS_TOTAL UNITS BUY]]=0,0,SUMIFS(LS[Amount],LS[Investor ID],INVESTORS_LIST[[#This Row],[INVESTOR CODE]],LS[B/S],"B")) -> 0 | I6: =IF(INVESTORS_LIST[[#This Row],[LS_TOTAL UNITS SOLD]]=0,0,SUMIFS(LS[Cost of Units Sold],LS[Investor ID],INVESTORS_LIST[[#This Row],[INVESTOR CODE]],LS[B/S],"S")) -> 0 | J6: =IF(INVESTORS_LIST[[#This Row],[LS_TOTAL CURRENT UNITS]]=0,0,INVESTORS_LIST[[#This Row],[LS_TOTAL CURRENT UNITS]]*INVESTORS_LIST[[#This Row],[LS_AVERAGE COST]]) -> 0 | K6: =IF(INVESTORS_LIST[[#This Row],[LS_TOTAL UNITS SOLD]]=0,0,SUMIFS(LS[Realized Gain],LS[Investor ID],INVESTORS_LIST[[#This Row],[INVESTOR CODE]],LS[B/S],"S")) -> 0 | L6: =SUMIFS(SIP[Unit],SIP[Investor ID],INVESTORS_LIST[[#This Row],[INVESTOR CODE]],SIP[B/S],"B") -> 0 | M6: =-SUMIFS(SIP[Unit],SIP[Investor ID],INVESTORS_LIST[[#This Row],[INVESTOR CODE]],SIP[B/S],"S") -> 0 | N6: =IF(INVESTORS_LIST[[#This Row],[SIP_TOTAL UNITS BUY]]=0,0,INVESTORS_LIST[[#This Row],[SIP_TOTAL UNITS BUY]]-INVESTORS_LIST[[#This Row],[SIP_TOTAL UNITS SOLD]]) -> 0 | O6: =IF(INVESTORS_LIST[[#This Row],[SIP_TOTAL UNITS BUY]]=0,0,SUMIFS(SIP[Amount],SIP[Investor ID],INVESTORS_LIST[[#This Row],[INVESTOR CODE]],SIP[B/S],"B")) -> 0 | P6: =IF(INVESTORS_LIST[[#This Row],[SIP_TOTAL UNITS SOLD]]=0,0,SUMIFS(SIP[Cost of Units Sold],SIP[Investor ID],INVESTORS_LIST[[#This Row],[INVESTOR CODE]],SIP[B/S],"S")) -> 0 | Q6: =IF(INVESTORS_LIST[[#This Row],[SIP_TOTAL CURRENT UNITS]]=0,0,INVESTORS_LIST[[#This Row],[SIP_TOTAL CURRENT UNITS]]*INVESTORS_LIST[[#This Row],[SIP_AVERAGE COST]]) -> 0 | R6: =IF(INVESTORS_LIST[[#This Row],[SIP_TOTAL UNITS SOLD]]=0,0,SUMIFS(SIP[Realized Gain],SIP[Investor ID],INVESTORS_LIST[[#This Row],[INVESTOR CODE]],SIP[B/S],"S")) -> 0 | S6: =INVESTORS_LIST[[#This Row],[LS_TOTAL UNITS BUY]]+INVESTORS_LIST[[#This Row],[SIP_TOTAL UNITS BUY]] -> 0 | T6: =INVESTORS_LIST[[#This Row],[LS_TOTAL UNITS SOLD]]+INVESTORS_LIST[[#This Row],[SIP_TOTAL UNITS SOLD]] -> 0 | V6: =SUMIFS(LS[BO UNIT TRANSFER],LS[Investor ID],INVESTORS_LIST[[#This Row],[INVESTOR CODE]],LS[B/S],"B") -> 0 | W6: =SUMIFS(SIP[BO UNIT TRANSFER],SIP[Investor ID],INVESTORS_LIST[[#This Row],[INVESTOR CODE]],SIP[B/S],"B") -> 0 | X6: =SUMIFS(LS[BO UNIT TRANSFER],LS[Investor ID],INVESTORS_LIST[[#This Row],[INVESTOR CODE]],LS[B/S],"S") -> 0 | Y6: =SUMIFS(SIP[BO UNIT TRANSFER],SIP[Investor ID],INVESTORS_LIST[[#This Row],[INVESTOR CODE]],SIP[B/S],"S") -> 0 | Z6: =SUM(INVESTORS_LIST[[#This Row],[BO OPENING BALANCE]:[BO SIP UNITS REPURCHASE]]) -> 0 | AA6: =INVESTORS_LIST[[#This Row],[TOTAL UNITS BUY]]-INVESTORS_LIST[[#This Row],[TOTAL UNITS SOLD]] -> 0 | AB6: =INVESTORS_LIST[[#This Row],[TOTAL CURRENT UNITS]]-INVESTORS_LIST[[#This Row],[BO UNITS HOLD]] -> 0 | AC6: =INDEX([3]!Table_1[BO ID],MATCH(INVESTORS_LIST[[#This Row],[INVESTOR CODE]],[3]!Table_1[INVESTOR CODE],0)) -> #REF! | AD6: =INDEX([3]!Table_1[Brokerage Name2],MATCH(INVESTORS_LIST[[#This Row],[INVESTOR CODE]],[3]!Table_1[INVESTOR CODE],0)) -> #REF! | AE6: =MID(INVESTORS_LIST[[#This Row],[BO ID]],4,5) -> #REF! | AF6: =MID(INVESTORS_LIST[[#This Row],[BO ID]],2,7) -> #REF! | AG6: =MID(INVESTORS_LIST[[#This Row],[BO ID]],9,7) -> #REF! | AH6: =RIGHT(INVESTORS_LIST[[#This Row],[BO ID]],1) -> #REF! | AI6: =INVESTORS_LIST[[#This Row],[LS_TOTAL COST VALUE OF CURRENT UNITS]]+INVESTORS_LIST[[#This Row],[SIP_TOTAL COST VALUE OF CURRENT UNITS]] -> 0 | AJ6: =IF(INVESTORS_LIST[[#This Row],[TOTAL CURRENT UNITS]]=0,0,INVESTORS_LIST[[#This Row],[LS_TOTAL CURRENT UNITS]]/INVESTORS_LIST[[#This Row],[TOTAL CURRENT UNITS]]) -> 0 | AK6: =IF(INVESTORS_LIST[[#This Row],[TOTAL CURRENT UNITS]]=0,0,INVESTORS_LIST[[#This Row],[SIP_TOTAL CURRENT UNITS]]/INVESTORS_LIST[[#This Row],[TOTAL CURRENT UNITS]]) -> 0 | AL6: {=IF(INVESTORS_LIST[[#This Row],[LS_TOTAL UNITS BUY]]>0,INDEX(LS[NAV at Cost (Average)],MATCH(CONCATENATE(COUNTIFS(LS[Investor ID],INVESTORS_LIST[[#This Row],[INVESTOR CODE]]),INVESTORS_LIST[[#This Row],[INVESTOR CODE]]),LS[Unique Code],0),),0)} -> 0 | AM6: {=IF(INVESTORS_LIST[[#This Row],[SIP_TOTAL UNITS BUY]]>0,INDEX(SIP[NAV at Cost (Average)],MATCH(CONCATENATE(COUNTIFS(SIP[Investor ID],INVESTORS_LIST[[#This Row],[INVESTOR CODE]]),INVESTORS_LIST[[#This Row],[INVESTOR CODE]]),SIP[Unique Code],0),),0)} -> 0 | AN6: =IF(INVESTORS_LIST[[#This Row],[TOTAL CURRENT UNITS]]=0,0,(INVESTORS_LIST[[#This Row],[LS_WEIGHT]]*INVESTORS_LIST[[#This Row],[LS_AVERAGE COST]])+(INVESTORS_LIST[[#This Row],[SIP_WEIGHT]]*INVESTORS_LIST[[#This Row],[SIP_AVERAGE COST]])) -> 0 | AO6: =NAV_MKT -> 14.224 | AP6: =IF(INVESTORS_LIST[[#This Row],[TOTAL CURRENT UNITS]]=0,0,INVESTORS_LIST[[#This Row],[TOTAL CURRENT UNITS]]*INVESTORS_LIST[[#This Row],[NAV]]) -> 0 | AQ6: =IF(INVESTORS_LIST[[#This Row],[LS_TOTAL CURRENT UNITS]]=0,0,INVESTORS_LIST[[#This Row],[LS_TOTAL CURRENT UNITS]]*INVESTORS_LIST[[#This Row],[NAV]]) -> 0 | AR6: =IF(INVESTORS_LIST[[#This Row],[SIP_TOTAL CURRENT UNITS]]=0,0,INVESTORS_LIST[[#This Row],[SIP_TOTAL CURRENT UNITS]]*INVESTORS_LIST[[#This Row],[NAV]]) -> 0 | AS6: =INVESTORS_LIST[[#This Row],[TOTAL CURRENT UNITS]] -> 0 | AT6: =IF(INVESTORS_LIST[[#This Row],[TOTAL SELLABLE UNITS]]=0,0,INVESTORS_LIST[[#This Row],[TOTAL SELLABLE UNITS]]*INVESTORS_LIST[[#This Row],[NAV]]) -> 0 | AU6: =INVESTORS_LIST[[#This Row],[LS_TOTAL REALIZED GAIN]]+INVESTORS_LIST[[#This Row],[SIP_TOTAL REALIZED GAIN]] -> 0 | AV6: =INVESTORS_LIST[[#This Row],[TOTAL MARKET VALUE]]-INVESTORS_LIST[[#This Row],[TOTAL COST VALUE OF CURRENT INVESTMENT]] -> 0 | AW6: =IFERROR(INVESTORS_LIST[[#This Row],[TOTAL CURRENT UNITS]]/SUM(INVESTORS_LIST[TOTAL CURRENT UNITS]),0) -> 0
A7: BISWAS ARIFUR RAHMAN | B7: A00007 | C7: Dear Mr. | D7: Individual | E7: =SUMIFS(LS[Unit],LS[Investor ID],INVESTORS_LIST[[#This Row],[INVESTOR CODE]],LS[B/S],"B") -> 0 | F7: =-SUMIFS(LS[Unit],LS[Investor ID],INVESTORS_LIST[[#This Row],[INVESTOR CODE]],LS[B/S],"S") -> 0 | G7: =IF(INVESTORS_LIST[[#This Row],[LS_TOTAL UNITS BUY]]=0,0,INVESTORS_LIST[[#This Row],[LS_TOTAL UNITS BUY]]-INVESTORS_LIST[[#This Row],[LS_TOTAL UNITS SOLD]]) -> 0 | H7: =IF(INVESTORS_LIST[[#This Row],[LS_TOTAL UNITS BUY]]=0,0,SUMIFS(LS[Amount],LS[Investor ID],INVESTORS_LIST[[#This Row],[INVESTOR CODE]],LS[B/S],"B")) -> 0 | I7: =IF(INVESTORS_LIST[[#This Row],[LS_TOTAL UNITS SOLD]]=0,0,SUMIFS(LS[Cost of Units Sold],LS[Investor ID],INVESTORS_LIST[[#This Row],[INVESTOR CODE]],LS[B/S],"S")) -> 0 | J7: =IF(INVESTORS_LIST[[#This Row],[LS_TOTAL CURRENT UNITS]]=0,0,INVESTORS_LIST[[#This Row],[LS_TOTAL CURRENT UNITS]]*INVESTORS_LIST[[#This Row],[LS_AVERAGE COST]]) -> 0 | K7: =IF(INVESTORS_LIST[[#This Row],[LS_TOTAL UNITS SOLD]]=0,0,SUMIFS(LS[Realized Gain],LS[Investor ID],INVESTORS_LIST[[#This Row],[INVESTOR CODE]],LS[B/S],"S")) -> 0 | L7: =SUMIFS(SIP[Unit],SIP[Investor ID],INVESTORS_LIST[[#This Row],[INVESTOR CODE]],SIP[B/S],"B") -> 0 | M7: =-SUMIFS(SIP[Unit],SIP[Investor ID],INVESTORS_LIST[[#This Row],[INVESTOR CODE]],SIP[B/S],"S") -> 0 | N7: =IF(INVESTORS_LIST[[#This Row],[SIP_TOTAL UNITS BUY]]=0,0,INVESTORS_LIST[[#This Row],[SIP_TOTAL UNITS BUY]]-INVESTORS_LIST[[#This Row],[SIP_TOTAL UNITS SOLD]]) -> 0 | O7: =IF(INVESTORS_LIST[[#This Row],[SIP_TOTAL UNITS BUY]]=0,0,SUMIFS(SIP[Amount],SIP[Investor ID],INVESTORS_LIST[[#This Row],[INVESTOR CODE]],SIP[B/S],"B")) -> 0 | P7: =IF(INVESTORS_LIST[[#This Row],[SIP_TOTAL UNITS SOLD]]=0,0,SUMIFS(SIP[Cost of Units Sold],SIP[Investor ID],INVESTORS_LIST[[#This Row],[INVESTOR CODE]],SIP[B/S],"S")) -> 0 | Q7: =IF(INVESTORS_LIST[[#This Row],[SIP_TOTAL CURRENT UNITS]]=0,0,INVESTORS_LIST[[#This Row],[SIP_TOTAL CURRENT UNITS]]*INVESTORS_LIST[[#This Row],[SIP_AVERAGE COST]]) -> 0 | R7: =IF(INVESTORS_LIST[[#This Row],[SIP_TOTAL UNITS SOLD]]=0,0,SUMIFS(SIP[Realized Gain],SIP[Investor ID],INVESTORS_LIST[[#This Row],[INVESTOR CODE]],SIP[B/S],"S")) -> 0 | S7: =INVESTORS_LIST[[#This Row],[LS_TOTAL UNITS BUY]]+INVESTORS_LIST[[#This Row],[SIP_TOTAL UNITS BUY]] -> 0 | T7: =INVESTORS_LIST[[#This Row],[LS_TOTAL UNITS SOLD]]+INVESTORS_LIST[[#This Row],[SIP_TOTAL UNITS SOLD]] -> 0 | V7: =SUMIFS(LS[BO UNIT TRANSFER],LS[Investor ID],INVESTORS_LIST[[#This Row],[INVESTOR CODE]],LS[B/S],"B") -> 0 | W7: =SUMIFS(SIP[BO UNIT TRANSFER],SIP[Investor ID],INVESTORS_LIST[[#This Row],[INVESTOR CODE]],SIP[B/S],"B") -> 0 | X7: =SUMIFS(LS[BO UNIT TRANSFER],LS[Investor ID],INVESTORS_LIST[[#This Row],[INVESTOR CODE]],LS[B/S],"S") -> 0 | Y7: =SUMIFS(SIP[BO UNIT TRANSFER],SIP[Investor ID],INVESTORS_LIST[[#This Row],[INVESTOR CODE]],SIP[B/S],"S") -> 0 | Z7: =SUM(INVESTORS_LIST[[#This Row],[BO OPENING BALANCE]:[BO SIP UNITS REPURCHASE]]) -> 0 | AA7: =INVESTORS_LIST[[#This Row],[TOTAL UNITS BUY]]-INVESTORS_LIST[[#This Row],[TOTAL UNITS SOLD]] -> 0 | AB7: =INVESTORS_LIST[[#This Row],[TOTAL CURRENT UNITS]]-INVESTORS_LIST[[#This Row],[BO UNITS HOLD]] -> 0 | AC7: =INDEX([3]!Table_1[BO ID],MATCH(INVESTORS_LIST[[#This Row],[INVESTOR CODE]],[3]!Table_1[INVESTOR CODE],0)) -> #REF! | AD7: =INDEX([3]!Table_1[Brokerage Name2],MATCH(INVESTORS_LIST[[#This Row],[INVESTOR CODE]],[3]!Table_1[INVESTOR CODE],0)) -> #REF! | AE7: =MID(INVESTORS_LIST[[#This Row],[BO ID]],4,5) -> #REF! | AF7: =MID(INVESTORS_LIST[[#This Row],[BO ID]],2,7) -> #REF! | AG7: =MID(INVESTORS_LIST[[#This Row],[BO ID]],9,7) -> #REF! | AH7: =RIGHT(INVESTORS_LIST[[#This Row],[BO ID]],1) -> #REF! | AI7: =INVESTORS_LIST[[#This Row],[LS_TOTAL COST VALUE OF CURRENT UNITS]]+INVESTORS_LIST[[#This Row],[SIP_TOTAL COST VALUE OF CURRENT UNITS]] -> 0 | AJ7: =IF(INVESTORS_LIST[[#This Row],[TOTAL CURRENT UNITS]]=0,0,INVESTORS_LIST[[#This Row],[LS_TOTAL CURRENT UNITS]]/INVESTORS_LIST[[#This Row],[TOTAL CURRENT UNITS]]) -> 0 | AK7: =IF(INVESTORS_LIST[[#This Row],[TOTAL CURRENT UNITS]]=0,0,INVESTORS_LIST[[#This Row],[SIP_TOTAL CURRENT UNITS]]/INVESTORS_LIST[[#This Row],[TOTAL CURRENT UNITS]]) -> 0 | AL7: {=IF(INVESTORS_LIST[[#This Row],[LS_TOTAL UNITS BUY]]>0,INDEX(LS[NAV at Cost (Average)],MATCH(CONCATENATE(COUNTIFS(LS[Investor ID],INVESTORS_LIST[[#This Row],[INVESTOR CODE]]),INVESTORS_LIST[[#This Row],[INVESTOR CODE]]),LS[Unique Code],0),),0)} -> 0 | AM7: {=IF(INVESTORS_LIST[[#This Row],[SIP_TOTAL UNITS BUY]]>0,INDEX(SIP[NAV at Cost (Average)],MATCH(CONCATENATE(COUNTIFS(SIP[Investor ID],INVESTORS_LIST[[#This Row],[INVESTOR CODE]]),INVESTORS_LIST[[#This Row],[INVESTOR CODE]]),SIP[Unique Code],0),),0)} -> 0 | AN7: =IF(INVESTORS_LIST[[#This Row],[TOTAL CURRENT UNITS]]=0,0,(INVESTORS_LIST[[#This Row],[LS_WEIGHT]]*INVESTORS_LIST[[#This Row],[LS_AVERAGE COST]])+(INVESTORS_LIST[[#This Row],[SIP_WEIGHT]]*INVESTORS_LIST[[#This Row],[SIP_AVERAGE COST]])) -> 0 | AO7: =NAV_MKT -> 14.224 | AP7: =IF(INVESTORS_LIST[[#This Row],[TOTAL CURRENT UNITS]]=0,0,INVESTORS_LIST[[#This Row],[TOTAL CURRENT UNITS]]*INVESTORS_LIST[[#This Row],[NAV]]) -> 0 | AQ7: =IF(INVESTORS_LIST[[#This Row],[LS_TOTAL CURRENT UNITS]]=0,0,INVESTORS_LIST[[#This Row],[LS_TOTAL CURRENT UNITS]]*INVESTORS_LIST[[#This Row],[NAV]]) -> 0 | AR7: =IF(INVESTORS_LIST[[#This Row],[SIP_TOTAL CURRENT UNITS]]=0,0,INVESTORS_LIST[[#This Row],[SIP_TOTAL CURRENT UNITS]]*INVESTORS_LIST[[#This Row],[NAV]]) -> 0 | AS7: =INVESTORS_LIST[[#This Row],[TOTAL CURRENT UNITS]] -> 0 | AT7: =IF(INVESTORS_LIST[[#This Row],[TOTAL SELLABLE UNITS]]=0,0,INVESTORS_LIST[[#This Row],[TOTAL SELLABLE UNITS]]*INVESTORS_LIST[[#This Row],[NAV]]) -> 0 | AU7: =INVESTORS_LIST[[#This Row],[LS_TOTAL REALIZED GAIN]]+INVESTORS_LIST[[#This Row],[SIP_TOTAL REALIZED GAIN]] -> 0 | AV7: =INVESTORS_LIST[[#This Row],[TOTAL MARKET VALUE]]-INVESTORS_LIST[[#This Row],[TOTAL COST VALUE OF CURRENT INVESTMENT]] -> 0 | AW7: =IFERROR(INVESTORS_LIST[[#This Row],[TOTAL CURRENT UNITS]]/SUM(INVESTORS_LIST[TOTAL CURRENT UNITS]),0) -> 0
A8: JEWEL SAHA | B8: A00008 | C8: Dear Mr. | D8: Individual | E8: =SUMIFS(LS[Unit],LS[Investor ID],INVESTORS_LIST[[#This Row],[INVESTOR CODE]],LS[B/S],"B") -> 0 | F8: =-SUMIFS(LS[Unit],LS[Investor ID],INVESTORS_LIST[[#This Row],[INVESTOR CODE]],LS[B/S],"S") -> 0 | G8: =IF(INVESTORS_LIST[[#This Row],[LS_TOTAL UNITS BUY]]=0,0,INVESTORS_LIST[[#This Row],[LS_TOTAL UNITS BUY]]-INVESTORS_LIST[[#This Row],[LS_TOTAL UNITS SOLD]]) -> 0 | H8: =IF(INVESTORS_LIST[[#This Row],[LS_TOTAL UNITS BUY]]=0,0,SUMIFS(LS[Amount],LS[Investor ID],INVESTORS_LIST[[#This Row],[INVESTOR CODE]],LS[B/S],"B")) -> 0 | I8: =IF(INVESTORS_LIST[[#This Row],[LS_TOTAL UNITS SOLD]]=0,0,SUMIFS(LS[Cost of Units Sold],LS[Investor ID],INVESTORS_LIST[[#This Row],[INVESTOR CODE]],LS[B/S],"S")) -> 0 | J8: =IF(INVESTORS_LIST[[#This Row],[LS_TOTAL CURRENT UNITS]]=0,0,INVESTORS_LIST[[#This Row],[LS_TOTAL CURRENT UNITS]]*INVESTORS_LIST[[#This Row],[LS_AVERAGE COST]]) -> 0 | K8: =IF(INVESTORS_LIST[[#This Row],[LS_TOTAL UNITS SOLD]]=0,0,SUMIFS(LS[Realized Gain],LS[Investor ID],INVESTORS_LIST[[#This Row],[INVESTOR CODE]],LS[B/S],"S")) -> 0 | L8: =SUMIFS(SIP[Unit],SIP[Investor ID],INVESTORS_LIST[[#This Row],[INVESTOR CODE]],SIP[B/S],"B") -> 0 | M8: =-SUMIFS(SIP[Unit],SIP[Investor ID],INVESTORS_LIST[[#This Row],[INVESTOR CODE]],SIP[B/S],"S") -> 0 | N8: =IF(INVESTORS_LIST[[#This Row],[SIP_TOTAL UNITS BUY]]=0,0,INVESTORS_LIST[[#This Row],[SIP_TOTAL UNITS BUY]]-INVESTORS_LIST[[#This Row],[SIP_TOTAL UNITS SOLD]]) -> 0 | O8: =IF(INVESTORS_LIST[[#This Row],[SIP_TOTAL UNITS BUY]]=0,0,SUMIFS(SIP[Amount],SIP[Investor ID],INVESTORS_LIST[[#This Row],[INVESTOR CODE]],SIP[B/S],"B")) -> 0 | P8: =IF(INVESTORS_LIST[[#This Row],[SIP_TOTAL UNITS SOLD]]=0,0,SUMIFS(SIP[Cost of Units Sold],SIP[Investor ID],INVESTORS_LIST[[#This Row],[INVESTOR CODE]],SIP[B/S],"S")) -> 0 | Q8: =IF(INVESTORS_LIST[[#This Row],[SIP_TOTAL CURRENT UNITS]]=0,0,INVESTORS_LIST[[#This Row],[SIP_TOTAL CURRENT UNITS]]*INVESTORS_LIST[[#This Row],[SIP_AVERAGE COST]]) -> 0 | R8: =IF(INVESTORS_LIST[[#This Row],[SIP_TOTAL UNITS SOLD]]=0,0,SUMIFS(SIP[Realized Gain],SIP[Investor ID],INVESTORS_LIST[[#This Row],[INVESTOR CODE]],SIP[B/S],"S")) -> 0 | S8: =INVESTORS_LIST[[#This Row],[LS_TOTAL UNITS BUY]]+INVESTORS_LIST[[#This Row],[SIP_TOTAL UNITS BUY]] -> 0 | T8: =INVESTORS_LIST[[#This Row],[LS_TOTAL UNITS SOLD]]+INVESTORS_LIST[[#This Row],[SIP_TOTAL UNITS SOLD]] -> 0 | V8: =SUMIFS(LS[BO UNIT TRANSFER],LS[Investor ID],INVESTORS_LIST[[#This Row],[INVESTOR CODE]],LS[B/S],"B") -> 0 | W8: =SUMIFS(SIP[BO UNIT TRANSFER],SIP[Investor ID],INVESTORS_LIST[[#This Row],[INVESTOR CODE]],SIP[B/S],"B") -> 0 | X8: =SUMIFS(LS[BO UNIT TRANSFER],LS[Investor ID],INVESTORS_LIST[[#This Row],[INVESTOR CODE]],LS[B/S],"S") -> 0 | Y8: =SUMIFS(SIP[BO UNIT TRANSFER],SIP[Investor ID],INVESTORS_LIST[[#This Row],[INVESTOR CODE]],SIP[B/S],"S") -> 0 | Z8: =SUM(INVESTORS_LIST[[#This Row],[BO OPENING BALANCE]:[BO SIP UNITS REPURCHASE]]) -> 0 | AA8: =INVESTORS_LIST[[#This Row],[TOTAL UNITS BUY]]-INVESTORS_LIST[[#This Row],[TOTAL UNITS SOLD]] -> 0 | AB8: =INVESTORS_LIST[[#This Row],[TOTAL CURRENT UNITS]]-INVESTORS_LIST[[#This Row],[BO UNITS HOLD]] -> 0 | AC8: =INDEX([3]!Table_1[BO ID],MATCH(INVESTORS_LIST[[#This Row],[INVESTOR CODE]],[3]!Table_1[INVESTOR CODE],0)) -> #REF! | AD8: =INDEX([3]!Table_1[Brokerage Name2],MATCH(INVESTORS_LIST[[#This Row],[INVESTOR CODE]],[3]!Table_1[INVESTOR CODE],0)) -> #REF! | AE8: =MID(INVESTORS_LIST[[#This Row],[BO ID]],4,5) -> #REF! | AF8: =MID(INVESTORS_LIST[[#This Row],[BO ID]],2,7) -> #REF! | AG8: =MID(INVESTORS_LIST[[#This Row],[BO ID]],9,7) -> #REF! | AH8: =RIGHT(INVESTORS_LIST[[#This Row],[BO ID]],1) -> #REF! | AI8: =INVESTORS_LIST[[#This Row],[LS_TOTAL COST VALUE OF CURRENT UNITS]]+INVESTORS_LIST[[#This Row],[SIP_TOTAL COST VALUE OF CURRENT UNITS]] -> 0 | AJ8: =IF(INVESTORS_LIST[[#This Row],[TOTAL CURRENT UNITS]]=0,0,INVESTORS_LIST[[#This Row],[LS_TOTAL CURRENT UNITS]]/INVESTORS_LIST[[#This Row],[TOTAL CURRENT UNITS]]) -> 0 | AK8: =IF(INVESTORS_LIST[[#This Row],[TOTAL CURRENT UNITS]]=0,0,INVESTORS_LIST[[#This Row],[SIP_TOTAL CURRENT UNITS]]/INVESTORS_LIST[[#This Row],[TOTAL CURRENT UNITS]]) -> 0 | AL8: {=IF(INVESTORS_LIST[[#This Row],[LS_TOTAL UNITS BUY]]>0,INDEX(LS[NAV at Cost (Average)],MATCH(CONCATENATE(COUNTIFS(LS[Investor ID],INVESTORS_LIST[[#This Row],[INVESTOR CODE]]),INVESTORS_LIST[[#This Row],[INVESTOR CODE]]),LS[Unique Code],0),),0)} -> 0 | AM8: {=IF(INVESTORS_LIST[[#This Row],[SIP_TOTAL UNITS BUY]]>0,INDEX(SIP[NAV at Cost (Average)],MATCH(CONCATENATE(COUNTIFS(SIP[Investor ID],INVESTORS_LIST[[#This Row],[INVESTOR CODE]]),INVESTORS_LIST[[#This Row],[INVESTOR CODE]]),SIP[Unique Code],0),),0)} -> 0 | AN8: =IF(INVESTORS_LIST[[#This Row],[TOTAL CURRENT UNITS]]=0,0,(INVESTORS_LIST[[#This Row],[LS_WEIGHT]]*INVESTORS_LIST[[#This Row],[LS_AVERAGE COST]])+(INVESTORS_LIST[[#This Row],[SIP_WEIGHT]]*INVESTORS_LIST[[#This Row],[SIP_AVERAGE COST]])) -> 0 | AO8: =NAV_MKT -> 14.224 | AP8: =IF(INVESTORS_LIST[[#This Row],[TOTAL CURRENT UNITS]]=0,0,INVESTORS_LIST[[#This Row],[TOTAL CURRENT UNITS]]*INVESTORS_LIST[[#This Row],[NAV]]) -> 0 | AQ8: =IF(INVESTORS_LIST[[#This Row],[LS_TOTAL CURRENT UNITS]]=0,0,INVESTORS_LIST[[#This Row],[LS_TOTAL CURRENT UNITS]]*INVESTORS_LIST[[#This Row],[NAV]]) -> 0 | AR8: =IF(INVESTORS_LIST[[#This Row],[SIP_TOTAL CURRENT UNITS]]=0,0,INVESTORS_LIST[[#This Row],[SIP_TOTAL CURRENT UNITS]]*INVESTORS_LIST[[#This Row],[NAV]]) -> 0 | AS8: =INVESTORS_LIST[[#This Row],[TOTAL CURRENT UNITS]] -> 0 | AT8: =IF(INVESTORS_LIST[[#This Row],[TOTAL SELLABLE UNITS]]=0,0,INVESTORS_LIST[[#This Row],[TOTAL SELLABLE UNITS]]*INVESTORS_LIST[[#This Row],[NAV]]) -> 0 | AU8: =INVESTORS_LIST[[#This Row],[LS_TOTAL REALIZED GAIN]]+INVESTORS_LIST[[#This Row],[SIP_TOTAL REALIZED GAIN]] -> 0 | AV8: =INVESTORS_LIST[[#This Row],[TOTAL MARKET VALUE]]-INVESTORS_LIST[[#This Row],[TOTAL COST VALUE OF CURRENT INVESTMENT]] -> 0 | AW8: =IFERROR(INVESTORS_LIST[[#This Row],[TOTAL CURRENT UNITS]]/SUM(INVESTORS_LIST[TOTAL CURRENT UNITS]),0) -> 0
A9: SHIBBIR AHMED | B9: A00009 | C9: Dear Mr. | D9: Individual | E9: =SUMIFS(LS[Unit],LS[Investor ID],INVESTORS_LIST[[#This Row],[INVESTOR CODE]],LS[B/S],"B") -> 0 | F9: =-SUMIFS(LS[Unit],LS[Investor ID],INVESTORS_LIST[[#This Row],[INVESTOR CODE]],LS[B/S],"S") -> 0 | G9: =IF(INVESTORS_LIST[[#This Row],[LS_TOTAL UNITS BUY]]=0,0,INVESTORS_LIST[[#This Row],[LS_TOTAL UNITS BUY]]-INVESTORS_LIST[[#This Row],[LS_TOTAL UNITS SOLD]]) -> 0 | H9: =IF(INVESTORS_LIST[[#This Row],[LS_TOTAL UNITS BUY]]=0,0,SUMIFS(LS[Amount],LS[Investor ID],INVESTORS_LIST[[#This Row],[INVESTOR CODE]],LS[B/S],"B")) -> 0 | I9: =IF(INVESTORS_LIST[[#This Row],[LS_TOTAL UNITS SOLD]]=0,0,SUMIFS(LS[Cost of Units Sold],LS[Investor ID],INVESTORS_LIST[[#This Row],[INVESTOR CODE]],LS[B/S],"S")) -> 0 | J9: =IF(INVESTORS_LIST[[#This Row],[LS_TOTAL CURRENT UNITS]]=0,0,INVESTORS_LIST[[#This Row],[LS_TOTAL CURRENT UNITS]]*INVESTORS_LIST[[#This Row],[LS_AVERAGE COST]]) -> 0 | K9: =IF(INVESTORS_LIST[[#This Row],[LS_TOTAL UNITS SOLD]]=0,0,SUMIFS(LS[Realized Gain],LS[Investor ID],INVESTORS_LIST[[#This Row],[INVESTOR CODE]],LS[B/S],"S")) -> 0 | L9: =SUMIFS(SIP[Unit],SIP[Investor ID],INVESTORS_LIST[[#This Row],[INVESTOR CODE]],SIP[B/S],"B") -> 0 | M9: =-SUMIFS(SIP[Unit],SIP[Investor ID],INVESTORS_LIST[[#This Row],[INVESTOR CODE]],SIP[B/S],"S") -> 0 | N9: =IF(INVESTORS_LIST[[#This Row],[SIP_TOTAL UNITS BUY]]=0,0,INVESTORS_LIST[[#This Row],[SIP_TOTAL UNITS BUY]]-INVESTORS_LIST[[#This Row],[SIP_TOTAL UNITS SOLD]]) -> 0 | O9: =IF(INVESTORS_LIST[[#This Row],[SIP_TOTAL UNITS BUY]]=0,0,SUMIFS(SIP[Amount],SIP[Investor ID],INVESTORS_LIST[[#This Row],[INVESTOR CODE]],SIP[B/S],"B")) -> 0 | P9: =IF(INVESTORS_LIST[[#This Row],[SIP_TOTAL UNITS SOLD]]=0,0,SUMIFS(SIP[Cost of Units Sold],SIP[Investor ID],INVESTORS_LIST[[#This Row],[INVESTOR CODE]],SIP[B/S],"S")) -> 0 | Q9: =IF(INVESTORS_LIST[[#This Row],[SIP_TOTAL CURRENT UNITS]]=0,0,INVESTORS_LIST[[#This Row],[SIP_TOTAL CURRENT UNITS]]*INVESTORS_LIST[[#This Row],[SIP_AVERAGE COST]]) -> 0 | R9: =IF(INVESTORS_LIST[[#This Row],[SIP_TOTAL UNITS SOLD]]=0,0,SUMIFS(SIP[Realized Gain],SIP[Investor ID],INVESTORS_LIST[[#This Row],[INVESTOR CODE]],SIP[B/S],"S")) -> 0 | S9: =INVESTORS_LIST[[#This Row],[LS_TOTAL UNITS BUY]]+INVESTORS_LIST[[#This Row],[SIP_TOTAL UNITS BUY]] -> 0 | T9: =INVESTORS_LIST[[#This Row],[LS_TOTAL UNITS SOLD]]+INVESTORS_LIST[[#This Row],[SIP_TOTAL UNITS SOLD]] -> 0 | V9: =SUMIFS(LS[BO UNIT TRANSFER],LS[Investor ID],INVESTORS_LIST[[#This Row],[INVESTOR CODE]],LS[B/S],"B") -> 0 | W9: =SUMIFS(SIP[BO UNIT TRANSFER],SIP[Investor ID],INVESTORS_LIST[[#This Row],[INVESTOR CODE]],SIP[B/S],"B") -> 0 | X9: =SUMIFS(LS[BO UNIT TRANSFER],LS[Investor ID],INVESTORS_LIST[[#This Row],[INVESTOR CODE]],LS[B/S],"S") -> 0 | Y9: =SUMIFS(SIP[BO UNIT TRANSFER],SIP[Investor ID],INVESTORS_LIST[[#This Row],[INVESTOR CODE]],SIP[B/S],"S") -> 0 | Z9: =SUM(INVESTORS_LIST[[#This Row],[BO OPENING BALANCE]:[BO SIP UNITS REPURCHASE]]) -> 0 | AA9: =INVESTORS_LIST[[#This Row],[TOTAL UNITS BUY]]-INVESTORS_LIST[[#This Row],[TOTAL UNITS SOLD]] -> 0 | AB9: =INVESTORS_LIST[[#This Row],[TOTAL CURRENT UNITS]]-INVESTORS_LIST[[#This Row],[BO UNITS HOLD]] -> 0 | AC9: =INDEX([3]!Table_1[BO ID],MATCH(INVESTORS_LIST[[#This Row],[INVESTOR CODE]],[3]!Table_1[INVESTOR CODE],0)) -> #REF! | AD9: =INDEX([3]!Table_1[Brokerage Name2],MATCH(INVESTORS_LIST[[#This Row],[INVESTOR CODE]],[3]!Table_1[INVESTOR CODE],0)) -> #REF! | AE9: =MID(INVESTORS_LIST[[#This Row],[BO ID]],4,5) -> #REF! | AF9: =MID(INVESTORS_LIST[[#This Row],[BO ID]],2,7) -> #REF! | AG9: =MID(INVESTORS_LIST[[#This Row],[BO ID]],9,7) -> #REF! | AH9: =RIGHT(INVESTORS_LIST[[#This Row],[BO ID]],1) -> #REF! | AI9: =INVESTORS_LIST[[#This Row],[LS_TOTAL COST VALUE OF CURRENT UNITS]]+INVESTORS_LIST[[#This Row],[SIP_TOTAL COST VALUE OF CURRENT UNITS]] -> 0 | AJ9: =IF(INVESTORS_LIST[[#This Row],[TOTAL CURRENT UNITS]]=0,0,INVESTORS_LIST[[#This Row],[LS_TOTAL CURRENT UNITS]]/INVESTORS_LIST[[#This Row],[TOTAL CURRENT UNITS]]) -> 0 | AK9: =IF(INVESTORS_LIST[[#This Row],[TOTAL CURRENT UNITS]]=0,0,INVESTORS_LIST[[#This Row],[SIP_TOTAL CURRENT UNITS]]/INVESTORS_LIST[[#This Row],[TOTAL CURRENT UNITS]]) -> 0 | AL9: {=IF(INVESTORS_LIST[[#This Row],[LS_TOTAL UNITS BUY]]>0,INDEX(LS[NAV at Cost (Average)],MATCH(CONCATENATE(COUNTIFS(LS[Investor ID],INVESTORS_LIST[[#This Row],[INVESTOR CODE]]),INVESTORS_LIST[[#This Row],[INVESTOR CODE]]),LS[Unique Code],0),),0)} -> 0 | AM9: {=IF(INVESTORS_LIST[[#This Row],[SIP_TOTAL UNITS BUY]]>0,INDEX(SIP[NAV at Cost (Average)],MATCH(CONCATENATE(COUNTIFS(SIP[Investor ID],INVESTORS_LIST[[#This Row],[INVESTOR CODE]]),INVESTORS_LIST[[#This Row],[INVESTOR CODE]]),SIP[Unique Code],0),),0)} -> 0 | AN9: =IF(INVESTORS_LIST[[#This Row],[TOTAL CURRENT UNITS]]=0,0,(INVESTORS_LIST[[#This Row],[LS_WEIGHT]]*INVESTORS_LIST[[#This Row],[LS_AVERAGE COST]])+(INVESTORS_LIST[[#This Row],[SIP_WEIGHT]]*INVESTORS_LIST[[#This Row],[SIP_AVERAGE COST]])) -> 0 | AO9: =NAV_MKT -> 14.224 | AP9: =IF(INVESTORS_LIST[[#This Row],[TOTAL CURRENT UNITS]]=0,0,INVESTORS_LIST[[#This Row],[TOTAL CURRENT UNITS]]*INVESTORS_LIST[[#This Row],[NAV]]) -> 0 | AQ9: =IF(INVESTORS_LIST[[#This Row],[LS_TOTAL CURRENT UNITS]]=0,0,INVESTORS_LIST[[#This Row],[LS_TOTAL CURRENT UNITS]]*INVESTORS_LIST[[#This Row],[NAV]]) -> 0 | AR9: =IF(INVESTORS_LIST[[#This Row],[SIP_TOTAL CURRENT UNITS]]=0,0,INVESTORS_LIST[[#This Row],[SIP_TOTAL CURRENT UNITS]]*INVESTORS_LIST[[#This Row],[NAV]]) -> 0 | AS9: =INVESTORS_LIST[[#This Row],[TOTAL CURRENT UNITS]] -> 0 | AT9: =IF(INVESTORS_LIST[[#This Row],[TOTAL SELLABLE UNITS]]=0,0,INVESTORS_LIST[[#This Row],[TOTAL SELLABLE UNITS]]*INVESTORS_LIST[[#This Row],[NAV]]) -> 0 | AU9: =INVESTORS_LIST[[#This Row],[LS_TOTAL REALIZED GAIN]]+INVESTORS_LIST[[#This Row],[SIP_TOTAL REALIZED GAIN]] -> 0 | AV9: =INVESTORS_LIST[[#This Row],[TOTAL MARKET VALUE]]-INVESTORS_LIST[[#This Row],[TOTAL COST VALUE OF CURRENT INVESTMENT]] -> 0 | AW9: =IFERROR(INVESTORS_LIST[[#This Row],[TOTAL CURRENT UNITS]]/SUM(INVESTORS_LIST[TOTAL CURRENT UNITS]),0) -> 0
A10: SHYAMAL KRISHNA SAHA | B10: A00010 | C10: Dear Mr. | D10: Individual | E10: =SUMIFS(LS[Unit],LS[Investor ID],INVESTORS_LIST[[#This Row],[INVESTOR CODE]],LS[B/S],"B") -> 0 | F10: =-SUMIFS(LS[Unit],LS[Investor ID],INVESTORS_LIST[[#This Row],[INVESTOR CODE]],LS[B/S],"S") -> 0 | G10: =IF(INVESTORS_LIST[[#This Row],[LS_TOTAL UNITS BUY]]=0,0,INVESTORS_LIST[[#This Row],[LS_TOTAL UNITS BUY]]-INVESTORS_LIST[[#This Row],[LS_TOTAL UNITS SOLD]]) -> 0 | H10: =IF(INVESTORS_LIST[[#This Row],[LS_TOTAL UNITS BUY]]=0,0,SUMIFS(LS[Amount],LS[Investor ID],INVESTORS_LIST[[#This Row],[INVESTOR CODE]],LS[B/S],"B")) -> 0 | I10: =IF(INVESTORS_LIST[[#This Row],[LS_TOTAL UNITS SOLD]]=0,0,SUMIFS(LS[Cost of Units Sold],LS[Investor ID],INVESTORS_LIST[[#This Row],[INVESTOR CODE]],LS[B/S],"S")) -> 0 | J10: =IF(INVESTORS_LIST[[#This Row],[LS_TOTAL CURRENT UNITS]]=0,0,INVESTORS_LIST[[#This Row],[LS_TOTAL CURRENT UNITS]]*INVESTORS_LIST[[#This Row],[LS_AVERAGE COST]]) -> 0 | K10: =IF(INVESTORS_LIST[[#This Row],[LS_TOTAL UNITS SOLD]]=0,0,SUMIFS(LS[Realized Gain],LS[Investor ID],INVESTORS_LIST[[#This Row],[INVESTOR CODE]],LS[B/S],"S")) -> 0 | L10: =SUMIFS(SIP[Unit],SIP[Investor ID],INVESTORS_LIST[[#This Row],[INVESTOR CODE]],SIP[B/S],"B") -> 0 | M10: =-SUMIFS(SIP[Unit],SIP[Investor ID],INVESTORS_LIST[[#This Row],[INVESTOR CODE]],SIP[B/S],"S") -> 0 | N10: =IF(INVESTORS_LIST[[#This Row],[SIP_TOTAL UNITS BUY]]=0,0,INVESTORS_LIST[[#This Row],[SIP_TOTAL UNITS BUY]]-INVESTORS_LIST[[#This Row],[SIP_TOTAL UNITS SOLD]]) -> 0 | O10: =IF(INVESTORS_LIST[[#This Row],[SIP_TOTAL UNITS BUY]]=0,0,SUMIFS(SIP[Amount],SIP[Investor ID],INVESTORS_LIST[[#This Row],[INVESTOR CODE]],SIP[B/S],"B")) -> 0 | P10: =IF(INVESTORS_LIST[[#This Row],[SIP_TOTAL UNITS SOLD]]=0,0,SUMIFS(SIP[Cost of Units Sold],SIP[Investor ID],INVESTORS_LIST[[#This Row],[INVESTOR CODE]],SIP[B/S],"S")) -> 0 | Q10: =IF(INVESTORS_LIST[[#This Row],[SIP_TOTAL CURRENT UNITS]]=0,0,INVESTORS_LIST[[#This Row],[SIP_TOTAL CURRENT UNITS]]*INVESTORS_LIST[[#This Row],[SIP_AVERAGE COST]]) -> 0 | R10: =IF(INVESTORS_LIST[[#This Row],[SIP_TOTAL UNITS SOLD]]=0,0,SUMIFS(SIP[Realized Gain],SIP[Investor ID],INVESTORS_LIST[[#This Row],[INVESTOR CODE]],SIP[B/S],"S")) -> 0 | S10: =INVESTORS_LIST[[#This Row],[LS_TOTAL UNITS BUY]]+INVESTORS_LIST[[#This Row],[SIP_TOTAL UNITS BUY]] -> 0 | T10: =INVESTORS_LIST[[#This Row],[LS_TOTAL UNITS SOLD]]+INVESTORS_LIST[[#This Row],[SIP_TOTAL UNITS SOLD]] -> 0 | V10: =SUMIFS(LS[BO UNIT TRANSFER],LS[Investor ID],INVESTORS_LIST[[#This Row],[INVESTOR CODE]],LS[B/S],"B") -> 0 | W10: =SUMIFS(SIP[BO UNIT TRANSFER],SIP[Investor ID],INVESTORS_LIST[[#This Row],[INVESTOR CODE]],SIP[B/S],"B") -> 0 | X10: =SUMIFS(LS[BO UNIT TRANSFER],LS[Investor ID],INVESTORS_LIST[[#This Row],[INVESTOR CODE]],LS[B/S],"S") -> 0 | Y10: =SUMIFS(SIP[BO UNIT TRANSFER],SIP[Investor ID],INVESTORS_LIST[[#This Row],[INVESTOR CODE]],SIP[B/S],"S") -> 0 | Z10: =SUM(INVESTORS_LIST[[#This Row],[BO OPENING BALANCE]:[BO SIP UNITS REPURCHASE]]) -> 0 | AA10: =INVESTORS_LIST[[#This Row],[TOTAL UNITS BUY]]-INVESTORS_LIST[[#This Row],[TOTAL UNITS SOLD]] -> 0 | AB10: =INVESTORS_LIST[[#This Row],[TOTAL CURRENT UNITS]]-INVESTORS_LIST[[#This Row],[BO UNITS HOLD]] -> 0 | AC10: =INDEX([3]!Table_1[BO ID],MATCH(INVESTORS_LIST[[#This Row],[INVESTOR CODE]],[3]!Table_1[INVESTOR CODE],0)) -> #REF! | AD10: =INDEX([3]!Table_1[Brokerage Name2],MATCH(INVESTORS_LIST[[#This Row],[INVESTOR CODE]],[3]!Table_1[INVESTOR CODE],0)) -> #REF! | AE10: =MID(INVESTORS_LIST[[#This Row],[BO ID]],4,5) -> #REF! | AF10: =MID(INVESTORS_LIST[[#This Row],[BO ID]],2,7) -> #REF! | AG10: =MID(INVESTORS_LIST[[#This Row],[BO ID]],9,7) -> #REF! | AH10: =RIGHT(INVESTORS_LIST[[#This Row],[BO ID]],1) -> #REF! | AI10: =INVESTORS_LIST[[#This Row],[LS_TOTAL COST VALUE OF CURRENT UNITS]]+INVESTORS_LIST[[#This Row],[SIP_TOTAL COST VALUE OF CURRENT UNITS]] -> 0 | AJ10: =IF(INVESTORS_LIST[[#This Row],[TOTAL CURRENT UNITS]]=0,0,INVESTORS_LIST[[#This Row],[LS_TOTAL CURRENT UNITS]]/INVESTORS_LIST[[#This Row],[TOTAL CURRENT UNITS]]) -> 0 | AK10: =IF(INVESTORS_LIST[[#This Row],[TOTAL CURRENT UNITS]]=0,0,INVESTORS_LIST[[#This Row],[SIP_TOTAL CURRENT UNITS]]/INVESTORS_LIST[[#This Row],[TOTAL CURRENT UNITS]]) -> 0 | AL10: {=IF(INVESTORS_LIST[[#This Row],[LS_TOTAL UNITS BUY]]>0,INDEX(LS[NAV at Cost (Average)],MATCH(CONCATENATE(COUNTIFS(LS[Investor ID],INVESTORS_LIST[[#This Row],[INVESTOR CODE]]),INVESTORS_LIST[[#This Row],[INVESTOR CODE]]),LS[Unique Code],0),),0)} -> 0 | AM10: {=IF(INVESTORS_LIST[[#This Row],[SIP_TOTAL UNITS BUY]]>0,INDEX(SIP[NAV at Cost (Average)],MATCH(CONCATENATE(COUNTIFS(SIP[Investor ID],INVESTORS_LIST[[#This Row],[INVESTOR CODE]]),INVESTORS_LIST[[#This Row],[INVESTOR CODE]]),SIP[Unique Code],0),),0)} -> 0 | AN10: =IF(INVESTORS_LIST[[#This Row],[TOTAL CURRENT UNITS]]=0,0,(INVESTORS_LIST[[#This Row],[LS_WEIGHT]]*INVESTORS_LIST[[#This Row],[LS_AVERAGE COST]])+(INVESTORS_LIST[[#This Row],[SIP_WEIGHT]]*INVESTORS_LIST[[#This Row],[SIP_AVERAGE COST]])) -> 0 | AO10: =NAV_MKT -> 14.224 | AP10: =IF(INVESTORS_LIST[[#This Row],[TOTAL CURRENT UNITS]]=0,0,INVESTORS_LIST[[#This Row],[TOTAL CURRENT UNITS]]*INVESTORS_LIST[[#This Row],[NAV]]) -> 0 | AQ10: =IF(INVESTORS_LIST[[#This Row],[LS_TOTAL CURRENT UNITS]]=0,0,INVESTORS_LIST[[#This Row],[LS_TOTAL CURRENT UNITS]]*INVESTORS_LIST[[#This Row],[NAV]]) -> 0 | AR10: =IF(INVESTORS_LIST[[#This Row],[SIP_TOTAL CURRENT UNITS]]=0,0,INVESTORS_LIST[[#This Row],[SIP_TOTAL CURRENT UNITS]]*INVESTORS_LIST[[#This Row],[NAV]]) -> 0 | AS10: =INVESTORS_LIST[[#This Row],[TOTAL CURRENT UNITS]] -> 0 | AT10: =IF(INVESTORS_LIST[[#This Row],[TOTAL SELLABLE UNITS]]=0,0,INVESTORS_LIST[[#This Row],[TOTAL SELLABLE UNITS]]*INVESTORS_LIST[[#This Row],[NAV]]) -> 0 | AU10: =INVESTORS_LIST[[#This Row],[LS_TOTAL REALIZED GAIN]]+INVESTORS_LIST[[#This Row],[SIP_TOTAL REALIZED GAIN]] -> 0 | AV10: =INVESTORS_LIST[[#This Row],[TOTAL MARKET VALUE]]-INVESTORS_LIST[[#This Row],[TOTAL COST VALUE OF CURRENT INVESTMENT]] -> 0 | AW10: =IFERROR(INVESTORS_LIST[[#This Row],[TOTAL CURRENT UNITS]]/SUM(INVESTORS_LIST[TOTAL CURRENT UNITS]),0) -> 0
