Workbook
Name CURRENT_NAV: BS!$C$46
Name fsa: Journals!$T$1
Name NAV: BS!$C$44
Name NAV_MKT: Journals!$T$1
Name TCV_STOCKS: #REF!
Name TMV_STOCKS: #REF!

Sheet Chart of Accounts
B2: Accounts Name | C2: Normal Balance | E2: Stock List
B3: Investments in stock | C3: DEBIT | E3: =#REF! -> #REF!
B4: Interest Receivables from Bank A/C | C4: DEBIT | E4: =#REF! -> #REF!
B5: Preliminary & issue expenses | C5: DEBIT | E5: =#REF! -> #REF!
B6: Accrued Management Fee | C6: CREDIT | E6: =#REF! -> #REF!
B7: Accrued Trustee Fee | C7: CREDIT | E7: =#REF! -> #REF!
B8: Accrued Custodian Fee | C8: CREDIT | E8: =#REF! -> #REF!
B9: Accrued BSEC fee | C9: CREDIT | E9: =#REF! -> #REF!
B10: Accrued Audit Fee | C10: CREDIT | E10: =#REF! -> #REF!
B11: Accrued CDBL Fee | C11: CREDIT | E11: =#REF! -> #REF!
B12: Fixed Deposit Receipts (FDR) | C12: DEBIT | E12: =#REF! -> #REF!
B13: Cash and cash equivalents | C13: DEBIT | E13: =#REF! -> #REF!
B14: Unit Capital | C14: CREDIT | E14: =#REF! -> #REF!
... B16: Interest income | C16: CREDIT | E16: =#REF! -> #REF!
B17: Interest income from BXSUKUK
B18: Interest income from APSCL
B19: Interest income from Bank Asia Bond
B20: Interest income from BRAC Bank Bond
B21: Interest income from Bank Acc.
B22: Interest income from FDR
B23: Interest income reduce for Bond Premium | C23: CREDIT
B24: Bank charges and excise duties | C24: DEBIT | E24: =#REF! -> #REF!
B25: Brokerage commission | C25: DEBIT | E25: =#REF! -> #REF!
B26: Unrealized gain on securities | C26: CREDIT | E26: =#REF! -> #REF!
B27: Unrealized gain on T-Bill
B28: Unrealized gain on T-Bond
B29: Unrealized loss on securities | C29: DEBIT | E29: =#REF! -> #REF!
B30: Amortization of preliminary and issue expense | C30: DEBIT | E30: =#REF! -> #REF!
B31: Management Fee | C31: DEBIT | E31: =#REF! -> #REF!
B32: Trustee fee | C32: DEBIT | E32: =#REF! -> #REF!
B33: BSEC Annual Fee | C33: DEBIT | E33: =#REF! -> #REF!
B34: Audit fee | C34: DEBIT | E34: =#REF! -> #REF!
B35: CDBL charges | C35: DEBIT | E35: =#REF! -> #REF!
B36: Fair value adjustment | C36: DEBIT | E36: =#REF! -> #REF!
B37: Fair value adjustment in T-Bill
B38: Fair value adjustment in T-Bond
B39: Interest receivables from FDR | C39: DEBIT | E39: =#REF! -> #REF!
B40: Payable to broker | C40: CREDIT | E40: =#REF! -> #REF!
B41: Other operating expenses | C41: DEBIT | E41: =#REF! -> #REF!
B42: Dividend income | C42: CREDIT | E42: =#REF! -> #REF!
...

Sheet INVESTOR_LIST
A1: INVESTOR NAME | B1: INVESTOR CODE
A2: HARI PADA SAHA | B2: A00002
A3: EKUSH WEALTH MANAGEMENT LIMITED | B3: A00003
A4: SADIA AHMED | B4: A00004
A5: MORSHEDA MIM | B5: A00005
A6: MD. JAHANGIR ALAM | B6: A00006
A7: BISWAS ARIFUR RAHMAN | B7: A00007
A8: JEWEL SAHA | B8: A00008
A9: SHIBBIR AHMED | B9: A00009
A10: SHYAMAL KRISHNA SAHA | B10: A00010
A11: NASRIN AKHTER | B11: A00011
A12: MRINMOY GHOSH | B12: A00012
... A562: JAKARIA MD. JONY | B562: A00559

Sheet Journals
A2: Check of Journal Entries | G2: =K6-L6 -> -0.0033416748
A3: Check of Trial Balance | G3: =SUM('TB-C'!H7:H5021)-SUM('TB-C'!I7:I5021) -> -0.0072669387
A4: Check of Balance Seet | G4: =BS!C25-BS!C42 -> -0.0033406019
A5: Check of Cash Balance | G5: =BS!C23-CF!B43 -> 94994187
J6: =ROUND(L6-K6,0) -> 0 | K6: =SUBTOTAL(9,K9:K18768) -> 6.3668025e+09 | L6: =SUBTOTAL(9,L9:L18768) -> 6.3668025e+09
A7: Year | B7: Month | C7: Day | D7: Value | F7: Transaction | G7: Transaction Type | J7: Account Name | K7: Debit | L7: Credit | N7: Ref. Acc.
E8: Date
A9: 2022 | B9: 9 | C9: 7 | D9: =DATE(A9,B9,C9) -> 44811 | E9: =DATE(A9,B9,C9) -> 44811 | F9: Unit Subscription - LUMPSUM | G9: C | I9: A00003 | J9: Cash and cash equivalents | K9: 2000
A10: 2022 | B10: 9 | C10: 7 | D10: =DATE(A10,B10,C10) -> 44811 | E10: =DATE(A10,B10,C10) -> 44811 | G10: C | I10: A00003 | J10: Unit Capital | L10: 2000
A11: 2022 | B11: 10 | C11: 31 | D11: =DATE(A11,B11,C11) -> 44865 | E11: =DATE(A11,B11,C11) -> 44865 | F11: Bank Charges - Cheque Book Issue | G11: C | J11: Bank charges and excise duties | K11: 201.25
A12: 2022 | B12: 10 | C12: 31 | D12: =DATE(A12,B12,C12) -> 44865 | E12: =DATE(A12,B12,C12) -> 44865 | G12: C | J12: Cash and cash equivalents | L12: 201.25
A13: 2022 | B13: 11 | C13: 1 | D13: =DATE(A13,B13,C13) -> 44866 | E13: =DATE(A13,B13,C13) -> 44866 | F13: Unit Subscription - LUMPSUM | G13: C | I13: A00003 | J13: Cash and cash equivalents | K13: 25000000
A14: 2022 | B14: 11 | C14: 1 | D14: =DATE(A14,B14,C14) -> 44866 | E14: =DATE(A14,B14,C14) -> 44866 | G14: C | I14: A00003 | J14: Unit Capital | L14: 25000000
A15: 2022 | B15: 12 | C15: 29 | D15: =DATE(A15,B15,C15) -> 44924 | E15: =DATE(A15,B15,C15) -> 44924 | F15: Interest Income - Midland Bank | G15: C | J15: Cash and cash equivalents | K15: 129176
A16: 2022 | B16: 12 | C16: 29 | D16: =DATE(A16,B16,C16) -> 44924 | E16: =DATE(A16,B16,C16) -> 44924 | G16: C | J16: Interest income | L16: 129176
A17: 2022 | B17: 10 | C17: 31 | D17: =DATE(A17,B17,C17) -> 44865 | E17: =DATE(A17,B17,C17) -> 44865 | F17: Bank Charges - Source Tax Source Tax | G17: C | J17: Bank charges and excise duties | K17: 12917.64
A18: 2022 | B18: 10 | C18: 31 | D18: =DATE(A18,B18,C18) -> 44865 | E18: =DATE(A18,B18,C18) -> 44865 | G18: C | J18: Cash and cash equivalents | L18: 12917.64
A19: 2022 | B19: 10 | C19: 31 | D19: =DATE(A19,B19,C19) -> 44865 | E19: =DATE(A19,B19,C19) -> 44865 | F19: Bank Charges - Service Charge | G19: C | J19: Bank charges and excise duties | K19: 575
A20: 2022 | B20: 10 | C20: 31 | D20: =DATE(A20,B20,C20) -> 44865 | E20: =DATE(A20,B20,C20) -> 44865 | G20: C | J20: Cash and cash equivalents | L20: 575
A21: 2022 | B21: 10 | C21: 31 | D21: =DATE(A21,B21,C21) -> 44865 | E21: =DATE(A21,B21,C21) -> 44865 | F21: Bank Charges - Excise Duty | G21: C | J21: Bank charges and excise duties | K21: 15000
A22: 2022 | B22: 10 | C22: 31 | D22: =DATE(A22,B22,C22) -> 44865 | E22: =DATE(A22,B22,C22) -> 44865 | G22: C | J22: Cash and cash equivalents | L22: 15000
A23: 2023 | B23: 1 | C23: 16 | D23: =DATE(A23,B23,C23) -> 44942 | E23: =DATE(A23,B23,C23) -> 44942 | F23: Unit Subscription - LUMPSUM | G23: C | I23: A00018 | J23: Cash and cash equivalents | K23: 800000
A24: 2023 | B24: 1 | C24: 16 | D24: =DATE(A24,B24,C24) -> 44942 | E24: =DATE(A24,B24,C24) -> 44942 | G24: C | I24: A00018 | J24: Unit Capital | L24: 800000
A25: 2023 | B25: 1 | C25: 16 | D25: =DATE(A25,B25,C25) -> 44942 | E25: =DATE(A25,B25,C25) -> 44942 | F25: Bank Charges - Clearing Charge | G25: C | J25: Bank charges and excise duties | K25: 25
A26: 2023 | B26: 1 | C26: 16 | D26: =DATE(A26,B26,C26) -> 44942 | E26: =DATE(A26,B26,C26) -> 44942 | G26: C | J26: Cash and cash equivalents | L26: 25
A27: 2023 | B27: 1 | C27: 17 | D27: =DATE(A27,B27,C27) -> 44943 | E27: =DATE(A27,B27,C27) -> 44943 | F27: Unit Subscription - LUMPSUM | G27: C | I27: A00327 | J27: Cash and cash equivalents | K27: 500000
A28: 2023 | B28: 1 | C28: 17 | D28: =DATE(A28,B28,C28) -> 44943 | E28: =DATE(A28,B28,C28) -> 44943 | G28: C | I28: A00327 | J28: Unit Capital | L28: 500000
A29: 2023 | B29: 1 | C29: 17 | D29: =DATE(A29,B29,C29) -> 44943 | E29: =DATE(A29,B29,C29) -> 44943 | F29: Bank Charges - Clearing Charge | G29: C | J29: Bank charges and excise duties | K29: 60
A30: 2023 | B30: 1 | C30: 17 | D30: =DATE(A30,B30,C30) -> 44943 | E30: =DATE(A30,B30,C30) -> 44943 | G30: C | J30: Cash and cash equivalents | L30: 60
A31: 2023 | B31: 1 | C31: 19 | D31: =DATE(A31,B31,C31) -> 44945 | E31: =DATE(A31,B31,C31) -> 44945 | F31: Unit Subscription - LUMPSUM | G31: C | I31: A00444 | J31: Cash and cash equivalents | K31: 200000
A32: 2023 | B32: 1 | C32: 19 | D32: =DATE(A32,B32,C32) -> 44945 | E32: =DATE(A32,B32,C32) -> 44945 | G32: C | I32: A00444 | J32: Unit Capital | L32: 200000
A33: 2023 | B33: 1 | C33: 25 | D33: =DATE(A33,B33,C33) -> 44951 | E33: =DATE(A33,B33,C33) -> 44951 | F33: Unit Subscription - LUMPSUM | G33: C | I33: A00022 | J33: Cash and cash equivalents | K33: 850000
A34: 2023 | B34: 1 | C34: 25 | D34: =DATE(A34,B34,C34) -> 44951 | E34: =DATE(A34,B34,C34) -> 44951 | G34: C | I34: A00022 | J34: Unit Capital | L34: 850000
A35: 2023 | B35: 1 | C35: 25 | D35: =DATE(A35,B35,C35) -> 44951 | E35: =DATE(A35,B35,C35) -> 44951 | F35: Bank Charges - Clearing Charge | G35: C | J35: Bank charges and excise duties | K35: 60
A36: 2023 | B36: 1 | C36: 25 | D36: =DATE(A36,B36,C36) -> 44951 | E36: =DATE(A36,B36,C36) -> 44951 | G36: C | J36: Cash and cash equivalents | L36: 60
A37: 2023 | B37: 1 | C37: 26 | D37: =DATE(A37,B37,C37) -> 44952 | E37: =DATE(A37,B37,C37) -> 44952 | F37: Unit Subscription - LUMPSUM | G37: C | I37: A00252 | J37: Cash and cash equivalents | K37: 700000
A38: 2023 | B38: 1 | C38: 26 | D38: =DATE(A38,B38,C38) -> 44952 | E38: =DATE(A38,B38,C38) -> 44952 | G38: C | I38: A00252 | J38: Unit Capital | L38: 700000
A39: 2023 | B39: 2 | C39: 5 | D39: =DATE(A39,B39,C39) -> 44962 | E39: =DATE(A39,B39,C39) -> 44962 | F39: Unit Subscription - LUMPSUM | G39: C | I39: A00170 | J39: Cash and cash equivalents | K39: 800000
A40: 2023 | B40: 2 | C40: 5 | D40: =DATE(A40,B40,C40) -> 44962 | E40: =DATE(A40,B40,C40) -> 44962 | G40: C | I40: A00170 | J40: Unit Capital | L40: 800000
A41: 2023 | B41: 2 | C41: 5 | D41: =DATE(A41,B41,C41) -> 44962 | E41: =DATE(A41,B41,C41) -> 44962 | F41: Bank Charges - Clearing Charge | G41: C | J41: Bank charges and excise duties | K41: 25
...

Sheet TB-C
A1: Check of Trial Balance | G1: =SUM(H7:H98)-SUM(I7:I98) -> -0.0072669387
A2: Check of Balance Sheet | G2: =BS!C25-BS!C42 -> -0.0033406019
A3: Check of Cash Balance | G3: =BS!C23-CF!B43 -> 94994187
B5: Desired Reporting Period | H5: During the Reporting Period | J5: For Balance Sheet | N5: For Retained Earnings
B6: Year | C6: Month | D6: Day | E6: Value | F6: Value | G6: Accounts | H6: Debit | I6: Credit | J6: Carry Forward Balance | K6: Carry Forward Balance | L6: On date | M6: On date | N6: Debit | O6: Credit
A7: Beginning | B7: 2025 | C7: 7 | D7: 1 | E7: =DATE(B7,C7,D7)-1 -> 45838 | F7: =DATE(B7,C7,D7) -> 45839 | G7: ='Chart of Accounts'!B3 -> Investments in stock | H7: =MAX(0,SUMIFS(Journals!$K$9:$K$1007564,Journals!$D$9:$D$1007564,">"&$E$7,Journals!$D$9:$D$1007564,"<"&$E$8,Journals!$J$9:$J$1007564,"investments in stock")-SUMIFS(Journals!$L$9:$L$1007564,Journals!$D$9:$D$1007564,">"&$E$7,Journals!$D$9:$D$1007564,"<"&$E$8,Journals!$J$9:$J$1007564,"investments in stock")) -> 30202480 | I7: =MAX(0,SUMIFS(Journals!$L$9:$L$1007564,Journals!$D$9:$D$1007564,">"&$E$7,Journals!$D$9:$D$1007564,"<"&$E$8,Journals!$J$9:$J$1007564,"Investments in stock")-SUMIFS(Journals!$K$9:$K$1007564,Journals!$D$9:$D$1007564,">"&$E$7,Journals!$D$9:$D$1007564,"<"&$E$8,Journals!$J$9:$J$1007564,"Investments in stock")) -> 0 | J7: =SUMIFS(Journals!$K$9:$K$1007564,Journals!$D$9:$D$1007564,"<"&$F$7,Journals!$J$9:$J$1007564,"investments in stock")-SUMIFS(Journals!$L$9:$L$1007564,Journals!$D$9:$D$1007564,"<"&$F$7,Journals!$J$9:$J$1007564,"investments in stock") -> 2797650.6 | L7: =J7+H7-I7 -> 33000130
A8: Ending | B8: 2026 | C8: 6 | D8: 30 | E8: =DATE(B8,C8,D8)+1 -> 46204 | F8: =DATE(B8,C8,D8)-1 -> 46202 | G8: ='Chart of Accounts'!B4 -> Interest Receivables from Bank A/C | H8: =MAX(0,SUMIFS(Journals!$K$9:$K$1007564,Journals!$D$9:$D$1007564,">"&$E$7,Journals!$D$9:$D$1007564,"<"&$E$8,Journals!$J$9:$J$1007564,"Interest Receivables from Bank A/C")-SUMIFS(Journals!$L$9:$L$1007564,Journals!$D$9:$D$1007564,">"&$E$7,Journals!$D$9:$D$1007564,"<"&$E$8,Journals!$J$9:$J$1007564,"Interest Receivables from Bank A/C")) -> 130333.46 | I8: =MAX(0,SUMIFS(Journals!$L$9:$L$1007564,Journals!$D$9:$D$1007564,">"&$E$7,Journals!$D$9:$D$1007564,"<"&$E$8,Journals!$J$9:$J$1007564,"Interest Receivables from Bank A/C")-SUMIFS(Journals!$K$9:$K$1007564,Journals!$D$9:$D$1007564,">"&$E$7,Journals!$D$9:$D$1007564,"<"&$E$8,Journals!$J$9:$J$1007564,"Interest Receivables from Bank A/C")) -> 0 | J8: =SUMIFS(Journals!$K$9:$K$1007564,Journals!$D$9:$D$1007564,"<"&$F$7,Journals!$J$9:$J$1007564,"Interest Receivables from Bank A/C")-SUMIFS(Journals!$L$9:$L$1007564,Journals!$D$9:$D$1007564,"<"&$F$7,Journals!$J$9:$J$1007564,"Interest Receivables from Bank A/C") -> 2762.8079 | L8: =J8+H8-I8 -> 133096.27
G9: Interest Receivables from Sukuk | H9: =MAX(0,SUMIFS(Journals!$K$9:$K$1007564,Journals!$D$9:$D$1007564,">"&$E$7,Journals!$D$9:$D$1007564,"<"&$E$8,Journals!$J$9:$J$1007564,"Interest Receivables from Sukuk")-SUMIFS(Journals!$L$9:$L$1007564,Journals!$D$9:$D$1007564,">"&$E$7,Journals!$D$9:$D$1007564,"<"&$E$8,Journals!$J$9:$J$1007564,"Interest Receivables from Sukuk")) -> 0 | I9: =MAX(0,SUMIFS(Journals!$L$9:$L$1007564,Journals!$D$9:$D$1007564,">"&$E$7,Journals!$D$9:$D$1007564,"<"&$E$8,Journals!$J$9:$J$1007564,"Interest Receivables from Sukuk")-SUMIFS(Journals!$K$9:$K$1007564,Journals!$D$9:$D$1007564,">"&$E$7,Journals!$D$9:$D$1007564,"<"&$E$8,Journals!$J$9:$J$1007564,"Interest Receivables from Sukuk")) -> 0 | J9: =SUMIFS(Journals!$K$9:$K$1007564,Journals!$D$9:$D$1007564,"<"&$F$7,Journals!$J$9:$J$1007564,"Interest Receivables from Sukuk")-SUMIFS(Journals!$L$9:$L$1007564,Journals!$D$9:$D$1007564,"<"&$F$7,Journals!$J$9:$J$1007564,"Interest Receivables from Sukuk") -> 1.1641532e-09 | L9: =J9+H9-I9 -> 1.1641532e-09
G10: Interest Receivables from Bond | H10: =MAX(0,SUMIFS(Journals!$K$9:$K$1007564,Journals!$D$9:$D$1007564,">"&$E$7,Journals!$D$9:$D$1007564,"<"&$E$8,Journals!$J$9:$J$1007564,"Interest Receivables from Bond")-SUMIFS(Journals!$L$9:$L$1007564,Journals!$D$9:$D$1007564,">"&$E$7,Journals!$D$9:$D$1007564,"<"&$E$8,Journals!$J$9:$J$1007564,"Interest Receivables from Bond")) -> 0 | I10: =MAX(0,SUMIFS(Journals!$L$9:$L$1007564,Journals!$D$9:$D$1007564,">"&$E$7,Journals!$D$9:$D$1007564,"<"&$E$8,Journals!$J$9:$J$1007564,"Interest Receivables from Bond")-SUMIFS(Journals!$K$9:$K$1007564,Journals!$D$9:$D$1007564,">"&$E$7,Journals!$D$9:$D$1007564,"<"&$E$8,Journals!$J$9:$J$1007564,"Interest Receivables from Bond")) -> 32785.351 | J10: =SUMIFS(Journals!$K$9:$K$1007564,Journals!$D$9:$D$1007564,"<"&$F$7,Journals!$J$9:$J$1007564,"Interest Receivables from Bond")-SUMIFS(Journals!$L$9:$L$1007564,Journals!$D$9:$D$1007564,"<"&$F$7,Journals!$J$9:$J$1007564,"Interest Receivables from Bond") -> 59214.369 | L10: =J10+H10-I10 -> 26429.019
B11: =CURRENT_NAV -> 14.267139 | G11: ='Chart of Accounts'!B5 -> Preliminary & issue expenses | H11: =MAX(0,SUMIFS(Journals!$K$9:$K$1007564,Journals!$D$9:$D$1007564,">"&$E$7,Journals!$D$9:$D$1007564,"<"&$E$8,Journals!$J$9:$J$1007564,"Preliminary & issue expenses")-SUMIFS(Journals!$L$9:$L$1007564,Journals!$D$9:$D$1007564,">"&$E$7,Journals!$D$9:$D$1007564,"<"&$E$8,Journals!$J$9:$J$1007564,"Preliminary & issue expenses")) -> 0 | I11: =MAX(0,SUMIFS(Journals!$L$9:$L$1007564,Journals!$D$9:$D$1007564,">"&$E$7,Journals!$D$9:$D$1007564,"<"&$E$8,Journals!$J$9:$J$1007564,"Preliminary & issue expenses")-SUMIFS(Journals!$K$9:$K$1007564,Journals!$D$9:$D$1007564,">"&$E$7,Journals!$D$9:$D$1007564,"<"&$E$8,Journals!$J$9:$J$1007564,"Preliminary & issue expenses")) -> 138713.88 | J11: =SUMIFS(Journals!$K$9:$K$1007564,Journals!$D$9:$D$1007564,"<"&$F$7,Journals!$J$9:$J$1007564,"Preliminary & issue expenses")-SUMIFS(Journals!$L$9:$L$1007564,Journals!$D$9:$D$1007564,"<"&$F$7,Journals!$J$9:$J$1007564,"Preliminary & issue expenses") -> 559729.36 | L11: =J11+H11-I11 -> 421015.48
G12: ='Chart of Accounts'!B6 -> Accrued Management Fee | H12: =SUMIFS(Journals!$K$9:$K$1007564,Journals!$D$9:$D$1007564,">"&$E$7,Journals!$D$9:$D$1007564,"<"&$E$8,Journals!$J$9:$J$1007564,"Accrued Management Fee") -> 2188653.6 | I12: =MAX(0,SUMIFS(Journals!$L$9:$L$1007564,Journals!$D$9:$D$1007564,">"&$E$7,Journals!$D$9:$D$1007564,"<"&$E$8,Journals!$J$9:$J$1007564,"Accrued Management Fee")) -> 2130135.1 | K12: =SUMIFS(Journals!$L$9:$L$1007564,Journals!$D$9:$D$1007564,"<"&$F$7,Journals!$J$9:$J$1007564,"Accrued Management Fee")-SUMIFS(Journals!$K$9:$K$1007564,Journals!$D$9:$D$1007564,"<"&$F$7,Journals!$J$9:$J$1007564,"Accrued Management Fee") -> 236441.3 | M12: =K12+I12-H12 -> 177922.86
E13: 203746.91 | G13: ='Chart of Accounts'!B7 -> Accrued Trustee Fee | H13: =MAX(0,SUMIFS(Journals!$K$9:$K$1007564,Journals!$D$9:$D$1007564,">"&$E$7,Journals!$D$9:$D$1007564,"<"&$E$8,Journals!$J$9:$J$1007564,"accrued trustee fee")-SUMIFS(Journals!$L$9:$L$1007564,Journals!$D$9:$D$1007564,">"&$E$7,Journals!$D$9:$D$1007564,"<"&$E$8,Journals!$J$9:$J$1007564,"accrued trustee fee")) -> 0 | I13: =MAX(0,SUMIFS(Journals!$L$9:$L$1007564,Journals!$D$9:$D$1007564,">"&$E$7,Journals!$D$9:$D$1007564,"<"&$E$8,Journals!$J$9:$J$1007564,"accrued trustee fee")-SUMIFS(Journals!$K$9:$K$1007564,Journals!$D$9:$D$1007564,">"&$E$7,Journals!$D$9:$D$1007564,"<"&$E$8,Journals!$J$9:$J$1007564,"accrued trustee fee")) -> 147197 | K13: =SUMIFS(Journals!$L$9:$L$1007564,Journals!$D$9:$D$1007564,"<"&$F$7,Journals!$J$9:$J$1007564,"Accrued Trustee Fee")-SUMIFS(Journals!$K$9:$K$1007564,Journals!$D$9:$D$1007564,"<"&$F$7,Journals!$J$9:$J$1007564,"Accrued Trustee Fee") -> 65816.504 | M13: =K13+I13-H13 -> 213013.5
E14: 65816.504 | G14: ='Chart of Accounts'!B8 -> Accrued Custodian Fee | H14: =MAX(0,SUMIFS(Journals!$K$9:$K$1007564,Journals!$D$9:$D$1007564,">"&$E$7,Journals!$D$9:$D$1007564,"<"&$E$8,Journals!$J$9:$J$1007564,"accrued custodian fee")-SUMIFS(Journals!$L$9:$L$1007564,Journals!$D$9:$D$1007564,">"&$E$7,Journals!$D$9:$D$1007564,"<"&$E$8,Journals!$J$9:$J$1007564,"accrued custodian fee")) -> 0 | I14: =MAX(0,SUMIFS(Journals!$L$9:$L$1007564,Journals!$D$9:$D$1007564,">"&$E$7,Journals!$D$9:$D$1007564,"<"&$E$8,Journals!$J$9:$J$1007564,"accrued custodian fee")-SUMIFS(Journals!$K$9:$K$1007564,Journals!$D$9:$D$1007564,">"&$E$7,Journals!$D$9:$D$1007564,"<"&$E$8,Journals!$J$9:$J$1007564,"accrued custodian fee")) -> 56173.838 | K14: =SUMIFS(Journals!$L$9:$L$1007564,Journals!$D$9:$D$1007564,"<"&$F$7,Journals!$J$9:$J$1007564,"Accrued Custodian Fee")-SUMIFS(Journals!$K$9:$K$1007564,Journals!$D$9:$D$1007564,"<"&$F$7,Journals!$J$9:$J$1007564,"Accrued Custodian Fee") -> 123123.68 | M14: =K14+I14-H14 -> 179297.52
E15: =E13-E14 -> 137930.41 | G15: ='Chart of Accounts'!B9 -> Accrued BSEC fee | H15: =MAX(0,SUMIFS(Journals!$K$9:$K$1007564,Journals!$D$9:$D$1007564,">"&$E$7,Journals!$D$9:$D$1007564,"<"&$E$8,Journals!$J$9:$J$1007564,"accrued bsec fee")-SUMIFS(Journals!$L$9:$L$1007564,Journals!$D$9:$D$1007564,">"&$E$7,Journals!$D$9:$D$1007564,"<"&$E$8,Journals!$J$9:$J$1007564,"accrued bsec fee")) -> 0 | I15: =MAX(0,SUMIFS(Journals!$L$9:$L$1007564,Journals!$D$9:$D$1007564,">"&$E$7,Journals!$D$9:$D$1007564,"<"&$E$8,Journals!$J$9:$J$1007564,"accrued bsec fee")-SUMIFS(Journals!$K$9:$K$1007564,Journals!$D$9:$D$1007564,">"&$E$7,Journals!$D$9:$D$1007564,"<"&$E$8,Journals!$J$9:$J$1007564,"accrued bsec fee")) -> 0 | K15: =SUMIFS(Journals!$L$9:$L$1007564,Journals!$D$9:$D$1007564,"<"&$F$7,Journals!$J$9:$J$1007564,"accrued bsec fee")-SUMIFS(Journals!$K$9:$K$1007564,Journals!$D$9:$D$1007564,"<"&$F$7,Journals!$J$9:$J$1007564,"accrued bsec fee") -> 0 | M15: =K15+I15-H15 -> 0
G16: ='Chart of Accounts'!B10 -> Accrued Audit Fee | H16: =MAX(0,SUMIFS(Journals!$K$9:$K$1007564,Journals!$D$9:$D$1007564,">"&$E$7,Journals!$D$9:$D$1007564,"<"&$E$8,Journals!$J$9:$J$1007564,"accrued audit fee")) -> 40250 | I16: =MAX(0,SUMIFS(Journals!$L$9:$L$1007564,Journals!$D$9:$D$1007564,">"&$E$7,Journals!$D$9:$D$1007564,"<"&$E$8,Journals!$J$9:$J$1007564,"accrued audit fee")) -> 0 | K16: =SUMIFS(Journals!$L$9:$L$1007564,Journals!$D$9:$D$1007564,"<"&$F$7,Journals!$J$9:$J$1007564,"accrued audit fee")-SUMIFS(Journals!$K$9:$K$1007564,Journals!$D$9:$D$1007564,"<"&$F$7,Journals!$J$9:$J$1007564,"accrued audit fee") -> 40250 | M16: =K16+I16-H16 -> 0
G17: ='Chart of Accounts'!B11 -> Accrued CDBL Fee | H17: =MAX(0,SUMIFS(Journals!$K$9:$K$1007564,Journals!$D$9:$D$1007564,">"&$E$7,Journals!$D$9:$D$1007564,"<"&$E$8,Journals!$J$9:$J$1007564,"accrued CDBL fee")-SUMIFS(Journals!$L$9:$L$1007564,Journals!$D$9:$D$1007564,">"&$E$7,Journals!$D$9:$D$1007564,"<"&$E$8,Journals!$J$9:$J$1007564,"accrued CDBL fee")) -> 0 | I17: =MAX(0,SUMIFS(Journals!$L$9:$L$1007564,Journals!$D$9:$D$1007564,">"&$E$7,Journals!$D$9:$D$1007564,"<"&$E$8,Journals!$J$9:$J$1007564,"accrued CDBL fee")-SUMIFS(Journals!$K$9:$K$1007564,Journals!$D$9:$D$1007564,">"&$E$7,Journals!$D$9:$D$1007564,"<"&$E$8,Journals!$J$9:$J$1007564,"accrued CDBL fee")) -> 0 | K17: =SUMIFS(Journals!$L$9:$L$1007564,Journals!$D$9:$D$1007564,"<"&$F$7,Journals!$J$9:$J$1007564,"accrued cdbl fee")-SUMIFS(Journals!$K$9:$K$1007564,Journals!$D$9:$D$1007564,"<"&$F$7,Journals!$J$9:$J$1007564,"accrued cdbl fee") -> 0 | M17: =K17+I17-H17 -> 0
G18: ='Chart of Accounts'!B12 -> Fixed Deposit Receipts (FDR) | H18: =MAX(0,SUMIFS(Journals!$K$9:$K$1007564,Journals!$D$9:$D$1007564,">"&$E$7,Journals!$D$9:$D$1007564,"<"&$E$8,Journals!$J$9:$J$1007564,"Fixed Deposit Receipts (FDR)")-SUMIFS(Journals!$L$9:$L$1007564,Journals!$D$9:$D$1007564,">"&$E$7,Journals!$D$9:$D$1007564,"<"&$E$8,Journals!$J$9:$J$1007564,"Fixed Deposit Receipts (FDR)")) -> 0 | I18: =MAX(0,SUMIFS(Journals!$L$9:$L$1007564,Journals!$D$9:$D$1007564,">"&$E$7,Journals!$D$9:$D$1007564,"<"&$E$8,Journals!$J$9:$J$1007564,"Fixed Deposit Receipts (FDR)")-SUMIFS(Journals!$K$9:$K$1007564,Journals!$D$9:$D$1007564,">"&$E$7,Journals!$D$9:$D$1007564,"<"&$E$8,Journals!$J$9:$J$1007564,"Fixed Deposit Receipts (FDR)")) -> 31000000 | J18: =SUMIFS(Journals!$K$9:$K$1007564,Journals!$D$9:$D$1007564,"<"&$F$7,Journals!$J$9:$J$1007564,"Fixed Deposit Receipts (FDR)")-SUMIFS(Journals!$L$9:$L$1007564,Journals!$D$9:$D$1007564,"<"&$F$7,Journals!$J$9:$J$1007564,"Fixed Deposit Receipts (FDR)") -> 85000000 | L18: =J18+H18-I18 -> 54000000
G19: ='Chart of Accounts'!B13 -> Cash and cash equivalents | H19: =MAX(0,SUMIFS(Journals!$K$9:$K$1006910,Journals!$D$9:$D$1006910,">"&$E$7,Journals!$D$9:$D$1006910,"<"&$E$8,Journals!$J$9:$J$1006910,"Cash and cash equivalents")-SUMIFS(Journals!$L$9:$L$1006910,Journals!$D$9:$D$1006910,">"&$E$7,Journals!$D$9:$D$1006910,"<"&$E$8,Journals!$J$9:$J$1006910,"Cash and cash equivalents")) -> 15938868 | I19: =MAX(0,SUMIFS(Journals!$L$9:$L$1006910,Journals!$D$9:$D$1006910,">"&$E$7,Journals!$D$9:$D$1006910,"<"&$E$8,Journals!$J$9:$J$1006910,"Cash and cash equivalents")-SUMIFS(Journals!$K$9:$K$1006910,Journals!$D$9:$D$1006910,">"&$E$7,Journals!$D$9:$D$1006910,"<"&$E$8,Journals!$J$9:$J$1006910,"Cash and cash equivalents")) -> 0 | J19: =SUMIFS(Journals!$K$9:$K$1007564,Journals!$D$9:$D$1007564,"<"&$F$7,Journals!$J$9:$J$1007564,"Cash and cash equivalents")-SUMIFS(Journals!$L$9:$L$1007564,Journals!$D$9:$D$1007564,"<"&$F$7,Journals!$J$9:$J$1007564,"Cash and cash equivalents") -> 15519657 | L19: =J19+H19-I19 -> 31458525
G20: ='Chart of Accounts'!B14 -> Unit Capital | H20: =SUMIFS(Journals!$K$9:$K$1007564,Journals!$D$9:$D$1007564,">"&$E$7,Journals!$D$9:$D$1007564,"<"&$E$8,Journals!$J$9:$J$1007564,"unit capital") -> 263102130 | I20: =MAX(0,SUMIFS(Journals!$L$9:$L$1007564,Journals!$D$9:$D$1007564,">"&$E$7,Journals!$D$9:$D$1007564,"<"&$E$8,Journals!$J$9:$J$1007564,"unit capital")) -> 212650510 | K20: =SUMIFS(Journals!$L$9:$L$1007564,Journals!$D$9:$D$1007564,"<"&$F$7,Journals!$J$9:$J$1007564,"unit capital")-SUMIFS(Journals!$K$9:$K$1007564,Journals!$D$9:$D$1007564,"<"&$F$7,Journals!$J$9:$J$1007564,"unit capital") -> 462377570 | M20: =K20+I20-H20 -> 411925950
G21: ='Chart of Accounts'!B15 -> Unit premium reserve | H21: =SUMIFS(Journals!$K$9:$K$1007564,Journals!$D$9:$D$1007564,">"&$E$7,Journals!$D$9:$D$1007564,"<"&$E$8,Journals!$J$9:$J$1007564,"unit premium reserve") -> 88676215 | I21: =SUMIFS(Journals!$L$9:$L$1007564,Journals!$D$9:$D$1007564,">"&$E$7,Journals!$D$9:$D$1007564,"<"&$E$8,Journals!$J$9:$J$1007564,"unit premium reserve") -> 70419620 | K21: =SUMIFS(Journals!$L$9:$L$1007564,Journals!$D$9:$D$1007564,"<"&$F$7,Journals!$J$9:$J$1007564,"unit premium reserve")-SUMIFS(Journals!$K$9:$K$1007564,Journals!$D$9:$D$1007564,"<"&$F$7,Journals!$J$9:$J$1007564,"unit premium reserve") -> 41293538 | M21: =K21+I21-H21 -> 23036942
G22: Interest income | H22: =MAX(0,SUMIFS(Journals!$K$9:$K$1007564,Journals!$D$9:$D$1007564,">"&$E$7,Journals!$D$9:$D$1007564,"<"&$E$8,Journals!$J$9:$J$1007564,"interest income")-SUMIFS(Journals!$L$9:$L$1007564,Journals!$D$9:$D$1007564,">"&$E$7,Journals!$D$9:$D$1007564,"<"&$E$8,Journals!$J$9:$J$1007564,"interest income")) -> 0 | I22: =MAX(0,SUMIFS(Journals!$L$9:$L$1007564,Journals!$D$9:$D$1007564,">"&$E$7,Journals!$D$9:$D$1007564,"<"&$E$8,Journals!$J$9:$J$1007564,"interest income")-SUMIFS(Journals!$K$9:$K$1007564,Journals!$D$9:$D$1007564,">"&$E$7,Journals!$D$9:$D$1007564,"<"&$E$8,Journals!$J$9:$J$1007564,"interest income")) -> 7800790.8 | K22: =SUMIFS(Journals!$L$9:$L$1007564,Journals!$D$9:$D$1007564,"<"&$F$7,Journals!$J$9:$J$1007564,"Interest income")-SUMIFS(Journals!$K$9:$K$1007564,Journals!$D$9:$D$1007564,"<"&$F$7,Journals!$J$9:$J$1007564,"Interest income") -> 19919416 | M22: =K22+I22-H22 -> 27720207 | O22: =SUMIFS(Journals!$L$9:$L$1007564,Journals!$D$9:$D$1007564,"<"&$F$7,Journals!$J$9:$J$1007564,"interest income")-SUMIFS(Journals!$K$9:$K$1007564,Journals!$D$9:$D$1007564,"<"&$F$7,Journals!$J$9:$J$1007564,"interest income") -> 19919416
G23: Interest income from T-Bond | H23: =MAX(0,SUMIFS(Journals!$K$9:$K$1007494,Journals!$D$9:$D$1007494,">"&$E$7,Journals!$D$9:$D$1007494,"<"&$E$8,Journals!$J$9:$J$1007494,"Interest income from T-Bond")-SUMIFS(Journals!$L$9:$L$1007494,Journals!$D$9:$D$1007494,">"&$E$7,Journals!$D$9:$D$1007494,"<"&$E$8,Journals!$J$9:$J$1007494,"Interest income from T-Bond")) -> 0 | I23: =MAX(0,SUMIFS(Journals!$L$9:$L$1007494,Journals!$D$9:$D$1007494,">"&$E$7,Journals!$D$9:$D$1007494,"<"&$E$8,Journals!$J$9:$J$1007494,"Interest income from T-Bond")-SUMIFS(Journals!$K$9:$K$1007494,Journals!$D$9:$D$1007494,">"&$E$7,Journals!$D$9:$D$1007494,"<"&$E$8,Journals!$J$9:$J$1007494,"Interest income from T-Bond")) -> 23849013 | K23: =SUMIFS(Journals!$L$9:$L$1007494,Journals!$D$9:$D$1007494,"<"&$F$7,Journals!$J$9:$J$1007494,"Interest income from T-Bond")-SUMIFS(Journals!$K$9:$K$1007494,Journals!$D$9:$D$1007494,"<"&$F$7,Journals!$J$9:$J$1007494,"Interest income from T-Bond") -> 33626216 | M23: =K23+I23-H23 -> 57475229 | O23: =SUMIFS(Journals!$L$9:$L$1007494,Journals!$D$9:$D$1007494,"<"&$F$7,Journals!$J$9:$J$1007494,"Interest income from T-Bond")-SUMIFS(Journals!$K$9:$K$1007494,Journals!$D$9:$D$1007494,"<"&$F$7,Journals!$J$9:$J$1007494,"Interest income from T-Bond") -> 33626216
G24: Interest income from BXSUKUK | H24: =MAX(0,SUMIFS(Journals!$K$9:$K$1007564,Journals!$D$9:$D$1007564,">"&$E$7,Journals!$D$9:$D$1007564,"<"&$E$8,Journals!$J$9:$J$1007564,"Interest income from BXSUKUK")-SUMIFS(Journals!$L$9:$L$1007564,Journals!$D$9:$D$1007564,">"&$E$7,Journals!$D$9:$D$1007564,"<"&$E$8,Journals!$J$9:$J$1007564,"Interest income from BXSUKUK")) -> 0 | I24: =MAX(0,SUMIFS(Journals!$L$9:$L$1007492,Journals!$D$9:$D$1007492,">"&$E$7,Journals!$D$9:$D$1007492,"<"&$E$8,Journals!$J$9:$J$1007492,"Interest income from BXSUKUK")-SUMIFS(Journals!$K$9:$K$1007492,Journals!$D$9:$D$1007492,">"&$E$7,Journals!$D$9:$D$1007492,"<"&$E$8,Journals!$J$9:$J$1007492,"Interest income from BXSUKUK")) -> 0 | K24: =SUMIFS(Journals!$L$9:$L$1007564,Journals!$D$9:$D$1007564,"<"&$F$7,Journals!$J$9:$J$1007564,"Interest income from BXSUKUK")-SUMIFS(Journals!$K$9:$K$1007564,Journals!$D$9:$D$1007564,"<"&$F$7,Journals!$J$9:$J$1007564,"Interest income from BXSUKUK") -> 448642.74 | M24: =K24+I24-H24 -> 448642.74 | O24: =SUMIFS(Journals!$L$9:$L$1007564,Journals!$D$9:$D$1007564,"<"&$F$7,Journals!$J$9:$J$1007564,"Interest income from BXSUKUK")-SUMIFS(Journals!$K$9:$K$1007564,Journals!$D$9:$D$1007564,"<"&$F$7,Journals!$J$9:$J$1007564,"Interest income from BXSUKUK") -> 448642.74
G25: Interest income from APSCL | H25: =MAX(0,SUMIFS(Journals!$K$9:$K$1007564,Journals!$D$9:$D$1007564,">"&$E$7,Journals!$D$9:$D$1007564,"<"&$E$8,Journals!$J$9:$J$1007564,"Interest income from APSCL")-SUMIFS(Journals!$L$9:$L$1007564,Journals!$D$9:$D$1007564,">"&$E$7,Journals!$D$9:$D$1007564,"<"&$E$8,Journals!$J$9:$J$1007564,"Interest income from APSCL")) -> 0 | I25: =MAX(0,SUMIFS(Journals!$L$9:$L$1007564,Journals!$D$9:$D$1007564,">"&$E$7,Journals!$D$9:$D$1007564,"<"&$E$8,Journals!$J$9:$J$1007564,"Interest income from APSCL")-SUMIFS(Journals!$K$9:$K$1007564,Journals!$D$9:$D$1007564,">"&$E$7,Journals!$D$9:$D$1007564,"<"&$E$8,Journals!$J$9:$J$1007564,"Interest income from APSCL")) -> 304658.4 | K25: =SUMIFS(Journals!$L$9:$L$1007564,Journals!$D$9:$D$1007564,"<"&$F$7,Journals!$J$9:$J$1007564,"Interest income from APSCL")-SUMIFS(Journals!$K$9:$K$1007564,Journals!$D$9:$D$1007564,"<"&$F$7,Journals!$J$9:$J$1007564,"Interest income from APSCL") -> 1278526.9 | M25: =K25+I25-H25 -> 1583185.3 | O25: =SUMIFS(Journals!$L$9:$L$1007564,Journals!$D$9:$D$1007564,"<"&$F$7,Journals!$J$9:$J$1007564,"Interest income from APSCL")-SUMIFS(Journals!$K$9:$K$1007564,Journals!$D$9:$D$1007564,"<"&$F$7,Journals!$J$9:$J$1007564,"Interest income from APSCL") -> 1278526.9
G26: Interest income from Bank Asia Bond | H26: =MAX(0,SUMIFS(Journals!$K$9:$K$1007564,Journals!$D$9:$D$1007564,">"&$E$7,Journals!$D$9:$D$1007564,"<"&$E$8,Journals!$J$9:$J$1007564,"Interest income from Bank Asia Bond")-SUMIFS(Journals!$L$9:$L$1007564,Journals!$D$9:$D$1007564,">"&$E$7,Journals!$D$9:$D$1007564,"<"&$E$8,Journals!$J$9:$J$1007564,"Interest income from Bank Asia Bond")) -> 0 | I26: =MAX(0,SUMIFS(Journals!$L$9:$L$1007564,Journals!$D$9:$D$1007564,">"&$E$7,Journals!$D$9:$D$1007564,"<"&$E$8,Journals!$J$9:$J$1007564,"Interest income from Bank Asia Bond")-SUMIFS(Journals!$K$9:$K$1007564,Journals!$D$9:$D$1007564,">"&$E$7,Journals!$D$9:$D$1007564,"<"&$E$8,Journals!$J$9:$J$1007564,"Interest income from Bank Asia Bond")) -> 3805011.2 | K26: =SUMIFS(Journals!$L$9:$L$1007564,Journals!$D$9:$D$1007564,"<"&$F$7,Journals!$J$9:$J$1007564,"Interest income from Bank Asia Bond")-SUMIFS(Journals!$K$9:$K$1007564,Journals!$D$9:$D$1007564,"<"&$F$7,Journals!$J$9:$J$1007564,"Interest income from Bank Asia Bond") -> 873164.87 | M26: =K26+I26-H26 -> 4678176 | O26: =SUMIFS(Journals!$L$9:$L$1007564,Journals!$D$9:$D$1007564,"<"&$F$7,Journals!$J$9:$J$1007564,"Interest income from Bank Asia Bond")-SUMIFS(Journals!$K$9:$K$1007564,Journals!$D$9:$D$1007564,"<"&$F$7,Journals!$J$9:$J$1007564,"Interest income from Bank Asia Bond") -> 873164.87
G27: Interest income from BRAC Bank Bond | H27: =MAX(0,SUMIFS(Journals!$K$9:$K$1007564,Journals!$D$9:$D$1007564,">"&$E$7,Journals!$D$9:$D$1007564,"<"&$E$8,Journals!$J$9:$J$1007564,"Interest income from BRAC Bank Bond")-SUMIFS(Journals!$L$9:$L$1007564,Journals!$D$9:$D$1007564,">"&$E$7,Journals!$D$9:$D$1007564,"<"&$E$8,Journals!$J$9:$J$1007564,"Interest income from BRAC Bank Bond")) -> 0 | I27: =MAX(0,SUMIFS(Journals!$L$9:$L$1007564,Journals!$D$9:$D$1007564,">"&$E$7,Journals!$D$9:$D$1007564,"<"&$E$8,Journals!$J$9:$J$1007564,"Interest income from BRAC Bank Bond")-SUMIFS(Journals!$K$9:$K$1007564,Journals!$D$9:$D$1007564,">"&$E$7,Journals!$D$9:$D$1007564,"<"&$E$8,Journals!$J$9:$J$1007564,"Interest income from BRAC Bank Bond")) -> 5594936.2 | K27: =SUMIFS(Journals!$L$9:$L$1007564,Journals!$D$9:$D$1007564,"<"&$F$7,Journals!$J$9:$J$1007564,"Interest income from BRAC Bank Bond")-SUMIFS(Journals!$K$9:$K$1007564,Journals!$D$9:$D$1007564,"<"&$F$7,Journals!$J$9:$J$1007564,"Interest income from BRAC Bank Bond") -> 2800879.1 | M27: =K27+I27-H27 -> 8395815.4 | O27: =SUMIFS(Journals!$L$9:$L$1007564,Journals!$D$9:$D$1007564,"<"&$F$7,Journals!$J$9:$J$1007564,"Interest income from BRAC Bank Bond")-SUMIFS(Journals!$K$9:$K$1007564,Journals!$D$9:$D$1007564,"<"&$F$7,Journals!$J$9:$J$1007564,"Interest income from BRAC Bank Bond") -> 2800879.1
G28: Interest income from Dhaka Bank Bond | H28: =MAX(0,SUMIFS(Journals!$K$9:$K$1007564,Journals!$D$9:$D$1007564,">"&$E$7,Journals!$D$9:$D$1007564,"<"&$E$8,Journals!$J$9:$J$1007564,"Interest income from Dhaka Bank Bond")-SUMIFS(Journals!$L$9:$L$1007564,Journals!$D$9:$D$1007564,">"&$E$7,Journals!$D$9:$D$1007564,"<"&$E$8,Journals!$J$9:$J$1007564,"Interest income from Dhaka Bank Bond")) -> 0 | I28: =MAX(0,SUMIFS(Journals!$L$9:$L$1007564,Journals!$D$9:$D$1007564,">"&$E$7,Journals!$D$9:$D$1007564,"<"&$E$8,Journals!$J$9:$J$1007564,"Interest income from Dhaka Bank Bond")-SUMIFS(Journals!$K$9:$K$1007564,Journals!$D$9:$D$1007564,">"&$E$7,Journals!$D$9:$D$1007564,"<"&$E$8,Journals!$J$9:$J$1007564,"Interest income from Dhaka Bank Bond")) -> 442019.01 | K28: =SUMIFS(Journals!$L$9:$L$1007564,Journals!$D$9:$D$1007564,"<"&$F$7,Journals!$J$9:$J$1007564,"Interest income from Dhaka Bank Bond")-SUMIFS(Journals!$K$9:$K$1007564,Journals!$D$9:$D$1007564,"<"&$F$7,Journals!$J$9:$J$1007564,"Interest income from Dhaka Bank Bond") -> 0 | M28: =K28+I28-H28 -> 442019.01 | O28: =SUMIFS(Journals!$L$9:$L$1007564,Journals!$D$9:$D$1007564,"<"&$F$7,Journals!$J$9:$J$1007564,"Interest income from Dhaka Bank Bond")-SUMIFS(Journals!$K$9:$K$1007564,Journals!$D$9:$D$1007564,"<"&$F$7,Journals!$J$9:$J$1007564,"Interest income from Dhaka Bank Bond") -> 0
G29: Interest income from Bank Acc. | H29: =MAX(0,SUMIFS(Journals!$K$9:$K$1007564,Journals!$D$9:$D$1007564,">"&$E$7,Journals!$D$9:$D$1007564,"<"&$E$8,Journals!$J$9:$J$1007564,"Interest income from Bank Acc.")-SUMIFS(Journals!$L$9:$L$1007564,Journals!$D$9:$D$1007564,">"&$E$7,Journals!$D$9:$D$1007564,"<"&$E$8,Journals!$J$9:$J$1007564,"Interest income from Bank Acc.")) -> 0 | I29: =MAX(0,SUMIFS(Journals!$L$9:$L$1007564,Journals!$D$9:$D$1007564,">"&$E$7,Journals!$D$9:$D$1007564,"<"&$E$8,Journals!$J$9:$J$1007564,"Interest income from Bank Acc.")-SUMIFS(Journals!$K$9:$K$1007564,Journals!$D$9:$D$1007564,">"&$E$7,Journals!$D$9:$D$1007564,"<"&$E$8,Journals!$J$9:$J$1007564,"Interest income from Bank Acc.")) -> 0 | K29: =SUMIFS(Journals!$L$9:$L$1007564,Journals!$D$9:$D$1007564,"<"&$F$7,Journals!$J$9:$J$1007564,"Interest income from Bank Acc.")-SUMIFS(Journals!$K$9:$K$1007564,Journals!$D$9:$D$1007564,"<"&$F$7,Journals!$J$9:$J$1007564,"Interest income from Bank Acc.") -> 0 | M29: =K29+I29-H29 -> 0 | O29: =SUMIFS(Journals!$L$9:$L$1007564,Journals!$D$9:$D$1007564,"<"&$F$7,Journals!$J$9:$J$1007564,"Interest income from Bank Acc.")-SUMIFS(Journals!$K$9:$K$1007564,Journals!$D$9:$D$1007564,"<"&$F$7,Journals!$J$9:$J$1007564,"Interest income from Bank Acc.") -> 0
G30: Interest income from FDR | H30: =MAX(0,SUMIFS(Journals!$K$9:$K$1007564,Journals!$D$9:$D$1007564,">"&$E$7,Journals!$D$9:$D$1007564,"<"&$E$8,Journals!$J$9:$J$1007564,"Interest income from FDR")-SUMIFS(Journals!$L$9:$L$1007564,Journals!$D$9:$D$1007564,">"&$E$7,Journals!$D$9:$D$1007564,"<"&$E$8,Journals!$J$9:$J$1007564,"Interest income from FDR")) -> 0 | I30: =MAX(0,SUMIFS(Journals!$L$9:$L$1007564,Journals!$D$9:$D$1007564,">"&$E$7,Journals!$D$9:$D$1007564,"<"&$E$8,Journals!$J$9:$J$1007564,"Interest income from FDR")-SUMIFS(Journals!$K$9:$K$1007564,Journals!$D$9:$D$1007564,">"&$E$7,Journals!$D$9:$D$1007564,"<"&$E$8,Journals!$J$9:$J$1007564,"Interest income from FDR")) -> 0 | K30: =SUMIFS(Journals!$L$9:$L$1007564,Journals!$D$9:$D$1007564,"<"&$F$7,Journals!$J$9:$J$1007564,"Interest income from FDR")-SUMIFS(Journals!$K$9:$K$1007564,Journals!$D$9:$D$1007564,"<"&$F$7,Journals!$J$9:$J$1007564,"Interest income from FDR") -> 0 | M30: =K30+I30-H30 -> 0 | O30: =SUMIFS(Journals!$L$9:$L$1007564,Journals!$D$9:$D$1007564,"<"&$F$7,Journals!$J$9:$J$1007564,"Interest income from FDR")-SUMIFS(Journals!$K$9:$K$1007564,Journals!$D$9:$D$1007564,"<"&$F$7,Journals!$J$9:$J$1007564,"Interest income from FDR") -> 0
G31: Interest income reduce for Bond Premium | H31: =MAX(0,SUMIFS(Journals!$K$9:$K$1007564,Journals!$D$9:$D$1007564,">"&$E$7,Journals!$D$9:$D$1007564,"<"&$E$8,Journals!$J$9:$J$1007564,"Interest income reduce for Bond Premium")-SUMIFS(Journals!$L$9:$L$1007564,Journals!$D$9:$D$1007564,">"&$E$7,Journals!$D$9:$D$1007564,"<"&$E$8,Journals!$J$9:$J$1007564,"Interest income reduce for Bond Premium")) -> 0 | I31: =MAX(0,SUMIFS(Journals!$L$9:$L$1007564,Journals!$D$9:$D$1007564,">"&$E$7,Journals!$D$9:$D$1007564,"<"&$E$8,Journals!$J$9:$J$1007564,"Interest income reduce for Bond Premium")-SUMIFS(Journals!$K$9:$K$1007564,Journals!$D$9:$D$1007564,">"&$E$7,Journals!$D$9:$D$1007564,"<"&$E$8,Journals!$J$9:$J$1007564,"Interest income reduce for Bond Premium")) -> 0 | J31: =SUMIFS(Journals!$K$9:$K$1007564,Journals!$D$9:$D$1007564,"<"&$F$7,Journals!$J$9:$J$1007564,"Interest income reduce for Bond Premium")-SUMIFS(Journals!$L$9:$L$1007564,Journals!$D$9:$D$1007564,"<"&$F$7,Journals!$J$9:$J$1007564,"Interest income reduce for Bond Premium") -> 0 | L31: =J31+H31-I31 -> 0
G32: Bank charges and excise duties | H32: =MAX(0,SUMIFS(Journals!$K$9:$K$1007564,Journals!$D$9:$D$1007564,">"&$E$7,Journals!$D$9:$D$1007564,"<"&$E$8,Journals!$J$9:$J$1007564,"Bank charges and excise duties")-SUMIFS(Journals!$L$9:$L$1007564,Journals!$D$9:$D$1007564,">"&$E$7,Journals!$D$9:$D$1007564,"<"&$E$8,Journals!$J$9:$J$1007564,"Bank charges and excise duties")) -> 167021.48 | I32: =MAX(0,SUMIFS(Journals!$L$9:$L$1007564,Journals!$D$9:$D$1007564,">"&$E$7,Journals!$D$9:$D$1007564,"<"&$E$8,Journals!$J$9:$J$1007564,"Bank charges and excise duties")-SUMIFS(Journals!$K$9:$K$1007564,Journals!$D$9:$D$1007564,">"&$E$7,Journals!$D$9:$D$1007564,"<"&$E$8,Journals!$J$9:$J$1007564,"Bank charges and excise duties")) -> 0 | N32: =SUMIFS(Journals!$K$9:$K$1007564,Journals!$D$9:$D$1007564,"<"&$F$7,Journals!$J$9:$J$1007564,"Bank charges and excise duties")-SUMIFS(Journals!$L$9:$L$1007564,Journals!$D$9:$D$1007564,"<"&$F$7,Journals!$J$9:$J$1007564,"Bank charges and excise duties") -> 646075.36
G33: ='Chart of Accounts'!B25 -> Brokerage commission | H33: =MAX(0,SUMIFS(Journals!$K$9:$K$1007564,Journals!$D$9:$D$1007564,">"&$E$7,Journals!$D$9:$D$1007564,"<"&$E$8,Journals!$J$9:$J$1007564,"Brokerage Commission")-SUMIFS(Journals!$L$9:$L$1007564,Journals!$D$9:$D$1007564,">"&$E$7,Journals!$D$9:$D$1007564,"<"&$E$8,Journals!$J$9:$J$1007564,"Brokerage Commission")) -> 3714.73 | I33: =MAX(0,SUMIFS(Journals!$L$9:$L$1007564,Journals!$D$9:$D$1007564,">"&$E$7,Journals!$D$9:$D$1007564,"<"&$E$8,Journals!$J$9:$J$1007564,"brokerage commission")-SUMIFS(Journals!$K$9:$K$1007564,Journals!$D$9:$D$1007564,">"&$E$7,Journals!$D$9:$D$1007564,"<"&$E$8,Journals!$J$9:$J$1007564,"brokerage commission")) -> 0 | N33: =SUMIFS(Journals!$K$9:$K$1007564,Journals!$D$9:$D$1007564,"<"&$F$7,Journals!$J$9:$J$1007564,"brokerage commission")-SUMIFS(Journals!$L$9:$L$1007564,Journals!$D$9:$D$1007564,"<"&$F$7,Journals!$J$9:$J$1007564,"brokerage commission") -> 22405.918
G34: Unrealized gain on securities | H34: =MAX(0,SUMIFS(Journals!$K$9:$K$1007564,Journals!$D$9:$D$1007564,">"&$E$7,Journals!$D$9:$D$1007564,"<"&$E$8,Journals!$J$9:$J$1007564,"Unrealized gain on securities")-SUMIFS(Journals!$L$9:$L$1007564,Journals!$D$9:$D$1007564,">"&$E$7,Journals!$D$9:$D$1007564,"<"&$E$8,Journals!$J$9:$J$1007564,"Unrealized gain on securities")) -> 0 | I34: =MAX(0,SUMIFS(Journals!$L$9:$L$1007564,Journals!$D$9:$D$1007564,">"&$E$7,Journals!$D$9:$D$1007564,"<"&$E$8,Journals!$J$9:$J$1007564,"Unrealized gain on securities")-SUMIFS(Journals!$K$9:$K$1007564,Journals!$D$9:$D$1007564,">"&$E$7,Journals!$D$9:$D$1007564,"<"&$E$8,Journals!$J$9:$J$1007564,"Unrealized gain on securities")) -> 396063.49 | J34: =SUMIFS(Journals!$K$9:$K$1007564,Journals!$D$9:$D$1007564,"<"&$F$7,Journals!$J$9:$J$1007564,"Unrealized gain on securities")-SUMIFS(Journals!$L$9:$L$1007564,Journals!$D$9:$D$1007564,"<"&$F$7,Journals!$J$9:$J$1007564,"Unrealized gain on securities") -> -160630.88 | N34: =SUMIFS(Journals!K6:K1007561,Journals!D6:D1007561,"<"&F4,Journals!J6:J1007561,"Unrealized gain on securities")-SUMIFS(Journals!L6:L1007561,Journals!D6:D1007561,"<"&F4,Journals!J6:J1007561,"Unrealized gain on securities") -> 0 | O34: =SUMIFS(Journals!$L$9:$L$1003833,Journals!$D$9:$D$1003833,"<"&$F$7,Journals!$J$9:$J$1003833,"unrealized gain on securities")-SUMIFS(Journals!$K$9:$K$1003833,Journals!$D$9:$D$1003833,"<"&$F$7,Journals!$J$9:$J$1003833,"unrealized gain on securities") -> 160630.88
G35: Unrealized gain on T-Bill | H35: =MAX(0,SUMIFS(Journals!$K$9:$K$1007564,Journals!$D$9:$D$1007564,">"&$E$7,Journals!$D$9:$D$1007564,"<"&$E$8,Journals!$J$9:$J$1007564,"Unrealized gain on T-Bill")-SUMIFS(Journals!$L$9:$L$1007564,Journals!$D$9:$D$1007564,">"&$E$7,Journals!$D$9:$D$1007564,"<"&$E$8,Journals!$J$9:$J$1007564,"Unrealized gain on T-Bill")) -> 0 | I35: =MAX(0,SUMIFS(Journals!$L$9:$L$1007564,Journals!$D$9:$D$1007564,">"&$E$7,Journals!$D$9:$D$1007564,"<"&$E$8,Journals!$J$9:$J$1007564,"Unrealized gain on T-Bill")-SUMIFS(Journals!$K$9:$K$1007564,Journals!$D$9:$D$1007564,">"&$E$7,Journals!$D$9:$D$1007564,"<"&$E$8,Journals!$J$9:$J$1007564,"Unrealized gain on T-Bill")) -> 0 | K35: =SUMIFS(Journals!$L$9:$L$1007564,Journals!$D$9:$D$1007564,"<"&$F$7,Journals!$J$9:$J$1007564,"Unrealized gain on T-Bill")-SUMIFS(Journals!$K$9:$K$1007564,Journals!$D$9:$D$1007564,"<"&$F$7,Journals!$J$9:$J$1007564,"Unrealized gain on T-Bill") -> -0.19999999 | N35: =SUMIFS(Journals!K7:K1007562,Journals!D7:D1007562,"<"&F5,Journals!J7:J1007562,"Unrealized gain on T-Bill")-SUMIFS(Journals!L7:L1007562,Journals!D7:D1007562,"<"&F5,Journals!J7:J1007562,"Unrealized gain on T-Bill") -> 0 | O35: =SUMIFS(Journals!$L$9:$L$1003833,Journals!$D$9:$D$1003833,"<"&$F$7,Journals!$J$9:$J$1003833,"Unrealized gain on T-Bill")-SUMIFS(Journals!$K$9:$K$1003833,Journals!$D$9:$D$1003833,"<"&$F$7,Journals!$J$9:$J$1003833,"Unrealized gain on T-Bill") -> -0.19999999
G36: Unrealized gain on T-Bond | H36: =MAX(0,SUMIFS(Journals!$K$9:$K$1007564,Journals!$D$9:$D$1007564,">"&$E$7,Journals!$D$9:$D$1007564,"<"&$E$8,Journals!$J$9:$J$1007564,"Unrealized gain on T-Bond")-SUMIFS(Journals!$L$9:$L$1007564,Journals!$D$9:$D$1007564,">"&$E$7,Journals!$D$9:$D$1007564,"<"&$E$8,Journals!$J$9:$J$1007564,"Unrealized gain on T-Bond")) -> 0 | I36: =MAX(0,SUMIFS(Journals!$L$9:$L$1007564,Journals!$D$9:$D$1007564,">"&$E$7,Journals!$D$9:$D$1007564,"<"&$E$8,Journals!$J$9:$J$1007564,"Unrealized gain on T-Bond")-SUMIFS(Journals!$K$9:$K$1007564,Journals!$D$9:$D$1007564,">"&$E$7,Journals!$D$9:$D$1007564,"<"&$E$8,Journals!$J$9:$J$1007564,"Unrealized gain on T-Bond")) -> 24729620 | K36: =SUMIFS(Journals!$L$9:$L$1007564,Journals!$D$9:$D$1007564,"<"&$F$7,Journals!$J$9:$J$1007564,"Unrealized gain on T-Bond")-SUMIFS(Journals!$K$9:$K$1007564,Journals!$D$9:$D$1007564,"<"&$F$7,Journals!$J$9:$J$1007564,"Unrealized gain on T-Bond") -> 4692855.2 | N36: =SUMIFS(Journals!K8:K1007563,Journals!D8:D1007563,"<"&F6,Journals!J8:J1007563,"Unrealized gain on T-Bond")-SUMIFS(Journals!L8:L1007563,Journals!D8:D1007563,"<"&F6,Journals!J8:J1007563,"Unrealized gain on T-Bond") -> 0 | O36: =SUMIFS(Journals!$L$9:$L$1003833,Journals!$D$9:$D$1003833,"<"&$F$7,Journals!$J$9:$J$1003833,"Unrealized gain on T-Bond")-SUMIFS(Journals!$K$9:$K$1003833,Journals!$D$9:$D$1003833,"<"&$F$7,Journals!$J$9:$J$1003833,"Unrealized gain on T-Bond") -> 4692855.2
G37: ='Chart of Accounts'!B29 -> Unrealized loss on securities | H37: =MAX(0,SUMIFS(Journals!$K$9:$K$1007564,Journals!$D$9:$D$1007564,">"&$E$7,Journals!$D$9:$D$1007564,"<"&$E$8,Journals!$J$9:$J$1007564,"Unrealized loss on securities")-SUMIFS(Journals!$L$9:$L$1007564,Journals!$D$9:$D$1007564,">"&$E$7,Journals!$D$9:$D$1007564,"<"&$E$8,Journals!$J$9:$J$1007564,"Unrealized loss on securities")) -> 0 | I37: =MAX(0,SUMIFS(Journals!$L$9:$L$1007564,Journals!$D$9:$D$1007564,">"&$E$7,Journals!$D$9:$D$1007564,"<"&$E$8,Journals!$J$9:$J$1007564,"Unrealized loss on securities")-SUMIFS(Journals!$K$9:$K$1007564,Journals!$D$9:$D$1007564,">"&$E$7,Journals!$D$9:$D$1007564,"<"&$E$8,Journals!$J$9:$J$1007564,"Unrealized loss on securities")) -> 0 | N37: =SUMIFS(Journals!K9:K1007564,Journals!D9:D1007564,"<"&F7,Journals!J9:J1007564,"unrealized loss on securities")-SUMIFS(Journals!L9:L1007564,Journals!D9:D1007564,"<"&F7,Journals!J9:J1007564,"unrealized loss on securities") -> 0
G38: ='Chart of Accounts'!B30 -> Amortization of preliminary and issue expense | H38: =MAX(0,SUMIFS(Journals!$K$9:$K$1007564,Journals!$D$9:$D$1007564,">"&$E$7,Journals!$D$9:$D$1007564,"<"&$E$8,Journals!$J$9:$J$1007564,"Amortization of preliminary and issue expense")-SUMIFS(Journals!$L$9:$L$1007564,Journals!$D$9:$D$1007564,">"&$E$7,Journals!$D$9:$D$1007564,"<"&$E$8,Journals!$J$9:$J$1007564,"Amortization of preliminary and issue expense")) -> 138713.88 | I38: =MAX(0,SUMIFS(Journals!$L$9:$L$1007564,Journals!$D$9:$D$1007564,">"&$E$7,Journals!$D$9:$D$1007564,"<"&$E$8,Journals!$J$9:$J$1007564,"Amortization of preliminary and issue expense")-SUMIFS(Journals!$K$9:$K$1007564,Journals!$D$9:$D$1007564,">"&$E$7,Journals!$D$9:$D$1007564,"<"&$E$8,Journals!$J$9:$J$1007564,"Amortization of preliminary and issue expense")) -> 0 | N38: =SUMIFS(Journals!$K$9:$K$1007564,Journals!$D$9:$D$1007564,"<"&$F$7,Journals!$J$9:$J$1007564,"Amortization of preliminary and issue expense")-SUMIFS(Journals!$L$9:$L$1007564,Journals!$D$9:$D$1007564,"<"&$F$7,Journals!$J$9:$J$1007564,"Amortization of preliminary and issue expense") -> 440270.64
G39: ='Chart of Accounts'!B31 -> Management Fee | H39: =MAX(0,SUMIFS(Journals!$K$9:$K$1007564,Journals!$D$9:$D$1007564,">"&$E$7,Journals!$D$9:$D$1007564,"<"&$E$8,Journals!$J$9:$J$1007564,"management fee")-SUMIFS(Journals!$L$9:$L$1007564,Journals!$D$9:$D$1007564,">"&$E$7,Journals!$D$9:$D$1007564,"<"&$E$8,Journals!$J$9:$J$1007564,"management fee")) -> 2130135.1 | I39: =MAX(0,SUMIFS(Journals!$L$9:$L$1007564,Journals!$D$9:$D$1007564,">"&$E$7,Journals!$D$9:$D$1007564,"<"&$E$8,Journals!$J$9:$J$1007564,"management fee")-SUMIFS(Journals!$K$9:$K$1007564,Journals!$D$9:$D$1007564,">"&$E$7,Journals!$D$9:$D$1007564,"<"&$E$8,Journals!$J$9:$J$1007564,"management fee")) -> 0 | N39: =SUMIFS(Journals!$K$9:$K$1007564,Journals!$D$9:$D$1007564,"<"&$F$7,Journals!$J$9:$J$1007564,"management fee")-SUMIFS(Journals!$L$9:$L$1007564,Journals!$D$9:$D$1007564,"<"&$F$7,Journals!$J$9:$J$1007564,"management fee") -> 3385722.9
G40: ='Chart of Accounts'!B32 -> Trustee fee | H40: =MAX(0,SUMIFS(Journals!$K$9:$K$1007564,Journals!$D$9:$D$1007564,">"&$E$7,Journals!$D$9:$D$1007564,"<"&$E$8,Journals!$J$9:$J$1007564,"trustee fee")-SUMIFS(Journals!$L$9:$L$1007564,Journals!$D$9:$D$1007564,">"&$E$7,Journals!$D$9:$D$1007564,"<"&$E$8,Journals!$J$9:$J$1007564,"trustee fee")) -> 213013.5 | I40: =MAX(0,SUMIFS(Journals!$L$9:$L$1007564,Journals!$D$9:$D$1007564,">"&$E$7,Journals!$D$9:$D$1007564,"<"&$E$8,Journals!$J$9:$J$1007564,"trustee fee")-SUMIFS(Journals!$K$9:$K$1007564,Journals!$D$9:$D$1007564,">"&$E$7,Journals!$D$9:$D$1007564,"<"&$E$8,Journals!$J$9:$J$1007564,"trustee fee")) -> 0 | N40: =SUMIFS(Journals!$K$9:$K$1007564,Journals!$D$9:$D$1007564,"<"&$F$7,Journals!$J$9:$J$1007564,"trustee fee")-SUMIFS(Journals!$L$9:$L$1007564,Journals!$D$9:$D$1007564,"<"&$F$7,Journals!$J$9:$J$1007564,"trustee fee") -> 361206.69
G41: Advanced BSEC Annual Fee | H41: =MAX(0,SUMIFS(Journals!$K$9:$K$1007494,Journals!$D$9:$D$1007494,">"&$E$7,Journals!$D$9:$D$1007494,"<"&$E$8,Journals!$J$9:$J$1007494,"Advanced BSEC Annual Fee")-SUMIFS(Journals!$L$9:$L$1007494,Journals!$D$9:$D$1007494,">"&$E$7,Journals!$D$9:$D$1007494,"<"&$E$8,Journals!$J$9:$J$1007494,"Advanced BSEC Annual Fee")) -> 138836.11 | I41: =MAX(0,SUMIFS(Journals!$L$9:$L$1007494,Journals!$D$9:$D$1007494,">"&$E$7,Journals!$D$9:$D$1007494,"<"&$E$8,Journals!$J$9:$J$1007494,"Advanced BSEC Annual Fee")-SUMIFS(Journals!$K$9:$K$1007494,Journals!$D$9:$D$1007494,">"&$E$7,Journals!$D$9:$D$1007494,"<"&$E$8,Journals!$J$9:$J$1007494,"Advanced BSEC Annual Fee")) -> 0 | J41: =SUMIFS(Journals!$K$9:$K$1007494,Journals!$D$9:$D$1007494,"<"&$F$7,Journals!$J$9:$J$1007494,"Advanced BSEC Annual Fee")-SUMIFS(Journals!$L$9:$L$1007494,Journals!$D$9:$D$1007494,"<"&$F$7,Journals!$J$9:$J$1007494,"Advanced BSEC Annual Fee") -> 0 | L41: =J41+H41-I41 -> 138836.11
...

Sheet TB-P
A1: Check of Trial Balance | G1: =SUM(H7:H103)-SUM(I7:I103) -> 1.5326144e+08
A2: Check of Balance Sheet | G2: =BS!C25-BS!C42 -> -0.0033406019
A3: Check of Cash Balance | G3: =BS!C23-CF!B43 -> 94994187
B5: Desired Reporting Period | H5: During the Reporting Period | J5: For Balance Sheet | N5: For Retained Earnings
B6: Year | C6: Month | D6: Day | E6: Value | F6: Value | G6: Accounts | H6: Debit | I6: Credit | J6: Carry Forward Balance | K6: Carry Forward Balance | L6: On date | M6: On date | N6: Debit | O6: Credit
A7: Beginning | B7: 2024 | C7: 7 | D7: 1 | E7: =DATE(B7,C7,D7)-1 -> 45473 | F7: =DATE(B7,C7,D7) -> 45474 | G7: ='Chart of Accounts'!B3 -> Investments in stock | H7: =MAX(0,SUMIFS(Journals!$K$9:$K$1007564,Journals!$D$9:$D$1007564,">"&$E$7,Journals!$D$9:$D$1007564,"<"&$E$8,Journals!$J$9:$J$1007564,"investments in stock")-SUMIFS(Journals!$L$9:$L$1007564,Journals!$D$9:$D$1007564,">"&$E$7,Journals!$D$9:$D$1007564,"<"&$E$8,Journals!$J$9:$J$1007564,"investments in stock")) -> 0 | I7: =MAX(0,SUMIFS(Journals!$L$9:$L$1007564,Journals!$D$9:$D$1007564,">"&$E$7,Journals!$D$9:$D$1007564,"<"&$E$8,Journals!$J$9:$J$1007564,"Investments in stock")-SUMIFS(Journals!$K$9:$K$1007564,Journals!$D$9:$D$1007564,">"&$E$7,Journals!$D$9:$D$1007564,"<"&$E$8,Journals!$J$9:$J$1007564,"Investments in stock")) -> 0 | J7: =SUMIFS(Journals!$K$9:$K$1007564,Journals!$D$9:$D$1007564,"<"&$F$7,Journals!$J$9:$J$1007564,"investments in stock")-SUMIFS(Journals!$L$9:$L$1007564,Journals!$D$9:$D$1007564,"<"&$F$7,Journals!$J$9:$J$1007564,"investments in stock") -> 2797650.6 | L7: =J7+H7-I7 -> 2797650.6
A8: Ending | B8: 2025 | C8: 6 | D8: 30 | E8: =DATE(B8,C8,D8)+1 -> 45839 | F8: =DATE(B8,C8,D8) -> 45838 | G8: ='Chart of Accounts'!B4 -> Interest Receivables from Bank A/C | H8: =MAX(0,SUMIFS(Journals!$K$9:$K$1007564,Journals!$D$9:$D$1007564,">"&$E$7,Journals!$D$9:$D$1007564,"<"&$E$8,Journals!$J$9:$J$1007564,"Interest Receivables from Bank A/C")-SUMIFS(Journals!$L$9:$L$1007564,Journals!$D$9:$D$1007564,">"&$E$7,Journals!$D$9:$D$1007564,"<"&$E$8,Journals!$J$9:$J$1007564,"Interest Receivables from Bank A/C")) -> 369.04647 | I8: =MAX(0,SUMIFS(Journals!$L$9:$L$1007564,Journals!$D$9:$D$1007564,">"&$E$7,Journals!$D$9:$D$1007564,"<"&$E$8,Journals!$J$9:$J$1007564,"Interest Receivables from Bank A/C")-SUMIFS(Journals!$K$9:$K$1007564,Journals!$D$9:$D$1007564,">"&$E$7,Journals!$D$9:$D$1007564,"<"&$E$8,Journals!$J$9:$J$1007564,"Interest Receivables from Bank A/C")) -> 0 | J8: =SUMIFS(Journals!$K$9:$K$1007564,Journals!$D$9:$D$1007564,"<"&$F$7,Journals!$J$9:$J$1007564,"Interest Receivables from Bank A/C")-SUMIFS(Journals!$L$9:$L$1007564,Journals!$D$9:$D$1007564,"<"&$F$7,Journals!$J$9:$J$1007564,"Interest Receivables from Bank A/C") -> 2393.7615 | L8: =J8+H8-I8 -> 2762.8079
G9: Interest Receivables from Sukuk | H9: =MAX(0,SUMIFS(Journals!$K$9:$K$1007564,Journals!$D$9:$D$1007564,">"&$E$7,Journals!$D$9:$D$1007564,"<"&$E$8,Journals!$J$9:$J$1007564,"Interest Receivables from Sukuk")-SUMIFS(Journals!$L$9:$L$1007564,Journals!$D$9:$D$1007564,">"&$E$7,Journals!$D$9:$D$1007564,"<"&$E$8,Journals!$J$9:$J$1007564,"Interest Receivables from Sukuk")) -> 0 | I9: =MAX(0,SUMIFS(Journals!$L$9:$L$1007564,Journals!$D$9:$D$1007564,">"&$E$7,Journals!$D$9:$D$1007564,"<"&$E$8,Journals!$J$9:$J$1007564,"Interest Receivables from Sukuk")-SUMIFS(Journals!$K$9:$K$1007564,Journals!$D$9:$D$1007564,">"&$E$7,Journals!$D$9:$D$1007564,"<"&$E$8,Journals!$J$9:$J$1007564,"Interest Receivables from Sukuk")) -> 205490.74 | J9: =SUMIFS(Journals!$K$9:$K$1007564,Journals!$D$9:$D$1007564,"<"&$F$7,Journals!$J$9:$J$1007564,"Interest Receivables from Sukuk")-SUMIFS(Journals!$L$9:$L$1007564,Journals!$D$9:$D$1007564,"<"&$F$7,Journals!$J$9:$J$1007564,"Interest Receivables from Sukuk") -> 205490.74 | L9: =J9+H9-I9 -> 0
G10: Interest Receivables from Bond | H10: =MAX(0,SUMIFS(Journals!$K$9:$K$1007564,Journals!$D$9:$D$1007564,">"&$E$7,Journals!$D$9:$D$1007564,"<"&$E$8,Journals!$J$9:$J$1007564,"Interest Receivables from Bond")-SUMIFS(Journals!$L$9:$L$1007564,Journals!$D$9:$D$1007564,">"&$E$7,Journals!$D$9:$D$1007564,"<"&$E$8,Journals!$J$9:$J$1007564,"Interest Receivables from Bond")) -> 0 | I10: =MAX(0,SUMIFS(Journals!$L$9:$L$1007564,Journals!$D$9:$D$1007564,">"&$E$7,Journals!$D$9:$D$1007564,"<"&$E$8,Journals!$J$9:$J$1007564,"Interest Receivables from Bond")-SUMIFS(Journals!$K$9:$K$1007564,Journals!$D$9:$D$1007564,">"&$E$7,Journals!$D$9:$D$1007564,"<"&$E$8,Journals!$J$9:$J$1007564,"Interest Receivables from Bond")) -> 208338.76 | J10: =SUMIFS(Journals!$K$9:$K$1007564,Journals!$D$9:$D$1007564,"<"&$F$7,Journals!$J$9:$J$1007564,"Interest Receivables from Bond")-SUMIFS(Journals!$L$9:$L$1007564,Journals!$D$9:$D$1007564,"<"&$F$7,Journals!$J$9:$J$1007564,"Interest Receivables from Bond") -> 267553.13 | L10: =J10+H10-I10 -> 59214.369
G11: ='Chart of Accounts'!B5 -> Preliminary & issue expenses | H11: =MAX(0,SUMIFS(Journals!$K$9:$K$1007564,Journals!$D$9:$D$1007564,">"&$E$7,Journals!$D$9:$D$1007564,"<"&$E$8,Journals!$J$9:$J$1007564,"Preliminary & issue expenses")-SUMIFS(Journals!$L$9:$L$1007564,Journals!$D$9:$D$1007564,">"&$E$7,Journals!$D$9:$D$1007564,"<"&$E$8,Journals!$J$9:$J$1007564,"Preliminary & issue expenses")) -> 0 | I11: =MAX(0,SUMIFS(Journals!$L$9:$L$1007564,Journals!$D$9:$D$1007564,">"&$E$7,Journals!$D$9:$D$1007564,"<"&$E$8,Journals!$J$9:$J$1007564,"Preliminary & issue expenses")-SUMIFS(Journals!$K$9:$K$1007564,Journals!$D$9:$D$1007564,">"&$E$7,Journals!$D$9:$D$1007564,"<"&$E$8,Journals!$J$9:$J$1007564,"Preliminary & issue expenses")) -> 184261.73 | J11: =SUMIFS(Journals!$K$9:$K$1007564,Journals!$D$9:$D$1007564,"<"&$F$7,Journals!$J$9:$J$1007564,"Preliminary & issue expenses")-SUMIFS(Journals!$L$9:$L$1007564,Journals!$D$9:$D$1007564,"<"&$F$7,Journals!$J$9:$J$1007564,"Preliminary & issue expenses") -> 743991.09 | L11: =J11+H11-I11 -> 559729.36
G12: ='Chart of Accounts'!B6 -> Accrued Management Fee | H12: =SUMIFS(Journals!$K$9:$K$1006910,Journals!$D$9:$D$1006910,">"&$E$7,Journals!$D$9:$D$1006910,"<"&$E$8,Journals!$J$9:$J$1006910,"Accrued Management Fee") -> 2674281.6 | I12: =MAX(0,SUMIFS(Journals!$L$9:$L$1006910,Journals!$D$9:$D$1006910,">"&$E$7,Journals!$D$9:$D$1006910,"<"&$E$8,Journals!$J$9:$J$1006910,"Accrued Management Fee")) -> 2325669.4 | K12: =SUMIFS(Journals!$L$9:$L$1007564,Journals!$D$9:$D$1007564,"<"&$F$7,Journals!$J$9:$J$1007564,"Accrued Management Fee")-SUMIFS(Journals!$K$9:$K$1007564,Journals!$D$9:$D$1007564,"<"&$F$7,Journals!$J$9:$J$1007564,"Accrued Management Fee") -> 585053.54 | M12: =K12+I12-H12 -> 236441.3
G13: ='Chart of Accounts'!B7 -> Accrued Trustee Fee | H13: =MAX(0,SUMIFS(Journals!$K$9:$K$1007564,Journals!$D$9:$D$1007564,">"&$E$7,Journals!$D$9:$D$1007564,"<"&$E$8,Journals!$J$9:$J$1007564,"accrued trustee fee")-SUMIFS(Journals!$L$9:$L$1007564,Journals!$D$9:$D$1007564,">"&$E$7,Journals!$D$9:$D$1007564,"<"&$E$8,Journals!$J$9:$J$1007564,"accrued trustee fee")) -> 207.91499 | I13: =MAX(0,SUMIFS(Journals!$L$9:$L$1007564,Journals!$D$9:$D$1007564,">"&$E$7,Journals!$D$9:$D$1007564,"<"&$E$8,Journals!$J$9:$J$1007564,"accrued trustee fee")-SUMIFS(Journals!$K$9:$K$1007564,Journals!$D$9:$D$1007564,">"&$E$7,Journals!$D$9:$D$1007564,"<"&$E$8,Journals!$J$9:$J$1007564,"accrued trustee fee")) -> 0 | K13: =SUMIFS(Journals!$L$9:$L$1007564,Journals!$D$9:$D$1007564,"<"&$F$7,Journals!$J$9:$J$1007564,"Accrued Trustee Fee")-SUMIFS(Journals!$K$9:$K$1007564,Journals!$D$9:$D$1007564,"<"&$F$7,Journals!$J$9:$J$1007564,"Accrued Trustee Fee") -> 66024.419 | M13: =K13+I13-H13 -> 65816.504
G14: ='Chart of Accounts'!B8 -> Accrued Custodian Fee | H14: =MAX(0,SUMIFS(Journals!$K$9:$K$1007564,Journals!$D$9:$D$1007564,">"&$E$7,Journals!$D$9:$D$1007564,"<"&$E$8,Journals!$J$9:$J$1007564,"accrued custodian fee")-SUMIFS(Journals!$L$9:$L$1007564,Journals!$D$9:$D$1007564,">"&$E$7,Journals!$D$9:$D$1007564,"<"&$E$8,Journals!$J$9:$J$1007564,"accrued custodian fee")) -> 0 | I14: =MAX(0,SUMIFS(Journals!$L$9:$L$1007564,Journals!$D$9:$D$1007564,">"&$E$7,Journals!$D$9:$D$1007564,"<"&$E$8,Journals!$J$9:$J$1007564,"accrued custodian fee")-SUMIFS(Journals!$K$9:$K$1007564,Journals!$D$9:$D$1007564,">"&$E$7,Journals!$D$9:$D$1007564,"<"&$E$8,Journals!$J$9:$J$1007564,"accrued custodian fee")) -> 123123.68 | K14: =SUMIFS(Journals!$L$9:$L$1007564,Journals!$D$9:$D$1007564,"<"&$F$7,Journals!$J$9:$J$1007564,"Accrued Custodian Fee")-SUMIFS(Journals!$K$9:$K$1007564,Journals!$D$9:$D$1007564,"<"&$F$7,Journals!$J$9:$J$1007564,"Accrued Custodian Fee") -> 0 | M14: =K14+I14-H14 -> 123123.68
G15: ='Chart of Accounts'!B9 -> Accrued BSEC fee | H15: =MAX(0,SUMIFS(Journals!$K$9:$K$1007564,Journals!$D$9:$D$1007564,">"&$E$7,Journals!$D$9:$D$1007564,"<"&$E$8,Journals!$J$9:$J$1007564,"accrued bsec fee")-SUMIFS(Journals!$L$9:$L$1007564,Journals!$D$9:$D$1007564,">"&$E$7,Journals!$D$9:$D$1007564,"<"&$E$8,Journals!$J$9:$J$1007564,"accrued bsec fee")) -> 0 | I15: =MAX(0,SUMIFS(Journals!$L$9:$L$1007564,Journals!$D$9:$D$1007564,">"&$E$7,Journals!$D$9:$D$1007564,"<"&$E$8,Journals!$J$9:$J$1007564,"accrued bsec fee")-SUMIFS(Journals!$K$9:$K$1007564,Journals!$D$9:$D$1007564,">"&$E$7,Journals!$D$9:$D$1007564,"<"&$E$8,Journals!$J$9:$J$1007564,"accrued bsec fee")) -> 0 | K15: =SUMIFS(Journals!$L$9:$L$1007564,Journals!$D$9:$D$1007564,"<"&$F$7,Journals!$J$9:$J$1007564,"accrued bsec fee")-SUMIFS(Journals!$K$9:$K$1007564,Journals!$D$9:$D$1007564,"<"&$F$7,Journals!$J$9:$J$1007564,"accrued bsec fee") -> 0 | M15: =K15+I15-H15 -> 0
G16: ='Chart of Accounts'!B10 -> Accrued Audit Fee | H16: =MAX(0,SUMIFS(Journals!$K$9:$K$1006983,Journals!$D$9:$D$1006983,">"&$E$7,Journals!$D$9:$D$1006983,"<"&$E$8,Journals!$J$9:$J$1006983,"accrued audit fee")) -> 34500 | I16: =MAX(0,SUMIFS(Journals!$L$9:$L$1006983,Journals!$D$9:$D$1006983,">"&$E$7,Journals!$D$9:$D$1006983,"<"&$E$8,Journals!$J$9:$J$1006983,"accrued audit fee")) -> 40250 | K16: =SUMIFS(Journals!$L$9:$L$1007564,Journals!$D$9:$D$1007564,"<"&$F$7,Journals!$J$9:$J$1007564,"accrued audit fee")-SUMIFS(Journals!$K$9:$K$1007564,Journals!$D$9:$D$1007564,"<"&$F$7,Journals!$J$9:$J$1007564,"accrued audit fee") -> 34500 | M16: =K16+I16-H16 -> 40250
G17: ='Chart of Accounts'!B11 -> Accrued CDBL Fee | H17: =MAX(0,SUMIFS(Journals!$K$9:$K$1007564,Journals!$D$9:$D$1007564,">"&$E$7,Journals!$D$9:$D$1007564,"<"&$E$8,Journals!$J$9:$J$1007564,"accrued CDBL fee")-SUMIFS(Journals!$L$9:$L$1007564,Journals!$D$9:$D$1007564,">"&$E$7,Journals!$D$9:$D$1007564,"<"&$E$8,Journals!$J$9:$J$1007564,"accrued CDBL fee")) -> 0 | I17: =MAX(0,SUMIFS(Journals!$L$9:$L$1007564,Journals!$D$9:$D$1007564,">"&$E$7,Journals!$D$9:$D$1007564,"<"&$E$8,Journals!$J$9:$J$1007564,"accrued CDBL fee")-SUMIFS(Journals!$K$9:$K$1007564,Journals!$D$9:$D$1007564,">"&$E$7,Journals!$D$9:$D$1007564,"<"&$E$8,Journals!$J$9:$J$1007564,"accrued CDBL fee")) -> 0 | K17: =SUMIFS(Journals!$L$9:$L$1007564,Journals!$D$9:$D$1007564,"<"&$F$7,Journals!$J$9:$J$1007564,"accrued cdbl fee")-SUMIFS(Journals!$K$9:$K$1007564,Journals!$D$9:$D$1007564,"<"&$F$7,Journals!$J$9:$J$1007564,"accrued cdbl fee") -> 0 | M17: =K17+I17-H17 -> 0
G18: ='Chart of Accounts'!B12 -> Fixed Deposit Receipts (FDR) | H18: =MAX(0,SUMIFS(Journals!$K$9:$K$1007564,Journals!$D$9:$D$1007564,">"&$E$7,Journals!$D$9:$D$1007564,"<"&$E$8,Journals!$J$9:$J$1007564,"Fixed Deposit Receipts (FDR)")-SUMIFS(Journals!$L$9:$L$1007564,Journals!$D$9:$D$1007564,">"&$E$7,Journals!$D$9:$D$1007564,"<"&$E$8,Journals!$J$9:$J$1007564,"Fixed Deposit Receipts (FDR)")) -> 0 | I18: =MAX(0,SUMIFS(Journals!$L$9:$L$1007564,Journals!$D$9:$D$1007564,">"&$E$7,Journals!$D$9:$D$1007564,"<"&$E$8,Journals!$J$9:$J$1007564,"Fixed Deposit Receipts (FDR)")-SUMIFS(Journals!$K$9:$K$1007564,Journals!$D$9:$D$1007564,">"&$E$7,Journals!$D$9:$D$1007564,"<"&$E$8,Journals!$J$9:$J$1007564,"Fixed Deposit Receipts (FDR)")) -> 5000000 | J18: =SUMIFS(Journals!$K$9:$K$1007564,Journals!$D$9:$D$1007564,"<"&$F$7,Journals!$J$9:$J$1007564,"Fixed Deposit Receipts (FDR)")-SUMIFS(Journals!$L$9:$L$1007564,Journals!$D$9:$D$1007564,"<"&$F$7,Journals!$J$9:$J$1007564,"Fixed Deposit Receipts (FDR)") -> 90000000 | L18: =J18+H18-I18 -> 85000000
