Workbook
Name CURRENT_NAV: BS!$C$44
Name NAV: [1]BS!$C$43
Name NAV: BS!$C$42
Name NAV_MKT: Journals!$T$1
Name TCV_STOCKS: #REF!
Name TCV_STOCKS: #REF!
Name TMV_STOCKS: #REF!
Name TMV_STOCKS: #REF!

Sheet Chart of Accounts
B2: Accounts Name | C2: Normal Balance | E2: Stock List
B3: Investments in stock | C3: DEBIT | E3: =#REF! -> #REF!
B4: Interest Receivables from Bank A/C | C4: DEBIT | E4: =#REF! -> #REF!
B5: Preliminary & issue expenses | C5: DEBIT | E5: =#REF! -> #REF!
B6: Accrued Management Fee | C6: CREDIT | E6: =#REF! -> #REF!
B7: Accrued Trustee Fee | C7: CREDIT | E7: =#REF! -> #REF!
B8: Accrued Custodian Fee | C8: CREDIT | E8: =#REF! -> #REF!
B9: Accrued BSEC fee | C9: CREDIT | E9: =#REF! -> #REF!
B10: Accrued Audit Fee | C10: CREDIT | E10: =#REF! -> #REF!
B11: Accrued CDBL Fee | C11: CREDIT | E11: =#REF! -> #REF!
B12: Fixed Deposit Receipts (FDR) | C12: DEBIT | E12: =#REF! -> #REF!
B13: Cash and cash equivalents | C13: DEBIT | E13: =#REF! -> #REF!
B14: Unit Capital | C14: CREDIT | E14: =#REF! -> #REF!
... B16: Interest income | C16: CREDIT | E16: =#REF! -> #REF!
B17: Interest income from FDR | C17: CREDIT
B18: Interest income from Renata Pref. Share | C18: CREDIT
B19: Interest income from Bank Acc. | C19: CREDIT
B20: Interest income from T-Bill | C20: CREDIT
B21: Interest income from T-Bond | C21: CREDIT
B22: Bank charges and excise duties | C22: DEBIT | E22: =#REF! -> #REF!
B23: Brokerage commission | C23: DEBIT | E23: =#REF! -> #REF!
B24: Unrealized gain on securities | C24: CREDIT | E24: =#REF! -> #REF!
B25: Unrealized gain on T-Bill
B26: Unrealized gain on T-Bond
B27: Unrealized loss on securities | C27: DEBIT | E27: =#REF! -> #REF!
B28: Amortization of preliminary and issue expense | C28: DEBIT | E28: =#REF! -> #REF!
B29: Management Fee | C29: DEBIT | E29: =#REF! -> #REF!
B30: Trustee fee | C30: DEBIT | E30: =#REF! -> #REF!
B31: BSEC Annual Fee | C31: DEBIT | E31: =#REF! -> #REF!
B32: Audit fee | C32: DEBIT | E32: =#REF! -> #REF!
B33: CDBL charges | C33: DEBIT | E33: =#REF! -> #REF!
B34: Fair value adjustment | C34: DEBIT | E34: =#REF! -> #REF!
B35: Fair value adjustment T-Bill | C35: DEBIT
B36: Fair value adjustment T-Bond | C36: DEBIT
B37: Interest receivables from FDR | C37: DEBIT | E37: =#REF! -> #REF!
B38: Interest receivables from Renata Pref. Share | C38: DEBIT
B39: Interest receivables from Bank Acc. | C39: DEBIT
B40: Payable to broker | C40: CREDIT | E40: =#REF! -> #REF!
B41: Other operating expenses | C41: DEBIT | E41: =#REF! -> #REF!
B42: Dividend income | C42: CREDIT | E42: =#REF! -> #REF!
...

Sheet INVESTOR_LIST
A1: INVESTOR NAME | B1: INVESTOR CODE
A2: HARI PADA SAHA | B2: A00002
A3: EKUSH WEALTH MANAGEMENT LIMITED | B3: A00003
A4: SADIA AHMED | B4: A00004
A5: MORSHEDA MIM | B5: A00005
A6: MD. JAHANGIR ALAM | B6: A00006
A7: BISWAS ARIFUR RAHMAN | B7: A00007
A8: JEWEL SAHA | B8: A00008
A9: SHIBBIR AHMED | B9: A00009
A10: SHYAMAL KRISHNA SAHA | B10: A00010
A11: NASRIN AKHTER | B11: A00011
A12: MRINMOY GHOSH | B12: A00012
... A493: SIKDER FAZLE RABBI | B493: A00493

Sheet Journals
A2: Check of Journal Entries | L2: =K6-L6 -> -0.00157547
A3: Check of Trial Balance | L3: =SUM('TB-C'!H7:H5014)-SUM('TB-C'!I7:I5014) -> 0.0028882474
A4: Check of Balance Seet | L4: =BS!C25-BS!C40 -> 0
A5: Check of Cash Balance | G5: =BS!C23-CF!B44 -> -2739690.1
J6: =ROUND(L6-K6,0) -> 0 | K6: =SUBTOTAL(9,K9:K22408) -> 6.7264836e+09 | L6: =SUBTOTAL(9,L9:L22408) -> 6.7264836e+09
A7: Year | B7: Month | C7: Day | D7: Value | F7: Transaction | G7: Transaction Type | J7: Account Name | K7: Debit | L7: Credit | N7: Ref. Acc.
E8: Date
A9: 2019 | B9: 11 | C9: 26 | D9: =DATE(A9,B9,C9) -> 43795 | E9: =DATE(A9,B9,C9) -> 43795 | F9: Unit Subscription - LUMPSUM | G9: C | H9: {=IFERROR(INDEX(INVESTOR_LIST[INVESTOR NAME],MATCH(I9,INVESTOR_LIST[INVESTOR CODE],0),)," ")} -> HARI PADA SAHA | I9: A00002 | J9: Cash and cash equivalents | K9: 500000 | Q9: A00002
A10: 2019 | B10: 11 | C10: 26 | D10: =DATE(A10,B10,C10) -> 43795 | E10: =DATE(A10,B10,C10) -> 43795 | G10: C | H10: {=IFERROR(INDEX(INVESTOR_LIST[INVESTOR NAME],MATCH(I10,INVESTOR_LIST[INVESTOR CODE],0),)," ")} -> HARI PADA SAHA | I10: A00002 | J10: Unit Capital | L10: 500000 | M10: 0 | O10: =SUMIF(J9:L3763,"UNIT PREMIUM RESERVE",L9:L3763) -> 39052552 | Q10: A00002
A11: 2019 | B11: 11 | C11: 26 | D11: =DATE(A11,B11,C11) -> 43795 | E11: =DATE(A11,B11,C11) -> 43795 | F11: Unit Subscription - LUMPSUM | G11: C | H11: {=IFERROR(INDEX(INVESTOR_LIST[INVESTOR NAME],MATCH(I11,INVESTOR_LIST[INVESTOR CODE],0),)," ")} -> EKUSH WEALTH MANAGEMENT LIMITED | I11: A00003 | J11: Cash and cash equivalents | K11: 10000000 | M11: 0 | Q11: A00003
A12: 2019 | B12: 11 | C12: 26 | D12: =DATE(A12,B12,C12) -> 43795 | E12: =DATE(A12,B12,C12) -> 43795 | G12: C | H12: {=IFERROR(INDEX(INVESTOR_LIST[INVESTOR NAME],MATCH(I12,INVESTOR_LIST[INVESTOR CODE],0),)," ")} -> EKUSH WEALTH MANAGEMENT LIMITED | I12: A00003 | J12: Unit Capital | L12: 10000000 | M12: 0 | Q12: A00003
A13: 2019 | B13: 11 | C13: 26 | D13: =DATE(A13,B13,C13) -> 43795 | E13: =DATE(A13,B13,C13) -> 43795 | F13: Bank charge has been charged | G13: C | H13: {=IFERROR(INDEX(INVESTOR_LIST[INVESTOR NAME],MATCH(I13,INVESTOR_LIST[INVESTOR CODE],0),)," ")} | J13: Bank charges and excise duties | K13: 60 | M13: 26
A14: 2019 | B14: 11 | C14: 26 | D14: =DATE(A14,B14,C14) -> 43795 | E14: =DATE(A14,B14,C14) -> 43795 | G14: C | H14: {=IFERROR(INDEX(INVESTOR_LIST[INVESTOR NAME],MATCH(I14,INVESTOR_LIST[INVESTOR CODE],0),)," ")} | J14: Cash and cash equivalents | L14: 60 | M14: 0
A15: 2019 | B15: 12 | C15: 22 | D15: =DATE(A15,B15,C15) -> 43821 | E15: =DATE(A15,B15,C15) -> 43821 | F15: Unit Subscription - LUMPSUM | G15: C | H15: {=IFERROR(INDEX(INVESTOR_LIST[INVESTOR NAME],MATCH(I15,INVESTOR_LIST[INVESTOR CODE],0),)," ")} -> SADIA AHMED | I15: A00004 | J15: Cash and cash equivalents | K15: 700000 | M15: 8 | Q15: A00004
A16: 2019 | B16: 12 | C16: 22 | D16: =DATE(A16,B16,C16) -> 43821 | E16: =DATE(A16,B16,C16) -> 43821 | G16: C | H16: {=IFERROR(INDEX(INVESTOR_LIST[INVESTOR NAME],MATCH(I16,INVESTOR_LIST[INVESTOR CODE],0),)," ")} -> SADIA AHMED | I16: A00004 | J16: Unit Capital | L16: 700000 | M16: 0 | Q16: A00004
A17: 2019 | B17: 12 | C17: 22 | D17: =DATE(A17,B17,C17) -> 43821 | E17: =DATE(A17,B17,C17) -> 43821 | F17: Bank charge has been charged | G17: C | H17: {=IFERROR(INDEX(INVESTOR_LIST[INVESTOR NAME],MATCH(I17,INVESTOR_LIST[INVESTOR CODE],0),)," ")} | J17: Bank charges and excise duties | K17: 25 | M17: 0
A18: 2019 | B18: 12 | C18: 22 | D18: =DATE(A18,B18,C18) -> 43821 | E18: =DATE(A18,B18,C18) -> 43821 | G18: C | H18: {=IFERROR(INDEX(INVESTOR_LIST[INVESTOR NAME],MATCH(I18,INVESTOR_LIST[INVESTOR CODE],0),)," ")} | J18: Cash and cash equivalents | L18: 25 | M18: 0
A19: 2019 | B19: 12 | C19: 30 | D19: =DATE(A19,B19,C19) -> 43829 | E19: =DATE(A19,B19,C19) -> 43829 | F19: Interest Credited in the Bank Account-1090000732 | G19: C | H19: {=IFERROR(INDEX(INVESTOR_LIST[INVESTOR NAME],MATCH(I19,INVESTOR_LIST[INVESTOR CODE],0),)," ")} | J19: Cash and cash equivalents | K19: 66136
A20: 2019 | B20: 12 | C20: 30 | D20: =DATE(A20,B20,C20) -> 43829 | E20: =DATE(A20,B20,C20) -> 43829 | G20: C | H20: {=IFERROR(INDEX(INVESTOR_LIST[INVESTOR NAME],MATCH(I20,INVESTOR_LIST[INVESTOR CODE],0),)," ")} | J20: Interest income | L20: 66136 | M20: 0
A21: 2019 | B21: 12 | C21: 30 | D21: =DATE(A21,B21,C21) -> 43829 | E21: =DATE(A21,B21,C21) -> 43829 | F21: Unit Subscription - LUMPSUM | G21: C | H21: {=IFERROR(INDEX(INVESTOR_LIST[INVESTOR NAME],MATCH(I21,INVESTOR_LIST[INVESTOR CODE],0),)," ")} -> MORSHEDA MIM | I21: A00005 | J21: Cash and cash equivalents | K21: 50000 | M21: 1 | Q21: A00005
A22: 2019 | B22: 12 | C22: 30 | D22: =DATE(A22,B22,C22) -> 43829 | E22: =DATE(A22,B22,C22) -> 43829 | G22: C | H22: {=IFERROR(INDEX(INVESTOR_LIST[INVESTOR NAME],MATCH(I22,INVESTOR_LIST[INVESTOR CODE],0),)," ")} -> MORSHEDA MIM | I22: A00005 | J22: Unit Capital | L22: 50000 | M22: 0 | Q22: A00005
A23: 2019 | B23: 12 | C23: 30 | D23: =DATE(A23,B23,C23) -> 43829 | E23: =DATE(A23,B23,C23) -> 43829 | F23: Bank charge has been charged | G23: C | H23: {=IFERROR(INDEX(INVESTOR_LIST[INVESTOR NAME],MATCH(I23,INVESTOR_LIST[INVESTOR CODE],0),)," ")} | J23: Bank charges and excise duties | K23: 9920 | M23: 2
A24: 2019 | B24: 12 | C24: 30 | D24: =DATE(A24,B24,C24) -> 43829 | E24: =DATE(A24,B24,C24) -> 43829 | G24: C | H24: {=IFERROR(INDEX(INVESTOR_LIST[INVESTOR NAME],MATCH(I24,INVESTOR_LIST[INVESTOR CODE],0),)," ")} | J24: Cash and cash equivalents | L24: 9920 | M24: 0
A25: 2019 | B25: 12 | C25: 30 | D25: =DATE(A25,B25,C25) -> 43829 | E25: =DATE(A25,B25,C25) -> 43829 | F25: Bank charge has been charged | G25: C | H25: {=IFERROR(INDEX(INVESTOR_LIST[INVESTOR NAME],MATCH(I25,INVESTOR_LIST[INVESTOR CODE],0),)," ")} | J25: Bank charges and excise duties | K25: 575 | M25: 5
A26: 2019 | B26: 12 | C26: 30 | D26: =DATE(A26,B26,C26) -> 43829 | E26: =DATE(A26,B26,C26) -> 43829 | G26: C | H26: {=IFERROR(INDEX(INVESTOR_LIST[INVESTOR NAME],MATCH(I26,INVESTOR_LIST[INVESTOR CODE],0),)," ")} | J26: Cash and cash equivalents | L26: 575 | M26: 0
A27: 2019 | B27: 12 | C27: 30 | D27: =DATE(A27,B27,C27) -> 43829 | E27: =DATE(A27,B27,C27) -> 43829 | F27: Bank charge has been charged | G27: C | H27: {=IFERROR(INDEX(INVESTOR_LIST[INVESTOR NAME],MATCH(I27,INVESTOR_LIST[INVESTOR CODE],0),)," ")} | J27: Bank charges and excise duties | K27: 12000 | M27: 0
A28: 2019 | B28: 12 | C28: 30 | D28: =DATE(A28,B28,C28) -> 43829 | E28: =DATE(A28,B28,C28) -> 43829 | G28: C | H28: {=IFERROR(INDEX(INVESTOR_LIST[INVESTOR NAME],MATCH(I28,INVESTOR_LIST[INVESTOR CODE],0),)," ")} | J28: Cash and cash equivalents | L28: 12000 | M28: 0
A29: 2019 | B29: 12 | C29: 31 | D29: =DATE(A29,B29,C29) -> 43830 | E29: =DATE(A29,B29,C29) -> 43830 | F29: Audit fee expense has been occurred | G29: NC | H29: {=IFERROR(INDEX(INVESTOR_LIST[INVESTOR NAME],MATCH(I29,INVESTOR_LIST[INVESTOR CODE],0),)," ")} | J29: Audit fee | K29: 10000
A30: 2019 | B30: 12 | C30: 31 | D30: =DATE(A30,B30,C30) -> 43830 | E30: =DATE(A30,B30,C30) -> 43830 | G30: NC | H30: {=IFERROR(INDEX(INVESTOR_LIST[INVESTOR NAME],MATCH(I30,INVESTOR_LIST[INVESTOR CODE],0),)," ")} | J30: Accrued Audit Fee | L30: 10000
A31: 2020 | B31: 1 | C31: 12 | D31: =DATE(A31,B31,C31) -> 43842 | E31: =DATE(A31,B31,C31) -> 43842 | F31: Unit Subscription - LUMPSUM | G31: C | H31: {=IFERROR(INDEX(INVESTOR_LIST[INVESTOR NAME],MATCH(I31,INVESTOR_LIST[INVESTOR CODE],0),)," ")} -> MD. JAHANGIR ALAM | I31: A00006 | J31: Cash and cash equivalents | K31: 50000 | M31: 2 | Q31: A00006
A32: 2020 | B32: 1 | C32: 12 | D32: =DATE(A32,B32,C32) -> 43842 | E32: =DATE(A32,B32,C32) -> 43842 | G32: C | H32: {=IFERROR(INDEX(INVESTOR_LIST[INVESTOR NAME],MATCH(I32,INVESTOR_LIST[INVESTOR CODE],0),)," ")} -> MD. JAHANGIR ALAM | I32: A00006 | J32: Unit Capital | L32: =K31 -> 50000 | M32: 0 | Q32: A00006
A33: 2020 | B33: 1 | C33: 12 | D33: =DATE(A33,B33,C33) -> 43842 | E33: =DATE(A33,B33,C33) -> 43842 | F33: Bank charge has been charged | G33: C | H33: {=IFERROR(INDEX(INVESTOR_LIST[INVESTOR NAME],MATCH(I33,INVESTOR_LIST[INVESTOR CODE],0),)," ")} | J33: Bank charges and excise duties | K33: 10 | M33: 1
A34: 2020 | B34: 1 | C34: 12 | D34: =DATE(A34,B34,C34) -> 43842 | E34: =DATE(A34,B34,C34) -> 43842 | G34: C | H34: {=IFERROR(INDEX(INVESTOR_LIST[INVESTOR NAME],MATCH(I34,INVESTOR_LIST[INVESTOR CODE],0),)," ")} | J34: Cash and cash equivalents | L34: 10 | M34: 0
A35: 2020 | B35: 1 | C35: 13 | D35: =DATE(A35,B35,C35) -> 43843 | E35: =DATE(A35,B35,C35) -> 43843 | F35: Unit Subscription - LUMPSUM | G35: C | H35: {=IFERROR(INDEX(INVESTOR_LIST[INVESTOR NAME],MATCH(I35,INVESTOR_LIST[INVESTOR CODE],0),)," ")} -> BISWAS ARIFUR RAHMAN | I35: A00007 | J35: Cash and cash equivalents | K35: 10000 | M35: 3 | Q35: A00007
A36: 2020 | B36: 1 | C36: 13 | D36: =DATE(A36,B36,C36) -> 43843 | E36: =DATE(A36,B36,C36) -> 43843 | G36: C | H36: {=IFERROR(INDEX(INVESTOR_LIST[INVESTOR NAME],MATCH(I36,INVESTOR_LIST[INVESTOR CODE],0),)," ")} -> BISWAS ARIFUR RAHMAN | I36: A00007 | J36: Unit Capital | L36: =K35 -> 10000 | M36: 0 | Q36: A00007
A37: 2020 | B37: 1 | C37: 15 | D37: =DATE(A37,B37,C37) -> 43845 | E37: =DATE(A37,B37,C37) -> 43845 | F37: Unit Subscription - LUMPSUM | G37: C | H37: {=IFERROR(INDEX(INVESTOR_LIST[INVESTOR NAME],MATCH(I37,INVESTOR_LIST[INVESTOR CODE],0),)," ")} -> JEWEL SAHA | I37: A00008 | J37: Cash and cash equivalents | K37: 5000 | M37: 2 | Q37: A00008
A38: 2020 | B38: 1 | C38: 15 | D38: =DATE(A38,B38,C38) -> 43845 | E38: =DATE(A38,B38,C38) -> 43845 | G38: C | H38: {=IFERROR(INDEX(INVESTOR_LIST[INVESTOR NAME],MATCH(I38,INVESTOR_LIST[INVESTOR CODE],0),)," ")} -> JEWEL SAHA | I38: A00008 | J38: Unit Capital | L38: =K37 -> 5000 | M38: 0 | Q38: A00008
A39: 2020 | B39: 1 | C39: 20 | D39: =DATE(A39,B39,C39) -> 43850 | E39: =DATE(A39,B39,C39) -> 43850 | F39: Bank charge has been charged | G39: C | H39: {=IFERROR(INDEX(INVESTOR_LIST[INVESTOR NAME],MATCH(I39,INVESTOR_LIST[INVESTOR CODE],0),)," ")} | J39: Bank charges and excise duties | K39: 10 | M39: 0
A40: 2020 | B40: 1 | C40: 20 | D40: =DATE(A40,B40,C40) -> 43850 | E40: =DATE(A40,B40,C40) -> 43850 | G40: C | H40: {=IFERROR(INDEX(INVESTOR_LIST[INVESTOR NAME],MATCH(I40,INVESTOR_LIST[INVESTOR CODE],0),)," ")} | J40: Cash and cash equivalents | L40: 10 | M40: 0
A41: 2020 | B41: 1 | C41: 20 | D41: =DATE(A41,B41,C41) -> 43850 | E41: =DATE(A41,B41,C41) -> 43850 | F41: Unit Subscription - LUMPSUM | G41: C | H41: {=IFERROR(INDEX(INVESTOR_LIST[INVESTOR NAME],MATCH(I41,INVESTOR_LIST[INVESTOR CODE],0),)," ")} -> SHIBBIR AHMED | I41: A00009 | J41: Cash and cash equivalents | K41: 100000 | M41: 6 | Q41: A00009
...

Sheet TB-C
A1: Check of Trial Balance | G1: =SUM(H7:H91)-SUM(I7:I91) -> 0.0028882474
A2: Check of Balance Sheet | G2: =BS!C25-BS!C40 -> 0
A3: Check of Cash Balance | G3: =BS!C23-CF!B44 -> -2739690.1
B5: Desired Reporting Period | H5: During the Reporting Period | J5: For Balance Sheet | N5: For Retained Earnings
B6: Year | C6: Month | D6: Day | E6: Value | F6: Value | G6: Accounts | H6: Debit | I6: Credit | J6: Carry Forward Balance | K6: Carry Forward Balance | L6: On date | M6: On date | N6: Debit | O6: Credit
A7: Beginning | B7: 2026 | C7: 1 | D7: 1 | E7: =DATE(B7,C7,D7)-1 -> 46022 | F7: =DATE(B7,C7,D7) -> 46023 | G7: ='Chart of Accounts'!B3 -> Investments in stock | H7: =MAX(0,SUMIFS(Journals!$K$9:$K$1011204,Journals!$D$9:$D$1011204,">"&$E$7,Journals!$D$9:$D$1011204,"<"&$E$8,Journals!$J$9:$J$1011204,"investments in stock")-SUMIFS(Journals!$L$9:$L$1011204,Journals!$D$9:$D$1011204,">"&$E$7,Journals!$D$9:$D$1011204,"<"&$E$8,Journals!$J$9:$J$1011204,"investments in stock")) -> 42662512 | I7: =MAX(0,SUMIFS(Journals!$L$9:$L$1011204,Journals!$D$9:$D$1011204,">"&$E$7,Journals!$D$9:$D$1011204,"<"&$E$8,Journals!$J$9:$J$1011204,"Investments in stock")-SUMIFS(Journals!$K$9:$K$1011204,Journals!$D$9:$D$1011204,">"&$E$7,Journals!$D$9:$D$1011204,"<"&$E$8,Journals!$J$9:$J$1011204,"Investments in stock")) -> 0 | J7: =SUMIFS(Journals!$K$9:$K$1011204,Journals!$D$9:$D$1011204,"<"&$F$7,Journals!$J$9:$J$1011204,"investments in stock")-SUMIFS(Journals!$L$9:$L$1011204,Journals!$D$9:$D$1011204,"<"&$F$7,Journals!$J$9:$J$1011204,"investments in stock") -> 2.0852119e+08 | L7: =J7+H7-I7 -> 2.511837e+08
A8: Ending | B8: 2026 | C8: 12 | D8: 31 | E8: =DATE(B8,C8,D8)+1 -> 46388 | F8: =DATE(B8,C8,D8) -> 46387 | G8: ='Chart of Accounts'!B4 -> Interest Receivables from Bank A/C | H8: =MAX(0,SUMIFS(Journals!$K$9:$K$1011204,Journals!$D$9:$D$1011204,">"&$E$7,Journals!$D$9:$D$1011204,"<"&$E$8,Journals!$J$9:$J$1011204,"Interest Receivables from Bank A/C")-SUMIFS(Journals!$L$9:$L$1011204,Journals!$D$9:$D$1011204,">"&$E$7,Journals!$D$9:$D$1011204,"<"&$E$8,Journals!$J$9:$J$1011204,"Interest Receivables from Bank A/C")) -> 113337.69 | I8: =MAX(0,SUMIFS(Journals!$L$9:$L$1011204,Journals!$D$9:$D$1011204,">"&$E$7,Journals!$D$9:$D$1011204,"<"&$E$8,Journals!$J$9:$J$1011204,"Interest Receivables from Bank A/C")-SUMIFS(Journals!$K$9:$K$1011204,Journals!$D$9:$D$1011204,">"&$E$7,Journals!$D$9:$D$1011204,"<"&$E$8,Journals!$J$9:$J$1011204,"Interest Receivables from Bank A/C")) -> 0 | J8: =SUMIFS(Journals!$K$9:$K$1011204,Journals!$D$9:$D$1011204,"<"&$F$7,Journals!$J$9:$J$1011204,"Interest Receivables from Bank A/C")-SUMIFS(Journals!$L$9:$L$1011204,Journals!$D$9:$D$1011204,"<"&$F$7,Journals!$J$9:$J$1011204,"Interest Receivables from Bank A/C") -> 7601.57 | L8: =J8+H8-I8 -> 120939.26 | P8: 463070.35 | Q8: =L8-P8 -> -342131.09
G9: ='Chart of Accounts'!B5 -> Preliminary & issue expenses | H9: =MAX(0,SUMIFS(Journals!$K$9:$K$1011204,Journals!$D$9:$D$1011204,">"&$E$7,Journals!$D$9:$D$1011204,"<"&$E$8,Journals!$J$9:$J$1011204,"Preliminary & issue expenses")-SUMIFS(Journals!$L$9:$L$1011204,Journals!$D$9:$D$1011204,">"&$E$7,Journals!$D$9:$D$1011204,"<"&$E$8,Journals!$J$9:$J$1011204,"Preliminary & issue expenses")) -> 0 | I9: =MAX(0,SUMIFS(Journals!$L$9:$L$1011204,Journals!$D$9:$D$1011204,">"&$E$7,Journals!$D$9:$D$1011204,"<"&$E$8,Journals!$J$9:$J$1011204,"Preliminary & issue expenses")-SUMIFS(Journals!$K$9:$K$1011204,Journals!$D$9:$D$1011204,">"&$E$7,Journals!$D$9:$D$1011204,"<"&$E$8,Journals!$J$9:$J$1011204,"Preliminary & issue expenses")) -> 32967.033 | J9: =SUMIFS(Journals!$K$9:$K$1011204,Journals!$D$9:$D$1011204,"<"&$F$7,Journals!$J$9:$J$1011204,"Preliminary & issue expenses")-SUMIFS(Journals!$L$9:$L$1011204,Journals!$D$9:$D$1011204,"<"&$F$7,Journals!$J$9:$J$1011204,"Preliminary & issue expenses") -> 173862.83 | L9: =J9+H9-I9 -> 140895.8
G10: ='Chart of Accounts'!B6 -> Accrued Management Fee | H10: =SUMIFS(Journals!$K$9:$K$1011204,Journals!$D$9:$D$1011204,">"&$E$7,Journals!$D$9:$D$1011204,"<"&$E$8,Journals!$J$9:$J$1011204,"Accrued Management Fee") -> 1766038.9 | I10: =MAX(0,SUMIFS(Journals!$L$9:$L$1011204,Journals!$D$9:$D$1011204,">"&$E$7,Journals!$D$9:$D$1011204,"<"&$E$8,Journals!$J$9:$J$1011204,"Accrued Management Fee")) -> 1199767.6 | K10: =SUMIFS(Journals!$L$9:$L$1011204,Journals!$D$9:$D$1011204,"<"&$F$7,Journals!$J$9:$J$1011204,"Accrued Management Fee")-SUMIFS(Journals!$K$9:$K$1011204,Journals!$D$9:$D$1011204,"<"&$F$7,Journals!$J$9:$J$1011204,"Accrued Management Fee") -> 2956354.5 | M10: =K10+I10-H10 -> 2390083.3
G11: ='Chart of Accounts'!B7 -> Accrued Trustee Fee | H11: =MAX(0,SUMIFS(Journals!$K$9:$K$1011204,Journals!$D$9:$D$1011204,">"&$E$7,Journals!$D$9:$D$1011204,"<"&$E$8,Journals!$J$9:$J$1011204,"accrued trustee fee")-SUMIFS(Journals!$L$9:$L$1011204,Journals!$D$9:$D$1011204,">"&$E$7,Journals!$D$9:$D$1011204,"<"&$E$8,Journals!$J$9:$J$1011204,"accrued trustee fee")) -> 0 | I11: =MAX(0,SUMIFS(Journals!$L$9:$L$1011204,Journals!$D$9:$D$1011204,">"&$E$7,Journals!$D$9:$D$1011204,"<"&$E$8,Journals!$J$9:$J$1011204,"accrued trustee fee")-SUMIFS(Journals!$K$9:$K$1011204,Journals!$D$9:$D$1011204,">"&$E$7,Journals!$D$9:$D$1011204,"<"&$E$8,Journals!$J$9:$J$1011204,"accrued trustee fee")) -> 98794.008 | K11: =SUMIFS(Journals!$L$9:$L$1011204,Journals!$D$9:$D$1011204,"<"&$F$7,Journals!$J$9:$J$1011204,"Accrued Trustee Fee")-SUMIFS(Journals!$K$9:$K$1011204,Journals!$D$9:$D$1011204,"<"&$F$7,Journals!$J$9:$J$1011204,"Accrued Trustee Fee") -> 106016.66 | M11: =K11+I11-H11 -> 204810.67
G12: ='Chart of Accounts'!B8 -> Accrued Custodian Fee | H12: =MAX(0,SUMIFS(Journals!$K$9:$K$1011204,Journals!$D$9:$D$1011204,">"&$E$7,Journals!$D$9:$D$1011204,"<"&$E$8,Journals!$J$9:$J$1011204,"accrued custodian fee")-SUMIFS(Journals!$L$9:$L$1011204,Journals!$D$9:$D$1011204,">"&$E$7,Journals!$D$9:$D$1011204,"<"&$E$8,Journals!$J$9:$J$1011204,"accrued custodian fee")) -> 0 | I12: =MAX(0,SUMIFS(Journals!$L$9:$L$1011204,Journals!$D$9:$D$1011204,">"&$E$7,Journals!$D$9:$D$1011204,"<"&$E$8,Journals!$J$9:$J$1011204,"accrued custodian fee")-SUMIFS(Journals!$K$9:$K$1011204,Journals!$D$9:$D$1011204,">"&$E$7,Journals!$D$9:$D$1011204,"<"&$E$8,Journals!$J$9:$J$1011204,"accrued custodian fee")) -> 0 | K12: =SUMIFS(Journals!$L$9:$L$1011204,Journals!$D$9:$D$1011204,"<"&$F$7,Journals!$J$9:$J$1011204,"Accrued Custodian Fee")-SUMIFS(Journals!$K$9:$K$1011204,Journals!$D$9:$D$1011204,"<"&$F$7,Journals!$J$9:$J$1011204,"Accrued Custodian Fee") -> 0 | M12: =K12+I12-H12 -> 0
G13: ='Chart of Accounts'!B9 -> Accrued BSEC fee | H13: =MAX(0,SUMIFS(Journals!$K$9:$K$1011204,Journals!$D$9:$D$1011204,">"&$E$7,Journals!$D$9:$D$1011204,"<"&$E$8,Journals!$J$9:$J$1011204,"accrued bsec fee")-SUMIFS(Journals!$L$9:$L$1011204,Journals!$D$9:$D$1011204,">"&$E$7,Journals!$D$9:$D$1011204,"<"&$E$8,Journals!$J$9:$J$1011204,"accrued bsec fee")) -> 0 | I13: =MAX(0,SUMIFS(Journals!$L$9:$L$1011204,Journals!$D$9:$D$1011204,">"&$E$7,Journals!$D$9:$D$1011204,"<"&$E$8,Journals!$J$9:$J$1011204,"accrued bsec fee")-SUMIFS(Journals!$K$9:$K$1011204,Journals!$D$9:$D$1011204,">"&$E$7,Journals!$D$9:$D$1011204,"<"&$E$8,Journals!$J$9:$J$1011204,"accrued bsec fee")) -> 0 | K13: =SUMIFS(Journals!$L$9:$L$1011204,Journals!$D$9:$D$1011204,"<"&$F$7,Journals!$J$9:$J$1011204,"accrued bsec fee")-SUMIFS(Journals!$K$9:$K$1011204,Journals!$D$9:$D$1011204,"<"&$F$7,Journals!$J$9:$J$1011204,"accrued bsec fee") -> 0 | M13: =K13+I13-H13 -> 0
G14: ='Chart of Accounts'!B10 -> Accrued Audit Fee | H14: =MAX(0,SUMIFS(Journals!$K$9:$K$1011204,Journals!$D$9:$D$1011204,">"&$E$7,Journals!$D$9:$D$1011204,"<"&$E$8,Journals!$J$9:$J$1011204,"accrued audit fee")) -> 46000 | I14: =MAX(0,SUMIFS(Journals!$L$9:$L$1011204,Journals!$D$9:$D$1011204,">"&$E$7,Journals!$D$9:$D$1011204,"<"&$E$8,Journals!$J$9:$J$1011204,"accrued audit fee")) -> 0 | K14: =SUMIFS(Journals!$L$9:$L$1011204,Journals!$D$9:$D$1011204,"<"&$F$7,Journals!$J$9:$J$1011204,"accrued audit fee")-SUMIFS(Journals!$K$9:$K$1011204,Journals!$D$9:$D$1011204,"<"&$F$7,Journals!$J$9:$J$1011204,"accrued audit fee") -> 45999.997 | M14: =K14+I14-H14 -> -0.0033333334
G15: ='Chart of Accounts'!B11 -> Accrued CDBL Fee | H15: =MAX(0,SUMIFS(Journals!$K$9:$K$1011204,Journals!$D$9:$D$1011204,">"&$E$7,Journals!$D$9:$D$1011204,"<"&$E$8,Journals!$J$9:$J$1011204,"accrued CDBL fee")-SUMIFS(Journals!$L$9:$L$1011204,Journals!$D$9:$D$1011204,">"&$E$7,Journals!$D$9:$D$1011204,"<"&$E$8,Journals!$J$9:$J$1011204,"accrued CDBL fee")) -> 0 | I15: =MAX(0,SUMIFS(Journals!$L$9:$L$1011204,Journals!$D$9:$D$1011204,">"&$E$7,Journals!$D$9:$D$1011204,"<"&$E$8,Journals!$J$9:$J$1011204,"accrued CDBL fee")-SUMIFS(Journals!$K$9:$K$1011204,Journals!$D$9:$D$1011204,">"&$E$7,Journals!$D$9:$D$1011204,"<"&$E$8,Journals!$J$9:$J$1011204,"accrued CDBL fee")) -> 0 | K15: =SUMIFS(Journals!$L$9:$L$1011204,Journals!$D$9:$D$1011204,"<"&$F$7,Journals!$J$9:$J$1011204,"accrued cdbl fee")-SUMIFS(Journals!$K$9:$K$1011204,Journals!$D$9:$D$1011204,"<"&$F$7,Journals!$J$9:$J$1011204,"accrued cdbl fee") -> 0 | M15: =K15+I15-H15 -> 0
G16: ='Chart of Accounts'!B12 -> Fixed Deposit Receipts (FDR) | H16: =MAX(0,SUMIFS(Journals!$K$9:$K$1011204,Journals!$D$9:$D$1011204,">"&$E$7,Journals!$D$9:$D$1011204,"<"&$E$8,Journals!$J$9:$J$1011204,"Fixed Deposit Receipts (FDR)")-SUMIFS(Journals!$L$9:$L$1011204,Journals!$D$9:$D$1011204,">"&$E$7,Journals!$D$9:$D$1011204,"<"&$E$8,Journals!$J$9:$J$1011204,"Fixed Deposit Receipts (FDR)")) -> 0 | I16: =MAX(0,SUMIFS(Journals!$L$9:$L$1011204,Journals!$D$9:$D$1011204,">"&$E$7,Journals!$D$9:$D$1011204,"<"&$E$8,Journals!$J$9:$J$1011204,"Fixed Deposit Receipts (FDR)")-SUMIFS(Journals!$K$9:$K$1011204,Journals!$D$9:$D$1011204,">"&$E$7,Journals!$D$9:$D$1011204,"<"&$E$8,Journals!$J$9:$J$1011204,"Fixed Deposit Receipts (FDR)")) -> 6000000 | J16: =SUMIFS(Journals!$K$9:$K$1011204,Journals!$D$9:$D$1011204,"<"&$F$7,Journals!$J$9:$J$1011204,"Fixed Deposit Receipts (FDR)")-SUMIFS(Journals!$L$9:$L$1011204,Journals!$D$9:$D$1011204,"<"&$F$7,Journals!$J$9:$J$1011204,"Fixed Deposit Receipts (FDR)") -> 6000000 | L16: =J16+H16-I16 -> 0
G17: ='Chart of Accounts'!B13 -> Cash and cash equivalents | H17: =MAX(0,SUMIFS(Journals!$K$9:$K$1011204,Journals!$D$9:$D$1011204,">"&$E$7,Journals!$D$9:$D$1011204,"<"&$E$8,Journals!$J$9:$J$1011204,"Cash and cash equivalents")-SUMIFS(Journals!$L$9:$L$1011204,Journals!$D$9:$D$1011204,">"&$E$7,Journals!$D$9:$D$1011204,"<"&$E$8,Journals!$J$9:$J$1011204,"Cash and cash equivalents")) -> 0 | I17: =MAX(0,SUMIFS(Journals!$L$9:$L$1011204,Journals!$D$9:$D$1011204,">"&$E$7,Journals!$D$9:$D$1011204,"<"&$E$8,Journals!$J$9:$J$1011204,"Cash and cash equivalents")-SUMIFS(Journals!$K$9:$K$1011204,Journals!$D$9:$D$1011204,">"&$E$7,Journals!$D$9:$D$1011204,"<"&$E$8,Journals!$J$9:$J$1011204,"Cash and cash equivalents")) -> 1311849.8 | J17: =SUMIFS(Journals!$K$9:$K$1011204,Journals!$D$9:$D$1011204,"<"&$F$7,Journals!$J$9:$J$1011204,"Cash and cash equivalents")-SUMIFS(Journals!$L$9:$L$1011204,Journals!$D$9:$D$1011204,"<"&$F$7,Journals!$J$9:$J$1011204,"Cash and cash equivalents") -> 1784563.8 | L17: =J17+H17-I17 -> 472714.03
G18: ='Chart of Accounts'!B14 -> Unit Capital | H18: =SUMIFS(Journals!$K$9:$K$1011204,Journals!$D$9:$D$1011204,">"&$E$7,Journals!$D$9:$D$1011204,"<"&$E$8,Journals!$J$9:$J$1011204,"unit capital") -> 15641800 | I18: =MAX(0,SUMIFS(Journals!$L$9:$L$1011204,Journals!$D$9:$D$1011204,">"&$E$7,Journals!$D$9:$D$1011204,"<"&$E$8,Journals!$J$9:$J$1011204,"unit capital")) -> 41360240 | K18: =SUMIFS(Journals!$L$9:$L$1011204,Journals!$D$9:$D$1011204,"<"&$F$7,Journals!$J$9:$J$1011204,"unit capital")-SUMIFS(Journals!$K$9:$K$1011204,Journals!$D$9:$D$1011204,"<"&$F$7,Journals!$J$9:$J$1011204,"unit capital") -> 156111010 | M18: =K18+I18-H18 -> 181829450
G19: ='Chart of Accounts'!B15 -> Unit premium reserve | H19: =SUMIFS(Journals!$K$9:$K$1011204,Journals!$D$9:$D$1011204,">"&$E$7,Journals!$D$9:$D$1011204,"<"&$E$8,Journals!$J$9:$J$1011204,"unit premium reserve") -> 7711214.3 | I19: =SUMIFS(Journals!$L$9:$L$1011204,Journals!$D$9:$D$1011204,">"&$E$7,Journals!$D$9:$D$1011204,"<"&$E$8,Journals!$J$9:$J$1011204,"unit premium reserve") -> 19849776 | K19: =SUMIFS(Journals!$L$9:$L$1011204,Journals!$D$9:$D$1011204,"<"&$F$7,Journals!$J$9:$J$1011204,"unit premium reserve")-SUMIFS(Journals!$K$9:$K$1011204,Journals!$D$9:$D$1011204,"<"&$F$7,Journals!$J$9:$J$1011204,"unit premium reserve") -> 10427123 | M19: =K19+I19-H19 -> 22565685
G20: ='Chart of Accounts'!B16 -> Interest income | H20: =MAX(0,SUMIFS(Journals!$K$9:$K$1011204,Journals!$D$9:$D$1011204,">"&$E$7,Journals!$D$9:$D$1011204,"<"&$E$8,Journals!$J$9:$J$1011204,"interest income")-SUMIFS(Journals!$L$9:$L$1011204,Journals!$D$9:$D$1011204,">"&$E$7,Journals!$D$9:$D$1011204,"<"&$E$8,Journals!$J$9:$J$1011204,"interest income")) -> 0 | I20: =MAX(0,SUMIFS(Journals!$L$9:$L$1011204,Journals!$D$9:$D$1011204,">"&$E$7,Journals!$D$9:$D$1011204,"<"&$E$8,Journals!$J$9:$J$1011204,"interest income")-SUMIFS(Journals!$K$9:$K$1011204,Journals!$D$9:$D$1011204,">"&$E$7,Journals!$D$9:$D$1011204,"<"&$E$8,Journals!$J$9:$J$1011204,"interest income")) -> 0 | O20: =SUMIFS(Journals!$L$9:$L$1011204,Journals!$D$9:$D$1011204,"<"&$F$7,Journals!$J$9:$J$1011204,"interest income")-SUMIFS(Journals!$K$9:$K$1011204,Journals!$D$9:$D$1011204,"<"&$F$7,Journals!$J$9:$J$1011204,"interest income") -> 16114040
G21: Interest income from FDR | H21: =MAX(0,SUMIFS(Journals!$K$9:$K$1011204,Journals!$D$9:$D$1011204,">"&$E$7,Journals!$D$9:$D$1011204,"<"&$E$8,Journals!$J$9:$J$1011204,"Interest income from FDR")-SUMIFS(Journals!$L$9:$L$1011204,Journals!$D$9:$D$1011204,">"&$E$7,Journals!$D$9:$D$1011204,"<"&$E$8,Journals!$J$9:$J$1011204,"Interest income from FDR")) -> 0 | I21: =MAX(0,SUMIFS(Journals!$L$9:$L$1011204,Journals!$D$9:$D$1011204,">"&$E$7,Journals!$D$9:$D$1011204,"<"&$E$8,Journals!$J$9:$J$1011204,"Interest income from FDR")-SUMIFS(Journals!$K$9:$K$1011204,Journals!$D$9:$D$1011204,">"&$E$7,Journals!$D$9:$D$1011204,"<"&$E$8,Journals!$J$9:$J$1011204,"Interest income from FDR")) -> 74749.798 | O21: =SUMIFS(Journals!$L$9:$L$1011204,Journals!$D$9:$D$1011204,"<"&$F$7,Journals!$J$9:$J$1011204,"Interest income from FDR")-SUMIFS(Journals!$K$9:$K$1011204,Journals!$D$9:$D$1011204,"<"&$F$7,Journals!$J$9:$J$1011204,"Interest income from FDR") -> 0
G22: Interest income from Renata Pref. Share | H22: =MAX(0,SUMIFS(Journals!$K$9:$K$1011204,Journals!$D$9:$D$1011204,">"&$E$7,Journals!$D$9:$D$1011204,"<"&$E$8,Journals!$J$9:$J$1011204,"Interest income from Renata Pref. Share")-SUMIFS(Journals!$L$9:$L$1011204,Journals!$D$9:$D$1011204,">"&$E$7,Journals!$D$9:$D$1011204,"<"&$E$8,Journals!$J$9:$J$1011204,"Interest income from Renata Pref. Share")) -> 0 | I22: =MAX(0,SUMIFS(Journals!$L$9:$L$1011204,Journals!$D$9:$D$1011204,">"&$E$7,Journals!$D$9:$D$1011204,"<"&$E$8,Journals!$J$9:$J$1011204,"Interest income from Renata Pref. Share")-SUMIFS(Journals!$K$9:$K$1011204,Journals!$D$9:$D$1011204,">"&$E$7,Journals!$D$9:$D$1011204,"<"&$E$8,Journals!$J$9:$J$1011204,"Interest income from Renata Pref. Share")) -> 519576.92 | O22: =SUMIFS(Journals!$L$9:$L$1011204,Journals!$D$9:$D$1011204,"<"&$F$7,Journals!$J$9:$J$1011204,"Interest income from Renata Pref. Share")-SUMIFS(Journals!$K$9:$K$1011204,Journals!$D$9:$D$1011204,"<"&$F$7,Journals!$J$9:$J$1011204,"Interest income from Renata Pref. Share") -> 402053.57
G23: Interest income from Bank Acc. | H23: =MAX(0,SUMIFS(Journals!$K$9:$K$1011204,Journals!$D$9:$D$1011204,">"&$E$7,Journals!$D$9:$D$1011204,"<"&$E$8,Journals!$J$9:$J$1011204,"Interest income from Bank Acc.")-SUMIFS(Journals!$L$9:$L$1011204,Journals!$D$9:$D$1011204,">"&$E$7,Journals!$D$9:$D$1011204,"<"&$E$8,Journals!$J$9:$J$1011204,"Interest income from Bank Acc.")) -> 0 | I23: =MAX(0,SUMIFS(Journals!$L$9:$L$1011204,Journals!$D$9:$D$1011204,">"&$E$7,Journals!$D$9:$D$1011204,"<"&$E$8,Journals!$J$9:$J$1011204,"Interest income from Bank Acc.")-SUMIFS(Journals!$K$9:$K$1011204,Journals!$D$9:$D$1011204,">"&$E$7,Journals!$D$9:$D$1011204,"<"&$E$8,Journals!$J$9:$J$1011204,"Interest income from Bank Acc.")) -> 113337.69 | O23: =SUMIFS(Journals!$L$9:$L$1011204,Journals!$D$9:$D$1011204,"<"&$F$7,Journals!$J$9:$J$1011204,"Interest income from Bank Acc.")-SUMIFS(Journals!$K$9:$K$1011204,Journals!$D$9:$D$1011204,"<"&$F$7,Journals!$J$9:$J$1011204,"Interest income from Bank Acc.") -> 0
G24: Interest income from T-Bill | H24: =MAX(0,SUMIFS(Journals!$K$9:$K$1011204,Journals!$D$9:$D$1011204,">"&$E$7,Journals!$D$9:$D$1011204,"<"&$E$8,Journals!$J$9:$J$1011204,"Interest income from T-Bill")-SUMIFS(Journals!$L$9:$L$1011204,Journals!$D$9:$D$1011204,">"&$E$7,Journals!$D$9:$D$1011204,"<"&$E$8,Journals!$J$9:$J$1011204,"Interest income from T-Bill")) -> 0 | I24: =MAX(0,SUMIFS(Journals!$L$9:$L$1011204,Journals!$D$9:$D$1011204,">"&$E$7,Journals!$D$9:$D$1011204,"<"&$E$8,Journals!$J$9:$J$1011204,"Interest income from T-Bill")-SUMIFS(Journals!$K$9:$K$1011204,Journals!$D$9:$D$1011204,">"&$E$7,Journals!$D$9:$D$1011204,"<"&$E$8,Journals!$J$9:$J$1011204,"Interest income from T-Bill")) -> 0 | O24: =SUMIFS(Journals!$L$9:$L$1011204,Journals!$D$9:$D$1011204,"<"&$F$7,Journals!$J$9:$J$1011204,"Interest income from T-Bill")-SUMIFS(Journals!$K$9:$K$1011204,Journals!$D$9:$D$1011204,"<"&$F$7,Journals!$J$9:$J$1011204,"Interest income from T-Bill") -> 0
G25: Interest income from T-Bond | H25: =MAX(0,SUMIFS(Journals!$K$9:$K$1011204,Journals!$D$9:$D$1011204,">"&$E$7,Journals!$D$9:$D$1011204,"<"&$E$8,Journals!$J$9:$J$1011204,"Interest income from T-Bond")-SUMIFS(Journals!$L$9:$L$1011204,Journals!$D$9:$D$1011204,">"&$E$7,Journals!$D$9:$D$1011204,"<"&$E$8,Journals!$J$9:$J$1011204,"Interest income from T-Bond")) -> 0 | I25: =MAX(0,SUMIFS(Journals!$L$9:$L$1011204,Journals!$D$9:$D$1011204,">"&$E$7,Journals!$D$9:$D$1011204,"<"&$E$8,Journals!$J$9:$J$1011204,"Interest income from T-Bond")-SUMIFS(Journals!$K$9:$K$1011204,Journals!$D$9:$D$1011204,">"&$E$7,Journals!$D$9:$D$1011204,"<"&$E$8,Journals!$J$9:$J$1011204,"Interest income from T-Bond")) -> 0 | O25: =SUMIFS(Journals!$L$9:$L$1011204,Journals!$D$9:$D$1011204,"<"&$F$7,Journals!$J$9:$J$1011204,"Interest income from T-Bond")-SUMIFS(Journals!$K$9:$K$1011204,Journals!$D$9:$D$1011204,"<"&$F$7,Journals!$J$9:$J$1011204,"Interest income from T-Bond") -> 0
G26: ='Chart of Accounts'!B22 -> Bank charges and excise duties | H26: =MAX(0,SUMIFS(Journals!$K$9:$K$1011204,Journals!$D$9:$D$1011204,">"&$E$7,Journals!$D$9:$D$1011204,"<"&$E$8,Journals!$J$9:$J$1011204,"Bank charges and excise duties")-SUMIFS(Journals!$L$9:$L$1011204,Journals!$D$9:$D$1011204,">"&$E$7,Journals!$D$9:$D$1011204,"<"&$E$8,Journals!$J$9:$J$1011204,"Bank charges and excise duties")) -> 26469 | I26: =MAX(0,SUMIFS(Journals!$L$9:$L$1011204,Journals!$D$9:$D$1011204,">"&$E$7,Journals!$D$9:$D$1011204,"<"&$E$8,Journals!$J$9:$J$1011204,"Bank charges and excise duties")-SUMIFS(Journals!$K$9:$K$1011204,Journals!$D$9:$D$1011204,">"&$E$7,Journals!$D$9:$D$1011204,"<"&$E$8,Journals!$J$9:$J$1011204,"Bank charges and excise duties")) -> 0 | N26: =SUMIFS(Journals!$K$9:$K$1011204,Journals!$D$9:$D$1011204,"<"&$F$7,Journals!$J$9:$J$1011204,"Bank charges and excise duties")-SUMIFS(Journals!$L$9:$L$1011204,Journals!$D$9:$D$1011204,"<"&$F$7,Journals!$J$9:$J$1011204,"Bank charges and excise duties") -> 548004.57
G27: ='Chart of Accounts'!B23 -> Brokerage commission | H27: =MAX(0,SUMIFS(Journals!$K$9:$K$1011204,Journals!$D$9:$D$1011204,">"&$E$7,Journals!$D$9:$D$1011204,"<"&$E$8,Journals!$J$9:$J$1011204,"brokerage commission")-SUMIFS(Journals!$L$9:$L$1011204,Journals!$D$9:$D$1011204,">"&$E$7,Journals!$D$9:$D$1011204,"<"&$E$8,Journals!$J$9:$J$1011204,"brokerage commission")) -> 485345.52 | I27: =MAX(0,SUMIFS(Journals!$L$9:$L$1011204,Journals!$D$9:$D$1011204,">"&$E$7,Journals!$D$9:$D$1011204,"<"&$E$8,Journals!$J$9:$J$1011204,"brokerage commission")-SUMIFS(Journals!$K$9:$K$1011204,Journals!$D$9:$D$1011204,">"&$E$7,Journals!$D$9:$D$1011204,"<"&$E$8,Journals!$J$9:$J$1011204,"brokerage commission")) -> 0 | N27: =SUMIFS(Journals!$K$9:$K$1011204,Journals!$D$9:$D$1011204,"<"&$F$7,Journals!$J$9:$J$1011204,"brokerage commission")-SUMIFS(Journals!$L$9:$L$1011204,Journals!$D$9:$D$1011204,"<"&$F$7,Journals!$J$9:$J$1011204,"brokerage commission") -> 3755798.7
G28: ='Chart of Accounts'!B24 -> Unrealized gain on securities | H28: =MAX(0,SUMIFS(Journals!$K$9:$K$1011204,Journals!$D$9:$D$1011204,">"&$E$7,Journals!$D$9:$D$1011204,"<"&$E$8,Journals!$J$9:$J$1011204,"Unrealized gain on securities")-SUMIFS(Journals!$L$9:$L$1011204,Journals!$D$9:$D$1011204,">"&$E$7,Journals!$D$9:$D$1011204,"<"&$E$8,Journals!$J$9:$J$1011204,"Unrealized gain on securities")) -> 0 | I28: =MAX(0,SUMIFS(Journals!$L$9:$L$1011204,Journals!$D$9:$D$1011204,">"&$E$7,Journals!$D$9:$D$1011204,"<"&$E$8,Journals!$J$9:$J$1011204,"Unrealized gain on securities")-SUMIFS(Journals!$K$9:$K$1011204,Journals!$D$9:$D$1011204,">"&$E$7,Journals!$D$9:$D$1011204,"<"&$E$8,Journals!$J$9:$J$1011204,"Unrealized gain on securities")) -> 10155077 | O28: =SUMIFS(Journals!$L$9:$L$1011204,Journals!$D$9:$D$1011204,"<"&$F$7,Journals!$J$9:$J$1011204,"unrealized gain on securities")-SUMIFS(Journals!$K$9:$K$1011204,Journals!$D$9:$D$1011204,"<"&$F$7,Journals!$J$9:$J$1011204,"unrealized gain on securities") -> 91188891
G29: Unrealized gain on T-Bill | H29: =MAX(0,SUMIFS(Journals!$K$9:$K$1011204,Journals!$D$9:$D$1011204,">"&$E$7,Journals!$D$9:$D$1011204,"<"&$E$8,Journals!$J$9:$J$1011204,"Unrealized gain on T-Bill")-SUMIFS(Journals!$L$9:$L$1011204,Journals!$D$9:$D$1011204,">"&$E$7,Journals!$D$9:$D$1011204,"<"&$E$8,Journals!$J$9:$J$1011204,"Unrealized gain on T-Bill")) -> 0 | I29: =MAX(0,SUMIFS(Journals!$L$9:$L$1011204,Journals!$D$9:$D$1011204,">"&$E$7,Journals!$D$9:$D$1011204,"<"&$E$8,Journals!$J$9:$J$1011204,"Unrealized gain on T-Bill")-SUMIFS(Journals!$K$9:$K$1011204,Journals!$D$9:$D$1011204,">"&$E$7,Journals!$D$9:$D$1011204,"<"&$E$8,Journals!$J$9:$J$1011204,"Unrealized gain on T-Bill")) -> 0 | O29: =SUMIFS(Journals!$L$9:$L$1011204,Journals!$D$9:$D$1011204,"<"&$F$7,Journals!$J$9:$J$1011204,"Unrealized gain on T-Bill")-SUMIFS(Journals!$K$9:$K$1011204,Journals!$D$9:$D$1011204,"<"&$F$7,Journals!$J$9:$J$1011204,"Unrealized gain on T-Bill") -> 0
G30: Unrealized gain on T-Bond | H30: =MAX(0,SUMIFS(Journals!$K$9:$K$1011204,Journals!$D$9:$D$1011204,">"&$E$7,Journals!$D$9:$D$1011204,"<"&$E$8,Journals!$J$9:$J$1011204,"Unrealized gain on T-Bond")-SUMIFS(Journals!$L$9:$L$1011204,Journals!$D$9:$D$1011204,">"&$E$7,Journals!$D$9:$D$1011204,"<"&$E$8,Journals!$J$9:$J$1011204,"Unrealized gain on T-Bond")) -> 0 | I30: =MAX(0,SUMIFS(Journals!$L$9:$L$1011204,Journals!$D$9:$D$1011204,">"&$E$7,Journals!$D$9:$D$1011204,"<"&$E$8,Journals!$J$9:$J$1011204,"Unrealized gain on T-Bond")-SUMIFS(Journals!$K$9:$K$1011204,Journals!$D$9:$D$1011204,">"&$E$7,Journals!$D$9:$D$1011204,"<"&$E$8,Journals!$J$9:$J$1011204,"Unrealized gain on T-Bond")) -> 0 | O30: =SUMIFS(Journals!$L$9:$L$1011204,Journals!$D$9:$D$1011204,"<"&$F$7,Journals!$J$9:$J$1011204,"Unrealized gain on T-Bond")-SUMIFS(Journals!$K$9:$K$1011204,Journals!$D$9:$D$1011204,"<"&$F$7,Journals!$J$9:$J$1011204,"Unrealized gain on T-Bond") -> 0
G31: ='Chart of Accounts'!B27 -> Unrealized loss on securities | H31: =MAX(0,SUMIFS(Journals!$K$9:$K$1011204,Journals!$D$9:$D$1011204,">"&$E$7,Journals!$D$9:$D$1011204,"<"&$E$8,Journals!$J$9:$J$1011204,"Unrealized loss on securities")-SUMIFS(Journals!$L$9:$L$1011204,Journals!$D$9:$D$1011204,">"&$E$7,Journals!$D$9:$D$1011204,"<"&$E$8,Journals!$J$9:$J$1011204,"Unrealized loss on securities")) -> 0 | I31: =MAX(0,SUMIFS(Journals!$L$9:$L$1011204,Journals!$D$9:$D$1011204,">"&$E$7,Journals!$D$9:$D$1011204,"<"&$E$8,Journals!$J$9:$J$1011204,"Unrealized loss on securities")-SUMIFS(Journals!$K$9:$K$1011204,Journals!$D$9:$D$1011204,">"&$E$7,Journals!$D$9:$D$1011204,"<"&$E$8,Journals!$J$9:$J$1011204,"Unrealized loss on securities")) -> 0 | N31: =SUMIFS(Journals!K9:K1011204,Journals!D9:D1011204,"<"&F7,Journals!J9:J1011204,"unrealized loss on securities")-SUMIFS(Journals!L9:L1011204,Journals!D9:D1011204,"<"&F7,Journals!J9:J1011204,"unrealized loss on securities") -> 87355603
G32: ='Chart of Accounts'!B28 -> Amortization of preliminary and issue expense | H32: =MAX(0,SUMIFS(Journals!$K$9:$K$1011204,Journals!$D$9:$D$1011204,">"&$E$7,Journals!$D$9:$D$1011204,"<"&$E$8,Journals!$J$9:$J$1011204,"Amortization of preliminary and issue expense")-SUMIFS(Journals!$L$9:$L$1011204,Journals!$D$9:$D$1011204,">"&$E$7,Journals!$D$9:$D$1011204,"<"&$E$8,Journals!$J$9:$J$1011204,"Amortization of preliminary and issue expense")) -> 32967.033 | I32: =MAX(0,SUMIFS(Journals!$L$9:$L$1011204,Journals!$D$9:$D$1011204,">"&$E$7,Journals!$D$9:$D$1011204,"<"&$E$8,Journals!$J$9:$J$1011204,"Amortization of preliminary and issue expense")-SUMIFS(Journals!$K$9:$K$1011204,Journals!$D$9:$D$1011204,">"&$E$7,Journals!$D$9:$D$1011204,"<"&$E$8,Journals!$J$9:$J$1011204,"Amortization of preliminary and issue expense")) -> 0 | N32: =SUMIFS(Journals!$K$9:$K$1011204,Journals!$D$9:$D$1011204,"<"&$F$7,Journals!$J$9:$J$1011204,"Amortization of preliminary and issue expense")-SUMIFS(Journals!$L$9:$L$1011204,Journals!$D$9:$D$1011204,"<"&$F$7,Journals!$J$9:$J$1011204,"Amortization of preliminary and issue expense") -> 826137.17
G33: ='Chart of Accounts'!B29 -> Management Fee | H33: =MAX(0,SUMIFS(Journals!$K$9:$K$1011204,Journals!$D$9:$D$1011204,">"&$E$7,Journals!$D$9:$D$1011204,"<"&$E$8,Journals!$J$9:$J$1011204,"management fee")-SUMIFS(Journals!$L$9:$L$1011204,Journals!$D$9:$D$1011204,">"&$E$7,Journals!$D$9:$D$1011204,"<"&$E$8,Journals!$J$9:$J$1011204,"management fee")) -> 1199767.6 | I33: =MAX(0,SUMIFS(Journals!$L$9:$L$1011204,Journals!$D$9:$D$1011204,">"&$E$7,Journals!$D$9:$D$1011204,"<"&$E$8,Journals!$J$9:$J$1011204,"management fee")-SUMIFS(Journals!$K$9:$K$1011204,Journals!$D$9:$D$1011204,">"&$E$7,Journals!$D$9:$D$1011204,"<"&$E$8,Journals!$J$9:$J$1011204,"management fee")) -> 0 | N33: =SUMIFS(Journals!$K$9:$K$1011204,Journals!$D$9:$D$1011204,"<"&$F$7,Journals!$J$9:$J$1011204,"management fee")-SUMIFS(Journals!$L$9:$L$1011204,Journals!$D$9:$D$1011204,"<"&$F$7,Journals!$J$9:$J$1011204,"management fee") -> 19811568
G34: ='Chart of Accounts'!B30 -> Trustee fee | H34: =MAX(0,SUMIFS(Journals!$K$9:$K$1011204,Journals!$D$9:$D$1011204,">"&$E$7,Journals!$D$9:$D$1011204,"<"&$E$8,Journals!$J$9:$J$1011204,"trustee fee")-SUMIFS(Journals!$L$9:$L$1011204,Journals!$D$9:$D$1011204,">"&$E$7,Journals!$D$9:$D$1011204,"<"&$E$8,Journals!$J$9:$J$1011204,"trustee fee")) -> 98794.008 | I34: =MAX(0,SUMIFS(Journals!$L$9:$L$1011204,Journals!$D$9:$D$1011204,">"&$E$7,Journals!$D$9:$D$1011204,"<"&$E$8,Journals!$J$9:$J$1011204,"trustee fee")-SUMIFS(Journals!$K$9:$K$1011204,Journals!$D$9:$D$1011204,">"&$E$7,Journals!$D$9:$D$1011204,"<"&$E$8,Journals!$J$9:$J$1011204,"trustee fee")) -> 0 | N34: =SUMIFS(Journals!$K$9:$K$1011204,Journals!$D$9:$D$1011204,"<"&$F$7,Journals!$J$9:$J$1011204,"trustee fee")-SUMIFS(Journals!$L$9:$L$1011204,Journals!$D$9:$D$1011204,"<"&$F$7,Journals!$J$9:$J$1011204,"trustee fee") -> 970223.91
G35: ='Chart of Accounts'!B31 -> BSEC Annual Fee | H35: =MAX(0,SUMIFS(Journals!$K$9:$K$1011204,Journals!$D$9:$D$1011204,">"&$E$7,Journals!$D$9:$D$1011204,"<"&$E$8,Journals!$J$9:$J$1011204,"bsec annual fee")-SUMIFS(Journals!$L$9:$L$1011204,Journals!$D$9:$D$1011204,">"&$E$7,Journals!$D$9:$D$1011204,"<"&$E$8,Journals!$J$9:$J$1011204,"bsec annual fee")) -> 0 | I35: =MAX(0,SUMIFS(Journals!$L$9:$L$1011204,Journals!$D$9:$D$1011204,">"&$E$7,Journals!$D$9:$D$1011204,"<"&$E$8,Journals!$J$9:$J$1011204,"bsec annual fee")-SUMIFS(Journals!$K$9:$K$1011204,Journals!$D$9:$D$1011204,">"&$E$7,Journals!$D$9:$D$1011204,"<"&$E$8,Journals!$J$9:$J$1011204,"bsec annual fee")) -> 0 | N35: =SUMIFS(Journals!$K$9:$K$1011204,Journals!$D$9:$D$1011204,"<"&$F$7,Journals!$J$9:$J$1011204,"bsec annual fee")-SUMIFS(Journals!$L$9:$L$1011204,Journals!$D$9:$D$1011204,"<"&$F$7,Journals!$J$9:$J$1011204,"bsec annual fee") -> 952709.73
G36: ='Chart of Accounts'!B32 -> Audit fee | H36: =MAX(0,SUMIFS(Journals!$K$9:$K$1011204,Journals!$D$9:$D$1011204,">"&$E$7,Journals!$D$9:$D$1011204,"<"&$E$8,Journals!$J$9:$J$1011204,"audit fee")-SUMIFS(Journals!$L$9:$L$1011204,Journals!$D$9:$D$1011204,">"&$E$7,Journals!$D$9:$D$1011204,"<"&$E$8,Journals!$J$9:$J$1011204,"audit fee")) -> 0 | I36: =MAX(0,SUMIFS(Journals!$L$9:$L$1011204,Journals!$D$9:$D$1011204,">"&$E$7,Journals!$D$9:$D$1011204,"<"&$E$8,Journals!$J$9:$J$1011204,"audit fee")-SUMIFS(Journals!$K$9:$K$1011204,Journals!$D$9:$D$1011204,">"&$E$7,Journals!$D$9:$D$1011204,"<"&$E$8,Journals!$J$9:$J$1011204,"audit fee")) -> 0 | N36: =SUMIFS(Journals!$K$9:$K$1011204,Journals!$D$9:$D$1011204,"<"&$F$7,Journals!$J$9:$J$1011204,"audit fee")-SUMIFS(Journals!$L$9:$L$1011204,Journals!$D$9:$D$1011204,"<"&$F$7,Journals!$J$9:$J$1011204,"audit fee") -> 247000
G37: ='Chart of Accounts'!B33 -> CDBL charges | H37: =MAX(0,SUMIFS(Journals!$K$9:$K$1011204,Journals!$D$9:$D$1011204,">"&$E$7,Journals!$D$9:$D$1011204,"<"&$E$8,Journals!$J$9:$J$1011204,"cdbl charges")-SUMIFS(Journals!$L$9:$L$1011204,Journals!$D$9:$D$1011204,">"&$E$7,Journals!$D$9:$D$1011204,"<"&$E$8,Journals!$J$9:$J$1011204,"cdbl charges")) -> 13687.862 | I37: =MAX(0,SUMIFS(Journals!$L$9:$L$1011204,Journals!$D$9:$D$1011204,">"&$E$7,Journals!$D$9:$D$1011204,"<"&$E$8,Journals!$J$9:$J$1011204,"cdbl charges")-SUMIFS(Journals!$K$9:$K$1011204,Journals!$D$9:$D$1011204,">"&$E$7,Journals!$D$9:$D$1011204,"<"&$E$8,Journals!$J$9:$J$1011204,"cdbl charges")) -> 0 | N37: =SUMIFS(Journals!$K$9:$K$1011204,Journals!$D$9:$D$1011204,"<"&$F$7,Journals!$J$9:$J$1011204,"cdbl charges")-SUMIFS(Journals!$L$9:$L$1011204,Journals!$D$9:$D$1011204,"<"&$F$7,Journals!$J$9:$J$1011204,"cdbl charges") -> 336428.67
G38: ='Chart of Accounts'!B34 -> Fair value adjustment | H38: =MAX(0,SUMIFS(Journals!$K$9:$K$1011204,Journals!$D$9:$D$1011204,">"&$E$7,Journals!$D$9:$D$1011204,"<"&$E$8,Journals!$J$9:$J$1011204,"Fair value adjustment")-SUMIFS(Journals!$L$9:$L$1011204,Journals!$D$9:$D$1011204,">"&$E$7,Journals!$D$9:$D$1011204,"<"&$E$8,Journals!$J$9:$J$1011204,"Fair value adjustment")) -> 10155077 | I38: =MAX(0,SUMIFS(Journals!$L$9:$L$1011204,Journals!$D$9:$D$1011204,">"&$E$7,Journals!$D$9:$D$1011204,"<"&$E$8,Journals!$J$9:$J$1011204,"fair value adjustment")-SUMIFS(Journals!$K$9:$K$1011204,Journals!$D$9:$D$1011204,">"&$E$7,Journals!$D$9:$D$1011204,"<"&$E$8,Journals!$J$9:$J$1011204,"fair value adjustment")) -> 0 | J38: =MAX(0,SUMIFS(Journals!K9:K1011204,Journals!D9:D1011204,"<"&F7,Journals!J9:J1011204,"fair value adjustment")-SUMIFS(Journals!L9:L1011204,Journals!D9:D1011204,"<"&F7,Journals!J9:J1011204,"fair value adjustment")) -> 3833287.7 | K38: =MAX(0,SUMIFS(Journals!L9:L1011204,Journals!D9:D1011204,"<"&F7,Journals!J9:J1011204,"Fair value adjustment")-SUMIFS(Journals!K9:K1011204,Journals!D9:D1011204,"<"&F7,Journals!J9:J1011204,"fair value adjustment")) -> 0 | L38: =MAX(0,H38-I38+J38-K38) -> 13988365 | M38: =MAX(0,I38-H38-J38+K38) -> 0
G39: Fair value adjustment T-Bill | H39: =MAX(0,SUMIFS(Journals!$K$9:$K$1011204,Journals!$D$9:$D$1011204,">"&$E$7,Journals!$D$9:$D$1011204,"<"&$E$8,Journals!$J$9:$J$1011204,"Fair value adjustment T-Bill")-SUMIFS(Journals!$L$9:$L$1011204,Journals!$D$9:$D$1011204,">"&$E$7,Journals!$D$9:$D$1011204,"<"&$E$8,Journals!$J$9:$J$1011204,"Fair value adjustment T-Bill")) -> 0 | I39: =MAX(0,SUMIFS(Journals!$L$9:$L$1011204,Journals!$D$9:$D$1011204,">"&$E$7,Journals!$D$9:$D$1011204,"<"&$E$8,Journals!$J$9:$J$1011204,"Fair value adjustment T-Bill")-SUMIFS(Journals!$K$9:$K$1011204,Journals!$D$9:$D$1011204,">"&$E$7,Journals!$D$9:$D$1011204,"<"&$E$8,Journals!$J$9:$J$1011204,"Fair value adjustment T-Bill")) -> 0 | J39: =MAX(0,SUMIFS(Journals!K9:K1011204,Journals!D9:D1011204,"<"&F7,Journals!J9:J1011204,"Fair value adjustment T-Bill")-SUMIFS(Journals!L9:L1011204,Journals!D9:D1011204,"<"&F7,Journals!J9:J1011204,"Fair value adjustment T-Bill")) -> 0 | K39: =MAX(0,SUMIFS(Journals!L9:L1011204,Journals!D9:D1011204,"<"&F7,Journals!J9:J1011204,"Fair value adjustment T-Bill")-SUMIFS(Journals!K9:K1011204,Journals!D9:D1011204,"<"&F7,Journals!J9:J1011204,"Fair value adjustment T-Bill")) -> 0 | L39: =MAX(0,H39-I39+J39-K39) -> 0 | M39: =MAX(0,I39-H39-J39+K39) -> 0
G40: Fair value adjustment T-Bond | H40: =MAX(0,SUMIFS(Journals!$K$9:$K$1011204,Journals!$D$9:$D$1011204,">"&$E$7,Journals!$D$9:$D$1011204,"<"&$E$8,Journals!$J$9:$J$1011204,"Fair value adjustment T-Bond")-SUMIFS(Journals!$L$9:$L$1011204,Journals!$D$9:$D$1011204,">"&$E$7,Journals!$D$9:$D$1011204,"<"&$E$8,Journals!$J$9:$J$1011204,"Fair value adjustment T-Bond")) -> 0 | I40: =MAX(0,SUMIFS(Journals!$L$9:$L$1011204,Journals!$D$9:$D$1011204,">"&$E$7,Journals!$D$9:$D$1011204,"<"&$E$8,Journals!$J$9:$J$1011204,"Fair value adjustment T-Bond")-SUMIFS(Journals!$K$9:$K$1011204,Journals!$D$9:$D$1011204,">"&$E$7,Journals!$D$9:$D$1011204,"<"&$E$8,Journals!$J$9:$J$1011204,"Fair value adjustment T-Bond")) -> 0 | J40: =MAX(0,SUMIFS(Journals!K9:K1011204,Journals!D9:D1011204,"<"&F7,Journals!J9:J1011204,"Fair value adjustment T-Bond")-SUMIFS(Journals!L9:L1011204,Journals!D9:D1011204,"<"&F7,Journals!J9:J1011204,"Fair value adjustment T-Bond")) -> 0 | K40: =MAX(0,SUMIFS(Journals!L9:L1011204,Journals!D9:D1011204,"<"&F7,Journals!J9:J1011204,"Fair value adjustment T-Bond")-SUMIFS(Journals!K9:K1011204,Journals!D9:D1011204,"<"&F7,Journals!J9:J1011204,"Fair value adjustment T-Bond")) -> 0 | L40: =MAX(0,H40-I40+J40-K40) -> 0 | M40: =MAX(0,I40-H40-J40+K40) -> 0
G41: Interest receivables from FDR | H41: =MAX(0,SUMIFS(Journals!$K$9:$K$1011204,Journals!$D$9:$D$1011204,">"&$E$7,Journals!$D$9:$D$1011204,"<"&$E$8,Journals!$J$9:$J$1011204,"Interest receivables from FDR")-SUMIFS(Journals!$L$9:$L$1011204,Journals!$D$9:$D$1011204,">"&$E$7,Journals!$D$9:$D$1011204,"<"&$E$8,Journals!$J$9:$J$1011204,"Interest receivables from FDR")) -> 0 | I41: =MAX(0,SUMIFS(Journals!$L$9:$L$1011204,Journals!$D$9:$D$1011204,">"&$E$7,Journals!$D$9:$D$1011204,"<"&$E$8,Journals!$J$9:$J$1011204,"Interest receivables from FDR")-SUMIFS(Journals!$K$9:$K$1011204,Journals!$D$9:$D$1011204,">"&$E$7,Journals!$D$9:$D$1011204,"<"&$E$8,Journals!$J$9:$J$1011204,"Interest receivables from FDR")) -> 118833.53 | J41: =SUMIFS(Journals!$K$9:$K$1011204,Journals!$D$9:$D$1011204,"<"&$F$7,Journals!$J$9:$J$1011204,"Interest receivables from FDR")-SUMIFS(Journals!$L$9:$L$1011204,Journals!$D$9:$D$1011204,"<"&$F$7,Journals!$J$9:$J$1011204,"Interest receivables from FDR") -> 118833.54 | L41: =J41+H41-I41 -> 0.0033333333
...

Sheet TB-P
A1: Check of Trial Balance | G1: =SUM(H7:H95)-SUM(I7:I95) -> 3.2961369e-05
A2: Check of Balance Sheet | G2: =BS!C25-BS!C40 -> 0
A3: Check of Cash Balance | G3: =BS!C23-CF!B44 -> -2739690.1
B5: Desired Reporting Period | H5: During the Reporting Period | J5: For Balance Sheet | N5: For Retained Earnings
B6: Year | C6: Month | D6: Day | E6: Value | F6: Value | G6: Accounts | H6: Debit | I6: Credit | J6: Carry Forward Balance | K6: Carry Forward Balance | L6: On date | M6: On date | N6: Debit | O6: Credit
A7: Beginning | B7: 2025 | C7: 1 | D7: 1 | E7: =DATE(B7,C7,D7)-1 -> 45657 | F7: =DATE(B7,C7,D7) -> 45658 | G7: ='Chart of Accounts'!B3 -> Investments in stock | H7: =MAX(0,SUMIFS(Journals!$K$9:$K$1011204,Journals!$D$9:$D$1011204,">"&$E$7,Journals!$D$9:$D$1011204,"<"&$E$8,Journals!$J$9:$J$1011204,"investments in stock")-SUMIFS(Journals!$L$9:$L$1011204,Journals!$D$9:$D$1011204,">"&$E$7,Journals!$D$9:$D$1011204,"<"&$E$8,Journals!$J$9:$J$1011204,"investments in stock")) -> 1.2163911e+08 | I7: =MAX(0,SUMIFS(Journals!$L$9:$L$1011204,Journals!$D$9:$D$1011204,">"&$E$7,Journals!$D$9:$D$1011204,"<"&$E$8,Journals!$J$9:$J$1011204,"Investments in stock")-SUMIFS(Journals!$K$9:$K$1011204,Journals!$D$9:$D$1011204,">"&$E$7,Journals!$D$9:$D$1011204,"<"&$E$8,Journals!$J$9:$J$1011204,"Investments in stock")) -> 0 | J7: =SUMIFS(Journals!$K$9:$K$1011204,Journals!$D$9:$D$1011204,"<"&$F$7,Journals!$J$9:$J$1011204,"investments in stock")-SUMIFS(Journals!$L$9:$L$1011204,Journals!$D$9:$D$1011204,"<"&$F$7,Journals!$J$9:$J$1011204,"investments in stock") -> 86882081 | L7: =J7+H7-I7 -> 2.0852119e+08
A8: Ending | B8: 2025 | C8: 12 | D8: 31 | E8: =DATE(B8,C8,D8)+1 -> 46023 | F8: =DATE(B8,C8,D8) -> 46022 | G8: ='Chart of Accounts'!B4 -> Interest Receivables from Bank A/C | H8: =MAX(0,SUMIFS(Journals!$K$9:$K$1011204,Journals!$D$9:$D$1011204,">"&$E$7,Journals!$D$9:$D$1011204,"<"&$E$8,Journals!$J$9:$J$1011204,"Interest Receivables from Bank A/C")-SUMIFS(Journals!$L$9:$L$1011204,Journals!$D$9:$D$1011204,">"&$E$7,Journals!$D$9:$D$1011204,"<"&$E$8,Journals!$J$9:$J$1011204,"Interest Receivables from Bank A/C")) -> 6917.47 | I8: =MAX(0,SUMIFS(Journals!$L$9:$L$1011204,Journals!$D$9:$D$1011204,">"&$E$7,Journals!$D$9:$D$1011204,"<"&$E$8,Journals!$J$9:$J$1011204,"Interest Receivables from Bank A/C")-SUMIFS(Journals!$K$9:$K$1011204,Journals!$D$9:$D$1011204,">"&$E$7,Journals!$D$9:$D$1011204,"<"&$E$8,Journals!$J$9:$J$1011204,"Interest Receivables from Bank A/C")) -> 0 | J8: =SUMIFS(Journals!$K$9:$K$1011204,Journals!$D$9:$D$1011204,"<"&$F$7,Journals!$J$9:$J$1011204,"Interest Receivables from Bank A/C")-SUMIFS(Journals!$L$9:$L$1011204,Journals!$D$9:$D$1011204,"<"&$F$7,Journals!$J$9:$J$1011204,"Interest Receivables from Bank A/C") -> 684.1 | L8: =J8+H8-I8 -> 7601.57
G9: ='Chart of Accounts'!B5 -> Preliminary & issue expenses | H9: =MAX(0,SUMIFS(Journals!$K$9:$K$1011204,Journals!$D$9:$D$1011204,">"&$E$7,Journals!$D$9:$D$1011204,"<"&$E$8,Journals!$J$9:$J$1011204,"Preliminary & issue expenses")-SUMIFS(Journals!$L$9:$L$1011204,Journals!$D$9:$D$1011204,">"&$E$7,Journals!$D$9:$D$1011204,"<"&$E$8,Journals!$J$9:$J$1011204,"Preliminary & issue expenses")) -> 0 | I9: =MAX(0,SUMIFS(Journals!$L$9:$L$1011204,Journals!$D$9:$D$1011204,">"&$E$7,Journals!$D$9:$D$1011204,"<"&$E$8,Journals!$J$9:$J$1011204,"Preliminary & issue expenses")-SUMIFS(Journals!$K$9:$K$1011204,Journals!$D$9:$D$1011204,">"&$E$7,Journals!$D$9:$D$1011204,"<"&$E$8,Journals!$J$9:$J$1011204,"Preliminary & issue expenses")) -> 142464.68 | J9: =SUMIFS(Journals!$K$9:$K$1011204,Journals!$D$9:$D$1011204,"<"&$F$7,Journals!$J$9:$J$1011204,"Preliminary & issue expenses")-SUMIFS(Journals!$L$9:$L$1011204,Journals!$D$9:$D$1011204,"<"&$F$7,Journals!$J$9:$J$1011204,"Preliminary & issue expenses") -> 316327.51 | L9: =J9+H9-I9 -> 173862.83
G10: Accrued Management Fee | H10: =SUMIFS(Journals!$K$9:$K$1010900,Journals!$D$9:$D$1010900,">"&$E$7,Journals!$D$9:$D$1010900,"<"&$E$8,Journals!$J$9:$J$1010900,"Accrued Management Fee") -> 1705923.3 | I10: =MAX(0,SUMIFS(Journals!$L$9:$L$1011204,Journals!$D$9:$D$1011204,">"&$E$7,Journals!$D$9:$D$1011204,"<"&$E$8,Journals!$J$9:$J$1011204,"Accrued Management Fee")) -> 3748377.1 | K10: =SUMIFS(Journals!$L$9:$L$1011204,Journals!$D$9:$D$1011204,"<"&$F$7,Journals!$J$9:$J$1011204,"Accrued Management Fee")-SUMIFS(Journals!$K$9:$K$1011204,Journals!$D$9:$D$1011204,"<"&$F$7,Journals!$J$9:$J$1011204,"Accrued Management Fee") -> 913900.67 | M10: =K10+I10-H10 -> 2956354.5
G11: ='Chart of Accounts'!B7 -> Accrued Trustee Fee | H11: =MAX(0,SUMIFS(Journals!$K$9:$K$1011204,Journals!$D$9:$D$1011204,">"&$E$7,Journals!$D$9:$D$1011204,"<"&$E$8,Journals!$J$9:$J$1011204,"accrued trustee fee")-SUMIFS(Journals!$L$9:$L$1011204,Journals!$D$9:$D$1011204,">"&$E$7,Journals!$D$9:$D$1011204,"<"&$E$8,Journals!$J$9:$J$1011204,"accrued trustee fee")) -> 0 | I11: =MAX(0,SUMIFS(Journals!$L$9:$L$1011204,Journals!$D$9:$D$1011204,">"&$E$7,Journals!$D$9:$D$1011204,"<"&$E$8,Journals!$J$9:$J$1011204,"accrued trustee fee")-SUMIFS(Journals!$K$9:$K$1011204,Journals!$D$9:$D$1011204,">"&$E$7,Journals!$D$9:$D$1011204,"<"&$E$8,Journals!$J$9:$J$1011204,"accrued trustee fee")) -> 37067.556 | K11: =SUMIFS(Journals!$L$9:$L$1011204,Journals!$D$9:$D$1011204,"<"&$F$7,Journals!$J$9:$J$1011204,"Accrued Trustee Fee")-SUMIFS(Journals!$K$9:$K$1011204,Journals!$D$9:$D$1011204,"<"&$F$7,Journals!$J$9:$J$1011204,"Accrued Trustee Fee") -> 68949.105 | M11: =K11+I11-H11 -> 106016.66
G12: ='Chart of Accounts'!B8 -> Accrued Custodian Fee | H12: =MAX(0,SUMIFS(Journals!$K$9:$K$1011204,Journals!$D$9:$D$1011204,">"&$E$7,Journals!$D$9:$D$1011204,"<"&$E$8,Journals!$J$9:$J$1011204,"accrued custodian fee")-SUMIFS(Journals!$L$9:$L$1011204,Journals!$D$9:$D$1011204,">"&$E$7,Journals!$D$9:$D$1011204,"<"&$E$8,Journals!$J$9:$J$1011204,"accrued custodian fee")) -> 0 | I12: =MAX(0,SUMIFS(Journals!$L$9:$L$1011204,Journals!$D$9:$D$1011204,">"&$E$7,Journals!$D$9:$D$1011204,"<"&$E$8,Journals!$J$9:$J$1011204,"accrued custodian fee")-SUMIFS(Journals!$K$9:$K$1011204,Journals!$D$9:$D$1011204,">"&$E$7,Journals!$D$9:$D$1011204,"<"&$E$8,Journals!$J$9:$J$1011204,"accrued custodian fee")) -> 0 | K12: =SUMIFS(Journals!$L$9:$L$1011204,Journals!$D$9:$D$1011204,"<"&$F$7,Journals!$J$9:$J$1011204,"Accrued Custodian Fee")-SUMIFS(Journals!$K$9:$K$1011204,Journals!$D$9:$D$1011204,"<"&$F$7,Journals!$J$9:$J$1011204,"Accrued Custodian Fee") -> 0 | M12: =K12+I12-H12 -> 0
G13: ='Chart of Accounts'!B9 -> Accrued BSEC fee | H13: =MAX(0,SUMIFS(Journals!$K$9:$K$1011204,Journals!$D$9:$D$1011204,">"&$E$7,Journals!$D$9:$D$1011204,"<"&$E$8,Journals!$J$9:$J$1011204,"accrued bsec fee")-SUMIFS(Journals!$L$9:$L$1011204,Journals!$D$9:$D$1011204,">"&$E$7,Journals!$D$9:$D$1011204,"<"&$E$8,Journals!$J$9:$J$1011204,"accrued bsec fee")) -> 0 | I13: =MAX(0,SUMIFS(Journals!$L$9:$L$1011204,Journals!$D$9:$D$1011204,">"&$E$7,Journals!$D$9:$D$1011204,"<"&$E$8,Journals!$J$9:$J$1011204,"accrued bsec fee")-SUMIFS(Journals!$K$9:$K$1011204,Journals!$D$9:$D$1011204,">"&$E$7,Journals!$D$9:$D$1011204,"<"&$E$8,Journals!$J$9:$J$1011204,"accrued bsec fee")) -> 0 | K13: =SUMIFS(Journals!$L$9:$L$1011204,Journals!$D$9:$D$1011204,"<"&$F$7,Journals!$J$9:$J$1011204,"accrued bsec fee")-SUMIFS(Journals!$K$9:$K$1011204,Journals!$D$9:$D$1011204,"<"&$F$7,Journals!$J$9:$J$1011204,"accrued bsec fee") -> 0 | M13: =K13+I13-H13 -> 0
G14: ='Chart of Accounts'!B10 -> Accrued Audit Fee | H14: =MAX(0,SUMIFS(Journals!$K$9:$K$1011204,Journals!$D$9:$D$1011204,">"&$E$7,Journals!$D$9:$D$1011204,"<"&$E$8,Journals!$J$9:$J$1011204,"accrued audit fee")-SUMIFS(Journals!$L$9:$L$1011204,Journals!$D$9:$D$1011204,">"&$E$7,Journals!$D$9:$D$1011204,"<"&$E$8,Journals!$J$9:$J$1011204,"accrued audit fee")) -> 0 | I14: =MAX(0,SUMIFS(Journals!$L$9:$L$1011204,Journals!$D$9:$D$1011204,">"&$E$7,Journals!$D$9:$D$1011204,"<"&$E$8,Journals!$J$9:$J$1011204,"accrued audit fee")-SUMIFS(Journals!$K$9:$K$1011204,Journals!$D$9:$D$1011204,">"&$E$7,Journals!$D$9:$D$1011204,"<"&$E$8,Journals!$J$9:$J$1011204,"accrued audit fee")) -> 0 | K14: =SUMIFS(Journals!$L$9:$L$1011204,Journals!$D$9:$D$1011204,"<"&$F$7,Journals!$J$9:$J$1011204,"accrued audit fee")-SUMIFS(Journals!$K$9:$K$1011204,Journals!$D$9:$D$1011204,"<"&$F$7,Journals!$J$9:$J$1011204,"accrued audit fee") -> 45999.997 | M14: =K14+I14-H14 -> 45999.997
G15: ='Chart of Accounts'!B11 -> Accrued CDBL Fee | H15: =MAX(0,SUMIFS(Journals!$K$9:$K$1011204,Journals!$D$9:$D$1011204,">"&$E$7,Journals!$D$9:$D$1011204,"<"&$E$8,Journals!$J$9:$J$1011204,"accrued CDBL fee")-SUMIFS(Journals!$L$9:$L$1011204,Journals!$D$9:$D$1011204,">"&$E$7,Journals!$D$9:$D$1011204,"<"&$E$8,Journals!$J$9:$J$1011204,"accrued CDBL fee")) -> 0 | I15: =MAX(0,SUMIFS(Journals!$L$9:$L$1011204,Journals!$D$9:$D$1011204,">"&$E$7,Journals!$D$9:$D$1011204,"<"&$E$8,Journals!$J$9:$J$1011204,"accrued CDBL fee")-SUMIFS(Journals!$K$9:$K$1011204,Journals!$D$9:$D$1011204,">"&$E$7,Journals!$D$9:$D$1011204,"<"&$E$8,Journals!$J$9:$J$1011204,"accrued CDBL fee")) -> 0 | K15: =SUMIFS(Journals!$L$9:$L$1011204,Journals!$D$9:$D$1011204,"<"&$F$7,Journals!$J$9:$J$1011204,"accrued cdbl fee")-SUMIFS(Journals!$K$9:$K$1011204,Journals!$D$9:$D$1011204,"<"&$F$7,Journals!$J$9:$J$1011204,"accrued cdbl fee") -> 0 | M15: =K15+I15-H15 -> 0
G16: ='Chart of Accounts'!B12 -> Fixed Deposit Receipts (FDR) | H16: =MAX(0,SUMIFS(Journals!$K$9:$K$1011204,Journals!$D$9:$D$1011204,">"&$E$7,Journals!$D$9:$D$1011204,"<"&$E$8,Journals!$J$9:$J$1011204,"Fixed Deposit Receipts (FDR)")-SUMIFS(Journals!$L$9:$L$1011204,Journals!$D$9:$D$1011204,">"&$E$7,Journals!$D$9:$D$1011204,"<"&$E$8,Journals!$J$9:$J$1011204,"Fixed Deposit Receipts (FDR)")) -> 0 | I16: =MAX(0,SUMIFS(Journals!$L$9:$L$1011204,Journals!$D$9:$D$1011204,">"&$E$7,Journals!$D$9:$D$1011204,"<"&$E$8,Journals!$J$9:$J$1011204,"Fixed Deposit Receipts (FDR)")-SUMIFS(Journals!$K$9:$K$1011204,Journals!$D$9:$D$1011204,">"&$E$7,Journals!$D$9:$D$1011204,"<"&$E$8,Journals!$J$9:$J$1011204,"Fixed Deposit Receipts (FDR)")) -> 0 | J16: =SUMIFS(Journals!$K$9:$K$1011204,Journals!$D$9:$D$1011204,"<"&$F$7,Journals!$J$9:$J$1011204,"Fixed Deposit Receipts (FDR)")-SUMIFS(Journals!$L$9:$L$1011204,Journals!$D$9:$D$1011204,"<"&$F$7,Journals!$J$9:$J$1011204,"Fixed Deposit Receipts (FDR)") -> 6000000 | L16: =J16+H16-I16 -> 6000000
G17: ='Chart of Accounts'!B13 -> Cash and cash equivalents | H17: =MAX(0,SUMIFS(Journals!$K$9:$K$1011204,Journals!$D$9:$D$1011204,">"&$E$7,Journals!$D$9:$D$1011204,"<"&$E$8,Journals!$J$9:$J$1011204,"Cash and cash equivalents")-SUMIFS(Journals!$L$9:$L$1011204,Journals!$D$9:$D$1011204,">"&$E$7,Journals!$D$9:$D$1011204,"<"&$E$8,Journals!$J$9:$J$1011204,"Cash and cash equivalents")) -> 0 | I17: =MAX(0,SUMIFS(Journals!$L$9:$L$1011204,Journals!$D$9:$D$1011204,">"&$E$7,Journals!$D$9:$D$1011204,"<"&$E$8,Journals!$J$9:$J$1011204,"Cash and cash equivalents")-SUMIFS(Journals!$K$9:$K$1011204,Journals!$D$9:$D$1011204,">"&$E$7,Journals!$D$9:$D$1011204,"<"&$E$8,Journals!$J$9:$J$1011204,"Cash and cash equivalents")) -> 21065069 | J17: =SUMIFS(Journals!$K$9:$K$1011204,Journals!$D$9:$D$1011204,"<"&$F$7,Journals!$J$9:$J$1011204,"Cash and cash equivalents")-SUMIFS(Journals!$L$9:$L$1011204,Journals!$D$9:$D$1011204,"<"&$F$7,Journals!$J$9:$J$1011204,"Cash and cash equivalents") -> 22849633 | L17: =J17+H17-I17 -> 1784563.8
G18: ='Chart of Accounts'!B14 -> Unit Capital | H18: =MAX(0,SUMIFS(Journals!$K$9:$K$1011204,Journals!$D$9:$D$1011204,">"&$E$7,Journals!$D$9:$D$1011204,"<"&$E$8,Journals!$J$9:$J$1011204,"unit capital")) -> 34224720 | I18: =MAX(0,SUMIFS(Journals!$L$9:$L$1011204,Journals!$D$9:$D$1011204,">"&$E$7,Journals!$D$9:$D$1011204,"<"&$E$8,Journals!$J$9:$J$1011204,"unit capital")) -> 82095460 | K18: =SUMIFS(Journals!$L$9:$L$1011204,Journals!$D$9:$D$1011204,"<"&$F$7,Journals!$J$9:$J$1011204,"unit capital")-SUMIFS(Journals!$K$9:$K$1011204,Journals!$D$9:$D$1011204,"<"&$F$7,Journals!$J$9:$J$1011204,"unit capital") -> 108240270 | M18: =K18+I18-H18 -> 156111010
